File: ball-data/compression/wilson regular duty.is_comp_RawData/Specimen_RawData_1.csv
Time,Extension,Load
(sec),(mm),(N)
0.00000,0.00006,-0.17509
1.12200,-9.53666,-125.75610
1.92400,-16.35392,-277.39074
2.64800,-22.50806,-429.69950
3.23400,-24.99500,-461.13797
3.59200,-21.07634,-305.67549
4.30000,-14.29854,-152.98883
5.47000,-4.35238,-19.14240
6.48400,-3.32448,-13.83712
7.46600,-12.59675,-165.77067
8.23600,-19.14155,-318.21072
8.89400,-24.73491,-471.06799
9.32200,-23.93230,-402.92174
9.74600,-19.11405,-248.69144
10.67800,-10.94794,-97.04676
11.87800,-0.74827,0.00707
12.89600,-7.85532,-75.32145
13.80200,-15.58868,-227.38967
14.52800,-21.76027,-380.07136
15.11600,-25.68862,-492.29000
15.45800,-22.24642,-336.89305
16.04400,-16.21366,-183.96003
17.16200,-6.69828,-41.32413
18.25200,-1.06904,0.01471
19.30600,-11.50876,-137.47280
20.11000,-18.34294,-289.91185
20.78400,-24.07227,-443.14235
21.23200,-24.54371,-426.71617
21.62200,-20.17776,-272.77820
22.44200,-12.68249,-120.54882
23.64000,-2.49854,-2.64908
24.69600,-6.30713,-48.63625
25.65800,-14.63719,-200.53532
26.40200,-20.96088,-352.95866
26.92800,-25.43206,-482.02556
27.35800,-23.01681,-361.54997
27.86200,-17.52777,-208.48939
28.92400,-8.44867,-60.85586
30.02000,0.43120,0.00829
31.12800,-10.26556,-111.71229
31.97000,-17.42499,-263.66487
32.66200,-23.30672,-416.58994
33.17400,-24.80385,-437.38730
33.55000,-20.63862,-283.70909
34.32200,-13.43081,-131.01830
35.51400,-3.29811,-6.95685
36.58600,-5.48007,-35.30013
37.56800,-14.14410,-186.78848
38.32200,-20.55354,-339.01829
38.89600,-25.43200,-478.96847
39.32600,-23.01549,-359.78261
39.83200,-17.51091,-206.68512
40.89800,-8.39779,-59.35179
41.98800,0.43282,0.01275
43.10000,-10.29982,-110.63935
43.94600,-17.49333,-262.72019
44.63600,-23.35791,-415.38905
45.14200,-24.80451,-435.69844
45.52000,-20.61692,-281.83026
46.29600,-13.37993,-129.22363
47.48800,-3.24729,-6.20901
48.55400,-5.48425,-34.46999
49.54200,-14.19504,-185.93866
50.29600,-20.60454,-338.20648
50.86400,-25.43206,-476.83828
51.29400,-23.01382,-358.47485
51.80200,-17.49118,-205.29805
52.86600,-8.39785,-58.66704
53.95600,0.43192,-0.03717
55.07400,-10.35100,-110.29394
55.92200,-17.56101,-262.49854
56.61200,-23.42619,-415.47615
57.11000,-24.80624,-434.42354
57.49600,-20.52502,-278.34987
58.28200,-13.22616,-125.96712
59.47800,-3.06045,-4.75917
60.52400,-5.50338,-34.06288
61.51600,-14.24580,-185.55639
62.27000,-20.65518,-337.88171
62.83200,-25.43206,-475.40441
63.26600,-22.97047,-356.00238
63.77600,-17.43922,-203.47634
64.84400,-8.31283,-57.14526
65.92400,0.43234,-0.03158
67.04401,-10.36780,-109.61638
67.89600,-17.61225,-262.22402
68.58400,-23.46033,-414.94366
69.08000,-24.78610,-432.46146
69.46800,-20.47904,-276.36139
70.26000,-13.14119,-124.06856
71.45600,-2.97489,-4.08858
72.49201,-5.49986,-33.49461
73.49001,-14.29699,-185.45896
74.24400,-20.70606,-337.96158
74.80000,-25.43206,-474.05031
75.23801,-22.92323,-353.60351
75.75800,-17.31277,-200.27833
76.83801,-8.09179,-54.04934
77.89201,0.43234,-0.02330
79.01601,-10.40140,-109.38209
79.86601,-17.62917,-261.41429
80.55400,-23.47725,-414.22080
81.04801,-24.78544,-431.58852
81.43601,-20.47480,-275.70814
82.22601,-13.15835,-123.85123
83.42201,-2.99187,-4.00576
84.46001,-5.50404,-33.10451
85.46001,-14.31379,-184.86783
86.21401,-20.72304,-337.33360
86.76801,-25.43212,-473.02745
87.20801,-22.90267,-352.17144
87.73801,-17.20640,-197.46896
88.82201,-7.95571,-52.05046
89.86000,0.43240,0.01677
90.98601,-10.41862,-109.01371
91.83601,-17.64597,-260.83108
92.52400,-23.49434,-413.75194
93.01801,-24.76870,-430.03779
93.40601,-20.45722,-274.70436
94.21001,-13.02239,-121.30477
95.40801,-2.83916,-3.05220
96.43001,-5.52832,-33.03345
97.43001,-14.33077,-184.39472
98.18601,-20.75712,-337.28585
98.73601,-25.43212,-472.11159
99.17600,-22.90763,-351.78937
99.70600,-17.20664,-197.07941
100.78800,-7.97257,-52.00502
101.82800,0.43341,-0.01439
102.95600,-10.43602,-108.68414
103.81001,-17.69697,-261.13903
104.49801,-23.54487,-414.34739
104.98601,-24.76624,-429.27198
105.37401,-20.45214,-274.21389
106.17600,-13.03931,-121.24337
107.37200,-2.87318,-3.08972
108.39800,-5.52778,-32.64767
109.40401,-14.38171,-184.71660
110.15601,-20.77416,-336.89216
110.70400,-25.43206,-471.28450
111.14401,-22.90649,-351.30966
111.67001,-17.24329,-197.42817
112.75601,-7.97257,-51.73159
113.79601,0.43353,-0.01682
114.92400,-10.43596,-108.20706
115.78001,-17.71413,-260.73890
116.46600,-23.54475,-413.51959
116.95400,-24.76870,-428.79883
117.34200,-20.45345,-273.83832
118.14401,-13.03931,-120.97230
119.34001,-2.87318,-3.00686
120.36601,-5.52790,-32.39338
121.37201,-14.38171,-184.10282
122.12601,-20.79114,-336.57417
122.67201,-25.43206,-470.53777
123.11201,-22.90219,-350.64448
123.64201,-17.20682,-196.38911
124.72601,-7.95571,-51.29560
125.76401,0.43270,-0.03397
126.89401,-10.45312,-108.01605
127.74801,-17.71413,-260.11432
128.43601,-23.56173,-413.28803
128.92202,-24.77103,-428.42358
129.31002,-20.45829,-273.55215
130.11402,-13.02239,-120.39225
131.31202,-2.83916,-2.77628
132.33400,-5.52796,-32.10833
133.34202,-14.39863,-183.90534
134.09402,-20.79114,-335.90648
134.64000,-25.43212,-469.87582
135.08000,-22.90536,-350.41913
135.61000,-17.20598,-196.09705
136.69802,-7.92229,-50.70331
137.73202,0.43294,0.02132
138.86402,-10.47022,-107.87729
139.71800,-17.73112,-259.88301
140.40600,-23.57901,-413.14177
140.89000,-24.76882,-427.81118
141.27800,-20.45441,-273.15322
142.08200,-13.02239,-120.11288
143.27800,-2.85620,-2.78074
144.30200,-5.52796,-31.86068
145.31202,-14.41567,-183.73083
146.06602,-20.82510,-336.24083
146.60800,-25.43212,-469.25012
147.04800,-22.90751,-350.06419
147.57800,-17.20527,-195.75395
148.66600,-7.92235,-50.50992
149.70002,0.43300,-0.05989
150.83400,-10.48690,-107.76292
151.68800,-17.74815,-259.73504
152.37600,-23.59622,-413.00829
152.86000,-24.74915,-426.32155
153.24800,-20.42882,-272.11243
154.05400,-12.98843,-119.37461
155.25202,-2.80514,-2.46584
156.27000,-5.53256,-31.71258
157.28402,-14.44999,-183.95422
158.03802,-20.85888,-336.56958
158.57600,-25.43212,-468.66789
159.01800,-22.88132,-348.82288
159.55000,-17.16957,-194.74285
160.63800,-7.88785,-49.95922
161.66802,0.43401,0.02551
162.80200,-10.48696,-107.46260
163.65600,-17.74815,-259.22641
164.34602,-23.61333,-413.03024
164.82800,-24.75202,-426.07419
165.21600,-20.42977,-271.93718
166.02200,-12.98843,-119.12270
167.22000,-2.80520,-2.47083
168.23800,-5.53256,-31.52808
169.25202,-14.44993,-183.50538
170.00402,-20.84214,-335.73382
170.54400,-25.43212,-468.12322
170.98600,-22.88204,-348.53384
171.51800,-17.17184,-194.58102
172.60600,-7.88785,-49.78875
173.63600,0.43413,-0.02127
174.77600,-10.53820,-107.97744
175.63000,-17.79916,-259.98984
176.31602,-23.63013,-412.99611
176.79600,-24.75070,-425.65104
177.18400,-20.43007,-271.65450
177.99000,-12.98843,-118.93836
179.18800,-2.80514,-2.38175
180.20602,-5.52874,-31.33000
181.22000,-14.44993,-183.13140
181.97402,-20.85888,-335.64530
182.51202,-25.43212,-467.63886
182.95202,-22.90452,-349.01068
183.48202,-17.20742,-195.07799
184.57000,-7.92235,-50.09676
185.60400,0.43371,0.03778
186.74200,-10.52116,-107.36231
187.59602,-17.78235,-259.08180
188.28002,-23.59622,-411.53938
188.76400,-24.75064,-425.28734
189.15202,-20.42804,-271.38144
189.95800,-12.98843,-118.75582
191.15600,-2.80520,-2.28659
192.17602,-5.55528,-31.46943
193.19202,-14.48407,-183.47304
193.94202,-20.85888,-335.31178
194.48002,-25.43212,-467.30850
194.92202,-22.88300,-348.04326
195.45202,-17.18697,-194.46373
196.54200,-7.88785,-49.53922
197.57200,0.43347,-0.01098
198.71200,-10.53826,-107.33417
199.57000,-17.83306,-259.91311
200.25602,-23.66385,-413.11722
200.73202,-24.75268,-425.05480
201.12002,-20.42691,-271.12843
201.92802,-12.97163,-118.33646
203.12600,-2.78810,-2.17028
204.14402,-5.55642,-31.32206
205.16000,-14.48407,-183.06162
205.91200,-20.87574,-335.27758
206.44802,-25.43212,-466.79594
206.89002,-22.88330,-347.82596
207.42002,-17.18990,-194.30202
208.51002,-7.88785,-49.36350
209.54002,0.43443,0.01029
210.68002,-10.53820,-107.12108
211.53402,-17.79921,-258.69178
212.22002,-23.63013,-411.73220
212.70002,-24.75166,-424.71159
213.08802,-20.42637,-270.93211
213.89402,-12.98843,-118.39340
215.09202,-2.80520,-2.30057
216.11202,-5.55235,-31.14773
217.12800,-14.48407,-182.76213
217.88000,-20.87574,-334.94983
218.41602,-25.43212,-466.37125
218.85802,-22.88461,-347.56701
219.39002,-17.17190,-193.75235
220.47802,-7.88785,-49.23035
221.50802,0.43485,-0.00294
222.64802,-10.53814,-106.89414
223.50602,-17.83311,-259.12700
224.19002,-23.64687,-411.80767
224.66802,-24.75231,-424.46014
225.05802,-20.40562,-270.14351
225.86602,-12.95453,-117.71230
227.06402,-2.77106,-2.05544
228.08002,-5.55235,-31.00960
229.10000,-14.51827,-183.14190
229.85200,-20.91000,-335.45829
230.38402,-25.43212,-465.91464
230.82600,-22.88407,-347.31712
231.35602,-17.18990,-193.93634
232.44602,-7.88785,-49.15647
233.47602,0.43497,0.04505
234.61802,-10.55512,-106.92162
235.47402,-17.83311,-258.79484
236.16000,-23.66385,-411.97423
236.63602,-24.75154,-424.09249
237.02602,-20.40269,-269.87486
237.83402,-12.95453,-117.57608
239.03202,-2.77106,-2.00614
240.04800,-5.55612,-30.81818
241.06202,-14.46709,-181.73892
241.81602,-20.87574,-334.21211
242.35200,-25.43212,-465.58958
242.79400,-22.88443,-347.07632
243.32600,-17.16963,-193.31418
244.41602,-7.87081,-48.80978
245.44402,0.43377,0.03400
246.58602,-10.55518,-106.71899
247.44602,-17.86690,-259.23746
248.13000,-23.68113,-412.09977
248.60402,-24.75393,-423.94031
248.99200,-20.43049,-270.44879
249.80202,-12.95453,-117.44116
251.00002,-2.77106,-1.92235
252.01600,-5.55588,-30.76047
253.03602,-14.51827,-182.55033
253.78802,-20.90994,-334.83140
254.32000,-25.43218,-465.29599
254.76202,-22.88461,-346.92846
255.29400,-17.16951,-193.19382
256.38400,-7.87081,-48.73986
257.41202,0.43419,0.01012
258.55402,-10.55524,-106.46531
259.41202,-17.85004,-258.56189
260.09602,-23.66379,-411.26948
260.57202,-24.75363,-423.65890
260.96200,-20.40514,-269.61723
261.77200,-12.93755,-116.97905
262.97000,-2.75402,-1.88893
263.98400,-5.55247,-30.61541
265.00600,-14.53543,-182.64757
265.75803,-20.92686,-334.91805
266.28803,-25.43212,-464.83979
266.73000,-22.88527,-346.72715
267.26203,-17.16951,-193.05103
268.35203,-7.87081,-48.63005
269.38000,0.43509,0.01368
270.52200,-10.55524,-106.27824
271.38203,-17.86690,-258.65247
272.06803,-23.69817,-411.90524
272.54000,-24.75512,-423.38159
272.93003,-20.40436,-269.41767
273.73800,-12.95453,-117.12786
274.93600,-2.77112,-1.90321
275.95203,-5.55217,-30.47437
276.97400,-14.53543,-182.37308
277.72600,-20.92686,-334.65303
278.25600,-25.43218,-464.60867
278.69800,-22.88545,-346.54301
279.22803,-17.18996,-193.30610
280.31803,-7.88791,-48.70867
281.34803,0.43467,0.00581
282.49200,-10.57204,-106.38430
283.35400,-17.90074,-259.12795
284.03600,-23.69823,-411.62688
284.50803,-24.75501,-423.20956
284.89603,-20.42804,-269.92125
285.70203,-12.98843,-117.52225
286.90003,-2.80526,-2.01940
287.92000,-5.55684,-30.44138
288.94400,-14.55258,-182.52868
289.69600,-20.94390,-334.81281
290.22400,-25.43218,-464.35878
290.66600,-22.88587,-346.40953
291.19803,-17.16951,-192.79037
292.28803,-7.87081,-48.48212
293.31600,0.43443,-0.01254
294.46003,-10.57216,-106.20453
295.32000,-17.88382,-258.48340
296.00403,-23.69823,-411.34004
296.47600,-24.75483,-423.02694
296.86400,-20.42625,-269.75129
297.67203,-12.97157,-117.17441
298.87003,-2.78816,-1.90158
299.88800,-5.55379,-30.33481
300.91400,-14.56974,-182.61719
301.66600,-20.96088,-335.05283
302.19203,-25.43218,-464.07927
302.63400,-22.88521,-346.18843
303.16600,-17.17035,-192.63901
304.25600,-7.87081,-48.35001
305.28403,0.43467,0.05157
306.42603,-10.55500,-105.74048
307.28600,-17.86690,-257.83353
307.97000,-23.68113,-410.55236
308.44400,-24.75501,-422.81985
308.83400,-20.40514,-269.01137
309.64400,-12.93761,-116.52236
310.84200,-2.75408,-1.72487
311.85603,-5.55743,-30.21293
312.88000,-14.55258,-182.03078
313.63203,-20.94396,-334.36116
314.16000,-25.43218,-463.74314
314.60203,-22.88838,-346.11102
315.13400,-17.17137,-192.55908
316.22403,-7.87081,-48.28824
317.25200,0.43509,0.01574
318.39800,-10.58920,-106.12669
319.25600,-17.88388,-258.02381
319.94000,-23.69823,-410.86450
320.41203,-24.75602,-422.65683
320.80003,-20.42708,-269.50378
321.60800,-12.97157,-116.99002
322.80603,-2.78816,-1.86486
323.82400,-5.55743,-30.17153
324.84803,-14.55265,-181.80745
325.60203,-20.96094,-334.52123
326.12803,-25.43218,-463.50174
326.57000,-22.88324,-345.86441
327.10000,-17.18679,-192.73629
328.19203,-7.87087,-48.22820
329.22000,0.43521,0.02321
330.36400,-10.57192,-105.66524
331.22600,-17.90080,-258.20667
331.91203,-23.73201,-411.58188
332.38000,-24.75596,-422.50685
332.77003,-20.39964,-268.62292
333.58200,-12.92045,-116.09037
334.78003,-2.73716,-1.61140
335.79203,-5.55839,-30.11603
336.81600,-14.55258,-181.62739
337.56803,-20.94390,-333.87415
338.09600,-25.43218,-463.23080
338.53803,-22.88419,-345.68936
339.07203,-17.15385,-191.99034
340.16203,-7.85401,-47.93025
341.18803,0.43509,0.02313
342.33400,-10.58914,-105.84016
343.19403,-17.90074,-258.01923
343.87803,-23.71515,-410.79208
344.34803,-24.75674,-422.26110
344.73800,-20.39898,-268.46103
345.55003,-12.92045,-115.97504
346.74803,-2.73716,-1.57979
347.76000,-5.55803,-29.99016
348.78600,-14.56974,-181.76531
349.53803,-20.96094,-334.09696
350.06403,-25.43218,-462.98292
350.50600,-22.88473,-345.53416
351.04000,-17.15349,-191.86422
352.13203,-7.83733,-47.63815
353.15600,0.43604,0.06620
354.30003,-10.57216,-105.39180
355.16000,-17.88382,-257.39037
355.84403,-23.69817,-410.04892
356.31600,-24.75758,-422.14405
356.70603,-20.39797,-268.36162
357.52003,-12.90335,-115.58738
358.71803,-2.72030,-1.54675
359.72803,-5.55869,-29.90715
360.75600,-14.58679,-181.92573
361.50803,-20.97804,-334.35084
362.08203,-25.76007,-475.56706
362.50600,-22.52259,-332.89611
363.08203,-16.50776,-178.83521
364.20203,-6.97008,-37.76518
365.22403,-0.06397,0.03883
366.35803,-11.33812,-118.59219
367.19403,-18.44518,-270.70917
367.86603,-24.15765,-423.35764
368.31003,-24.49390,-409.45206
368.71600,-19.90602,-255.27116
369.58003,-12.12113,-103.72395
370.78003,-1.92146,0.02771
371.78600,-6.48561,-42.42567
372.79203,-15.16423,-194.23380
373.53003,-21.43729,-346.32165
374.05003,-25.76007,-475.36131
374.47403,-22.52342,-332.71026
375.05003,-16.50752,-178.70177
376.17000,-6.97008,-37.69905
377.19203,-0.06350,0.05233
378.32400,-11.32102,-118.12004
379.16203,-18.44518,-270.47329
379.83400,-24.15753,-423.20471
380.27800,-24.49432,-409.29180
380.68403,-19.90632,-255.16940
381.55403,-12.07019,-102.83459
382.75403,-1.87004,0.08548
383.75600,-6.50516,-42.56298
384.76203,-15.18085,-194.44998
385.50200,-21.47107,-346.96918
386.11800,-25.72718,-473.79144
386.47600,-22.13461,-319.66638
387.09403,-15.85349,-166.05353
388.23800,-6.11999,-28.56242
389.26000,-1.05499,0.04737
390.37403,-12.01847,-130.55108
391.19003,-18.95500,-282.64267
391.85000,-24.56487,-435.23986
392.27403,-24.20375,-396.17583
392.69600,-19.39380,-242.11997
393.62200,-11.22052,-90.63695
394.82203,-1.02007,0.08943
395.82000,-7.39303,-55.01850
396.79603,-15.74228,-206.71301
397.52403,-21.93007,-359.20683
398.08603,-25.72963,-473.71499
398.44403,-22.14011,-319.79963
399.05603,-15.90407,-166.99126
400.20000,-6.17105,-29.02172
401.22803,-1.05451,0.06680
402.34803,-12.06965,-131.32071
403.16403,-19.00607,-283.69090
403.82400,-24.61617,-436.58573
404.27003,-23.90444,-383.51815
404.71003,-18.89468,-229.56125
405.68600,-10.40439,-79.35895
406.88603,-0.20424,0.07881
407.88403,-8.24025,-67.40262
408.83003,-16.30364,-219.30760
409.54603,-22.38902,-371.72623
410.09200,-25.49532,-460.61072
410.44600,-21.74903,-307.12066
411.10403,-15.21948,-154.13720
412.26800,-5.32127,-20.57266
413.29603,-2.15852,-0.05802
414.39000,-12.69929,-142.97113
415.18803,-19.48229,-295.26899
415.83800,-25.00702,-448.39151
416.27003,-23.55641,-369.57871
416.74003,-18.28214,-215.27132
417.77003,-9.41810,-66.51071
418.88000,0.01722,0.08317
419.95203,-9.06893,-80.06961
420.86603,-16.84713,-231.74619
421.57203,-22.84802,-384.46490
422.09200,-25.26005,-447.67607
422.45603,-21.30928,-293.64740
423.16403,-14.46924,-140.69801
424.34403,-4.43710,-12.55775
425.37003,-3.30283,-5.50061
426.44403,-13.36248,-155.73784
427.22600,-20.00921,-308.28467
427.86203,-25.41526,-461.10958
428.27603,-23.22165,-356.84876
428.77603,-17.72257,-203.03288
429.83800,-8.63653,-56.71949
430.85603,0.01722,0.05107
432.02003,-9.89026,-93.12335
432.90600,-17.42511,-245.16681
433.60000,-23.32388,-397.82491
434.11603,-24.76224,-421.29256
434.50600,-20.40305,-267.81410
435.31600,-12.93761,-115.57978
436.51400,-2.75414,-1.50595
437.53003,-5.57663,-29.63979
438.55603,-14.58679,-180.88711
439.31003,-20.99520,-333.57266
439.88203,-25.76013,-474.22290
440.30603,-22.52522,-332.13899
440.88203,-16.50764,-178.24339
442.00200,-6.97026,-37.36601
443.02403,-0.06051,0.02294
444.16203,-11.37226,-118.28209
445.00200,-18.51286,-271.08423
445.67400,-24.22545,-424.05944
446.13803,-24.20733,-395.69732
446.56003,-19.39966,-241.91137
447.48203,-11.25460,-90.75895
448.68200,-1.05421,0.05436
449.68603,-7.41294,-54.87004
450.66600,-15.79346,-207.13076
451.39400,-21.98101,-359.76790
451.98800,-25.49687,-460.00447
452.34403,-21.72553,-306.08052
453.00600,-15.16818,-152.99327
454.17000,-5.27033,-19.89256
455.19403,-2.13801,-0.02068
456.29403,-12.73337,-143.15908
457.09003,-19.49921,-295.16036
457.73800,-25.00702,-447.66318
458.16803,-23.57954,-369.99255
458.63803,-18.29666,-215.29917
459.66600,-9.45224,-66.71512
460.77800,0.00006,0.08571
461.85403,-9.12083,-80.47136
462.77003,-16.91523,-232.74610
463.47600,-22.91654,-385.81401
464.01400,-25.01856,-434.00928
464.39800,-20.77320,-277.81479
465.16803,-13.54998,-125.07517
466.36203,-3.40011,-4.73358
467.45400,-5.58099,-29.55148
468.48603,-14.63737,-181.54960
469.23803,-21.02952,-334.05934
469.80603,-25.76031,-473.80477
470.23803,-22.43709,-328.92227
470.82000,-16.38663,-175.68957
471.94403,-6.81702,-35.65423
472.95000,-0.03952,0.00215
474.09003,-11.37220,-118.00594
474.92603,-18.47902,-269.91690
475.59803,-24.19149,-422.67688
476.06803,-24.18581,-394.50008
476.49203,-19.34878,-240.44568
477.42603,-11.11828,-88.71553
478.62603,-0.91837,0.10889
479.61800,-7.41222,-54.67440
480.59600,-15.77648,-206.35193
481.32403,-21.96415,-358.91410
481.92000,-25.49777,-459.71937
482.27800,-21.70287,-305.14300
482.94003,-15.15102,-152.48301
484.10403,-5.25340,-19.62325
485.12603,-2.13861,0.01583
486.22803,-12.75047,-143.14190
487.02603,-19.53317,-295.59255
487.67400,-25.04128,-448.36842
488.10203,-23.56089,-369.05106
488.57203,-18.28106,-214.77016
489.60003,-9.43532,-66.35783
490.71203,0.01722,0.07088
491.78600,-9.08621,-79.72619
492.70400,-16.89813,-231.98331
493.40803,-22.88222,-384.35869
493.95000,-25.01945,-433.69517
494.33400,-20.77386,-277.65822
495.10403,-13.55003,-124.90491
496.29803,-3.40005,-4.63799
497.30203,-4.48786,-16.48751
498.35403,-14.02506,-168.37828
499.12003,-20.53668,-320.87307
499.69600,-25.43224,-460.51167
500.14400,-22.82423,-341.96045
500.68603,-17.03062,-188.23391
501.78803,-7.63315,-44.57213
502.89000,-0.03833,0.04471
504.03200,-11.38912,-118.05081
504.87003,-18.51286,-270.38885
505.54203,-24.22539,-423.34899
506.00803,-24.18838,-394.26304
506.43603,-19.30268,-239.05808
507.37003,-11.08450,-88.12051
508.57003,-0.88441,0.07581
509.55800,-7.41145,-54.47895
510.53803,-15.79358,-206.45643
511.26603,-21.98107,-358.95046
511.86003,-25.49927,-459.49660
512.22003,-21.68099,-304.23798
512.88800,-15.08376,-151.11609
514.05403,-5.16850,-18.74317
515.06603,-2.13700,-0.06127
516.16803,-12.75047,-142.88984
516.96600,-19.53323,-295.22860
517.61200,-25.02424,-447.43575
518.04206,-23.56244,-368.82356
518.51203,-18.28064,-214.58045
519.54206,-9.41816,-66.03281
520.65203,0.01716,0.08277
521.72803,-9.10355,-79.78443
522.64403,-16.89807,-231.65369
523.35206,-22.91654,-384.92400
523.89000,-25.02089,-433.40284
524.27203,-20.79927,-278.13951
525.04006,-13.58411,-125.25802
526.23400,-3.43407,-4.81810
527.24200,-4.48971,-16.40110
528.29400,-14.02512,-168.13107
529.06200,-20.55372,-320.92579
529.63606,-25.43230,-460.06795
530.08406,-22.82357,-341.66571
530.62400,-17.04874,-188.37158
531.72206,-7.68409,-45.05249
532.73006,0.45518,0.07297
533.88406,-10.64038,-104.82416
534.74806,-17.98600,-257.28455
535.43400,-23.81721,-410.76481
535.92006,-24.48237,-406.89323
536.33200,-19.81627,-251.69279
537.21406,-11.90050,-99.49285
538.41400,-1.70005,0.08290
539.39800,-6.48662,-41.40459
540.41006,-15.21541,-193.35622
541.15000,-21.50491,-345.79910
541.76200,-25.73149,-471.84933
542.12606,-22.07369,-316.45406
542.75000,-15.75017,-163.14358
543.89600,-6.00101,-26.80738
544.90600,-1.02694,0.04809
546.03000,-12.08669,-130.22300
546.84800,-19.04033,-282.74601
547.50800,-24.65055,-435.48953
547.95200,-23.89111,-381.47941
548.39800,-18.81187,-226.65465
549.38406,-10.25121,-76.63560
550.58406,-0.05112,0.02777
551.57200,-8.27481,-66.89801
552.52206,-16.37072,-219.10883
553.23806,-22.45694,-371.64792
553.80400,-25.26519,-446.23867
554.17600,-21.21792,-289.96494
554.89200,-14.33256,-137.64672
556.07406,-4.28398,-10.97439
557.08200,-3.30044,-5.11577
558.16206,-13.41354,-155.40608
558.94400,-20.05980,-307.95733
559.57406,-25.41532,-459.18982
559.99200,-23.18481,-354.32197
560.49606,-17.65309,-200.69411
561.56606,-8.50003,-54.52174
562.57000,0.03402,0.05643
563.73600,-9.89044,-92.05836
564.62806,-17.47635,-244.80285
565.32200,-23.37512,-397.55363
565.83200,-24.76774,-420.02715
566.23006,-20.30703,-264.37612
567.05006,-12.78437,-112.47877
568.25000,-2.58410,-0.87366
569.24806,-5.56007,-28.86188
570.28400,-14.65435,-180.88348
571.03800,-21.06372,-333.69370
571.60206,-25.76055,-472.44318
572.03000,-22.48384,-329.68298
572.60806,-16.45598,-176.40611
573.73206,-6.88524,-36.03597
574.74606,-0.03510,0.10318
575.88800,-11.38918,-117.43259
576.72400,-18.49594,-269.18359
577.39606,-24.20859,-421.81399
577.86400,-24.19071,-393.69680
578.29006,-19.32343,-239.15626
579.22400,-11.10142,-88.00063
580.42400,-0.90145,0.07383
581.41400,-7.41210,-54.05432
582.39406,-15.79358,-205.69531
583.12200,-21.98113,-358.15272
583.71600,-25.49909,-458.56006
584.08000,-21.63118,-302.15697
584.75200,-15.01464,-149.47642
585.92206,-5.06638,-17.56527
587.02206,-3.29912,-5.02016
588.10206,-13.41354,-155.11652
588.88606,-20.07684,-308.09980
589.51406,-25.41532,-458.84117
589.93200,-23.18505,-354.14342
590.43606,-17.65363,-200.55074
591.50606,-8.49991,-54.39099
592.51000,0.03402,0.08223
593.67600,-9.89068,-91.91982
594.57000,-17.49351,-244.90729
595.26406,-23.39222,-397.69359
595.77206,-24.76965,-419.87661
596.17006,-20.30439,-264.09132
596.99400,-12.75029,-111.80479
598.19400,-2.54978,-0.77380
599.18806,-5.56042,-28.70756
600.22206,-14.63737,-180.23835
600.97600,-21.04662,-333.01476
601.54206,-25.76072,-472.08458
601.97400,-22.43655,-327.91995
602.55600,-16.38645,-174.92743
603.68606,-6.76584,-34.62521
604.78600,-1.02605,0.09773
605.91006,-12.08663,-129.71854
606.72800,-19.04033,-282.12992
607.38800,-24.65061,-434.83499
607.83406,-23.86964,-380.17165
608.27800,-18.80685,-226.22779
609.27000,-10.20063,-75.73314
610.47006,-0.00006,0.09299
611.45200,-8.27648,-66.50670
612.40206,-16.37078,-218.48017
613.11600,-22.44019,-370.51946
613.68400,-25.26531,-445.66743
614.05600,-21.21421,-289.50941
614.77406,-14.31564,-136.98759
615.96000,-4.23340,-10.34382
617.06200,-4.48798,-16.06614
618.11806,-14.05944,-167.91917
618.88406,-20.57070,-320.34989
619.45606,-25.43236,-459.09919
619.90406,-22.82500,-341.08482
620.44606,-17.02972,-187.52754
621.54806,-7.63321,-44.15586
622.65000,-0.03360,0.05059
623.79400,-11.40604,-117.41465
624.63406,-18.54688,-269.94333
625.30600,-24.25959,-422.87789
625.76800,-24.19071,-393.32598
626.19606,-19.30137,-238.40379
627.13606,-11.03373,-86.86702
628.33606,-0.83329,0.09183
629.41600,-8.27517,-66.43310
630.36806,-16.38758,-218.70160
631.08406,-22.47404,-371.34599
631.64800,-25.26626,-445.56126
632.02000,-21.21816,-289.56810
632.73806,-14.31582,-136.96618
633.92206,-4.25014,-10.48004
634.92600,-3.29560,-4.83037
636.00806,-13.43058,-155.02022
636.79006,-20.07690,-307.63628
637.41800,-25.41538,-458.33614
637.83606,-23.18733,-353.92527
638.34206,-17.63426,-199.91795
639.41006,-8.50003,-54.20979
640.41400,0.03396,0.09313
641.58000,-9.89062,-91.59530
642.47006,-17.45913,-243.60601
643.16400,-23.35826,-396.26606
643.67600,-24.77109,-419.51977
644.07406,-20.30715,-263.91709
644.89406,-12.78437,-112.15726
646.09406,-2.58416,-0.81461
647.09206,-5.56036,-28.50027
648.13000,-14.67133,-180.51289
648.88606,-21.09756,-333.92701
649.44606,-25.76084,-471.53946
649.87806,-22.44014,-327.75480
650.45800,-16.40445,-175.02850
651.58406,-6.81714,-35.06192
652.59000,-0.03348,0.02246
653.73206,-11.38924,-116.85515
654.57200,-18.52990,-269.19417
655.24400,-24.24261,-422.07889
655.70800,-24.19502,-393.25655
656.13606,-19.30173,-238.25876
657.07406,-11.05065,-86.97127
658.27406,-0.85039,0.11315
659.25806,-7.41222,-53.67499
660.24400,-15.84452,-206.03945
660.97206,-22.03201,-358.82983
661.56006,-25.50333,-458.04001
661.92400,-21.63280,-301.85634
662.59406,-15.03162,-149.37242
663.76200,-5.10058,-17.69035
664.76606,-2.13299,0.05771
665.87200,-12.78395,-142.25816
666.67206,-19.58411,-294.99793
667.31806,-25.07506,-447.30496
667.74400,-23.54247,-366.94333
668.21600,-18.24010,-212.90204
669.25200,-9.33332,-64.35097
670.35400,0.03396,0.09876
671.52206,-9.90760,-91.61621
672.41206,-17.47635,-243.72067
673.10600,-23.37518,-396.46562
673.61600,-24.77139,-419.32981
674.01406,-20.30278,-263.66830
674.83800,-12.75029,-111.47554
676.03800,-2.54978,-0.70809
677.03206,-5.56096,-28.45820
678.06806,-14.65435,-179.93046
678.82200,-21.06372,-332.70422
679.38606,-25.76090,-471.21834
679.81806,-22.43870,-327.53885
680.40206,-16.36893,-174.19472
681.53000,-6.76590,-34.36603
682.63000,-1.02366,0.07193
683.75606,-12.10379,-129.44238
684.57406,-19.05737,-281.86521
685.23400,-24.66789,-434.51916
685.67806,-23.87263,-379.67715
686.12400,-18.79166,-225.43747
687.11400,-10.20069,-75.42553
688.31400,-0.00012,0.07503
689.29806,-8.29221,-66.38358
690.25200,-16.42220,-218.98525
690.96600,-22.49131,-371.25438
691.52800,-25.26967,-445.19413
691.90000,-21.21433,-289.12084
692.62006,-14.29890,-136.41677
693.80400,-4.23340,-10.18212
694.90600,-4.49157,-15.82445
695.96206,-14.05944,-167.28828
696.73006,-20.58774,-320.18587
697.30006,-25.43242,-458.28875
697.74806,-22.82584,-340.63820
698.28800,-17.04844,-187.52512
699.38606,-7.68415,-44.51304
700.39406,0.45745,0.03340
701.55206,-10.67470,-104.25002
702.41600,-18.02044,-256.48875
703.09800,-23.81733,-409.10292
703.58406,-24.48876,-405.85060
703.99606,-19.80695,-250.59750
704.88406,-11.84938,-98.00177
706.08406,-1.64929,0.05095
707.16206,-7.41181,-53.47653
708.14606,-15.82760,-205.28492
708.87400,-22.01509,-357.93155
709.46406,-25.50465,-457.65076
709.82806,-21.65187,-302.11078
710.49806,-15.03192,-149.20918
711.66406,-5.11756,-17.77856
712.67006,-2.13162,0.04674
713.77800,-12.80093,-142.23249
714.57606,-19.58411,-294.63178
715.22406,-25.09198,-447.35137
715.64800,-23.54624,-366.75394
716.12006,-18.24423,-212.75803
717.15600,-9.33332,-64.16318
718.25806,0.03396,0.08545
719.42600,-9.90772,-91.36033
720.31806,-17.49357,-243.73613
721.01000,-23.37512,-396.07190
721.52000,-24.77163,-418.95796
721.91800,-20.30236,-263.42448
722.74200,-12.75029,-111.31041
723.94200,-2.54978,-0.65370
724.93606,-5.56072,-28.25783
725.97406,-14.67133,-179.90313
726.72800,-21.08064,-332.84567
727.29006,-25.76108,-470.76155
727.72206,-22.43942,-327.30296
728.30206,-16.40373,-174.63163
729.42600,-6.83424,-35.03726
730.43400,-0.02900,0.06932
731.57606,-11.38924,-116.41855
732.41600,-18.52996,-268.58576
733.08800,-24.24261,-421.37619
733.55206,-24.19663,-392.79319
733.98006,-19.29539,-237.72568
734.92006,-11.03379,-86.43300
736.12006,-0.83329,0.10002
737.20000,-8.27535,-65.93294
738.15206,-16.38765,-217.77146
738.86600,-22.45700,-369.91905
739.43200,-25.27224,-444.93504
739.80400,-21.21326,-288.87428
740.52606,-14.28204,-135.98973
741.70800,-4.23340,-10.12739
742.81006,-4.49282,-15.74343
743.87006,-14.09304,-167.63328
744.63806,-20.62170,-320.65433
745.20406,-25.43236,-457.78017
745.65206,-22.82721,-340.39825
746.19606,-17.01364,-186.66083
747.30206,-7.58244,-43.15031
748.39800,-0.02995,0.09202
749.54206,-11.40604,-116.52837
750.38406,-18.56398,-269.25245
751.05400,-24.25959,-421.76280
751.51606,-24.19675,-392.67618
751.94400,-19.29341,-237.48444
752.88606,-11.01681,-86.14932
754.08606,-0.81607,0.03932
755.17006,-8.32605,-66.57758
756.12400,-16.45640,-219.19956
756.83800,-22.52540,-371.68145
757.39606,-25.27201,-444.74099
757.76806,-21.21230,-288.81924
758.49006,-14.28210,-135.84937
759.67400,-4.21642,-9.96402
760.77406,-4.49396,-15.67294
761.83406,-14.09304,-167.51515
762.60006,-20.60478,-320.11744
763.16800,-25.43236,-457.66935
763.61600,-22.82853,-340.40298
764.16006,-17.01352,-186.53482
765.26200,-7.61629,-43.53962
766.36206,-0.02989,0.04302
767.50806,-11.42314,-116.72074
768.34600,-18.54688,-268.68692
769.01806,-24.25965,-421.57207
769.48006,-24.19645,-392.56372
769.90606,-19.31123,-237.90229
770.84000,-11.10142,-87.27300
772.04006,-0.90151,0.14939
773.03406,-7.44792,-53.69103
774.01806,-15.86156,-205.57672
774.74606,-22.04923,-358.36216
775.33200,-25.50800,-457.23863
775.69606,-21.62891,-301.19060
776.37200,-14.98104,-148.05246
777.54206,-5.03284,-16.85406
778.63806,-3.30170,-4.66340
779.72406,-13.46448,-154.70157
780.50606,-20.11128,-307.34252
781.13006,-25.41544,-456.94314
781.54806,-23.18756,-353.01536
782.05600,-17.61494,-198.88755
783.12806,-8.44897,-53.16452
784.22600,0.45787,0.04153
785.38606,-10.69168,-104.03282
786.25006,-18.03730,-256.26058
786.93206,-23.83443,-408.81328
787.41600,-24.49421,-405.49610
787.82806,-19.80115,-250.10016
788.71800,-11.83246,-97.45978
789.91800,-1.63219,0.09908
790.99606,-7.43034,-53.39256
791.98206,-15.86156,-205.43549
792.71000,-22.04923,-358.21486
793.29600,-25.50913,-457.13805
793.66006,-21.63053,-301.11549
794.33406,-14.99802,-148.23721
795.50400,-5.04952,-16.96494
796.60206,-3.30170,-4.65607
797.69006,-13.48158,-154.91171
798.47406,-20.14535,-308.04416
799.09406,-25.41544,-456.75997
799.51000,-23.21166,-353.81198
800.01406,-17.66822,-199.93708
801.08200,-8.53382,-54.20151
802.09000,0.03390,0.05310
803.26200,-9.94162,-91.51044
804.15406,-17.52783,-243.93713
804.84600,-23.40950,-396.39071
805.35206,-24.77755,-418.70508
805.75006,-20.29345,-262.87105
806.58406,-12.66545,-109.74201
807.78406,-2.46476,-0.44237
808.86206,-6.52644,-40.79942
809.88006,-15.30013,-192.85422
810.61806,-21.57289,-345.23312
811.22206,-25.73860,-469.48899
811.58800,-22.04840,-314.13082
812.21606,-15.69815,-160.92004
813.36806,-5.89937,-25.10297
814.46606,-2.13114,0.03240
815.57806,-12.83537,-142.25797
816.37606,-19.61801,-294.70202
817.02406,-25.12624,-447.54073
817.44606,-23.52490,-365.33657
817.92206,-18.18258,-210.96058
818.96000,-9.26552,-63.05536
820.05400,0.03390,0.08070
821.22600,-9.94156,-91.39253
822.11600,-17.51073,-243.37364
822.81006,-23.40944,-396.21454
823.31806,-24.75740,-417.62117
823.71606,-20.26846,-262.17723
824.54806,-12.66545,-109.67907
825.74806,-2.46476,-0.43147
826.82606,-6.53021,-40.81788
827.84406,-15.30007,-192.69304
828.58200,-21.57289,-345.14319
829.18606,-25.73962,-469.50679
829.55006,-22.07225,-314.84660
830.17600,-15.73349,-161.55647
831.32606,-5.95007,-25.59671
832.33000,-1.01845,0.04784
833.46000,-12.13811,-129.10998
834.27800,-19.09115,-281.60114
834.93806,-24.70191,-434.29304
835.37806,-23.87616,-378.98265
835.82606,-18.76392,-224.14310
836.82406,-10.11567,-73.85735
838.01606,0.01710,0.09639
839.09606,-9.13877,-78.60136
840.02000,-17.00031,-231.25183
840.72406,-22.98476,-383.97115
841.25606,-25.01383,-430.33537
841.64200,-20.71605,-274.28836
842.42006,-13.44815,-121.76953
843.61600,-3.28143,-3.47032
844.69606,-5.56742,-28.04857
845.73806,-14.70553,-179.75211
846.49206,-21.11466,-332.87875
847.05006,-25.76150,-469.81622
847.48406,-22.41568,-325.93649
848.07200,-16.31739,-172.52214
849.20200,-6.69870,-33.22348
850.29406,-1.01768,0.09731
851.42600,-12.15533,-129.35758
852.24400,-19.10825,-281.83620
852.90406,-24.71877,-434.67913
853.34406,-23.85481,-378.03549
853.79406,-18.72350,-223.14336
854.79206,-10.08135,-73.30105
855.98006,0.01710,0.07312
857.06200,-9.15533,-78.81904
857.98406,-17.00037,-231.11200
858.68806,-22.98482,-383.86121
859.22006,-25.01413,-430.28351
859.60600,-20.71748,-274.20914
860.38200,-13.46519,-122.01376
861.57806,-3.29841,-3.56511
862.66206,-5.59391,-28.31400
863.70406,-14.72245,-180.02128
864.45606,-21.11466,-332.72300
865.01406,-25.76150,-469.60060
865.44806,-22.41652,-325.86146
866.03406,-16.33431,-172.75358
867.16406,-6.71597,-33.38589
868.25806,-1.01720,0.09768
869.39000,-12.15533,-129.26981
870.21000,-19.12523,-282.11480
870.87006,-24.73528,-435.09573
871.30806,-23.85565,-377.95004
871.75606,-18.74771,-223.63976
872.75200,-10.11567,-73.72827
873.94400,0.01704,0.09624
875.02800,-9.17273,-78.94725
875.94606,-16.98357,-230.60493
876.65000,-22.96790,-383.22374
877.18400,-25.01545,-430.14579
877.56806,-20.74068,-274.81668
878.34406,-13.48217,-122.22127
879.54006,-3.31521,-3.63058
880.62400,-5.57232,-27.95117
881.66600,-14.70547,-179.53552
882.42006,-21.11472,-332.62741
882.97800,-25.76204,-469.51186
883.41206,-22.41915,-325.85762
883.99806,-16.33401,-172.66599
885.12806,-6.71597,-33.32153
886.22206,-1.01822,0.07704
887.35406,-12.15526,-129.09222
888.17406,-19.12517,-282.00720
888.83406,-24.73528,-434.95826
889.27206,-23.85607,-377.83679
889.72006,-18.74371,-223.50183
890.71800,-10.09845,-73.47545
891.90800,0.01704,0.07564
892.98806,-9.13871,-78.33949
893.91006,-16.98345,-230.44739
894.61600,-22.98482,-383.53369
895.14806,-25.01569,-430.07571
895.53206,-20.73978,-274.66208
896.31006,-13.46525,-121.85305
897.50606,-3.29841,-3.49840
898.58800,-5.57238,-27.96351
899.63406,-14.73937,-180.17121
900.38806,-21.14821,-333.45584
900.94200,-25.76168,-469.41172
901.37606,-22.41718,-325.73096
901.96206,-16.33443,-172.58609
903.09206,-6.71597,-33.31831
904.18606,-1.01684,0.06500
905.32006,-12.17242,-129.37381
906.14000,-19.14209,-282.30546
906.79806,-24.73533,-434.82058
907.23600,-23.85601,-377.79719
907.68400,-18.74371,-223.40469
908.68006,-10.11573,-73.65861
909.87206,0.01698,0.06743
910.95406,-9.15581,-78.57688
911.87806,-17.01717,-231.10796
912.58200,-23.00174,-383.94284
913.11206,-25.01658,-429.98474
913.49606,-20.74098,-274.64254
914.27206,-13.48223,-122.10154
915.46800,-3.31521,-3.55372
916.55400,-5.59432,-28.17756
917.60006,-14.75641,-180.37882
918.35006,-21.13158,-332.86776
918.90606,-25.76204,-469.20337
919.34000,-22.41951,-325.71830
919.92600,-16.33419,-172.51901
921.05806,-6.69876,-33.08815
922.15000,-1.01762,0.07078
923.28000,-12.13817,-128.65018
924.09800,-19.09121,-280.92343
924.75806,-24.70209,-433.52671
925.20006,-23.85601,-377.62403
925.64806,-18.74383,-223.31888
926.64406,-10.11573,-73.56985
927.83606,0.01698,0.09887
928.92006,-9.17279,-78.76663
929.84406,-17.03427,-231.39326
930.54806,-23.01836,-384.21437
931.07606,-25.01688,-429.86553
931.46000,-20.73829,-274.48839
932.23806,-13.46519,-121.76701
933.43400,-3.29841,-3.41011
934.51606,-5.57256,-27.85736
935.56006,-14.72245,-179.58362
936.31206,-21.11466,-332.29869
936.87006,-25.76186,-469.08371
937.30400,-22.41795,-325.51099
937.89000,-16.33461,-172.46332
939.02206,-6.69876,-33.01876
940.11406,-1.01379,0.09203
941.24806,-12.17242,-129.17271
942.06606,-19.12529,-281.66899
942.72606,-24.73533,-434.45490
943.16406,-23.85691,-377.61081
943.61206,-18.74395,-223.23130
944.60806,-10.11573,-73.46895
945.80006,0.01704,0.11723
946.88406,-9.17231,-78.67944
947.80600,-17.01735,-230.88796
948.51006,-23.00174,-383.61318
949.04006,-25.01742,-429.77564
949.42406,-20.73954,-274.48453
950.20200,-13.46525,-121.71308
951.39806,-3.29841,-3.43132
952.48206,-5.58984,-27.98906
953.52606,-14.73937,-179.81542
954.27800,-21.13158,-332.57958
954.83406,-25.76222,-468.92203
955.26806,-22.41933,-325.48659
955.85600,-16.31751,-172.08051
956.98806,-6.68148,-32.76902
958.07806,-1.01576,0.01997
959.21206,-12.17242,-129.07133
960.03000,-19.12529,-281.54338
960.69006,-24.73533,-434.38524
961.12806,-23.86032,-377.64072
961.57606,-18.74359,-223.14670
962.57406,-10.09851,-73.25042
963.76406,0.01704,0.09422
964.84606,-9.15575,-78.31474
965.77000,-17.01735,-230.77983
966.47206,-22.98482,-383.16559
967.00400,-25.01928,-429.77653
967.38806,-20.73925,-274.39576
968.16406,-13.48223,-121.88278
969.36006,-3.31527,-3.52809
970.44400,-5.57280,-27.76652
971.49006,-14.73943,-179.75260
972.24206,-21.13164,-332.52239
972.79806,-25.76258,-468.89517
973.23206,-22.42202,-325.54522
973.81806,-16.33395,-172.33798
974.95006,-6.69876,-32.97281
976.04206,-1.01582,0.06708
977.17806,-12.18952,-129.27986
977.99606,-19.14209,-281.86196
978.65606,-24.75196,-434.84937
979.09206,-23.85846,-377.43274
979.54006,-18.74425,-223.13429
980.53800,-10.09857,-73.22032
981.72800,0.01704,0.09648
982.81006,-9.15581,-78.24906
983.73600,-17.03439,-231.04221
984.44006,-23.01854,-383.89064
984.96800,-25.01969,-429.64626
985.35206,-20.73787,-274.26969
986.13006,-13.46525,-121.58412
987.32606,-3.29841,-3.37759
988.41006,-5.59474,-28.02249
989.45606,-14.75641,-179.95873
990.20806,-21.14826,-332.83655
990.76200,-25.76198,-468.75548
991.19606,-22.41933,-325.36827
991.78206,-16.33449,-172.25727
992.91406,-6.69870,-32.89849
994.00606,-1.01523,0.08299
995.14200,-12.18958,-129.20467
995.96000,-19.14209,-281.78954
996.62006,-24.75196,-434.67522
997.05600,-23.85852,-377.40681
997.50400,-18.74461,-223.06591
998.50206,-10.09851,-73.12287
999.69206,0.01698,0.09309
1000.77606,-9.17285,-78.47054
1001.70006,-17.03439,-230.99294
1002.40406,-23.01860,-383.79334
1002.93206,-25.02101,-429.63911
1003.31806,-20.71850,-273.62479
1004.09606,-13.44821,-121.28072
1005.29206,-3.28149,-3.25921
1006.37400,-5.59468,-27.92339
1007.42006,-14.75641,-179.88319
1008.17206,-21.14826,-332.72222
1008.72606,-25.76216,-468.58363
1009.16006,-22.42082,-325.31422
1009.74606,-16.33443,-172.19974
1010.87606,-6.71604,-33.05895
1011.97006,-1.01499,0.08522
1013.10600,-12.18952,-129.13551
1013.92600,-19.15895,-282.02806
1014.58606,-24.76906,-435.04354
1015.02000,-23.85852,-377.23880
1015.46806,-18.73928,-222.84351
1016.46606,-10.09857,-73.04587
1017.65606,0.01698,0.13277
1018.74206,-9.18977,-78.60441
1019.66206,-17.01729,-230.47332
1020.36806,-23.01854,-383.73362
1020.89606,-25.02077,-429.55711
1021.28000,-20.73697,-274.06754
1022.05806,-13.46525,-121.48108
1023.25400,-3.29847,-3.35028
1024.33800,-5.59504,-27.92019
1025.38406,-14.75647,-179.79749
1026.13612,-21.14826,-332.62711
1026.69006,-25.76204,-468.40888
1027.12400,-22.41831,-325.18715
1027.71006,-16.33378,-172.12128
1028.84206,-6.69876,-32.82876
1029.93406,-1.01403,0.16057
1031.07006,-12.18952,-129.02619
1031.88806,-19.14221,-281.55372
1032.54812,-24.75202,-434.44172
1032.98400,-23.86157,-377.27430
1033.43200,-18.74401,-222.95211
1034.43006,-10.09857,-73.00972
1035.62000,0.01698,0.12344
1036.70606,-9.18965,-78.53597
1037.62806,-17.03439,-230.75396
1038.33413,-23.03546,-384.12396
1038.86012,-25.02364,-429.53223
1039.24400,-20.73936,-274.09147
1040.02212,-13.46525,-121.39177
1041.21800,-3.29847,-3.30335
1042.30200,-5.59492,-27.84386
1043.34606,-14.73943,-179.31683
1044.09800,-21.13146,-332.01233
1044.65406,-25.76204,-468.27540
1045.08800,-22.41999,-325.11961
1045.67600,-16.31775,-171.76427
1046.80812,-6.68148,-32.61168
1047.89806,-1.01134,0.08520
1049.03600,-12.20651,-129.21089
1049.85400,-19.15895,-281.83052
1050.51400,-24.76900,-434.78925
1050.94800,-23.86187,-377.19838
1051.39600,-18.74419,-222.84074
1052.39400,-10.09857,-72.97506
1053.58413,0.01704,0.09348
1054.67000,-9.18953,-78.45015
1055.59400,-17.05131,-231.08635
1056.29812,-23.03552,-384.02233
1056.82413,-25.02262,-429.40170
1057.20800,-20.73679,-273.98370
1057.98400,-13.48217,-121.62803
1059.18000,-3.31533,-3.38378
1060.26600,-5.59534,-27.81026
1061.31200,-14.75647,-179.57062
1062.06413,-21.14814,-332.41700
1062.61800,-25.76240,-468.18089
1063.05200,-22.41969,-325.00193
1063.63800,-16.33521,-172.08740
1064.77000,-6.69876,-32.76704
1065.86200,-1.01337,0.11873
1066.99800,-12.18952,-128.85850
1067.81600,-19.14215,-281.36473
1068.47612,-24.75202,-434.19309
1068.91212,-23.86050,-377.09940
1069.36012,-18.74000,-222.71046
1070.35800,-10.09857,-72.97493
1071.54812,0.01698,0.07377
1072.63213,-9.17273,-78.16789
1073.55812,-17.05125,-230.95891
1074.26212,-23.03546,-383.85283
1074.78812,-25.02227,-429.31162
1075.17200,-20.73542,-273.84862
1075.95012,-13.46525,-121.33886
1077.14600,-3.29847,-3.27757
1078.23012,-5.59528,-27.78090
1079.27600,-14.75647,-179.48288
1080.02812,-21.14826,-332.36068
1080.58200,-25.76258,-468.07412
1081.01600,-22.42065,-325.06693
1081.60200,-16.33515,-172.01349
1082.73400,-6.69882,-32.73787
1083.82600,-1.01224,0.12294
1084.96412,-12.20656,-129.10699
1085.78000,-19.14215,-281.28626
1086.44013,-24.75202,-434.08856
1086.87612,-23.86175,-377.04848
1087.32413,-18.73947,-222.66949
1088.32012,-10.11573,-73.11382
1089.51212,0.01692,0.09112
1090.59612,-9.17261,-78.14744
1091.52000,-17.03433,-230.45860
1092.22400,-23.01854,-383.35342
1092.75212,-25.02609,-429.44435
1093.13612,-20.73853,-273.91827
1093.91212,-13.48223,-121.51843
1095.10800,-3.31533,-3.36993
1096.19412,-5.59576,-27.76958
1097.24400,-14.79049,-180.13325
1097.99400,-21.16506,-332.74289
1098.54600,-25.76222,-468.02346
1098.98012,-22.41795,-324.84997
1099.56600,-16.33449,-171.93275
1100.69800,-6.69876,-32.71210
1101.79000,-1.01283,0.07600
1102.92813,-12.20656,-129.06861
1103.74212,-19.12541,-280.79834
1104.40400,-24.75208,-433.96153
1104.84012,-23.86109,-376.95080
1105.28812,-18.74108,-222.59977
1106.28400,-10.11579,-73.11620
1107.47612,0.01698,0.12811
1108.56200,-9.18935,-78.34747
1109.48613,-17.05137,-230.83210
1110.19013,-23.03546,-383.71757
1110.71612,-25.02496,-429.22992
1111.10012,-20.73626,-273.79686
1111.87800,-13.46531,-121.21066
1113.07413,-3.29847,-3.31432
1114.15812,-5.59540,-27.72841
1115.20600,-14.77357,-179.67185
1115.95800,-21.16506,-332.56426
1116.51000,-25.76240,-467.86353
1116.94412,-22.41867,-324.80203
1117.53000,-16.33455,-171.89773
1118.66212,-6.69882,-32.64797
1119.75400,-1.00996,0.10910
1120.89213,-12.20656,-128.90441
1121.71200,-19.17587,-281.95340
1122.37213,-24.78640,-434.91907
1122.80413,-23.86157,-376.88047
1123.25212,-18.74060,-222.55529
1124.25000,-10.09857,-72.80737
1125.44013,0.01692,0.11844
1126.52600,-9.18929,-78.25349
1127.44800,-17.03439,-230.28083
1128.15212,-23.01860,-383.12815
1128.68000,-25.02442,-429.10986
1129.06413,-20.73488,-273.68816
1129.84012,-13.48223,-121.44187
1131.03600,-3.31527,-3.35052
1132.12213,-5.59552,-27.67585
1133.17200,-14.79055,-179.91252
1133.92200,-21.16501,-332.48961
1134.47400,-25.76246,-467.74272
1134.90812,-22.42082,-324.75602
1135.49400,-16.33407,-171.85422
1136.62400,-6.71609,-32.78547
1137.71800,-1.00949,0.11388
1138.85612,-12.20662,-128.84958
1139.67412,-19.15895,-281.42951
1140.33413,-24.76918,-434.27501
1140.76812,-23.86235,-376.85547
1141.21800,-18.72063,-222.03475
1142.21800,-10.06461,-72.33005
1143.40400,0.01692,0.12199
1144.49212,-9.20681,-78.46675
1145.41600,-17.06841,-230.99091
1146.12000,-23.05256,-383.94831
1146.64400,-25.02543,-429.08587
1147.03000,-20.70971,-272.87291
1147.80812,-13.44827,-120.87711
1149.00400,-3.28149,-3.13575
1150.08600,-5.59594,-27.66056
1151.13400,-14.77357,-179.50896
1151.88400,-21.14826,-331.90709
1152.43813,-25.76246,-467.67596
1152.87000,-22.44097,-325.41592
1153.45600,-16.35099,-172.14753
1154.58800,-6.71604,-32.81403
1155.68200,-1.01164,0.09786
1156.82012,-12.20656,-128.76693
1157.63800,-19.15901,-281.32085
1158.29812,-24.76912,-434.15911
1158.73200,-23.86223,-376.75411
1159.18000,-18.73582,-222.35081
1160.17813,-10.09857,-72.73372
1161.36800,0.01698,0.13090
1162.45600,-9.20663,-78.40098
1163.37800,-17.05143,-230.49412
1164.08200,-23.03546,-383.37037
1164.60800,-25.02633,-429.03468
1164.99212,-20.73189,-273.46514
1165.77212,-13.44821,-120.87425
1166.96800,-3.28149,-3.12111
1168.05000,-5.60054,-27.70124
1169.10200,-14.80747,-180.15552
1169.85400,-21.19962,-333.21191
1170.40212,-25.76270,-467.59028
1170.83800,-22.39619,-323.91362
1171.42813,-16.28355,-170.73693
1172.56200,-6.63048,-31.89451
1173.64600,-1.00883,0.08117
1174.78600,-12.22354,-129.05567
1175.60200,-19.15901,-281.22652
1176.26212,-24.76906,-434.13978
1176.69600,-23.86402,-376.76211
1177.14400,-18.74096,-222.42818
1178.14213,-10.09857,-72.69373
1179.33200,0.01692,0.12007
1180.41812,-9.18935,-78.11934
1181.34413,-17.06841,-230.82746
1182.04812,-23.05256,-383.76644
1182.57200,-25.02609,-428.95347
1182.95412,-20.75587,-274.11524
1183.73200,-13.48229,-121.33647
1184.92813,-3.31533,-3.33399
1186.01400,-5.60054,-27.62579
1187.06413,-14.79055,-179.70912
1187.81600,-21.18235,-332.64268
1188.36612,-25.76234,-467.53425
1188.80000,-22.41849,-324.60649
1189.38612,-16.33491,-171.67538
1190.51812,-6.69888,-32.55362
1191.61012,-1.01014,0.16708
1192.74613,-12.18964,-128.34703
1193.56413,-19.14221,-280.71025
1194.22400,-24.75208,-433.50443
1194.66000,-23.86390,-376.68854
1195.10800,-18.74108,-222.30797
1196.10400,-10.11585,-72.88122
1197.29600,0.01692,0.13477
1198.30000,0.01686,0.09622
1199.50000,0.01656,0.13732
1200.70012,0.01650,0.10243
1201.90000,0.01650,0.17012
1203.10012,0.01650,0.09644
1204.30000,0.01650,0.12775
1205.50000,0.01650,0.13292
1206.70012,0.01650,0.16870
1207.90000,0.01650,0.15140
1209.10012,0.01650,0.13932
1210.30000,0.01650,0.14083
1211.50000,0.01650,0.14262
1212.70012,0.01650,0.15284
1213.90000,0.01650,0.14639
1215.03812,0.01650,0.14576