File: ball-data/compression/Penn Regular Duty.is_comp_RawData/Specimen_RawData_1.csv
Time,Extension,Load
(sec),(mm),(N)
0.00000,-0.00012,0.08957
1.17000,-9.94485,-116.53714
2.02800,-17.23845,-268.71966
2.73600,-23.25650,-421.13613
3.27400,-24.55256,-421.15986
3.69400,-19.91367,-267.44008
4.53200,-12.32537,-114.72050
5.73000,-2.14178,-2.98362
6.77000,-6.54187,-50.74241
7.77600,-15.23215,-202.45543
8.50200,-21.40291,-354.03933
9.14400,-25.59421,-465.97246
9.53000,-21.58287,-310.00985
10.20400,-14.98044,-156.86437
11.36400,-5.11655,-24.22980
12.37000,-2.19619,-3.31426
13.48400,-12.85193,-150.17029
14.28200,-19.63547,-302.46038
14.94200,-25.24492,-454.88369
15.37000,-23.23408,-361.02656
15.89000,-17.60000,-206.91151
16.94600,-8.56801,-60.08948
17.95800,0.03402,0.26974
19.14000,-10.02688,-98.39217
20.03400,-17.62917,-249.97419
20.72600,-23.51078,-402.76371
21.23000,-24.59860,-412.67920
21.66400,-19.79320,-257.98880
22.53000,-12.00208,-105.64314
23.73000,-1.80259,-0.67071
24.74000,-6.60931,-47.99949
25.76600,-15.45307,-199.12347
26.50400,-21.72613,-351.71200
27.09800,-25.65765,-462.38236
27.48600,-21.67106,-308.19615
28.16000,-15.04902,-155.10464
29.32000,-5.18483,-23.55950
30.33200,-2.21568,-2.43665
31.46200,-13.00547,-148.49344
32.26800,-19.85597,-301.33193
32.92200,-25.41478,-453.28680
33.36200,-22.88054,-345.32495
33.91800,-16.99684,-191.80024
35.01200,-7.66711,-48.40019
36.01800,0.43533,0.23092
37.20000,-10.87846,-109.54551
38.07800,-18.34312,-262.30330
38.75800,-24.12291,-414.54062
39.25200,-23.94809,-382.75413
39.72000,-18.72033,-229.23041
40.70000,-10.21737,-79.10649
41.90000,-0.01704,0.23699
42.90200,-8.42918,-71.15271
43.87800,-16.74518,-224.03562
44.59000,-22.79720,-376.32488
45.15200,-24.85994,-420.43764
45.57400,-20.22392,-266.19237
46.40000,-12.66533,-113.99771
47.59800,-2.48216,-2.99532
48.69000,-6.62324,-46.37919
49.72800,-15.57206,-197.67003
50.47000,-21.87895,-350.50139
51.08200,-25.39918,-446.17787
51.47800,-21.17385,-291.35862
52.20000,-14.26512,-139.59833
53.38200,-4.21606,-14.51005
54.48200,-4.48332,-21.00995
55.57200,-14.34793,-171.79791
56.34600,-20.92740,-324.52587
56.93000,-25.77430,-462.23696
57.38600,-22.07781,-317.36791
58.02200,-15.68159,-164.59912
59.17000,-5.91659,-29.45654
60.26800,-2.21628,-1.88130
61.40600,-13.07309,-146.43930
62.21800,-19.97496,-299.38612
62.85800,-25.41478,-448.53896
63.29800,-22.88252,-342.55274
63.86200,-16.92719,-188.52493
64.96600,-7.51351,-45.76802
66.05400,-0.10397,0.16556
67.22801,-11.66117,-120.53266
68.08400,-18.93862,-272.89290
68.75601,-24.65008,-425.36672
69.21800,-23.62851,-368.09038
69.71201,-18.17188,-214.64175
70.74600,-9.28244,-66.10156
71.84001,0.01692,0.23813
73.03401,-10.14616,-95.04897
73.94801,-17.91772,-247.80458
74.64201,-23.81667,-400.87990
75.14001,-24.28829,-393.01474
75.59400,-19.21025,-239.13087
76.53401,-10.94823,-87.67493
77.73400,-0.74839,0.27697
78.82401,-8.44628,-69.52264
79.80200,-16.77927,-221.20075
80.52200,-22.89902,-374.65572
81.07001,-24.87883,-418.24933
81.49001,-20.25913,-264.85594
82.32001,-12.66545,-112.50052
83.51801,-2.48216,-2.51428
84.61401,-6.66623,-45.53137
85.65601,-15.64034,-195.92177
86.40000,-21.96445,-348.67454
87.00001,-25.41909,-444.09316
87.39800,-21.17314,-289.17419
88.13200,-14.16288,-136.49177
89.31600,-4.09749,-12.99590
90.40201,-4.48385,-20.13214
91.50001,-14.41597,-170.56825
92.27400,-20.99508,-322.75349
92.85001,-25.77460,-459.10913
93.31001,-22.03608,-314.01273
93.95600,-15.56177,-160.89333
95.10800,-5.76311,-27.28328
96.19000,-2.19738,-1.32433
97.33201,-13.09037,-144.56489
98.14600,-20.00910,-296.97750
98.78201,-25.41478,-445.37622
99.22401,-22.85968,-339.71112
99.79201,-16.87331,-185.85468
100.89600,-7.46263,-44.33321
101.97801,-0.10367,0.33429
103.15601,-11.69519,-119.16216
104.01601,-19.00612,-271.61947
104.68800,-24.71818,-424.21043
105.14401,-23.60741,-365.24292
105.64201,-18.11622,-211.81924
106.68001,-9.19724,-64.15563
107.76601,0.03396,0.41235
108.96401,-10.16302,-93.74830
109.87801,-17.93488,-245.56348
110.57201,-23.83401,-398.42255
111.06801,-24.28895,-391.02826
111.52400,-19.18412,-236.96134
112.47001,-10.88037,-85.74790
113.67001,-0.68034,0.41480
114.75401,-8.46500,-68.54720
115.73801,-16.84719,-220.37322
116.45200,-22.91588,-372.37234
116.99801,-24.87931,-416.32164
117.42400,-20.18799,-261.62094
118.26000,-12.56387,-109.98765
119.46001,-2.36306,-1.71981
120.54201,-6.66515,-44.57161
121.58401,-15.64028,-194.00829
122.32800,-21.96451,-346.17253
122.92801,-25.42016,-442.24199
123.32800,-21.14946,-287.22301
124.06400,-14.12844,-134.97487
125.24801,-4.06312,-12.29594
126.33001,-4.48619,-19.52392
127.42801,-14.41603,-168.81775
128.20601,-21.02916,-321.31337
128.77800,-25.77472,-457.09632
129.23801,-22.03082,-312.62573
129.88400,-15.56195,-160.00327
131.03801,-5.74589,-26.74499
132.11802,-2.20085,-1.14732
133.26400,-13.12391,-143.81007
134.08000,-20.05974,-296.20010
134.71000,-25.41484,-443.43632
135.15400,-22.83750,-337.68382
135.72200,-16.85639,-184.55172
136.82800,-7.42885,-43.48942
137.90600,-0.10356,0.22991
139.08602,-11.71228,-118.35946
139.94600,-19.02263,-270.19201
140.61802,-24.73522,-422.85535
141.07200,-23.60890,-363.99435
141.57400,-18.07843,-210.08786
142.61602,-9.12944,-62.84027
143.69400,0.03390,0.34381
144.89202,-10.16326,-92.83570
145.80802,-17.95216,-244.29018
146.50202,-23.85141,-397.00136
146.99600,-24.29218,-389.82272
147.45202,-19.18382,-235.91263
148.40002,-10.86333,-84.90629
149.60000,-0.66324,0.38887
150.68200,-8.46464,-67.74241
151.66600,-16.84719,-218.85611
152.38400,-22.94996,-371.44881
152.92602,-24.88116,-415.09055
153.35000,-20.20903,-261.21533
154.18800,-12.56381,-109.37182
155.38800,-2.36306,-1.54139
156.47000,-6.66766,-43.98427
157.51800,-15.69122,-193.69546
158.26202,-22.01539,-345.83271
158.85600,-25.42130,-440.86602
159.25602,-21.14408,-286.03902
159.99800,-14.07798,-133.35473
161.18600,-3.97803,-11.34651
162.25802,-4.49199,-19.05325
163.36000,-14.45016,-168.24614
164.13800,-21.06318,-320.49436
164.70402,-25.76730,-455.25238
165.16600,-22.02908,-311.45371
165.81602,-15.52733,-158.57110
166.97402,-5.67887,-25.68021
168.04600,-2.19589,-0.80571
169.19602,-13.15811,-143.24950
170.01002,-20.07672,-295.03120
170.63800,-25.41484,-441.89967
171.08000,-22.86099,-337.45550
171.64802,-16.87278,-184.12296
172.76002,-7.39512,-42.70400
173.83402,-0.10248,0.35211
175.01400,-11.71240,-117.33657
175.87800,-19.05707,-269.56486
176.55000,-24.76894,-422.30546
177.00002,-23.60801,-362.97683
177.50202,-18.07604,-209.23845
178.54600,-9.11240,-62.16883
179.62202,0.03396,0.38517
180.82000,-10.16344,-92.04919
181.74000,-17.98612,-243.83746
182.43600,-23.90181,-397.02345
182.92402,-24.29205,-388.82401
183.38200,-19.15679,-234.49460
184.33402,-10.81245,-83.78583
185.53402,-0.61218,0.32053
186.61002,-8.46470,-67.12446
187.59602,-16.86387,-218.09407
188.31402,-22.96694,-370.62731
188.85400,-24.88200,-414.12175
189.28002,-20.18308,-259.86064
190.12402,-12.49571,-107.82741
191.32400,-2.29508,-1.19310
192.39802,-6.67024,-43.51984
193.44802,-15.70832,-192.90794
194.19402,-22.04953,-345.40463
194.78402,-25.42172,-439.84663
195.18400,-21.14169,-285.21923
195.92602,-14.07792,-132.81484
197.11402,-3.97803,-11.15056
198.18600,-4.49599,-18.70201
199.29002,-14.46703,-167.55402
200.06802,-21.08022,-319.60309
200.63200,-25.76742,-454.06234
201.09402,-22.02861,-310.64315
201.74400,-15.52763,-157.98200
202.90400,-5.66153,-25.22871
203.97402,-2.20007,-0.65954
205.12202,-13.14090,-142.01581
205.93800,-20.07672,-293.84419
206.56602,-25.41484,-440.66507
207.01002,-22.83893,-335.90753
207.57800,-16.85562,-183.12695
208.69402,-7.34412,-41.83978
209.76202,-0.10128,0.43832
210.94202,-11.71235,-116.60033
211.80602,-19.05707,-268.35378
212.48002,-24.78586,-421.64031
212.92802,-23.60914,-362.17250
213.43002,-18.07419,-208.56364
214.48002,-9.06128,-61.15027
215.55000,0.03390,0.49933
216.74802,-10.16332,-91.32063
217.67002,-18.00316,-243.08978
218.36602,-23.91909,-396.31773
218.85200,-24.29343,-388.03477
219.31002,-19.15602,-233.83489
220.26600,-10.77837,-82.87147
221.46600,-0.57840,0.51588
222.53802,-8.46524,-66.50502
223.52802,-16.89813,-217.74812
224.24602,-23.00096,-370.29725
224.78202,-24.88361,-413.32126
225.20800,-20.18033,-259.09666
226.05402,-12.47861,-107.12289
227.25402,-2.27798,-0.98371
228.32600,-6.67036,-43.06253
229.37800,-15.72500,-192.39511
230.12202,-22.04959,-344.30612
230.71200,-25.42321,-439.09542
231.11402,-21.11980,-284.04420
231.86002,-14.02638,-131.54312
233.04800,-3.92674,-10.60190
234.11202,-4.50873,-18.56053
235.21802,-14.50099,-167.46275
235.99602,-21.11383,-319.55332
236.55602,-25.76796,-453.07435
237.01800,-22.03183,-310.14314
237.66802,-15.52745,-157.54316
238.82600,-5.67887,-25.12170
239.89802,-2.19649,-0.48156
241.05002,-13.17527,-142.02867
241.86602,-20.11122,-293.70917
242.49000,-25.41478,-439.76162
242.93200,-22.86189,-336.04704
243.50202,-16.85586,-182.67822
244.61802,-7.34412,-41.56101
245.68600,-0.10051,0.46454
246.87002,-11.74696,-116.52273
247.73402,-19.09145,-268.29410
248.40600,-24.80284,-421.22260
248.85200,-23.61016,-361.60558
249.35402,-18.07730,-208.09308
250.40400,-9.06128,-60.84345
251.47402,0.03390,0.52605
252.67402,-10.18048,-91.04629
253.59602,-18.02038,-242.61257
254.29002,-23.91909,-395.37072
254.77602,-24.29504,-387.37167
255.23402,-19.15560,-233.34123
256.19202,-10.76121,-82.37064
257.39200,-0.56148,0.50083
258.46200,-8.46476,-66.15872
259.45603,-16.93215,-217.80888
260.17002,-23.00096,-369.53773
260.70603,-24.88696,-412.79308
261.13202,-20.18739,-258.90529
261.98203,-12.44447,-106.39274
263.18200,-2.24390,-0.83710
264.25000,-6.67370,-42.86981
265.30403,-15.74186,-192.17787
266.04800,-22.06657,-344.05682
266.63603,-25.42435,-438.48079
267.03600,-21.14557,-284.21950
267.77600,-14.09460,-132.32661
268.96403,-3.99496,-10.99771
270.03803,-4.49193,-18.30107
271.14800,-14.51821,-167.23627
271.92603,-21.13087,-319.20947
272.48400,-25.76754,-452.32505
272.94800,-22.01121,-309.06854
273.60000,-15.49301,-156.62212
274.76203,-5.61041,-24.47198
275.82603,-2.19559,-0.54912
276.97803,-13.17510,-141.57871
277.79800,-20.14577,-293.90389
278.41800,-25.41490,-439.13446
278.86003,-22.86297,-335.62802
279.43003,-16.85562,-182.36993
280.54603,-7.34418,-41.44812
281.61400,-0.09823,0.39402
282.79800,-11.74696,-116.11649
283.66203,-19.09145,-267.62735
284.33003,-24.76900,-419.49697
284.78000,-23.61476,-361.26014
285.28403,-18.05751,-207.38488
286.33003,-9.07838,-60.88176
287.40200,0.03390,0.38724
288.60203,-10.18036,-90.73233
289.52403,-18.02044,-241.96701
290.21803,-23.91903,-394.61799
290.70603,-24.27544,-386.14303
291.16600,-19.11201,-231.84231
292.13000,-10.67649,-80.95051
293.33003,-0.47652,0.45685
294.39000,-8.46476,-65.85169
295.38400,-16.93215,-217.14672
296.10203,-23.03504,-369.68328
296.63400,-24.88672,-412.25724
297.06003,-20.18380,-258.32269
297.90803,-12.46163,-106.27113
299.10800,-2.26094,-0.83568
300.17800,-6.67346,-42.60197
301.23400,-15.75902,-191.84975
301.98203,-22.11751,-344.59077
302.56403,-25.42549,-437.93902
302.96403,-21.14593,-283.84330
303.70603,-14.07804,-131.73692
304.89400,-3.97809,-10.76264
305.96600,-4.49551,-18.11385
307.07400,-14.50105,-166.34842
307.85400,-21.13092,-318.47853
308.41203,-25.76778,-451.75958
308.87600,-22.00888,-308.54275
309.52800,-15.49284,-156.24514
310.69000,-5.61047,-24.24595
311.75403,-2.19445,-0.43700
312.90600,-13.17527,-140.98725
313.72403,-20.12861,-292.74574
314.34600,-25.41490,-438.40531
314.78803,-22.86314,-335.16318
315.35800,-16.85628,-182.02621
316.47600,-7.32720,-41.09249
317.54203,-0.09758,0.40928
318.72600,-11.74702,-115.63115
319.59200,-19.10813,-267.38763
320.26400,-24.82006,-420.30804
320.70800,-23.61291,-360.74474
321.21003,-18.07359,-207.40999
322.25803,-9.07844,-60.65472
323.33003,0.03390,0.54877
324.53003,-10.18024,-90.30472
325.45603,-18.05428,-242.11608
326.15003,-23.95317,-394.94108
326.63203,-24.29995,-386.63860
327.09003,-19.15757,-232.70406
328.04800,-10.76127,-81.87962
329.24803,-0.56148,0.51007
330.31803,-8.46494,-65.52552
331.31003,-16.91529,-216.20871
332.03003,-23.03510,-368.98483
332.56200,-24.88876,-411.86735
332.98800,-20.18858,-258.14461
333.83400,-12.47867,-106.28741
335.03403,-2.27804,-0.87268
336.10603,-6.67311,-42.29643
337.16203,-15.75896,-191.31029
337.91203,-22.13449,-344.41177
338.49200,-25.42656,-437.49243
338.89400,-21.12268,-282.76727
339.64000,-14.02650,-130.65420
340.82800,-3.92685,-10.24213
341.89400,-4.49533,-17.93963
343.00403,-14.51827,-166.15266
343.78600,-21.16506,-318.67746
344.34003,-25.76802,-451.20463
344.80403,-22.01455,-308.34710
345.45603,-15.49343,-155.99470
346.61800,-5.61047,-24.16826
347.68200,-2.19362,-0.37042
348.83400,-13.17533,-140.53816
349.65600,-20.16287,-292.95109
350.27403,-25.41484,-437.79857
350.71803,-22.84252,-334.12412
351.29000,-16.82088,-181.00398
352.40600,-7.31016,-40.68292
353.47003,-0.09662,0.45468
354.65403,-11.74702,-115.29453
355.52003,-19.10813,-266.83209
356.19000,-24.80302,-419.17790
356.63803,-23.59724,-359.66560
357.14000,-18.05643,-206.68672
358.19000,-9.04436,-60.08123
359.25803,0.03384,0.44784
360.45800,-10.18054,-89.86727
361.38203,-18.03754,-241.22816
362.07603,-23.93631,-393.84734
362.56200,-24.27860,-385.35152
363.02003,-19.13336,-231.76668
363.98203,-10.71033,-80.97921
365.18200,-0.51072,0.52595
366.24600,-8.46589,-65.25970
367.24003,-16.93221,-216.00036
367.95603,-23.01794,-367.94960
368.49003,-24.88965,-411.37781
368.91803,-20.15683,-256.97568
369.77003,-12.41033,-105.01571
370.97003,-2.21072,-0.56045
372.03403,-6.67203,-42.06919
373.09003,-15.75896,-190.84254
373.83800,-22.11745,-343.26945
374.42000,-25.42907,-437.06659
374.82000,-21.14049,-282.97836
375.57400,-13.97544,-129.52272
376.76400,-3.85887,-9.61671
377.82203,-4.50036,-17.75120
378.93200,-14.51827,-165.64503
379.71403,-21.16506,-318.09133
380.26800,-25.76790,-450.68312
380.73000,-22.02974,-308.40442
381.38000,-15.52703,-156.36368
382.54000,-5.66159,-24.45122
383.61003,-2.19673,-0.30585
384.76203,-13.17527,-140.13826
385.58203,-20.14589,-291.99332
386.20203,-25.41490,-437.28914
386.64400,-22.86356,-334.40784
387.21200,-16.87152,-181.72553
388.32803,-7.36122,-41.09392
389.39800,-0.09489,0.43974
390.58203,-11.74702,-114.92899
391.44803,-19.10813,-266.27222
392.12003,-24.82012,-419.21180
392.56403,-23.61386,-359.96180
393.06600,-18.07204,-206.67117
394.12003,-9.02732,-59.72118
395.18600,0.03384,0.53978
396.38603,-10.18066,-89.59363
397.31403,-18.07138,-241.47989
398.00803,-23.97015,-394.27917
398.49003,-24.28159,-385.10635
398.95000,-19.10813,-230.86451
399.91803,-10.64217,-79.87143
401.11800,-0.44208,0.54805
402.17400,-8.46679,-64.96117
403.17000,-16.94901,-215.89939
403.89000,-23.06924,-368.73922
404.41803,-24.89133,-411.04596
404.84600,-20.15379,-256.52977
405.70400,-12.35957,-103.98289
406.90403,-2.15912,-0.35856
407.96200,-6.67681,-41.95210
409.02003,-15.77606,-190.74276
409.76603,-22.11757,-342.77759
410.34803,-25.43075,-436.72390
410.75003,-21.11843,-282.09940
411.49603,-14.02644,-130.10079
412.68403,-3.92679,-10.02315
413.75003,-4.49856,-17.56546
414.86203,-14.53525,-165.61802
415.64203,-21.16513,-317.54650
416.19600,-25.76808,-450.15227
416.66003,-22.00840,-307.50807
417.31803,-15.44136,-154.52759
418.48000,-5.55929,-23.35269
419.53803,-2.19278,-0.25265
420.69003,-13.17533,-139.74167
421.50803,-20.12867,-290.94474
422.13000,-25.41484,-436.81309
422.57400,-22.84204,-333.34352
423.15003,-16.78554,-179.72361
424.26800,-7.25916,-39.87170
425.32603,-0.09279,0.46676
426.51000,-11.74702,-114.49888
427.38203,-19.15937,-266.99070
428.05203,-24.85420,-419.63924
428.49403,-23.59485,-358.91779
429.00200,-17.99682,-204.75311
430.05800,-8.94272,-58.51815
431.11400,0.03378,0.56394
432.31403,-10.18078,-89.34068
433.24403,-18.08830,-241.35739
433.93803,-23.98713,-394.20798
434.41803,-24.28159,-384.71054
434.87600,-19.12870,-231.05074
435.84003,-10.69347,-80.35272
437.04000,-0.49374,0.49338
438.10203,-8.46691,-64.74281
439.10000,-16.96611,-215.85187
439.81803,-23.06924,-368.28216
440.34600,-24.89491,-410.81224
440.77603,-20.13471,-255.83021
441.63203,-12.35945,-103.80107
442.83203,-2.15912,-0.25234
443.89000,-6.67723,-41.74703
444.94803,-15.77612,-190.28734
445.69403,-22.11757,-342.29200
446.27603,-25.43069,-436.33062
446.67800,-21.11849,-281.73866
447.43200,-13.95828,-128.78463
448.62200,-3.84183,-9.30553
449.67800,-4.49946,-17.46163
450.79000,-14.53531,-165.21206
451.57000,-21.16513,-317.02504
452.12403,-25.76814,-449.78146
452.58800,-22.00738,-307.22031
453.24603,-15.44166,-154.29310
454.40803,-5.55929,-23.29193
455.46603,-2.19129,-0.18973
456.61800,-13.17527,-139.42411
457.43803,-20.14589,-291.00016
458.05800,-25.41490,-436.40461
458.50200,-22.84300,-333.08279
459.07603,-16.80217,-179.83850
460.19203,-7.29318,-40.09610
461.25403,-0.09154,0.47695
462.44003,-11.76430,-114.48543
463.30800,-19.14221,-266.18626
463.98000,-24.85420,-419.30988
464.42203,-23.59599,-358.65001
464.92800,-18.01619,-205.00503
465.98400,-8.95952,-58.52154
467.04203,0.03384,0.52781
468.24203,-10.18066,-89.09512
469.17203,-18.08836,-241.00466
469.86603,-23.98713,-393.77555
470.34600,-24.28243,-384.41956
470.80403,-19.12457,-230.69628
471.77203,-10.65945,-79.68910
472.97200,-0.45936,0.57292
474.03003,-8.46631,-64.48756
475.03003,-16.98327,-215.83231
475.75003,-23.10302,-368.72704
476.27403,-24.89414,-410.48393
476.69803,-20.19283,-257.03609
477.55603,-12.39329,-104.14504
478.75600,-2.19404,-0.36551
479.81803,-6.67956,-41.58330
480.87803,-15.79298,-190.29569
481.62803,-22.16833,-343.22798
482.20400,-25.43410,-436.13065
482.60403,-21.13864,-282.05832
483.35403,-14.00928,-129.37606
484.54403,-3.89283,-9.60244
485.60603,-4.50341,-17.40327
486.71603,-14.51833,-164.56187
487.50003,-21.18204,-317.18094
488.05203,-25.76844,-449.45486
488.51603,-22.00559,-306.87302
489.17603,-15.42420,-153.85247
490.33800,-5.54243,-23.06618
491.39400,-2.19332,-0.10916
492.54803,-13.19226,-139.45215
493.37003,-20.17979,-291.43669
493.98603,-25.41496,-436.06125
494.43003,-22.83989,-332.81751
495.00600,-16.78309,-179.30115
496.12403,-7.25922,-39.66418
497.18203,-0.09076,0.48296
498.36603,-11.74702,-113.99072
499.23603,-19.14221,-265.76960
499.90803,-24.85420,-418.87797
500.35003,-23.59509,-358.37159
500.85603,-18.01553,-204.78358
501.91203,-8.95952,-58.49003
502.97003,0.03378,0.56007
504.17000,-10.18072,-88.89998
505.10203,-18.10522,-240.92730
505.79803,-24.02151,-394.35666
506.27403,-24.28273,-384.21456
506.73203,-19.11871,-230.29707
507.69803,-10.67661,-79.87916
508.89800,-0.47664,0.49423
509.95803,-8.46697,-64.38102
510.95603,-16.96617,-215.17059
511.67603,-23.08610,-367.93299
512.20203,-24.89503,-410.21731
512.63000,-20.14607,-255.64693
513.48603,-12.37637,-103.70273
514.68603,-2.17670,-0.30665
515.74603,-6.67604,-41.41230
516.80603,-15.79304,-190.01998
517.55200,-22.13449,-341.89582
518.13203,-25.43410,-435.86124
518.53203,-21.13708,-281.79776
519.28400,-13.99230,-129.02892
520.47400,-3.87585,-9.42059
521.53400,-4.50430,-17.29130
522.64600,-14.53531,-164.57144
523.42603,-21.16513,-316.27376
523.98003,-25.76850,-449.06713
524.44200,-22.02807,-307.27068
525.09800,-15.47591,-154.49012
526.26000,-5.59361,-23.44330
527.32200,-2.19140,-0.12686
528.47800,-13.20923,-139.43941
529.30200,-20.21316,-291.92265
529.91400,-25.41490,-435.65746
530.35806,-22.84103,-332.57872
530.93400,-16.78459,-179.15901
532.05200,-7.25922,-39.55913
533.11006,-0.09010,0.47787
534.29600,-11.76430,-114.02635
535.16600,-19.15937,-265.85301
535.83800,-24.87124,-419.04576
536.27600,-23.61542,-358.88791
536.78400,-18.01212,-204.53567
537.84000,-8.95958,-58.31382
538.89800,0.03378,0.51247
540.09800,-10.18072,-88.67531
541.02800,-18.08836,-240.27441
541.72006,-23.97021,-392.55988
542.20200,-24.28428,-384.02200
542.66006,-19.11907,-230.16209
543.62806,-10.65951,-79.50191
544.82800,-0.45942,0.56738
545.88606,-8.46619,-64.15474
546.88606,-16.98315,-215.21632
547.60400,-23.08616,-367.58654
548.13000,-24.89719,-410.11915
548.55600,-20.16999,-256.06314
549.41400,-12.37637,-103.59725
550.61400,-2.17676,-0.27072
551.67400,-6.67616,-41.24825
552.73400,-15.79304,-189.71207
553.48400,-22.16827,-342.47696
554.06000,-25.43607,-435.60203
554.46206,-21.12130,-281.19188
555.21406,-13.97550,-128.52589
556.40406,-3.85893,-9.23568
557.46206,-4.50155,-17.20086
558.57606,-14.55223,-164.66919
559.35806,-21.19909,-316.87893
559.90800,-25.76856,-448.73193
560.37200,-22.00828,-306.51029
561.02800,-15.45870,-154.07198
562.19000,-5.57633,-23.19263
563.25000,-2.18931,-0.13643
564.40406,-13.19226,-138.89792
565.22600,-20.17991,-290.77068
565.84206,-25.41496,-435.36767
566.28400,-22.86584,-333.15986
566.86200,-16.78411,-178.94844
567.98006,-7.25922,-39.47304
569.03800,-0.08783,0.44769
570.22400,-11.76442,-113.74016
571.09600,-19.17611,-265.91728
571.76606,-24.87130,-418.72531
572.20606,-23.59700,-357.96903
572.71206,-18.01141,-204.36339
573.76800,-8.95958,-58.24894
574.82606,0.03384,0.49236
576.02600,-10.18084,-88.42384
576.95800,-18.10522,-240.36458
577.65206,-24.00441,-393.06447
578.13000,-24.28656,-383.74152
578.58800,-19.11811,-229.86781
579.55600,-10.65951,-79.30447
580.75606,-0.45936,0.58703
581.81400,-8.46661,-63.87279
582.81400,-16.98321,-214.85453
583.53406,-23.10308,-367.54809
584.05806,-24.89832,-409.84757
584.48400,-20.16240,-255.64225
585.34000,-12.39329,-103.59997
586.54006,-2.19410,-0.19608
587.60206,-6.67879,-41.05528
588.66206,-15.79310,-189.36925
589.41400,-22.18525,-342.47003
589.98806,-25.43672,-435.32282
590.39000,-21.11239,-280.71282
591.14200,-13.97550,-128.35110
592.33200,-3.85893,-9.09320
593.39000,-4.50645,-16.95006
594.50200,-14.53531,-163.95928
595.28406,-21.18216,-315.98691
595.83406,-25.76043,-447.96858
596.30006,-22.00570,-306.08665
596.95800,-15.44130,-153.52320
598.12200,-5.54249,-22.73566
599.17806,-2.19087,0.05794
600.33406,-13.20911,-138.82902
601.15600,-20.19648,-290.72292
601.77000,-25.41496,-434.91844
602.21406,-22.84180,-332.08862
602.79006,-16.78387,-178.72907
603.90800,-7.25934,-39.27548
604.96600,-0.08490,0.57788
606.15206,-11.76436,-113.42676
607.02206,-19.15937,-265.07335
607.69400,-24.87130,-418.27727
608.13406,-23.59754,-357.71146
608.63800,-18.03174,-204.56059
609.69400,-8.97644,-58.24474
610.75400,0.03378,0.62187
611.95406,-10.18072,-88.20253
612.88406,-18.08842,-239.59631
613.57800,-23.98713,-392.28074
614.05600,-24.30688,-384.32669
614.51200,-19.15357,-230.64900
615.47800,-10.71039,-79.87206
616.67806,-0.51084,0.62346
617.74200,-8.46691,-63.74357
618.74400,-17.00019,-214.84245
619.46000,-23.08610,-366.80814
619.98600,-24.89964,-409.65021
620.41400,-20.14267,-254.99491
621.27206,-12.35957,-103.01566
622.47206,-2.15924,-0.05792
623.53000,-6.67795,-40.88818
624.59206,-15.80990,-189.40371
625.34206,-22.18519,-342.15029
625.91600,-25.43768,-435.05929
626.32000,-21.09212,-279.89795
627.07406,-13.94124,-127.62724
628.26606,-3.80811,-8.68823
629.31806,-4.50502,-16.82793
630.43006,-14.53531,-163.69877
631.21406,-21.19903,-316.03795
631.76200,-25.76066,-447.72603
632.22800,-22.00714,-305.99056
632.88606,-15.44130,-153.34204
634.04806,-5.55935,-22.80639
635.10600,-2.19027,0.04883
636.26406,-13.22621,-138.92248
637.08406,-20.19654,-290.45193
637.69806,-25.41508,-434.60563
638.14200,-22.84294,-331.97779
638.71800,-16.78375,-178.64607
639.83606,-7.25928,-39.19421
640.89406,-0.08371,0.58141
642.08000,-11.76436,-113.27418
642.95000,-19.15943,-264.73865
643.61806,-24.83722,-416.93859
644.06200,-23.59886,-357.55690
644.56806,-18.01290,-204.01187
645.62400,-8.95958,-57.90022
646.68200,0.03378,0.62143
647.88200,-10.18072,-88.02742
648.81606,-18.12208,-240.05905
649.50806,-24.00447,-392.44819
649.98600,-24.28775,-383.34772
650.44400,-19.11363,-229.37134
651.41206,-10.65951,-79.07478
652.61206,-0.45948,0.60921
653.67006,-8.46757,-63.57795
654.67006,-16.98327,-214.21522
655.38806,-23.08616,-366.43308
655.91400,-24.90071,-409.42948
656.33800,-20.18165,-255.73581
657.19400,-12.41039,-103.60369
658.39406,-2.21084,-0.13853
659.45800,-6.68154,-40.83304
660.52206,-15.82688,-189.49592
661.26800,-22.16839,-341.39540
661.84406,-25.43930,-434.88760
662.24400,-21.13146,-280.87541
662.99606,-13.99224,-128.31950
664.18606,-3.87591,-9.08351
665.24606,-4.50723,-16.75577
666.36206,-14.56915,-164.09192
667.14606,-21.23328,-316.65638
667.69000,-25.76072,-447.44715
668.15206,-22.05097,-307.10684
668.80806,-15.49295,-154.12102
669.97006,-5.61059,-23.23203
671.03406,-2.18853,0.10118
672.19000,-13.20918,-138.34516
673.01406,-20.21322,-290.51155
673.62606,-25.41502,-434.33733
674.07000,-22.84210,-331.72380
674.64606,-16.78291,-178.39575
675.76606,-7.24230,-38.90244
676.82200,-0.08365,0.58096
678.00806,-11.76442,-113.01704
678.88200,-19.19315,-265.25902
679.55200,-24.88857,-418.12796
679.99006,-23.60023,-357.34907
680.49606,-18.01386,-203.81298
681.55400,-8.94283,-57.65182
682.61006,0.03378,0.64142
683.81006,-10.18060,-87.82804
684.74400,-18.12220,-239.75918
685.43606,-24.00447,-392.12599
685.91406,-24.28913,-383.11806
686.37200,-19.10902,-229.14056
687.34206,-10.64235,-78.72163
688.54206,-0.44220,0.63585
689.59800,-8.46715,-63.49875
690.60206,-17.01699,-214.67052
691.32000,-23.12024,-367.09059
691.84206,-24.90406,-409.31117
692.26800,-20.15863,-254.98610
693.12606,-12.37655,-102.97752
694.32606,-2.17676,-0.03051
695.38606,-6.68237,-40.72378
696.45000,-15.82688,-189.18771
697.19806,-22.18531,-341.52873
697.77206,-25.44151,-434.69951
698.17400,-21.10689,-280.03786
698.92806,-13.95846,-127.66412
700.11806,-3.84189,-8.81105
701.17400,-4.51142,-16.71920
702.28800,-14.55229,-163.55664
703.07200,-21.21613,-315.89046
703.61806,-25.76079,-447.19424
704.08200,-22.02567,-306.13361
704.73806,-15.47591,-153.72613
705.90206,-5.57645,-22.85907
706.96206,-2.18806,0.12280
708.11806,-13.20923,-138.19864
708.94400,-20.23020,-290.74758
709.55400,-25.41502,-434.03883
709.99606,-22.86667,-332.34347
710.57000,-16.81795,-178.99226
711.69006,-7.27614,-39.20601
712.75006,-0.08060,0.55882
713.93806,-11.78146,-113.12358
714.81200,-19.21031,-265.36273
715.48006,-24.88857,-417.85713
715.91800,-23.60089,-357.23932
716.42206,-18.02952,-204.00248
717.47800,-8.97650,-57.93559
718.53800,0.03372,0.60614
719.73806,-10.18096,-87.71672
720.67400,-18.13906,-239.88897
721.36600,-24.02151,-392.37686
721.84206,-24.29032,-383.03055
722.30006,-19.10860,-228.96487
723.26800,-10.65957,-78.86456
724.46800,-0.45948,0.63517
725.52606,-8.46703,-63.30195
726.53206,-17.03367,-214.78005
727.25006,-23.13752,-367.34484
727.77000,-24.90514,-409.20131
728.19606,-20.15941,-254.86311
729.05400,-12.37643,-102.88967
730.25400,-2.17682,-0.05866
731.31400,-6.68160,-40.65233
732.37806,-15.82694,-188.96108
733.12606,-22.18531,-341.28141
733.70000,-25.44528,-434.65804
734.10006,-21.13350,-280.60513
734.85006,-14.00928,-128.38892
736.04006,-3.89289,-9.13800
737.10206,-4.50992,-16.64070
738.21406,-14.53537,-162.98404
738.99606,-21.18216,-314.75499
739.54600,-25.76103,-446.99341
740.01200,-22.00433,-305.36965
740.67006,-15.44147,-152.96181
741.83406,-5.54249,-22.46683
742.89000,-2.18638,0.12752
744.04806,-13.22621,-138.28293
744.87006,-20.21322,-290.03492
745.48206,-25.41508,-433.79113
745.92600,-22.84449,-331.48430
746.50006,-16.80097,-178.45286
747.61806,-7.27614,-39.11631
748.67806,-0.07940,0.64930
749.86600,-11.78152,-112.91556
750.74006,-19.21031,-265.15108
751.41006,-24.90597,-418.16525
751.84600,-23.60089,-357.02039
752.35006,-18.03150,-203.92481
753.40600,-8.97644,-57.86289
754.46606,0.03378,0.58278
755.66600,-10.18084,-87.54380
756.60006,-18.12220,-239.29248
757.29400,-24.02163,-392.16712
757.77000,-24.28871,-382.80301
758.22800,-19.10406,-228.68406
759.19806,-10.64229,-78.53445
760.39800,-0.44226,0.60719
761.45406,-8.46679,-63.18782
762.45606,-17.00019,-213.81615
763.17400,-23.10320,-366.13967
763.69806,-24.90609,-409.04339
764.12400,-20.15438,-254.58684
764.98206,-12.37643,-102.78799
766.18200,-2.17676,-0.05320
767.24206,-6.68118,-40.50331
768.30600,-15.82694,-188.75834
769.05400,-22.18525,-341.08017
769.62806,-25.44486,-434.49629
770.03000,-21.10761,-279.70171
770.78206,-13.97562,-127.69452
771.97406,-3.84195,-8.73415
773.03000,-4.51207,-16.56433
774.14606,-14.56921,-163.41811
774.93006,-21.23334,-315.85123
775.47406,-25.76096,-446.76796
775.93806,-22.02597,-305.90920
776.59406,-15.47538,-153.46088
777.75806,-5.57639,-22.72590
778.81806,-2.18543,0.21203
779.97600,-13.22627,-138.08090
780.80006,-20.23026,-290.21161
781.41006,-25.41502,-433.52436
781.85406,-22.84431,-331.34196
782.42806,-16.80001,-178.34516
783.54806,-7.25928,-38.91562
784.60600,-0.07516,0.57316
785.79206,-11.76442,-112.49341
786.66600,-19.19327,-264.54717
787.33800,-24.90597,-417.93421
787.77406,-23.60185,-356.88981
788.28000,-18.01278,-203.39889
789.33606,-8.95964,-57.59885
790.39406,0.03372,0.62237
791.59406,-10.18090,-87.37243
792.53206,-18.15610,-239.85591
793.22600,-24.05553,-392.85783
793.69806,-24.29367,-382.81601
794.15406,-19.12947,-229.18215
795.12200,-10.67667,-78.85954
796.32200,-0.47676,0.64638
797.38200,-8.46757,-63.06420
798.38406,-17.00025,-213.61232
799.10006,-23.08628,-365.39830
799.62606,-24.90753,-408.88309
800.05400,-20.13435,-253.98362
800.91406,-12.34259,-102.13120
802.11400,-2.14220,0.08613
803.17006,-6.68136,-40.37319
804.23400,-15.82688,-188.54138
804.98400,-22.20253,-341.23767
805.55600,-25.44480,-434.27762
805.95800,-21.10647,-279.57391
806.71000,-13.97562,-127.56251
807.90206,-3.84195,-8.71620
808.95806,-4.51333,-16.46723
810.07406,-14.56927,-163.28849
810.86006,-21.25056,-316.02222
811.40206,-25.76132,-446.52961
811.86806,-22.00684,-305.16589
812.52606,-15.44154,-152.72846
813.68806,-5.55947,-22.52770
814.74606,-2.18064,0.22606
815.90406,-13.22621,-137.88722
816.73006,-20.24748,-290.38927
817.33800,-25.41508,-433.35766
817.78000,-22.87044,-331.94471
818.35206,-16.83565,-178.95671
819.47006,-7.31034,-39.33437
820.53406,-0.07498,0.58769
821.72206,-11.78140,-112.61811
822.59406,-19.19321,-264.26617
823.26200,-24.87142,-416.69454
823.70200,-23.60412,-356.84690
824.20806,-18.01296,-203.26018
825.26406,-8.95964,-57.50404
826.32200,0.03366,0.66472
827.52206,-10.18084,-87.21693
828.45806,-18.13912,-239.23071
829.15206,-24.03837,-392.14276
829.62606,-24.29475,-382.67240
830.08406,-19.10813,-228.48690
831.05206,-10.65957,-78.59825
832.25200,-0.45954,0.66608
833.31006,-8.46715,-62.90047
834.31200,-17.00019,-213.41035
835.03206,-23.12030,-366.17972
835.55400,-24.90974,-408.87345
835.98006,-20.15749,-254.44854
836.83800,-12.37649,-102.54096
838.03800,-2.17682,0.00370
839.09800,-6.68082,-40.27027
840.16406,-15.84410,-188.65163
840.91406,-22.21933,-341.50466
841.48406,-25.44713,-434.15956
841.88606,-21.10438,-279.37990
842.63806,-13.97562,-127.49067
843.82806,-3.85899,-8.76721
844.88606,-4.51435,-16.47208
846.00200,-14.56921,-163.03137
846.78800,-21.25050,-315.89217
847.33000,-25.76144,-446.37226
847.79600,-22.00403,-304.95236
848.45406,-15.44130,-152.61333
849.61600,-5.55941,-22.41697
850.67400,-2.18513,0.21318
851.83200,-13.22633,-137.73230
852.65606,-20.23031,-289.72624
853.26606,-25.41508,-433.11801
853.71000,-22.84485,-331.03362
854.28600,-16.78357,-177.84918
855.40406,-7.25934,-38.77650
856.46206,-0.07384,0.62248
857.65000,-11.78158,-112.47993
858.52406,-19.21019,-264.46745
859.19400,-24.90609,-417.52663
859.62806,-23.62564,-357.48150
860.13006,-18.06617,-204.33148
861.18606,-9.01046,-58.03179
862.25006,0.03366,0.65114
863.45000,-10.18084,-87.10857
864.38606,-18.13918,-238.96676
865.08000,-24.03837,-391.90326
865.55400,-24.29606,-382.54756
866.00806,-19.14573,-229.34556
866.97600,-10.69365,-78.99218
868.17600,-0.49386,0.61253
869.23806,-8.46643,-62.82204
870.24400,-17.03379,-213.97216
870.96206,-23.13752,-366.41978
871.48206,-24.91375,-408.82520
871.90800,-20.15409,-254.26703
872.76606,-12.37655,-102.46971
873.96606,-2.17694,0.00392
875.02606,-6.67968,-40.24299
876.08800,-15.81002,-187.80824
876.83606,-22.16851,-339.88502
877.41206,-25.44797,-434.01290
877.81006,-21.14814,-280.46956
878.56006,-14.02668,-128.29123
879.75006,-3.90993,-9.08454
880.81400,-4.51716,-16.35711
881.93006,-14.56915,-162.88368
882.71606,-21.25056,-315.56252
883.25806,-25.76156,-446.10769
883.72406,-22.00499,-304.85779
884.38200,-15.44136,-152.51606
885.54600,-5.54255,-22.28398
886.60206,-2.18393,0.26755
887.76006,-13.22633,-137.52641
888.58606,-20.24748,-289.94422
889.19400,-25.41514,-432.93223
889.63606,-22.86865,-331.62966
890.20606,-16.85364,-179.06051
891.32406,-7.32744,-39.38576
892.39000,-0.07181,0.60798
893.57606,-11.76448,-112.00910
894.45200,-19.21037,-264.23210
895.12206,-24.90609,-417.32542
895.55806,-23.60741,-356.67062
896.06606,-17.99210,-202.65063
897.12206,-8.94290,-57.17626
898.17806,0.03366,0.65032
899.37806,-10.18102,-86.95008
900.31400,-18.13918,-238.80528
901.00806,-24.03843,-391.74750
901.48206,-24.29696,-382.44989
901.93806,-19.12415,-228.66311
902.90606,-10.67673,-78.64468
904.10600,-0.47682,0.59204
905.16600,-8.46691,-62.68575
906.17006,-17.01705,-213.42222
906.89000,-23.13752,-366.16478
907.41006,-24.91333,-408.67016
907.83406,-20.17047,-254.54842
908.69200,-12.39341,-102.68168
909.89200,-2.19416,-0.05327
910.95406,-6.68243,-40.18496
912.02000,-15.84410,-188.35016
912.77000,-22.21945,-341.03863
913.34000,-25.44958,-433.94610
913.73806,-21.14533,-280.32074
914.48806,-14.02668,-128.17434
915.67806,-3.90993,-9.09673
916.74206,-4.52254,-16.40725
917.85806,-14.56927,-162.71168
918.64406,-21.25063,-315.38874
919.18606,-25.76132,-445.95834
919.65000,-22.02275,-305.28553
920.30600,-15.47591,-153.03690
921.47006,-5.57651,-22.49748
922.53000,-2.18399,0.23520
923.68806,-13.22639,-137.42541
924.51200,-20.23031,-289.28952
925.12206,-25.41514,-432.73970
925.56400,-22.86703,-331.47514
926.13606,-16.83553,-178.68754
927.25400,-7.31034,-39.14563
928.31806,-0.07103,0.58324
929.50606,-11.78158,-112.16715
930.38200,-19.22759,-264.43969
931.05206,-24.92319,-417.60810
931.48600,-23.60627,-356.52950
931.99206,-18.00997,-202.94128
933.05006,-8.94290,-57.10616
934.10600,0.03360,0.61696
935.30600,-10.18096,-86.88257
936.24206,-18.13918,-238.62777
936.93400,-24.02169,-391.08228
937.41006,-24.30443,-382.60039
937.86806,-19.11219,-228.36031
938.83806,-10.64247,-78.18834
940.03800,-0.44238,0.62003
941.09406,-8.46673,-62.60867
942.10006,-17.03379,-213.56525
942.82006,-23.15480,-366.45588
943.33806,-24.91393,-408.55896
943.76406,-20.14529,-253.80997
944.62400,-12.35962,-102.06278
945.82406,-2.15936,0.04867
946.88200,-6.68166,-40.03765
947.94806,-15.84410,-188.14463
948.69806,-22.21951,-340.89655
949.26806,-25.45179,-433.85882
949.66600,-21.14641,-280.20333
950.41406,-14.04401,-128.33320
951.60406,-3.92697,-9.13723
952.67006,-4.52152,-16.32702
953.78606,-14.56927,-162.54470
954.57200,-21.25056,-315.20545
955.11406,-25.76222,-445.78459
955.57806,-22.03177,-305.40083
956.23406,-15.47579,-152.90003
957.39606,-5.59385,-22.58780
958.45806,-2.18088,0.29907
959.61600,-13.22633,-137.27190
960.44200,-20.24753,-289.48730
961.05006,-25.41514,-432.55080
961.49400,-22.85280,-330.85953
962.06806,-16.80061,-177.87056
963.18606,-7.27626,-38.73545
964.24606,-0.06774,0.63924
965.43606,-11.79862,-112.29925
966.31206,-19.24445,-264.60348
966.98206,-24.94029,-417.87826
967.41206,-23.62905,-357.19108
967.91406,-18.06444,-203.94482
968.97006,-9.01046,-57.83042
970.03406,0.03354,0.63179
971.23406,-10.18108,-86.71640
972.17206,-18.15622,-238.80102
972.86406,-24.03843,-391.32476
973.33606,-24.32261,-383.12525
973.79006,-19.16134,-229.33807
974.75806,-10.71051,-78.94411
975.95806,-0.51096,0.65143
977.02206,-8.46685,-62.48219
978.03000,-17.05095,-213.68105
978.74606,-23.13758,-365.76487
979.26606,-24.91608,-408.45085
979.68806,-20.19366,-254.89900
980.54806,-12.39341,-102.51524
981.74806,-2.19416,0.05313
982.81006,-6.68363,-39.95529
983.87606,-15.84410,-187.95658
984.62400,-22.20241,-340.21016
985.19606,-25.45424,-433.77742
985.59406,-21.14725,-280.13162
986.34406,-14.02668,-127.95810
987.53406,-3.91005,-8.99883
988.59800,-4.52272,-16.28094
989.71406,-14.56921,-162.33616
990.49806,-21.23340,-314.49668
991.04206,-25.76150,-445.61662
991.50606,-22.02645,-305.11215
992.16206,-15.47568,-152.80609
993.32406,-5.59379,-22.50309
994.38606,-2.18028,0.33300
995.54600,-13.24361,-137.41370
996.37206,-20.26463,-289.77474
996.97800,-25.41514,-432.33663
997.42206,-22.84958,-330.63337
998.00206,-16.74740,-176.70123
999.12606,-7.17462,-37.64577
1000.17406,-0.06571,0.62429
1001.36206,-11.78152,-111.86005
1002.24006,-19.24445,-264.49781
1002.90800,-24.92331,-417.22994
1003.34000,-23.63079,-357.08997
1003.84206,-18.06390,-203.84718
1004.89806,-9.01046,-57.74990
1005.96206,0.03360,0.68812
1007.16206,-10.18108,-86.59351
1008.10006,-18.15622,-238.59527
1008.79406,-24.05559,-391.66689
1009.26606,-24.30216,-382.23982
1009.72006,-19.14011,-228.68581
1010.69006,-10.67679,-78.44362
1011.89006,-0.47688,0.69205
1012.95006,-8.46787,-62.36510
1013.95606,-17.03379,-213.20006
1014.67406,-23.13758,-365.58308
1015.19400,-24.91835,-408.41479
1015.61600,-20.19020,-254.72445
1016.47606,-12.39347,-102.36690
1017.67600,-2.19416,0.05701
1018.73806,-6.68578,-39.99551
1019.80600,-15.86144,-188.12548
1020.55406,-22.21951,-340.45320
1021.12400,-25.45693,-433.71245
1021.52406,-21.12740,-279.41817
1022.27406,-14.00952,-127.55840
1023.46406,-3.89301,-8.78435
1024.52600,-4.52206,-16.18482
1025.64206,-14.56927,-162.20743
1026.42812,-21.25050,-314.79698
1026.97006,-25.76228,-445.40342
1027.43200,-22.05037,-305.71517
1028.08800,-15.49295,-153.04818
1029.25000,-5.61065,-22.60950
1030.31406,-2.18028,0.35320
1031.47400,-13.24361,-137.22117
1032.29812,-20.24760,-289.16776
1032.90600,-25.41520,-432.19835
1033.35012,-22.84659,-330.41537
1033.92406,-16.80175,-177.64946
1035.04406,-7.25940,-38.49233
1036.10206,-0.06965,0.65494
1037.29006,-11.78158,-111.74216
1038.16806,-19.24451,-264.25982
1038.83413,-24.90615,-416.51469
1039.27000,-23.61171,-356.30535
1039.77212,-18.04579,-203.35250
1040.83006,-8.97656,-57.28996
1041.89000,0.03366,0.68474
1043.09006,-10.18096,-86.44582
1044.02806,-18.15622,-238.43613
1044.72006,-24.03843,-390.96743
1045.19406,-24.30324,-382.12389
1045.64806,-19.14005,-228.57508
1046.61606,-10.69377,-78.53094
1047.81606,-0.49398,0.69046
1048.87800,-8.46757,-62.29812
1049.88612,-17.05095,-213.41331
1050.60400,-23.15486,-365.88386
1051.12213,-24.91919,-408.36584
1051.54812,-20.13920,-253.31564
1052.40812,-12.35969,-101.79040
1053.60800,-2.15936,0.15187
1054.66600,-6.68435,-39.79400
1055.73400,-15.86138,-187.91685
1056.48400,-22.23625,-340.77361
1057.05200,-25.45688,-433.60531
1057.45200,-21.12232,-279.19404
1058.20200,-14.00952,-127.47061
1059.39213,-3.89307,-8.77254
1060.45412,-4.53043,-16.20249
1061.57200,-14.58631,-162.41184
1062.35800,-21.26772,-315.03603
1062.89812,-25.76198,-445.28127
1063.36200,-22.02639,-304.92906
1064.02212,-15.44166,-152.04073
1065.18412,-5.55947,-22.05521
1066.24212,-2.17771,0.33051
1067.40212,-13.24361,-137.07332
1068.22612,-20.24760,-288.93169
1068.83413,-25.41520,-432.04807
1069.27600,-22.87140,-331.14929
1069.84800,-16.83648,-178.28139
1070.96612,-7.31040,-38.90678
1072.03000,-0.06427,0.61739
1073.21800,-11.78152,-111.58145
1074.09612,-19.24445,-264.14147
1074.76400,-24.92331,-416.83119
1075.19800,-23.61243,-356.19926
1075.70012,-18.04686,-203.25508
1076.75800,-8.97656,-57.24046
1077.81800,0.03354,0.65042
1079.01812,-10.18108,-86.30881
1079.95600,-18.15622,-238.24427
1080.65000,-24.05559,-391.27961
1081.12213,-24.30455,-382.02211
1081.57800,-19.11913,-227.96469
1082.55000,-10.64253,-77.83926
1083.75000,-0.44232,0.63626
1084.80600,-8.46763,-62.21522
1085.81413,-17.05095,-213.22299
1086.53400,-23.17196,-366.17577
1087.05000,-24.92164,-408.31182
1087.47612,-20.14344,-253.37745
1088.33800,-12.34271,-101.44123
1089.53812,-2.14220,0.20954
1090.59400,-6.68417,-39.73110
1091.66212,-15.86144,-187.77272
1092.41000,-22.21951,-340.11085
1092.98012,-25.45789,-433.53055
1093.38000,-21.12136,-279.05921
1094.13400,-13.97580,-126.85056
1095.32413,-3.85911,-8.47632
1096.38213,-4.52762,-16.10966
1097.50000,-14.58637,-162.24988
1098.28600,-21.26778,-314.85692
1098.82600,-25.76198,-445.11233
1099.29200,-22.00224,-304.11808
1099.95012,-15.44183,-151.93698
1101.11200,-5.55953,-22.07008
1102.17000,-2.17921,0.38272
1103.32800,-13.22639,-136.62632
1104.15600,-20.26463,-289.17836
1104.76212,-25.41520,-431.90144
1105.20800,-22.82805,-329.65194
1105.78212,-16.78369,-177.15354
1106.90212,-7.24248,-38.20073
1107.95800,-0.06272,0.63503
1109.14600,-11.78158,-111.48201
1110.02212,-19.22765,-263.52879
1110.69200,-24.92337,-416.73865
1111.12400,-23.63306,-356.87819
1111.62800,-18.04872,-203.25661
1112.68412,-8.99354,-57.36206
1113.74613,0.03354,0.64809
1114.94600,-10.18096,-86.22615
1115.88612,-18.17326,-238.51883
1116.58012,-24.07275,-391.63038
1117.04812,-24.32907,-382.87811
1117.50212,-19.16116,-228.83728
1118.47200,-10.69383,-78.42933
1119.67200,-0.49392,0.67782
1120.73400,-8.46829,-62.06726
1121.74212,-17.05101,-213.07312
1122.46200,-23.17196,-366.00359
1122.97800,-24.92266,-408.23977
1123.40212,-20.16007,-253.72904
1124.26400,-12.35986,-101.60919
1125.46412,-2.15948,0.24059
1126.52212,-6.68769,-39.69649
1127.59012,-15.86150,-187.63002
1128.33600,-22.20259,-339.44041
1128.90812,-25.45933,-433.44904
1129.30812,-21.12046,-279.02247
1130.06200,-13.97586,-126.78443
1131.25212,-3.85917,-8.43147
1132.31000,-4.52977,-16.06807
1133.42813,-14.58637,-162.10474
1134.21200,-21.25068,-314.28285
1134.75400,-25.76222,-444.91906
1135.22200,-21.97940,-303.39455
1135.88213,-15.40704,-151.24801
1137.04812,-5.49179,-21.46201
1138.09800,-2.18052,0.40224
1139.25800,-13.24361,-136.82348
1140.08413,-20.26476,-289.02506
1140.69013,-25.41532,-431.68653
1141.13612,-22.82662,-329.54656
1141.71012,-16.78285,-177.03913
1142.83012,-7.24248,-38.11192
1143.88612,-0.06146,0.61558
1145.07413,-11.78170,-111.35440
1145.95200,-19.24445,-263.79451
1146.62400,-24.95733,-417.56671
1147.05413,-23.61494,-356.09458
1147.55812,-18.02635,-202.67835
1148.61400,-8.97662,-57.11173
1149.67412,0.03360,0.69961
1150.87400,-10.18096,-86.16095
1151.81600,-18.19018,-238.73480
1152.50800,-24.07269,-391.43369
1152.98012,-24.28679,-381.16168
1153.43412,-19.11375,-227.63440
1154.40812,-10.62531,-77.47400
1155.60800,-0.42522,0.71522
1156.66212,-8.46781,-62.01335
1157.66812,-17.03391,-212.57021
1158.38612,-23.13770,-364.86834
1158.90812,-24.90382,-407.29612
1159.33200,-20.13382,-252.97008
1160.19412,-12.34276,-101.30926
1161.39400,-2.14226,0.18274
1162.45012,-6.68841,-39.64395
1163.51812,-15.86150,-187.49867
1164.26613,-22.21945,-339.75530
1164.83600,-25.46082,-433.39539
1165.23800,-21.09936,-278.26145
1165.99012,-13.97580,-126.67281
1167.18200,-3.84207,-8.32641
1168.23800,-4.53067,-16.02081
1169.35612,-14.58637,-161.91125
1170.14000,-21.25068,-314.07665
1170.68200,-25.76222,-444.81877
1171.14600,-22.02573,-304.62455
1171.80413,-15.45875,-152.09736
1172.96800,-5.55953,-22.02103
1174.02600,-2.17682,0.39920
1175.18600,-13.24361,-136.72133
1176.01212,-20.26469,-288.86519
1176.61800,-25.41526,-431.53383
1177.06413,-22.82757,-329.39646
1177.64213,-16.74853,-176.33781
1178.76212,-7.20864,-37.72145
1179.81413,-0.05985,0.66159
1181.00212,-11.78170,-111.22430
1181.88000,-19.24451,-263.62542
1182.54600,-24.90609,-415.92699
1182.98400,-23.59365,-355.20319
1183.48800,-18.01189,-202.29019
1184.54600,-8.94307,-56.62999
1185.60200,0.03354,0.67720
1186.80200,-10.18102,-86.03918
1187.74212,-18.17326,-238.20333
1188.43600,-24.07275,-391.25126
1188.90812,-24.28865,-381.10748
1189.36200,-19.11363,-227.55513
1190.33413,-10.64253,-77.63446
1191.53400,-0.44238,0.61606
1192.59012,-8.46685,-61.93677
1193.60012,-17.06829,-213.13781
1194.31600,-23.15486,-365.19017
1194.83600,-24.90705,-407.29579
1195.26000,-20.13645,-252.92775
1196.12213,-12.34271,-101.20875
1197.32200,-2.14232,0.23732
1198.28000,0.02164,0.59339
1199.48012,0.01638,0.70129
1200.68000,0.01638,0.67582
1201.88000,0.01638,0.66694
1203.08012,0.01638,0.67081
1204.28000,0.01638,0.69548
1205.48012,0.01638,0.66718
1206.68000,0.01638,0.69605
1207.88000,0.01638,0.68879
1209.08012,0.01638,0.69698
1210.28000,0.01638,0.68828
1211.48012,0.01638,0.72053
1212.68000,0.01638,0.69059
1213.88000,0.01638,0.72798
1215.08012,0.01638,0.62844
1216.28000,0.01638,0.67431
1217.48012,0.01638,0.67922
1218.68000,0.01638,0.70802
1219.88000,0.01638,0.66214
1221.08012,0.01638,0.64334
1222.28000,0.01638,0.68958
1223.48012,0.01638,0.71426
1223.67000,0.01638,0.70086