File: ball-data/compression/Wilson Extra Duty.is_comp_RawData/Specimen_RawData_1.csv
Time,Extension,Load
(sec),(mm),(N)
0.00000,0.00006,-0.11767
1.22600,-10.42077,-135.06217
2.07800,-17.66260,-300.45714
2.78800,-23.69787,-465.91364
3.31600,-24.13056,-428.29435
3.76800,-19.14962,-260.85166
4.71600,-10.76074,-95.82663
5.98200,0.00036,-0.02686
7.10200,-9.49535,-100.53238
8.02000,-17.30577,-265.82142
8.70800,-23.15420,-431.08389
9.24600,-24.68045,-448.60929
9.67000,-20.06805,-281.83680
10.51400,-12.34235,-117.59433
11.80800,-1.34311,0.00202
12.91800,-8.04175,-74.05241
13.90400,-16.45610,-239.24131
14.61200,-22.47386,-405.22303
15.20200,-24.95422,-460.12156
15.61400,-20.51778,-292.70209
16.41800,-13.02233,-127.04002
17.70600,-2.07392,-0.95166
18.81200,-7.23238,-60.27406
19.83200,-15.97988,-224.82015
20.55200,-22.09994,-390.61680
21.16000,-25.19733,-471.60644
21.56000,-20.93948,-303.76965
22.31800,-13.73706,-138.04416
23.59600,-2.87300,-4.34562
24.70800,-6.38253,-46.90136
25.75600,-15.46988,-210.94274
26.48800,-21.69229,-376.21941
27.11800,-25.42889,-482.61330
27.51000,-21.32034,-314.42139
28.22400,-14.40072,-148.90471
29.48800,-3.65451,-9.38251
30.61000,-5.48341,-33.80884
31.68000,-14.95993,-197.97251
32.42800,-21.31795,-363.50176
33.06400,-25.68796,-495.36206
33.45600,-21.74760,-327.22693
34.12800,-15.08441,-160.78547
35.37400,-4.48804,-15.99604
36.50400,-4.44750,-20.61709
37.60200,-14.43277,-185.33679
38.36600,-20.92656,-350.72748
38.94800,-25.76449,-498.46523
39.40800,-22.09838,-338.13398
40.04200,-15.68255,-171.75628
41.27000,-5.23636,-22.72428
42.38800,-3.30797,-8.40488
43.51800,-13.85484,-172.30444
44.29800,-20.48502,-336.89115
44.88000,-25.43212,-484.78037
45.35800,-22.47458,-350.41172
45.95400,-16.30543,-183.73495
47.15600,-6.06875,-30.96814
48.27200,-2.18549,-0.69708
49.42800,-13.22580,-158.88900
50.23200,-20.05968,-323.94111
50.86200,-25.41514,-483.29141
51.31000,-22.82548,-362.37273
51.87000,-16.89717,-195.69498
53.04400,-6.88500,-39.64409
54.15600,-1.10742,0.06782
55.33800,-12.59687,-146.01894
56.16400,-19.61789,-310.75902
56.82400,-25.22794,-476.54003
57.26200,-23.17477,-374.84046
57.78800,-17.49154,-208.36299
58.92600,-7.75213,-49.39713
60.04000,-0.11952,0.02294
61.24200,-11.91611,-132.80530
62.09400,-19.15841,-297.33088
62.76000,-24.82035,-462.99651
63.21600,-23.49907,-386.83515
63.72000,-17.97129,-219.12366
64.82400,-8.48264,-57.95282
66.02400,-0.11916,0.01190
67.23000,-11.95037,-132.92793
68.08400,-19.20977,-297.95744
68.74800,-24.85390,-463.41889
69.20001,-23.49638,-386.33257
69.70400,-17.97308,-218.82541
70.80801,-8.48264,-57.82298
72.00800,-0.11886,0.03992
73.22000,-12.00125,-133.45471
74.07001,-19.22681,-297.83098
74.73200,-24.85390,-462.72784
75.18401,-23.49667,-385.98407
75.68401,-18.01195,-219.45039
76.78600,-8.53352,-58.26043
77.89201,0.42146,0.02356
79.11601,-11.25274,-119.66656
79.99800,-18.75100,-284.48289
80.67001,-24.46299,-450.01242
81.13800,-23.81619,-398.46025
81.61800,-18.50700,-231.32345
82.67201,-9.36698,-68.62465
83.77600,0.01728,0.03948
85.01801,-10.55464,-107.01817
85.92800,-18.29212,-271.76756
86.61000,-24.08949,-437.82026
87.09200,-24.13260,-411.38496
87.56001,-18.95961,-242.72714
88.56201,-10.16625,-79.27241
89.76000,0.01734,0.05291
91.00201,-10.55464,-106.78653
91.91400,-18.30904,-271.76131
92.59600,-24.10641,-437.84913
93.07601,-24.13391,-411.12684
93.54000,-19.00212,-243.53331
94.54201,-10.20027,-79.55223
95.74400,0.01728,0.06446
96.98801,-10.57162,-106.79422
97.89800,-18.30892,-271.29194
98.57601,-24.07239,-436.36031
99.06001,-24.13200,-410.76299
99.52600,-18.98083,-242.73070
100.53001,-10.16619,-78.94578
101.72801,0.01734,0.05134
102.97401,-10.58872,-106.87680
103.88400,-18.32596,-271.26960
104.56201,-24.08937,-436.43087
105.04401,-24.13290,-410.47897
105.51201,-18.95686,-241.92279
106.52001,-10.11537,-78.11901
107.71201,0.01728,0.06146
108.95400,-10.55458,-105.99529
109.87000,-18.34294,-271.34951
110.55000,-24.12339,-437.01906
111.02801,-24.13314,-410.19268
111.49201,-19.00027,-242.86192
112.49600,-10.18323,-78.90058
113.69601,0.01728,0.07105
114.94601,-10.62274,-106.95428
115.85800,-18.37708,-271.89631
116.53600,-24.14037,-437.18517
117.01201,-24.13021,-409.83159
117.48000,-18.95303,-241.46121
118.48801,-10.11537,-77.85334
119.68001,0.01728,0.06294
120.92600,-10.58866,-106.20764
121.84001,-18.36016,-271.04059
122.51801,-24.12327,-436.20426
122.99600,-24.13481,-409.74285
123.46001,-19.00469,-242.54059
124.46600,-10.16625,-78.44458
125.66401,0.01728,0.04318
126.91200,-10.60594,-106.29051
127.82401,-18.36016,-270.74995
128.50602,-24.15735,-436.95509
128.98001,-24.13403,-409.48246
129.44802,-18.95829,-241.19074
130.45401,-10.13253,-77.89426
131.64802,0.01728,0.08238
132.89802,-10.62280,-106.38729
133.81002,-18.37714,-270.85433
134.49000,-24.15741,-436.59724
134.96400,-24.13529,-409.27414
135.43200,-18.96338,-241.18936
136.44000,-10.11543,-77.55167
137.63200,0.01728,0.06914
138.88200,-10.62274,-106.22298
139.79600,-18.39412,-271.05274
140.47402,-24.15741,-436.28894
140.94802,-24.13355,-409.05897
141.41600,-18.95208,-240.71388
142.42402,-10.11543,-77.41819
143.61602,0.01728,0.04557
144.86602,-10.62286,-106.05118
145.78002,-18.39412,-270.73644
146.45800,-24.15747,-436.03875
146.93200,-24.13403,-408.84305
147.40002,-18.95303,-240.53557
148.41000,-10.09803,-77.10164
149.60000,0.01728,0.06032
150.85000,-10.62274,-105.85142
151.76600,-18.41110,-270.91557
152.44400,-24.17445,-436.28030
152.91600,-24.13397,-408.63942
153.38400,-18.95226,-240.34927
154.39202,-10.11549,-77.22916
155.58402,0.01728,0.03937
156.83602,-10.63966,-106.03555
157.75202,-18.42814,-271.04165
158.43200,-24.20835,-436.99428
158.93002,-23.81745,-395.20402
159.41400,-18.45833,-227.54887
160.48002,-9.23120,-65.38596
161.66802,0.42116,0.01286
162.90400,-11.35480,-118.19601
163.79200,-18.90406,-283.39252
164.46400,-24.61599,-449.52698
164.94400,-23.49817,-382.28262
165.45202,-17.93021,-214.57730
166.56602,-8.36365,-54.52937
167.75202,-0.11545,0.04599
168.97402,-12.08639,-131.13364
169.83200,-19.38041,-295.95805
170.49400,-25.00702,-461.59342
170.96000,-23.15259,-368.89438
171.49600,-17.37704,-201.84679
172.65002,-7.51416,-44.47929
173.83602,-1.10497,0.06113
175.03802,-12.76703,-143.60324
175.87002,-19.83888,-308.26513
176.52600,-25.41520,-474.41743
176.97602,-22.80431,-355.92459
177.54600,-16.79158,-189.07208
178.73402,-6.66390,-34.91494
179.92002,-2.18842,-0.11385
181.10200,-13.44732,-156.43587
181.91200,-20.33184,-321.71384
182.51202,-25.43206,-474.67876
182.99400,-22.42967,-342.52852
183.60000,-16.18251,-176.36154
184.81602,-5.83127,-26.07221
186.00402,-3.31240,-6.10476
187.16000,-14.07594,-168.89451
187.94802,-20.77416,-333.90246
188.54600,-25.75684,-487.35298
189.01202,-22.05162,-329.60981
189.65800,-15.54623,-163.78975
190.90002,-4.98136,-17.83043
192.08802,-4.45838,-17.04761
193.21600,-14.68813,-181.42357
193.98800,-21.25008,-347.15872
194.63000,-25.69795,-485.24212
195.03202,-21.65115,-316.33351
195.72402,-14.84466,-150.65794
196.98800,-4.09702,-10.31380
198.16602,-5.54817,-29.55165
199.27000,-15.28261,-194.00418
200.02200,-21.67543,-359.19331
200.65002,-25.46255,-472.73748
201.04800,-21.29164,-304.81821
201.78602,-14.17986,-138.69784
203.06402,-3.31491,-4.71582
204.23800,-6.49308,-42.04668
205.32400,-15.87836,-207.06777
206.06002,-22.13401,-372.50914
206.66402,-25.20253,-458.87228
207.07400,-20.81978,-290.42114
207.86602,-13.36301,-124.82107
209.15800,-2.37986,-0.51053
210.31802,-7.39925,-54.66347
211.37002,-16.40456,-219.06050
212.09402,-22.55924,-384.82849
212.67402,-24.95829,-445.67373
213.09800,-20.36789,-277.16259
213.94402,-12.56327,-111.97491
215.24200,-1.53061,0.10586
216.40202,-8.28748,-67.45059
217.41802,-16.94943,-231.76879
218.12800,-22.98458,-397.40819
218.68400,-24.70484,-432.82207
219.12202,-19.91899,-264.55052
220.02200,-11.76406,-99.85340
221.32200,-0.71407,0.10309
222.48202,-9.11820,-79.95241
223.46200,-17.45895,-244.11591
224.16000,-23.39210,-409.48287
224.69602,-24.42311,-419.49626
225.14802,-19.44528,-251.70844
226.10802,-10.89676,-87.15566
227.39002,0.00012,0.09181
228.55802,-9.90616,-92.32149
229.50602,-17.96890,-256.84239
230.19602,-23.83413,-422.81270
230.70800,-24.13589,-406.69452
231.17602,-18.95148,-238.87403
232.18800,-10.08117,-75.79327
233.37600,0.01722,0.06118
234.63000,-10.65712,-104.75651
235.54800,-18.46210,-269.36321
236.22802,-24.24243,-435.23092
236.72202,-23.81805,-393.41144
237.20602,-18.45845,-226.12859
238.27802,-9.17960,-63.88392
239.46000,0.42170,0.05011
240.70402,-11.42278,-117.81396
241.59402,-18.98903,-283.12335
242.26600,-24.70179,-449.43634
242.73402,-23.52173,-381.40073
243.24000,-17.97099,-214.21697
244.35402,-8.39785,-54.12714
245.54400,-0.11318,0.04537
246.77202,-12.13793,-130.45517
247.63602,-19.48223,-296.07030
248.29802,-25.10896,-462.26859
248.75202,-23.15277,-367.20805
249.29002,-17.36090,-200.18775
250.44802,-7.46304,-43.04906
251.62800,-1.10306,0.07737
252.83602,-12.81791,-142.89965
253.67202,-19.92449,-308.00493
254.31802,-25.41520,-471.98407
254.76800,-22.80180,-354.22809
255.34002,-16.77287,-187.47170
256.53202,-6.61332,-33.65387
257.71200,-2.18704,-0.01105
258.89802,-13.48134,-155.50897
259.71002,-20.38290,-320.61175
260.30402,-25.43218,-472.34003
260.78403,-22.44934,-341.74636
261.38800,-16.21671,-175.93849
262.60400,-5.86547,-25.85264
263.79603,-3.31186,-5.62089
264.95800,-14.12712,-168.20893
265.75000,-20.85882,-333.84625
266.33600,-25.74853,-484.75318
266.80200,-22.07417,-328.93389
267.45000,-15.54593,-162.69816
268.69203,-4.98136,-17.34098
269.88000,-4.46095,-16.39759
271.01203,-14.72215,-180.35697
271.78403,-21.28423,-345.78186
272.42203,-25.69705,-483.19690
272.82400,-21.64882,-314.92826
273.52003,-14.81052,-148.97923
274.78403,-4.06323,-9.63458
275.95800,-5.55594,-28.89832
277.07203,-15.36805,-194.07939
277.82400,-21.76045,-359.39213
278.44203,-25.46405,-470.99173
278.84200,-21.26838,-302.85610
279.58200,-14.14560,-137.19107
280.86003,-3.28125,-4.20640
282.03403,-6.53595,-41.78877
283.12003,-15.91208,-206.00330
283.85800,-22.18490,-371.73625
284.45603,-25.20223,-457.09316
284.86603,-20.81865,-289.19615
285.65600,-13.38011,-124.21000
286.94803,-2.39702,-0.38238
288.11400,-7.43853,-54.28716
289.17400,-16.50722,-219.56809
289.89603,-22.64396,-385.15572
290.46600,-24.95901,-444.02704
290.88800,-20.38983,-276.63011
291.73203,-12.59753,-111.72001
293.03000,-1.56427,0.07976
294.19803,-8.32294,-66.98105
295.21803,-17.01723,-231.59690
295.92603,-23.03504,-396.77873
296.47600,-24.70795,-431.38131
296.91400,-19.93711,-263.93466
297.81803,-11.73010,-98.50872
299.11800,-0.68034,0.08216
300.27600,-9.13631,-79.23212
301.26400,-17.54445,-244.34885
301.96600,-23.51145,-411.06619
302.48603,-24.44536,-419.01071
302.93803,-19.46196,-251.04750
303.89800,-10.91374,-86.67033
305.18200,0.00006,0.08709
306.35603,-9.95752,-92.11486
307.31003,-18.07114,-257.51771
307.99600,-23.90181,-422.92949
308.49803,-24.15681,-406.26422
308.96600,-18.96326,-238.11202
309.98000,-10.08117,-75.17474
311.16803,0.01722,0.10539
312.43200,-10.74208,-105.03192
313.35203,-18.56380,-270.12747
314.03003,-24.32709,-436.00678
314.51203,-23.84106,-392.99972
314.99600,-18.47478,-225.55480
316.06403,-9.23138,-63.94455
317.25200,0.42307,0.04173
318.50000,-11.45704,-117.27894
319.39203,-19.04015,-282.58571
320.06200,-24.73510,-448.70671
320.52600,-23.52047,-380.11305
321.03403,-17.94797,-212.74030
322.15200,-8.34673,-52.99971
323.33603,-0.11234,0.02243
324.56803,-12.17213,-129.93415
325.43200,-19.51625,-295.23199
326.09200,-25.12588,-461.02729
326.54400,-23.15348,-366.04907
327.08400,-17.34141,-198.90442
328.24200,-7.44618,-42.36503
329.42000,-1.10072,0.07194
330.63400,-12.86897,-142.68992
331.47200,-19.99218,-308.11165
332.11003,-25.41520,-470.23915
332.55800,-22.82524,-353.95648
333.13203,-16.77305,-186.63649
334.32400,-6.61338,-33.20494
335.50403,-2.18381,0.00674
336.69403,-13.51530,-154.93020
337.51000,-20.45094,-320.78587
338.09600,-25.43212,-470.68775
338.57603,-22.45054,-340.66316
339.18403,-16.18263,-174.42420
340.40403,-5.79737,-24.76775
341.58800,-3.31443,-5.25200
342.75600,-14.17800,-168.03397
343.54800,-20.90988,-333.59639
344.12803,-25.74877,-483.13506
344.59403,-22.07189,-327.77283
345.24403,-15.52787,-161.64137
346.48800,-4.94692,-16.64991
347.67203,-4.46747,-15.97173
348.81003,-14.77327,-180.14187
349.58400,-21.35203,-346.05455
350.21200,-25.70799,-482.28662
350.61400,-21.66861,-314.56258
351.30800,-14.84460,-148.91276
352.57203,-4.09702,-9.57899
353.75200,-5.58625,-28.68324
354.86400,-15.36811,-192.78387
355.61603,-21.76039,-357.66609
356.23400,-25.46447,-469.59735
356.63400,-21.26414,-301.75619
357.38000,-14.09454,-135.66951
358.66000,-3.21267,-3.56076
359.82603,-6.53924,-41.20560
360.92000,-15.98012,-206.21529
361.65803,-22.25341,-372.04403
362.24600,-25.22399,-456.90984
362.65600,-20.84005,-288.93795
363.44403,-13.41431,-124.18523
364.73603,-2.43098,-0.38621
365.90803,-7.45432,-53.83173
366.96803,-16.52420,-218.61905
367.69000,-22.66088,-384.08171
368.25600,-24.98137,-443.98144
368.68003,-20.38553,-275.66602
369.52603,-12.58037,-110.87936
370.82400,-1.54747,0.11552
371.99200,-8.30578,-66.06242
373.01800,-17.05107,-231.06944
373.72600,-23.06936,-396.19695
374.27003,-24.72750,-431.21722
374.70800,-19.93322,-262.95003
375.61203,-11.74708,-98.23971
376.91203,-0.69715,0.11546
378.07603,-9.17045,-78.97540
379.06403,-17.57799,-243.80447
379.76000,-23.49428,-409.01847
380.28200,-24.44697,-418.02861
380.73203,-19.47804,-250.71179
381.69203,-10.93084,-86.38375
382.97803,0.00006,0.06750
384.15403,-9.97474,-91.58444
385.10803,-18.08818,-256.52234
385.79400,-23.91885,-421.94311
386.29400,-24.15944,-405.28309
386.76203,-18.95572,-237.17141
387.78200,-10.03023,-73.97763
388.96403,0.01716,0.09669
390.23000,-10.75888,-104.48743
391.15403,-18.61522,-270.07142
391.83003,-24.36117,-435.55994
392.30800,-23.84393,-392.11683
392.79400,-18.45409,-224.17879
393.86800,-9.16274,-62.61921
395.04800,0.42277,0.06708
396.30003,-11.49154,-116.99612
397.19203,-19.07405,-282.07762
397.86003,-24.75184,-447.82501
398.32203,-23.52143,-379.26514
398.82603,-17.98384,-212.85033
399.94403,-8.38081,-52.91407
401.13403,-0.09196,0.06270
402.37003,-12.18917,-129.29974
403.23800,-19.56713,-295.20111
403.89800,-25.17682,-461.30780
404.34200,-23.17626,-365.98258
404.87600,-17.41160,-199.78436
406.03200,-7.53126,-42.97125
407.22003,-1.09839,0.07578
408.43600,-12.88583,-142.02164
409.27403,-20.00921,-307.21463
409.91003,-25.41526,-468.93332
410.35803,-22.82697,-353.09333
410.93200,-16.77269,-185.86876
412.12600,-6.59616,-32.65839
413.30403,-2.18411,0.02636
414.49803,-13.54896,-154.63167
415.31200,-20.46792,-319.84948
415.89603,-25.43218,-469.38777
416.37600,-22.45198,-339.88677
416.98400,-16.18304,-173.80850
418.20400,-5.79737,-24.41881
419.38803,-3.31282,-4.92603
420.55603,-14.17806,-167.02600
421.35203,-20.94378,-333.15443
421.92800,-25.74871,-481.85889
422.39400,-22.07297,-327.01250
423.04803,-15.49493,-160.39109
424.29400,-4.89592,-15.93539
425.47200,-4.46675,-15.55443
426.61203,-14.79025,-179.48234
427.38603,-21.36919,-345.12803
428.01203,-25.70972,-481.33019
428.41403,-21.66772,-313.77889
429.11203,-14.81052,-147.66818
430.37600,-4.06329,-9.04322
431.55403,-5.57137,-28.02781
432.67400,-15.41917,-192.80491
433.42800,-21.82831,-358.32398
434.04000,-25.45000,-467.77979
434.44003,-21.24046,-300.23418
435.19203,-14.02680,-133.94802
436.47403,-3.12807,-2.94426
437.63403,-6.54253,-40.73340
438.72803,-15.98006,-205.14626
439.46803,-22.27069,-371.19266
440.05403,-25.22519,-455.93970
440.46403,-20.83425,-288.02738
441.26203,-13.32846,-122.28667
442.55403,-2.34608,-0.12413
443.71603,-7.45862,-53.36023
444.78003,-16.55787,-218.30324
445.50003,-22.67780,-383.25984
446.06403,-24.98304,-443.04214
446.48603,-20.40526,-275.46303
447.33400,-12.58037,-110.36177
448.63203,-1.54747,0.11672
449.80403,-8.34046,-65.93453
450.83203,-17.10231,-231.09797
451.54203,-23.13728,-396.90912
452.07803,-24.73067,-430.38305
452.51603,-19.92204,-261.93498
453.42400,-11.71318,-97.24149
454.72403,-0.66348,0.13506
455.89000,-9.18827,-78.57685
456.88003,-17.61231,-243.53182
457.57803,-23.54498,-409.19501
458.09403,-24.44924,-417.17812
458.54603,-19.44498,-249.10219
459.51400,-10.84576,-84.69396
460.79203,0.01716,0.10172
461.97200,-9.99214,-91.20397
462.93003,-18.13948,-256.70508
463.61603,-23.96979,-422.22407
464.11003,-24.16082,-404.49250
464.57803,-18.94496,-236.12732
465.60403,-9.97953,-72.80935
466.78200,0.03408,0.09660
468.05003,-10.75912,-103.77969
468.97403,-18.61528,-268.90066
469.64800,-24.34437,-433.83878
470.12803,-23.84531,-391.26683
470.61203,-18.46760,-223.83260
471.68803,-9.16274,-62.22466
472.87003,0.44053,0.13222
474.12403,-11.49166,-116.23207
475.02203,-19.12493,-282.24774
475.69203,-24.82054,-448.74784
476.14603,-23.52274,-378.45209
476.65603,-17.92268,-210.72473
477.77603,-8.31295,-51.71375
478.95800,-0.08921,0.08877
480.19803,-12.22325,-129.17753
481.06200,-19.56713,-294.01744
481.71803,-25.14286,-459.01176
482.16803,-23.15558,-364.36852
482.71003,-17.31767,-197.06307
483.87200,-7.39542,-41.07377
485.04603,-1.07645,0.09144
486.26603,-12.90293,-141.57544
487.10603,-20.04312,-306.92812
487.73803,-25.41526,-467.74462
488.18803,-22.80330,-351.52715
488.76403,-16.73586,-184.57038
489.96203,-6.52860,-31.59241
491.13403,-2.16581,0.09914
492.33400,-13.58322,-154.45322
493.15003,-20.51946,-320.12131
493.72803,-25.43224,-468.31280
494.20803,-22.44916,-339.09258
494.82003,-16.14645,-172.56496
496.04203,-5.74619,-23.66251
497.22200,-3.29954,-4.59778
498.39603,-14.21208,-166.85473
499.19003,-20.96094,-332.49538
499.76403,-25.74865,-480.80705
500.23203,-22.04750,-325.52306
500.89000,-15.44213,-158.89393
502.13803,-4.82794,-15.09742
503.31003,-4.45593,-15.09072
504.45803,-14.84101,-179.72723
505.23000,-21.40315,-345.03281
505.85203,-25.71038,-480.30034
506.25600,-21.64237,-312.24303
506.95603,-14.77632,-146.57665
508.22200,-4.01205,-8.51373
509.39400,-5.57962,-27.78373
510.51403,-15.41917,-191.93498
511.27203,-21.86245,-358.19024
511.88003,-25.45293,-466.99397
512.28003,-21.23938,-299.61910
513.03003,-14.04390,-133.71785
514.31200,-3.14535,-2.91871
515.47400,-6.54085,-40.33259
516.57000,-15.99698,-204.63850
517.31000,-22.28767,-370.63938
517.89600,-25.20809,-454.14723
518.30603,-20.80866,-286.59754
519.11003,-13.26018,-120.75820
520.40203,-2.27804,0.00442
521.56000,-7.45766,-52.84496
522.62200,-16.54112,-217.00691
523.34803,-22.71200,-383.17598
523.91003,-24.96756,-441.39437
524.33406,-20.35492,-273.44897
525.19200,-12.46139,-108.15606
526.49006,-1.42837,0.10533
527.64800,-8.34052,-65.43626
528.67806,-17.11917,-230.59487
529.38406,-23.12018,-395.38387
529.92400,-24.71267,-428.69087
530.36200,-19.89986,-260.74830
531.27600,-11.64556,-95.80724
532.57606,-0.59514,0.10418
533.73400,-9.18791,-78.13610
534.72400,-17.61243,-242.61812
535.42400,-23.56185,-408.71821
535.94000,-24.43172,-415.63306
536.39200,-19.42453,-248.03195
537.36600,-10.77813,-83.39620
538.63606,0.01716,0.13896
539.81806,-10.00942,-90.94846
540.77406,-18.13942,-255.79862
541.46000,-23.96979,-421.22070
541.95606,-24.14444,-403.05886
542.42400,-18.92714,-235.20963
543.45200,-9.94551,-72.06055
544.62606,0.03402,0.14090
545.89406,-10.75900,-103.15424
546.82000,-18.63244,-268.40629
547.49606,-24.37815,-433.84288
547.97400,-23.82701,-389.82220
548.45800,-18.44679,-222.76843
549.53400,-9.14612,-61.69283
550.71406,0.44232,0.10504
551.97006,-11.50894,-115.93075
552.86400,-19.10813,-280.89365
553.53206,-24.78610,-446.72001
553.99200,-23.50475,-377.01018
554.50400,-17.88418,-209.29269
555.63000,-8.22817,-50.42283
556.80200,-0.08622,0.09391
558.04400,-12.24023,-128.85517
558.91006,-19.60097,-294.04264
559.57000,-25.21120,-460.24088
560.01200,-23.15630,-363.78048
560.55400,-17.32000,-196.61637
561.72006,-7.36122,-40.40046
562.89000,-1.07430,0.10583
564.11200,-12.92021,-141.23925
564.95406,-20.07690,-306.94557
565.58200,-25.41538,-466.84708
566.03206,-22.80491,-350.98698
566.61006,-16.71912,-183.73858
567.80600,-6.52860,-31.34612
568.97800,-2.16306,0.07394
570.17806,-13.58322,-153.79599
570.99400,-20.51946,-319.13567
571.57200,-25.43224,-467.31282
572.05400,-22.42686,-337.66415
572.67006,-16.09438,-171.03579
573.89406,-5.67845,-22.76000
575.06606,-3.29799,-4.44196
576.24400,-14.24599,-166.86603
577.04006,-21.01254,-332.94730
577.60806,-25.74954,-479.93083
578.07606,-22.05234,-325.02193
578.73400,-15.44285,-158.40756
579.98400,-4.81096,-14.73705
581.15406,-4.45557,-14.83702
582.30400,-14.85799,-179.30029
583.07800,-21.43723,-345.00279
583.69606,-25.71241,-479.58463
584.10006,-21.64565,-311.76468
584.80200,-14.75922,-145.85066
586.06806,-3.99519,-8.18866
587.23806,-5.57980,-27.45302
588.36006,-15.43639,-191.55733
589.11806,-21.87949,-357.78411
589.72400,-25.45574,-466.26318
590.12400,-21.23909,-299.05379
590.87400,-14.04384,-133.34973
592.15800,-3.12819,-2.67661
593.31806,-6.54587,-40.03346
594.41600,-16.01402,-204.25139
595.15600,-22.30477,-370.19975
595.74006,-25.21311,-453.60871
596.15000,-20.80932,-286.08812
596.95200,-13.27745,-120.66116
598.24400,-2.29514,0.00103
599.40406,-7.46017,-52.51721
600.47006,-16.57526,-217.05050
601.19400,-22.72904,-382.76654
601.75400,-24.97192,-440.82377
602.17806,-20.35707,-272.94362
603.03406,-12.47831,-108.09294
604.33200,-1.44541,0.18007
605.49200,-8.34243,-65.08814
606.52406,-17.13627,-230.25976
607.23400,-23.17130,-396.04899
607.76800,-24.71602,-428.09475
608.20606,-19.90153,-260.32070
609.12200,-11.62858,-95.26749
610.42206,-0.57816,0.11567
611.57800,-9.18791,-77.69057
612.57200,-17.64621,-242.60418
613.27206,-23.59647,-408.90098
613.78406,-24.43549,-415.07699
614.23400,-19.44630,-248.07485
615.20606,-10.81221,-83.54723
616.48006,0.01710,0.11957
617.66206,-10.00960,-90.46459
618.62200,-18.17374,-255.79363
619.31006,-24.02133,-421.86361
619.80006,-24.14665,-402.46036
620.26800,-18.92135,-234.45308
621.30200,-9.89474,-70.98908
622.47006,0.03396,0.11365
623.74006,-10.77622,-102.96071
624.66600,-18.64954,-267.98520
625.34206,-24.39513,-433.53550
625.81806,-23.82976,-389.31251
626.30400,-18.42300,-221.75351
627.38800,-9.06128,-60.29301
628.55806,0.44244,0.09965
629.81400,-11.50894,-115.38860
630.71000,-19.12505,-280.49340
631.37606,-24.78604,-445.80903
631.83606,-23.51156,-376.69491
632.34800,-17.88699,-208.85680
633.47406,-8.22823,-50.09462
634.64606,-0.08347,0.08998
635.88800,-12.24029,-128.28508
636.75806,-19.63505,-294.07803
637.41400,-25.21126,-459.38764
637.85600,-23.16048,-363.39682
638.39800,-17.31899,-196.15844
639.55806,-7.41252,-40.73035
640.73400,-1.07059,0.14790
641.95800,-12.93719,-141.02733
642.79806,-20.07690,-306.09140
643.42600,-25.41538,-465.99627
643.87606,-22.81083,-350.58305
644.45406,-16.71996,-183.34279
645.65206,-6.51150,-30.93880
646.82200,-2.15738,0.13509
648.02206,-13.58334,-153.24541
648.84000,-20.53662,-318.74023
649.41600,-25.43230,-466.46576
649.89800,-22.43147,-337.31688
650.51200,-16.11237,-170.95350
651.73600,-5.69531,-22.70958
652.91006,-3.29452,-4.23204
654.08800,-14.24604,-166.23968
654.88200,-20.99538,-331.65783
655.45200,-25.74930,-479.14412
655.92006,-22.05390,-324.56230
656.57800,-15.44297,-158.03155
657.82800,-4.81096,-14.56101
658.99806,-4.45348,-14.60388
660.14800,-14.85799,-178.73378
660.92206,-21.43741,-344.20509
661.54006,-25.71427,-478.99202
661.94200,-21.67005,-312.02640
662.63806,-14.82762,-146.70485
663.90406,-4.06335,-8.52619
665.08200,-5.57507,-27.06729
666.20606,-15.45331,-191.27723
666.96206,-21.87949,-356.89436
667.56806,-25.45921,-465.72097
667.96800,-21.24279,-298.67923
668.72006,-14.02698,-132.68092
670.00200,-3.12831,-2.51160
671.16206,-6.54253,-39.59967
672.26000,-16.01414,-203.55554
673.00006,-22.30483,-369.34324
673.58406,-25.21718,-453.14100
673.99400,-20.81290,-285.71639
674.79206,-13.31147,-120.86566
676.08406,-2.32922,0.01101
677.24806,-7.46065,-52.17784
678.31400,-16.57526,-216.31066
679.04006,-22.74602,-382.45123
679.59800,-24.97611,-440.40520
680.02000,-20.38260,-273.24222
680.87400,-12.51287,-108.27424
682.17206,-1.47937,0.17508
683.33800,-8.35929,-64.92246
684.36806,-17.13633,-229.55904
685.08000,-23.18822,-395.72194
685.61206,-24.72218,-427.85283
686.04806,-19.92437,-260.50307
686.96600,-11.62858,-94.98321
688.26606,-0.57816,0.16365
689.42400,-9.20567,-77.50723
690.42006,-17.67982,-242.72988
691.11600,-23.59647,-408.10455
691.62806,-24.44147,-414.77632
692.08000,-19.42047,-246.93998
693.05400,-10.77825,-82.78760
694.32406,0.01710,0.10453
695.50606,-10.00978,-90.10278
696.46800,-18.19072,-255.48670
697.15406,-24.02145,-421.11520
697.64406,-24.15173,-402.13794
698.11206,-18.92093,-234.07815
699.14606,-9.89480,-70.79159
700.31400,0.03396,0.15381
701.58406,-10.77616,-102.56171
702.51200,-18.66670,-267.69765
703.18606,-24.39519,-432.74164
703.66206,-23.83371,-388.98379
704.14800,-18.42366,-221.26261
705.23206,-9.06134,-60.07425
706.40206,0.44340,0.12627
707.66206,-11.54308,-115.56163
708.55806,-19.15865,-280.60680
709.22600,-24.83733,-446.72497
709.68006,-23.51138,-376.20746
710.19006,-17.90552,-208.90472
711.31606,-8.24533,-50.14703
712.49006,-0.07922,0.10386
713.73400,-12.25703,-128.06922
714.60006,-19.61795,-292.87439
715.25806,-25.21126,-458.71638
715.70200,-23.14033,-362.11990
716.24400,-17.30045,-195.30822
717.41206,-7.32702,-39.52458
718.57806,-1.06718,0.12013
719.80400,-12.95417,-140.79972
720.64606,-20.11128,-306.23727
721.27000,-25.41538,-465.26872
721.72006,-22.81089,-350.12476
722.29600,-16.73562,-183.28542
723.49606,-6.51155,-30.71385
724.66600,-2.15900,0.14220
725.86806,-13.60020,-153.01179
726.68806,-20.57076,-318.96379
727.26000,-25.43230,-465.80840
727.74006,-22.45365,-337.53928
728.35406,-16.12923,-170.97021
729.57806,-5.71235,-22.70171
730.75400,-3.29733,-4.10390
731.93400,-14.26320,-166.03898
732.72800,-21.01242,-331.34267
733.29600,-25.74936,-478.43378
733.76406,-22.05055,-323.99680
734.42206,-15.44189,-157.65768
735.67206,-4.81096,-14.44116
736.84206,-4.46066,-14.42915
737.99206,-14.85805,-178.16307
738.76800,-21.45439,-343.92271
739.38406,-25.71684,-478.41359
739.78800,-21.64577,-310.80958
740.49006,-14.75934,-145.09644
741.75806,-3.97827,-7.77256
742.92600,-5.58757,-26.96136
744.05206,-15.47029,-191.11764
744.80806,-21.89635,-356.68503
745.41206,-25.46160,-465.26086
745.81006,-21.25959,-298.74500
746.55806,-14.07774,-133.27539
747.84000,-3.17883,-2.70466
749.00806,-6.56853,-39.74034
750.11006,-16.06514,-204.18510
750.85206,-22.37204,-370.65029
751.42806,-25.22094,-452.71121
751.83800,-20.80495,-285.07650
752.64000,-13.27751,-119.99871
753.93400,-2.27816,0.10092
755.09600,-7.49605,-52.36256
756.16406,-16.62591,-216.89652
756.88406,-22.74608,-381.74167
757.44200,-24.97778,-439.93931
757.86400,-20.37004,-272.47049
758.72206,-12.47837,-107.49031
760.02000,-1.44553,0.11732
761.18400,-8.37878,-64.93991
762.21406,-17.15337,-229.35010
762.92400,-23.18828,-395.01995
763.45606,-24.72445,-427.33166
763.89406,-19.88987,-259.10243
764.81200,-11.61148,-94.42882
766.11206,-0.56136,0.17190
767.27000,-9.22343,-77.44642
768.26406,-17.67988,-242.15303
768.96000,-23.59652,-407.37681
769.47206,-24.44302,-414.34776
769.92206,-19.43045,-246.89885
770.90000,-10.76115,-82.25283
772.16800,0.01704,0.18469
773.35206,-10.02688,-89.90766
774.31200,-18.19078,-254.84148
774.99806,-24.02157,-420.44107
775.48806,-24.15412,-401.67097
775.95200,-18.95500,-234.52774
776.98400,-9.94556,-71.17271
778.15800,0.03390,0.17391
779.43006,-10.79326,-102.46745
780.35806,-18.68380,-267.46497
781.03406,-24.42933,-433.13824
781.50606,-23.83742,-388.62888
781.99006,-18.43968,-221.29199
783.07200,-9.09566,-60.27701
784.24606,0.44430,0.13405
785.50806,-11.56006,-115.43501
786.40406,-19.17563,-280.36661
787.07200,-24.85408,-446.61708
787.52406,-23.51258,-375.73397
788.03600,-17.88155,-207.98597
789.16600,-8.19439,-49.30956
790.33406,-0.07498,0.20365
791.57806,-12.25709,-127.63669
792.44606,-19.63505,-292.69058
793.10406,-25.22830,-458.59586
793.54406,-23.16221,-362.45681
794.08200,-17.35145,-196.05434
795.24606,-7.41258,-40.30040
796.42206,-1.06443,0.16841
797.64800,-12.95423,-140.32587
798.49006,-20.11128,-305.58961
799.11400,-25.41538,-464.67409
799.56606,-22.78781,-348.87232
800.14200,-16.71822,-182.59063
801.34000,-6.51155,-30.52253
802.51000,-2.15816,0.18118
803.71406,-13.61724,-152.84239
804.53000,-20.55390,-317.79274
805.10406,-25.43236,-465.13338
805.58800,-22.40845,-335.61334
806.20200,-16.09414,-169.90362
807.42806,-5.66177,-22.01729
808.59800,-3.30074,-3.97193
809.78206,-14.29722,-166.22987
810.57606,-21.04674,-331.63182
811.14000,-25.75020,-477.88087
811.60806,-22.05025,-323.55607
812.26406,-15.45911,-157.65103
813.51406,-4.82800,-14.42857
814.68606,-4.46783,-14.28514
815.84206,-14.90899,-178.70437
816.61600,-21.48811,-344.23601
817.22800,-25.71792,-477.86333
817.63006,-21.66556,-311.02125
818.33000,-14.79318,-145.44722
819.59800,-4.01217,-7.89293
820.77000,-5.59474,-26.83992
821.89800,-15.48697,-190.95356
822.65206,-21.89647,-356.05416
823.25606,-25.46471,-464.88222
823.65406,-21.25666,-298.23251
824.40606,-14.04378,-132.36307
825.68806,-3.14547,-2.43702
826.85206,-6.57134,-39.43940
827.95200,-16.04816,-203.24459
828.69006,-22.32181,-368.47882
829.27206,-25.22340,-452.29666
829.68206,-20.80119,-284.58094
830.48600,-13.26023,-119.47597
831.78000,-2.26124,0.13308
832.94006,-7.49736,-52.07654
834.01000,-16.64313,-216.72584
834.73206,-22.78010,-382.06987
835.28600,-24.98089,-439.59320
835.70806,-20.36508,-271.93533
836.56806,-12.46145,-106.93808
837.86806,-1.41133,0.23961
839.02800,-8.37836,-64.57570
840.06006,-17.17041,-229.21791
840.76806,-23.18828,-394.34988
841.30206,-24.70807,-426.10940
841.73806,-19.88073,-258.48975
842.65606,-11.61148,-94.21116
843.95606,-0.56142,0.21839
845.11400,-9.22265,-77.10362
846.11006,-17.69722,-241.97930
846.80806,-23.63037,-407.80492
847.31606,-24.44512,-413.99200
847.76606,-19.42035,-246.26734
848.74206,-10.77831,-82.24581
850.01200,0.01704,0.17936
851.19806,-10.04404,-89.88204
852.16006,-18.22486,-255.13034
852.84206,-24.02157,-419.83601
853.33406,-24.13696,-400.55476
853.79806,-18.92601,-233.33343
854.83200,-9.91184,-70.54778
856.00200,0.03390,0.19358
857.27800,-10.82764,-102.60588
858.20406,-18.70072,-267.30543
858.87806,-24.42939,-432.55080
859.35006,-23.83903,-388.22051
859.83406,-18.43328,-220.76147
860.92006,-9.06146,-59.62267
862.09000,0.44495,0.10916
863.35206,-11.56018,-115.00466
864.25006,-19.19291,-280.35177
864.91600,-24.85414,-446.03672
865.37006,-23.49237,-374.54393
865.88200,-17.86241,-207.23229
867.01200,-8.17741,-48.86150
868.17806,-0.07318,0.17869
869.42400,-12.27395,-127.56845
870.29206,-19.65209,-292.54995
870.94806,-25.22842,-458.01185
871.39000,-23.14296,-361.42975
871.93206,-17.30033,-194.65119
873.10206,-7.31010,-38.95700
874.26606,-1.06366,0.18756
875.49400,-12.97115,-140.26198
876.33406,-20.11134,-305.02679
876.95806,-25.41544,-464.11183
877.41206,-22.76348,-347.64189
877.99206,-16.66549,-181.22368
879.19606,-6.40937,-29.26946
880.35406,-2.15613,0.14961
881.56200,-13.65132,-153.11979
882.37806,-20.58780,-318.17172
882.94806,-25.43236,-464.59410
883.43006,-22.42878,-335.93833
884.04600,-16.09450,-169.64858
885.27406,-5.64485,-21.69172
886.44200,-3.30319,-3.83535
887.62400,-14.28030,-165.44573
888.42206,-21.06384,-331.53754
888.98406,-25.75032,-477.32826
889.45406,-22.02573,-322.42168
890.10806,-15.45911,-157.39698
891.35600,-4.84498,-14.43580
892.53000,-4.47363,-14.16403
893.68400,-14.89201,-177.98973
894.46000,-21.48823,-343.69055
895.07200,-25.71977,-477.48826
895.47800,-21.61534,-309.13372
896.18806,-14.67444,-143.00373
897.46000,-3.85935,-6.64914
898.61400,-5.60341,-26.75330
899.74400,-15.50402,-190.87348
900.50200,-21.94735,-356.98842
901.10006,-25.47009,-464.62331
901.50006,-21.23089,-297.11030
902.25806,-13.97526,-130.99199
903.54406,-3.04388,-1.86375
904.69606,-6.57326,-39.28499
905.80006,-16.08218,-203.56786
906.54006,-22.37210,-369.41681
907.11806,-25.20815,-451.02783
907.52800,-20.77016,-283.31418
908.33606,-13.20959,-118.40907
909.63200,-2.19350,0.16986
910.78606,-7.51267,-52.08401
911.85406,-16.64318,-216.35996
912.57806,-22.79732,-382.02118
913.13200,-24.96576,-438.37719
913.55206,-20.36257,-271.59935
914.41006,-12.47837,-106.98230
915.71000,-1.42855,0.19593
916.87206,-8.37806,-64.31202
917.90606,-17.18727,-229.06708
918.61600,-23.22224,-394.83678
919.14606,-24.71136,-425.83115
919.58406,-19.85263,-257.42762
920.51806,-11.45860,-91.74276
921.81806,-0.40842,0.17418
922.95806,-9.22361,-76.89770
923.95806,-17.73135,-242.34537
924.65406,-23.64705,-407.72840
925.16206,-24.42682,-412.78206
925.61206,-19.38979,-245.16711
926.59606,-10.69335,-80.92289
927.85600,0.01698,0.17246
929.04006,-10.02700,-89.33647
930.00400,-18.22486,-254.63706
930.68806,-24.03861,-419.81261
931.18006,-24.11801,-399.36867
931.64606,-18.87788,-231.79639
932.68606,-9.82658,-69.21683
933.84606,0.03384,0.17423
935.12206,-10.82776,-102.29823
936.05206,-18.73456,-267.70378
936.72606,-24.46329,-433.06187
937.19606,-23.81810,-387.00394
937.68006,-18.41104,-219.93889
938.76806,-9.02750,-58.99832
939.93400,0.44627,0.15487
941.19806,-11.57680,-114.93859
942.09406,-19.19297,-279.77623
942.76200,-24.87147,-446.01981
943.21406,-23.49458,-374.29661
943.73006,-17.82247,-206.01222
944.86600,-8.09209,-47.74164
946.02206,-0.06971,0.13713
947.27000,-12.29111,-127.54086
948.13806,-19.66901,-292.49256
948.79406,-25.24534,-458.09805
949.23406,-23.14416,-361.05353
949.77406,-17.31564,-194.69861
950.94200,-7.34418,-39.22039
952.11006,-1.05965,0.16184
953.33806,-12.97115,-139.87385
954.17806,-20.11134,-304.56159
954.80206,-25.41550,-463.63182
955.25606,-22.76443,-347.34491
955.83406,-16.68139,-181.22394
957.03800,-6.42671,-29.31701
958.19806,-2.15380,0.22436
959.40606,-13.65132,-152.74493
960.22206,-20.58786,-317.65778
960.79206,-25.43242,-464.11026
961.27606,-22.40940,-334.89842
961.89006,-16.09480,-169.39485
963.11806,-5.64491,-21.57171
964.28606,-3.30325,-3.71594
965.47006,-14.29734,-165.40853
966.26606,-21.06390,-331.04766
966.82806,-25.75008,-476.80665
967.29806,-22.02322,-322.01007
967.95606,-15.42491,-156.46381
969.21000,-4.76032,-13.59530
970.37400,-4.47483,-14.03762
971.53000,-14.90905,-177.89217
972.30600,-21.50509,-343.59302
972.91606,-25.72204,-477.11827
973.32406,-21.59250,-308.09788
974.03406,-14.65740,-142.47394
975.30806,-3.82569,-6.34660
976.45806,-5.60485,-26.59871
977.59206,-15.53804,-191.15690
978.34406,-21.93025,-355.88626
978.94400,-25.47123,-464.26501
979.34406,-21.22772,-296.74022
980.09800,-14.00988,-131.29749
981.38200,-3.09417,-2.05423
982.54206,-6.58815,-39.31099
983.64606,-16.09916,-203.44865
984.38406,-22.37216,-368.91211
984.96206,-25.21174,-450.77629
985.37400,-20.74887,-282.37788
986.19006,-13.12457,-116.84739
987.48600,-2.10830,0.20611
988.62806,-7.50041,-51.60952
989.69806,-16.64324,-215.85496
990.42206,-22.79732,-381.56591
990.97606,-24.97127,-438.23566
991.39806,-20.33441,-270.46883
992.26606,-12.37667,-105.25648
993.56606,-1.32643,0.21447
994.71606,-8.37836,-64.08845
995.75206,-17.20413,-229.01418
996.46000,-23.22230,-394.34019
996.99206,-24.69528,-424.68883
997.42806,-19.85083,-257.15914
998.35600,-11.50978,-92.31692
999.65606,-0.45954,0.24191
1000.80406,-9.24023,-76.84669
1001.80206,-17.73147,-241.92581
1002.49806,-23.64711,-407.24266
1003.00606,-24.43412,-412.69396
1003.45200,-19.43655,-246.13209
1004.42806,-10.79541,-82.12507
1005.70006,0.01698,0.21207
1006.88406,-10.02688,-89.02573
1007.84800,-18.22486,-254.19688
1008.53406,-24.05559,-419.82230
1009.02406,-24.11986,-399.02795
1009.49206,-18.85163,-230.79367
1010.54006,-9.74144,-67.92735
1011.69006,0.03384,0.23842
1012.96806,-10.84474,-102.24443
1013.89406,-18.71776,-266.80632
1014.57006,-24.46329,-432.59852
1015.04006,-23.82265,-386.82066
1015.52406,-18.40632,-219.50921
1016.61600,-8.99354,-58.43855
1017.77806,0.44675,0.22472
1019.04206,-11.57686,-114.70599
1019.94206,-19.22735,-280.19097
1020.60806,-24.88857,-446.07282
1021.06006,-23.47772,-373.30344
1021.57200,-17.83826,-206.10731
1022.70606,-8.12617,-47.99933
1023.86600,-0.06673,0.15412
1025.11400,-12.29117,-127.18850
1025.98400,-19.68617,-292.45561
1026.64206,-25.27954,-458.68646
1027.07800,-23.14649,-360.81713
1027.61806,-17.31486,-194.44382
1028.78806,-7.32714,-38.86801
1029.95412,-1.05570,0.15715
1031.18406,-12.98825,-139.88527
1032.02806,-20.16251,-305.37900
1032.64600,-25.41550,-463.09322
1033.09800,-22.78991,-347.88977
1033.67200,-16.73466,-182.12916
1034.86806,-6.54546,-30.40977
1036.04200,-2.15565,0.19728
1037.25206,-13.66842,-152.76589
1038.07006,-20.62182,-318.12873
1038.63612,-25.43248,-463.67168
1039.11806,-22.43081,-335.36907
1039.73206,-16.11166,-169.48333
1040.95800,-5.67863,-21.78202
1042.13000,-3.30403,-3.68942
1043.31406,-14.29734,-165.03749
1044.11012,-21.06390,-330.52675
1044.67200,-25.75026,-476.43319
1045.14406,-22.00009,-320.91510
1045.81006,-15.33959,-154.68445
1047.06406,-4.67530,-12.80046
1048.21800,-4.48128,-13.94959
1049.37800,-14.94319,-178.18181
1050.15212,-21.52201,-343.63594
1050.76000,-25.72491,-476.85914
1051.16400,-21.63890,-309.25535
1051.87000,-14.72508,-143.46566
1053.14213,-3.91095,-6.85594
1054.30200,-5.60999,-26.46638
1055.43813,-15.55514,-191.16433
1056.19412,-21.98125,-356.87853
1056.78812,-25.47278,-463.86290
1057.18813,-21.22288,-296.31134
1057.94412,-13.99266,-130.76934
1059.23200,-3.04394,-1.74508
1060.38612,-6.59610,-39.20603
1061.49000,-16.09916,-203.08577
1062.23012,-22.38932,-368.93547
1062.80600,-25.21586,-450.60087
1063.21800,-20.74612,-282.00332
1064.03600,-13.10771,-116.38092
1065.33200,-2.09132,0.25493
1066.47200,-7.50017,-51.43340
1067.54413,-16.66035,-215.79681
1068.26812,-22.81442,-381.56658
1068.82012,-24.97294,-437.96062
1069.24000,-20.35306,-270.73817
1070.10612,-12.41063,-105.54852
1071.40600,-1.36027,0.20295
1072.56200,-8.39618,-64.12330
1073.59800,-17.22117,-229.08248
1074.30812,-23.25602,-394.85220
1074.83413,-24.71859,-425.43583
1075.26812,-19.89191,-257.96719
1076.19200,-11.57722,-93.12133
1077.49212,-0.52728,0.18091
1078.64812,-9.24071,-76.59885
1079.65000,-17.76555,-242.30244
1080.34612,-23.68137,-407.83018
1080.85200,-24.41307,-411.42996
1081.29812,-19.40157,-244.95561
1082.28000,-10.72731,-80.99807
1083.54413,0.01698,0.19969
1084.73200,-10.06114,-89.27315
1085.69800,-18.27568,-255.03019
1086.38213,-24.08979,-420.40244
1086.86800,-24.12076,-398.79233
1087.33413,-18.86813,-230.95416
1088.38000,-9.77558,-68.19774
1089.53400,0.03384,0.16345
1090.81413,-10.86196,-102.25427
1091.74400,-18.76798,-267.68049
1092.42000,-24.51423,-433.70489
1092.88400,-23.82396,-386.58947
1093.37000,-18.38856,-218.78779
1094.46612,-8.94236,-57.62914
1095.62213,0.44788,0.17400
1096.88800,-11.59354,-114.68124
1097.78600,-19.22735,-279.73516
1098.45200,-24.88857,-445.61490
1098.90212,-23.49883,-373.77533
1099.41212,-17.87389,-206.64388
1100.54600,-8.16037,-48.25955
1101.71012,-0.06278,0.15083
1102.96200,-12.32519,-127.49649
1103.83012,-19.70327,-292.44989
1104.48800,-25.29670,-458.80847
1104.92200,-23.14649,-360.52424
1105.46012,-17.33136,-194.51184
1106.63000,-7.34424,-38.89571
1107.79812,-1.05391,0.13703
1109.03000,-13.00553,-139.91325
1109.87213,-20.16251,-304.96448
1110.49012,-25.41550,-462.73757
1110.94200,-22.79265,-347.69926
1111.52400,-16.66566,-180.40469
1112.73012,-6.39245,-28.72147
1113.88612,-2.15356,0.19231
1115.09612,-13.66842,-152.36952
1115.91400,-20.62182,-317.62701
1116.48012,-25.43242,-463.21280
1116.96412,-22.40749,-334.28207
1117.58012,-16.07674,-168.57721
1118.81000,-5.61059,-21.01499
1119.97400,-3.30164,-3.50246
1121.16000,-14.31420,-165.05625
1121.95600,-21.08088,-330.52366
1122.51613,-25.75092,-475.94856
1122.98400,-22.04642,-322.18661
1123.64000,-15.45923,-156.68567
1124.89000,-4.82812,-13.94278
1126.06200,-4.47608,-13.77865
1127.22200,-14.94325,-177.85328
1127.99400,-21.50521,-342.68480
1128.60400,-25.72671,-476.52163
1129.00613,-21.65940,-309.63911
1129.71012,-14.75922,-143.86691
1130.98012,-3.96135,-7.15545
1132.14600,-5.61483,-26.39374
1133.28212,-15.55502,-190.78815
1134.03812,-21.98125,-356.44289
1134.63213,-25.47679,-463.68893
1135.03400,-21.19927,-295.31207
1135.79600,-13.92456,-129.48099
1137.08413,-2.97530,-1.45047
1138.22800,-6.57684,-38.80181
1139.33413,-16.09916,-202.71063
1140.07200,-22.37216,-367.95922
1140.65000,-25.22047,-450.41982
1141.05600,-20.81177,-283.68970
1141.86200,-13.26047,-118.64159
1143.15812,-2.24432,0.17799
1144.31812,-7.51811,-51.47606
1145.39213,-16.69419,-216.18010
1146.11400,-22.83140,-381.62023
1146.66400,-24.97599,-437.71043
1147.08200,-20.37184,-271.00312
1147.94600,-12.44465,-105.81123
1149.24613,-1.39429,0.23628
1150.40600,-8.39546,-63.84166
1151.44412,-17.23821,-229.06769
1152.15400,-23.27306,-394.97204
1152.68000,-24.69916,-424.20104
1153.11612,-19.83756,-256.20213
1154.05000,-11.45866,-91.23755
1155.35012,-0.40848,0.20439
1156.49212,-9.24119,-76.37075
1157.49012,-17.73147,-241.02632
1158.18813,-23.66409,-406.87840
1158.69600,-24.41719,-411.27425
1159.14213,-19.39984,-244.64112
1160.13000,-10.67649,-80.14164
1161.38800,0.01692,0.21699
1162.57600,-10.06138,-89.06871
1163.54000,-18.25870,-254.17810
1164.22400,-24.07275,-419.45420
1164.71200,-24.12453,-398.63881
1165.17600,-18.88870,-231.14413
1166.22400,-9.77564,-68.02127
1167.37800,0.03378,0.24770
1168.65600,-10.84498,-101.77769
1169.58800,-18.76798,-267.25113
1170.26212,-24.49743,-432.79462
1170.72800,-23.82677,-386.39538
1171.21012,-18.42408,-219.44329
1172.29812,-9.04454,-58.73723
1173.46612,0.44944,0.19356
1174.73200,-11.59360,-114.41433
1175.63213,-19.24445,-279.76928
1176.29413,-24.87154,-444.73451
1176.74800,-23.47940,-372.78701
1177.25613,-17.87563,-206.41245
1178.39213,-8.14327,-47.95220
1179.55413,-0.05985,0.17082
1180.80600,-12.32519,-127.27914
1181.67600,-19.72031,-292.46675
1182.33413,-25.31392,-458.97558
1182.76613,-23.14798,-360.31298
1183.30600,-17.31211,-193.88791
1184.47800,-7.31022,-38.45641
1185.64213,-1.05110,0.19258
1186.87612,-13.02239,-139.92434
1187.72012,-20.19641,-305.43869
1188.33413,-25.41556,-462.31847
1188.78812,-22.76880,-346.63577
1189.36612,-16.68031,-180.51444
1190.57200,-6.40961,-28.78576
1191.73012,-2.15111,0.18916
1192.94013,-13.66848,-152.14103
1193.76000,-20.63874,-317.69857
1194.32413,-25.43248,-462.82813
1194.80812,-22.40719,-333.99474
1195.42813,-16.04200,-167.69176
1196.66000,-5.55935,-20.43104
1197.72012,0.08406,0.21252
1199.02000,0.01656,0.24486
1200.32012,0.01650,0.19947
1201.62012,0.01650,0.24951
1202.92000,0.01650,0.25523
1204.22012,0.01650,0.22001
1205.52000,0.01650,0.23894
1206.82012,0.01650,0.23952
1208.12012,0.01650,0.25669
1209.42000,0.01650,0.22651
1210.72012,0.01650,0.23351
1212.02000,0.01650,0.28135
1213.32012,0.01650,0.22138
1214.62012,0.01650,0.24106
1215.92000,0.01650,0.23474
1216.60400,0.01650,0.21459