File: ball-data/compression/dunlop hard court.is_comp_RawData/Specimen_RawData_1.csv
Time,Extension,Load
(sec),(mm),(N)
0.00000,0.00000,0.04472
1.08200,-9.19646,-107.07054
1.92600,-16.37090,-246.25590
2.64200,-22.45682,-386.69910
3.26000,-24.78502,-402.50447
3.66000,-20.25100,-261.48507
4.45400,-12.98831,-122.33496
5.55400,-3.63765,-14.16902
6.48400,-3.32741,-14.83941
7.50000,-12.88571,-154.13844
8.27800,-19.49897,-293.75985
8.97400,-25.41520,-432.65555
9.42000,-22.87008,-328.08840
9.96200,-17.06321,-187.41297
11.00000,-8.21095,-57.19785
11.96800,0.01734,0.17148
13.04800,-9.17177,-89.19138
13.94800,-16.83003,-227.94690
14.65800,-22.86524,-367.71394
15.23600,-24.70556,-388.72220
15.65200,-19.96246,-247.67783
16.49800,-12.34229,-108.69983
17.59800,-2.99187,-7.85821
18.55200,-4.53378,-25.26329
19.57200,-13.76988,-164.17501
20.33800,-20.28084,-303.29943
20.94400,-25.43218,-425.47047
21.43400,-22.34166,-308.14629
22.03400,-16.16164,-167.98452
23.10200,-7.07184,-43.12236
24.03600,0.44370,0.13549
25.11800,-10.04362,-99.75557
26.00000,-17.54385,-238.57018
26.70600,-23.54463,-378.22720
27.24000,-24.33104,-370.91445
27.67600,-19.31356,-229.96599
28.59200,-11.27086,-92.49660
29.69200,-1.92110,-1.45875
30.61200,-5.62254,-36.86990
31.63000,-14.53525,-175.51256
32.38200,-20.92698,-314.43994
33.00200,-25.85884,-434.36252
33.44200,-21.87674,-293.04488
34.09400,-15.37302,-152.90973
35.17800,-6.15401,-33.16345
36.10400,-0.03587,0.11975
37.18800,-10.91278,-111.57717
38.04600,-18.20722,-250.45035
38.75000,-24.19125,-390.44961
39.24400,-23.94725,-355.23057
39.70200,-18.71292,-215.06362
40.67000,-10.33575,-79.53830
41.77000,-0.98617,0.19217
42.67800,-6.60847,-48.68918
43.68000,-15.23221,-187.00968
44.42600,-21.57289,-326.89948
45.06000,-25.57950,-419.64434
45.45200,-21.38712,-278.44984
46.15600,-14.57172,-138.84775
47.25200,-5.25323,-24.43144
48.17200,-1.03191,0.19556
49.25000,-11.71258,-123.15014
50.09000,-18.85259,-262.83232
50.79000,-24.80314,-402.88907
51.24600,-23.57195,-341.23026
51.73800,-18.06635,-200.67586
52.74400,-9.43514,-67.90267
53.84400,-0.08472,0.23069
54.74600,-7.52230,-60.16306
55.72600,-15.89504,-198.64267
56.46200,-22.15099,-338.61913
57.06600,-25.26878,-404.73536
57.46800,-20.81924,-262.89355
58.23600,-13.61796,-123.45871
59.33600,-4.26706,-15.71899
60.24000,-2.14925,-2.13981
61.30800,-12.47783,-134.97927
62.12600,-19.43123,-274.43668
62.81800,-25.31320,-413.81959
63.25000,-23.16879,-327.43875
63.78200,-17.38039,-186.50822
64.82000,-8.51701,-56.87355
65.82201,0.00042,0.18085
66.81800,-8.43211,-72.15442
67.77200,-16.55804,-210.97852
68.49800,-22.72880,-350.75884
69.06400,-24.98920,-391.39271
69.48000,-20.30051,-249.39027
70.30600,-12.74993,-110.35783
71.40601,-3.40011,-9.07264
72.40801,-4.53264,-22.32701
73.45001,-13.95702,-159.97307
74.23000,-20.58720,-299.76208
74.80000,-25.43224,-415.42776
75.29401,-22.29778,-300.90598
75.91200,-15.97223,-160.54114
76.99001,-6.80016,-38.24247
77.99201,-0.03522,0.13699
79.08200,-10.96432,-109.21436
79.95400,-18.37684,-248.84375
80.65801,-24.36093,-388.53623
81.12801,-23.99167,-352.80358
81.59400,-18.67417,-211.51237
82.57201,-10.21761,-76.46765
83.67201,-0.86701,0.15361
84.57001,-6.64680,-47.32796
85.58000,-15.33397,-184.98911
86.33000,-21.70939,-324.84408
86.98200,-25.30638,-403.60734
87.38600,-20.84429,-261.71491
88.15801,-13.60091,-122.05577
89.25800,-4.25032,-15.12862
90.26000,-3.32525,-10.30700
91.32001,-13.26000,-146.49870
92.12200,-20.07714,-286.40484
92.75201,-25.43218,-413.77749
93.24400,-22.32068,-300.52759
93.86201,-15.98963,-160.14423
94.94000,-6.81732,-38.02093
95.84400,0.44358,0.13647
96.93800,-10.14592,-95.80325
97.84001,-17.81602,-235.21977
98.55200,-23.86785,-375.15588
99.07800,-24.01517,-352.43865
99.54401,-18.69295,-211.17270
100.52001,-10.25121,-76.45043
101.62000,-0.90097,0.14737
102.52200,-6.64255,-46.75424
103.53401,-15.35077,-184.32962
104.28600,-21.74365,-324.23094
104.93201,-25.32474,-403.20728
105.33401,-20.89057,-262.12042
106.10201,-13.66907,-122.52870
107.20200,-4.31854,-15.41642
108.11201,-2.14800,-1.65860
109.18601,-12.52883,-133.14378
110.00800,-19.51601,-272.30598
110.70200,-25.41520,-412.00869
111.15801,-22.75941,-312.26538
111.73000,-16.71410,-172.33273
112.79201,-7.66717,-46.52110
113.69601,0.01734,0.14285
114.79001,-9.29165,-82.55085
115.72601,-17.25501,-222.11777
116.44601,-23.37477,-362.04275
116.99801,-24.35717,-363.55142
117.44201,-19.24899,-222.83768
118.37601,-11.06757,-86.33968
119.47601,-1.71692,-0.22783
120.37401,-5.64479,-33.89760
121.41000,-14.70499,-171.11614
122.17801,-21.23299,-311.13897
122.84601,-25.61825,-414.76004
123.24600,-21.36386,-273.54570
123.96201,-14.45178,-134.06971
125.06001,-5.11720,-21.85877
125.96401,-1.02904,0.14360
127.05000,-11.78062,-120.16853
127.89800,-18.98897,-259.35877
128.60001,-24.95608,-399.53876
129.07201,-23.19390,-324.63755
129.60400,-17.39988,-184.43841
130.64402,-8.51701,-55.55803
131.64602,0.00024,0.13956
132.64402,-8.44897,-70.18096
133.60600,-16.64295,-208.53529
134.33802,-22.86530,-348.75341
134.91800,-24.69043,-375.25434
135.34800,-19.77765,-234.48531
136.23002,-11.90002,-96.90194
137.33000,-2.54960,-3.23929
138.32800,-5.66087,-33.81079
139.36402,-14.72191,-170.73384
140.13000,-21.23299,-310.10231
140.79800,-25.61962,-413.92229
141.20002,-21.34437,-272.42582
141.91800,-14.41746,-133.19385
143.01600,-5.08372,-21.39083
144.01600,-2.14644,-1.44835
145.09402,-12.56237,-132.42488
145.91802,-19.56707,-271.48010
146.60600,-25.41526,-409.92457
147.06402,-22.74106,-310.36530
147.63600,-16.69724,-171.06034
148.70002,-7.63333,-45.62891
149.70002,0.44346,0.16048
150.79600,-10.16302,-94.44157
151.70202,-17.86708,-233.50552
152.41600,-23.93577,-373.42194
152.93800,-23.97368,-348.65379
153.40400,-18.65821,-208.85203
154.38600,-10.16625,-74.41936
155.48600,-0.81601,0.12585
156.48002,-7.57240,-57.80306
157.47000,-16.03076,-195.23144
158.21000,-22.32115,-334.72035
158.82200,-25.00995,-387.13451
159.24200,-20.27964,-245.52686
160.07600,-12.66527,-107.07671
161.17602,-3.31509,-7.64568
162.16802,-4.52965,-20.74383
163.21800,-14.02530,-157.11673
164.00202,-20.68926,-296.38790
164.63400,-25.83845,-422.07576
165.09602,-21.81498,-284.02450
165.77000,-15.13374,-144.13299
166.86202,-5.84789,-27.91119
167.85200,-1.02730,0.15787
168.94000,-11.79784,-119.23728
169.79200,-19.03997,-258.53435
170.49400,-25.00708,-398.56866
170.96200,-23.17644,-322.58667
171.49400,-17.37997,-183.10390
172.53802,-8.46589,-54.43779
173.53602,0.01734,0.15829
174.63200,-9.30917,-81.37099
175.57000,-17.28873,-220.30490
176.29200,-23.42612,-360.04324
176.84002,-24.34144,-360.54354
177.28402,-19.23596,-220.96369
178.22000,-11.03326,-84.94125
179.32000,-1.68301,-0.09508
180.31602,-6.66264,-45.60838
181.33202,-15.40184,-182.19657
182.08602,-21.81121,-321.71544
182.72602,-25.30985,-398.92595
183.13200,-20.82474,-258.10869
183.91200,-13.51584,-118.85638
185.01202,-4.16512,-13.62790
186.00402,-3.32089,-9.25616
187.07200,-13.32827,-144.20827
187.87600,-20.16210,-283.27184
188.49600,-25.43230,-408.47655
188.99000,-22.30441,-296.71324
189.60800,-15.97270,-157.64797
190.68800,-6.78294,-36.62023
191.68800,-0.03115,0.15176
192.78202,-10.99834,-106.20683
193.66200,-18.47896,-245.32942
194.37002,-24.49689,-385.12073
194.86202,-23.57889,-334.38414
195.36602,-17.95724,-193.81402
196.38400,-9.23114,-62.82253
197.47002,0.00030,0.14364
198.46800,-8.44897,-68.99283
199.43400,-16.67667,-206.89124
200.16602,-22.89944,-346.60272
200.74200,-24.69259,-372.85600
201.17402,-19.75206,-232.40613
202.06802,-11.78110,-94.42973
203.16802,-2.43050,-2.43177
204.15202,-5.66117,-32.97814
205.19202,-14.75599,-169.39692
205.96200,-21.30127,-308.88056
206.62002,-25.63457,-411.86534
207.02200,-21.36817,-271.30255
207.74200,-14.41758,-132.07466
208.84002,-5.08378,-20.88696
209.84002,-2.14525,-1.20390
210.92202,-12.59663,-131.31754
211.74802,-19.61807,-270.15653
212.43002,-25.41526,-407.23387
212.88602,-22.76324,-309.25071
213.45800,-16.71380,-170.22515
214.52200,-7.65025,-45.18514
215.52402,0.44412,0.11111
216.62002,-10.16296,-93.11404
217.53002,-17.90092,-231.99202
218.24602,-23.98689,-371.93481
218.76002,-23.99640,-347.44523
219.22602,-18.67340,-207.93231
220.20602,-10.20051,-74.08086
221.30602,-0.85003,0.13590
222.30402,-7.57401,-56.84237
223.30000,-16.08170,-194.39720
224.04200,-22.38919,-333.80099
224.64402,-25.03034,-385.81863
225.06602,-20.27337,-244.05057
225.90800,-12.59777,-105.18780
227.00802,-3.24705,-6.97312
227.99200,-4.53001,-20.15964
229.04400,-14.04216,-155.78221
229.83602,-20.77392,-295.96293
230.45602,-25.83325,-419.58459
230.91802,-21.83357,-282.96731
231.59402,-15.13368,-143.05606
232.68800,-5.83091,-27.28039
233.67602,-1.02545,0.14522
234.76400,-11.79784,-117.88273
235.61802,-19.05695,-256.79806
236.31802,-25.00696,-396.20586
236.78402,-23.20024,-321.67591
237.32802,-17.29202,-180.44226
238.37600,-8.34679,-52.52092
239.36002,0.01728,0.17895
240.45602,-9.30934,-80.32700
241.40002,-17.33973,-219.45864
242.12202,-23.47778,-358.97844
242.66202,-24.36171,-359.54095
243.11002,-19.20953,-219.23691
244.05402,-10.94794,-83.13969
245.15400,-1.59817,0.05732
246.14002,-6.66527,-44.88896
247.15800,-15.41881,-180.96436
247.91202,-21.82819,-319.88610
248.54802,-25.32845,-397.71948
248.95800,-20.79604,-256.21315
249.74602,-13.43117,-116.80975
250.84602,-4.08016,-12.66767
251.82802,-3.32214,-8.92147
252.89802,-13.34550,-143.10964
253.70602,-20.21316,-282.46205
254.32000,-25.43224,-406.26470
254.81602,-22.27912,-294.65787
255.44602,-15.85277,-154.74611
256.53000,-6.63024,-34.63516
257.51203,-0.03109,0.13173
258.60602,-10.99834,-105.04303
259.48800,-18.49600,-243.78642
260.19602,-24.51400,-383.39630
260.68402,-23.60113,-333.57296
261.18802,-17.97428,-193.15166
262.21003,-9.21434,-62.03086
263.29400,0.00030,0.15964
264.29400,-8.46679,-68.37057
265.26400,-16.72773,-206.30071
265.99600,-22.95056,-345.70988
266.56403,-24.71596,-372.06549
267.00000,-19.72533,-230.68473
267.89800,-11.73028,-92.99476
268.99803,-2.37974,-2.03633
269.97600,-5.66631,-32.44641
271.01400,-14.73889,-167.63510
271.78403,-21.28417,-306.54775
272.44400,-25.63457,-409.98667
272.84803,-21.33840,-269.34460
273.58003,-14.29884,-129.47076
274.68003,-4.94680,-19.34160
275.66400,-2.14357,-1.00675
276.74600,-12.59663,-130.14164
277.57603,-19.65185,-269.11691
278.25403,-25.41526,-405.14763
278.71200,-22.74010,-307.16287
279.30003,-16.55822,-166.64254
280.37003,-7.44654,-42.61288
281.34803,0.44561,0.08587
282.44400,-10.16302,-92.17966
283.35800,-17.93482,-231.11582
284.07400,-24.02121,-370.69041
284.58400,-23.99885,-345.96018
285.05800,-18.59609,-205.38226
286.04800,-10.04751,-71.67673
287.14800,-0.69715,0.16710
288.12803,-7.57497,-56.17439
289.12600,-16.09880,-193.29812
289.87003,-22.42310,-332.67129
290.47000,-25.01365,-383.39008
290.89203,-20.24861,-242.40246
291.73800,-12.54623,-103.84372
292.83800,-3.19587,-6.39113
293.81600,-4.53575,-19.81149
294.87403,-14.09292,-155.53211
295.66400,-20.80788,-294.95595
296.28003,-25.83409,-417.67269
296.74200,-21.83381,-281.84773
297.42203,-15.10002,-141.82195
298.51603,-5.79695,-26.73185
299.50000,-1.02419,0.13979
300.59200,-11.83180,-117.41390
301.44803,-19.10777,-256.36919
302.15003,-25.07470,-396.00663
302.60800,-23.19707,-320.21850
303.15003,-17.30996,-180.00523
304.19803,-8.36383,-52.22243
305.18403,0.01722,0.17430
306.28003,-9.30893,-79.60313
307.22803,-17.37393,-218.73035
307.95203,-23.52795,-358.32778
308.48800,-24.34228,-357.26763
308.94000,-19.14107,-216.74624
309.89203,-10.82860,-81.09902
310.99200,-1.47931,0.13541
311.96403,-6.66533,-44.34681
312.98800,-15.47011,-180.71592
313.74403,-21.89617,-319.75750
314.37200,-25.33096,-396.10863
314.78403,-20.76908,-254.52945
315.57203,-13.41389,-115.90217
316.67203,-4.06323,-12.30141
317.65200,-3.32436,-8.59708
318.72600,-13.37969,-142.70317
319.53600,-20.26404,-281.98460
320.14400,-25.43230,-404.39893
320.64203,-22.25533,-292.82691
321.27600,-15.80147,-153.15752
322.36003,-6.57936,-33.79045
323.33603,-0.02679,0.10641
324.43403,-11.03224,-104.70225
325.32000,-18.56404,-243.89928
326.03003,-24.59919,-383.67413
326.50803,-23.60418,-332.37964
327.01603,-17.93727,-191.69945
328.04000,-9.16310,-60.97194
329.11800,0.00024,0.16068
330.11800,-8.46661,-67.68672
331.09600,-16.79607,-206.35331
331.82800,-23.01842,-345.66488
332.38803,-24.71692,-370.69906
332.82203,-19.74213,-230.25498
333.72000,-11.74732,-92.77827
334.82000,-2.39678,-1.96434
335.80200,-5.68819,-32.29099
336.84403,-14.79001,-167.49717
337.61603,-21.35227,-306.61285
338.26800,-25.63612,-408.45539
338.67400,-21.31573,-267.80752
339.40600,-14.28186,-128.63287
340.50600,-4.92970,-18.98553
341.48800,-2.14501,-0.93690
342.57203,-12.61379,-129.56923
343.40200,-19.66871,-268.10084
344.07800,-25.41532,-403.55746
344.53803,-22.71774,-305.50519
345.12600,-16.54130,-165.72278
346.19803,-7.41258,-41.92711
347.17203,0.44477,0.13663
348.27003,-10.18006,-91.69511
349.18600,-17.96860,-230.58135
349.90403,-24.07233,-370.40796
350.41000,-23.97702,-344.09672
350.89000,-18.51507,-202.99824
351.88400,-9.94527,-69.99833
352.98400,-0.59508,0.17812
353.95203,-7.57527,-55.64599
354.95603,-16.14998,-193.21386
355.69803,-22.45694,-331.96837
356.29203,-25.03416,-382.92091
356.71403,-20.26583,-242.00926
357.56403,-12.52913,-103.08352
358.66403,-3.17877,-6.12552
359.64000,-4.53659,-19.46905
360.70000,-14.11014,-154.85322
361.49003,-20.82498,-293.97720
362.10400,-25.83504,-416.20526
362.57203,-21.76535,-279.15092
363.25803,-14.99808,-139.64560
364.35203,-5.69519,-25.54921
365.32400,-1.02372,0.14985
366.41803,-11.84884,-116.92560
367.27800,-19.15889,-256.20805
367.98000,-25.12582,-395.81247
368.43600,-23.15420,-317.94921
368.98203,-17.23959,-178.07743
370.03403,-8.26225,-50.74739
371.00803,0.01722,0.15382
372.10603,-9.32644,-79.23095
373.05403,-17.39097,-217.91918
373.77603,-23.52800,-356.88445
374.31200,-24.34431,-356.26624
374.76603,-19.11482,-215.47992
375.72200,-10.77784,-80.02554
376.82203,-1.42867,0.17888
377.79000,-6.68339,-44.09709
378.81403,-15.48692,-180.04952
379.57400,-21.94729,-319.58882
380.19600,-25.33419,-394.99823
380.60803,-20.76968,-253.74968
381.40200,-13.36295,-114.69088
382.50200,-4.01247,-11.72980
383.47600,-3.32376,-8.36504
384.55003,-13.37975,-141.88353
385.36003,-20.26404,-280.67637
385.96803,-25.43230,-403.06021
386.46803,-22.23040,-291.28008
387.10803,-15.73229,-151.42092
388.19403,-6.49404,-32.72723
389.16000,-0.02702,0.10796
390.25803,-11.03230,-104.00748
391.14603,-18.58090,-243.08911
391.85803,-24.63327,-383.13281
392.33203,-23.60203,-331.37225
392.84200,-17.91784,-190.69180
393.86800,-9.12920,-60.24353
394.94203,0.00024,0.17497
395.94203,-8.46631,-67.16189
396.92000,-16.79619,-205.39705
397.65403,-23.03552,-344.69433
398.21403,-24.69689,-368.78552
398.65600,-19.62238,-226.84220
399.56200,-11.59414,-90.32607
400.66203,-2.24414,-1.29177
401.62600,-5.68855,-31.90820
402.67203,-14.82409,-167.30830
403.44600,-21.40297,-306.50683
404.09200,-25.63750,-407.24412
404.50003,-21.28949,-266.35459
405.23800,-14.21370,-127.04230
406.33800,-4.86214,-18.15228
407.31200,-2.14561,-0.84446
408.39800,-12.63095,-129.07701
409.23400,-19.73705,-268.41173
409.90200,-25.41538,-402.15544
410.36203,-22.71708,-304.58424
410.95203,-16.52361,-164.77242
412.02203,-7.41258,-41.64008
412.99603,0.44531,0.15415
414.09403,-10.18024,-91.13763
415.01400,-18.00304,-230.24855
415.73203,-24.10659,-369.83505
416.23603,-23.95562,-342.42965
416.71403,-18.51717,-202.37900
417.71200,-9.91119,-69.26131
418.81200,-0.56118,0.17368
419.77800,-7.59028,-55.38934
420.78200,-16.16702,-192.56286
421.52603,-22.49126,-331.51235
422.11800,-25.01784,-381.12331
422.54603,-20.17507,-239.16766
423.40803,-12.35951,-100.32654
424.50803,-3.00938,-4.98299
425.46403,-4.53497,-19.19022
426.52603,-14.12718,-154.34285
427.32000,-20.87604,-293.93993
427.92800,-25.83456,-414.92164
428.39603,-21.76445,-278.35703
429.08603,-14.96418,-138.60648
430.18200,-5.64419,-24.82847
431.14800,-1.02228,0.12934
432.24203,-11.84884,-116.25350
433.10403,-19.17611,-255.49375
433.80800,-25.15990,-395.32669
434.26000,-23.15384,-317.09831
434.81200,-17.18512,-176.49826
435.86400,-8.21113,-49.90916
436.83203,0.01722,0.16650
437.93003,-9.32633,-78.70263
438.88403,-17.44251,-217.98376
439.61003,-23.61333,-357.62429
440.13603,-24.34503,-355.28060
440.59403,-19.07488,-213.93389
441.55403,-10.71009,-78.86294
442.65403,-1.35985,0.15939
443.61400,-6.68710,-43.77210
444.64000,-15.50390,-179.50647
445.40200,-21.98119,-319.12293
446.02003,-25.33305,-393.88791
446.43403,-20.73817,-252.32540
447.23203,-13.31130,-113.48595
448.33203,-3.96153,-11.14872
449.30003,-3.32776,-8.19722
450.37403,-13.37975,-141.15503
451.18803,-20.29794,-280.40545
451.79203,-25.43242,-401.84326
452.29203,-22.22902,-290.47707
452.93200,-15.73199,-151.02388
454.01803,-6.49410,-32.42545
454.98400,-0.02631,0.11798
456.08203,-11.03230,-103.43181
456.97200,-18.59788,-242.48695
457.68200,-24.63327,-381.93427
458.16003,-23.56059,-329.07575
458.67603,-17.82786,-188.36057
459.70603,-9.01046,-58.58625
460.76603,0.00018,0.17346
461.76603,-8.46613,-66.73259
462.74603,-16.81323,-204.79375
463.48203,-23.06942,-344.35134
464.03803,-24.69982,-367.84280
464.48203,-19.59702,-225.64249
465.39603,-11.50954,-88.81008
466.49603,-2.15894,-0.87930
467.45000,-5.69292,-31.66520
468.49603,-14.82409,-166.52651
469.27603,-21.45403,-306.55174
469.91600,-25.63935,-406.14795
470.32803,-21.23968,-264.39834
471.08003,-14.06052,-124.36023
472.18003,-4.70920,-16.70397
473.13603,-2.14513,-0.73663
474.22200,-12.63101,-128.47476
475.06003,-19.75403,-267.77873
475.72600,-25.41538,-400.95508
476.18803,-22.69693,-303.12892
476.79000,-16.40259,-162.28070
477.86203,-7.27596,-39.98459
478.82003,0.44597,0.14424
479.91803,-10.18012,-90.57033
480.84200,-18.03724,-230.09136
481.56200,-24.15765,-369.92583
482.06003,-23.95765,-341.50504
482.53803,-18.51771,-201.85420
483.53403,-9.92823,-69.12400
484.63403,-0.57810,0.20194
485.60203,-7.59339,-54.99511
486.60603,-16.16708,-191.76994
487.35603,-22.54220,-331.52550
487.94203,-25.01993,-380.07688
488.37003,-20.16855,-238.42758
489.23400,-12.34247,-99.69148
490.33400,-2.99211,-4.73162
491.28803,-4.54137,-18.98354
492.35003,-14.12718,-153.65650
493.14603,-20.89314,-293.36652
493.75200,-25.83510,-413.71603
494.22200,-21.73839,-276.96971
494.92000,-14.87844,-136.83922
496.01603,-5.55875,-23.92547
496.97200,-1.01947,0.18458
498.06600,-11.84896,-115.68190
498.93003,-19.19315,-254.93527
499.63203,-25.15990,-394.20407
500.08603,-23.13250,-315.61609
500.64603,-17.09824,-174.40533
501.70203,-8.09233,-48.33095
502.65603,0.01716,0.16038
503.75403,-9.32662,-78.28263
504.70400,-17.40819,-216.54496
505.43403,-23.61344,-356.57600
505.96003,-24.34736,-354.47460
506.41803,-19.07452,-213.41758
507.37603,-10.72695,-78.70675
508.47600,-1.37719,0.20507
509.43803,-6.68584,-43.45063
510.46203,-15.48692,-178.46787
511.22803,-21.99811,-318.57792
511.84403,-25.33664,-393.00647
512.26000,-20.71407,-251.09865
513.06806,-13.20929,-111.62288
514.16803,-3.85935,-10.29988
515.12403,-3.32902,-8.03712
516.20000,-13.39655,-140.83409
517.01606,-20.33190,-280.22289
517.61603,-25.43242,-400.82783
518.11603,-22.23069,-289.86502
518.76203,-15.68093,-149.74810
519.85003,-6.42612,-31.54141
520.80803,-0.02451,0.15438
521.90600,-11.03236,-102.87642
522.79803,-18.61492,-241.99970
523.51203,-24.68457,-382.13138
523.98400,-23.56059,-328.44160
524.50400,-17.79276,-187.23851
525.53400,-8.97656,-57.95415
526.59000,0.00018,0.20996
527.59000,-8.46733,-66.28918
528.57000,-16.81329,-204.14384
529.30600,-23.06948,-343.35770
529.86200,-24.70108,-367.11328
530.30400,-19.61855,-225.58384
531.22006,-11.50948,-88.50032
532.32000,-2.15894,-0.89188
533.27406,-5.69352,-31.45096
534.32000,-14.82409,-165.89021
535.10006,-21.45403,-305.70373
535.74006,-25.64061,-405.39335
536.15206,-21.24202,-263.93129
536.90000,-14.09466,-124.50423
538.00000,-4.74298,-16.85162
538.96000,-2.14387,-0.70871
540.04806,-12.64811,-128.17795
540.89000,-19.80533,-268.07342
541.55006,-25.41544,-400.12196
542.01200,-22.69454,-302.49668
542.61400,-16.40319,-161.84757
543.68806,-7.25886,-39.55433
544.64406,0.44645,0.13085
545.74200,-10.18036,-90.18388
546.66206,-18.00298,-228.58027
547.38200,-24.12387,-368.24577
547.88406,-23.95921,-340.95742
548.37006,-18.43615,-199.70151
549.37400,-9.79280,-67.27044
550.47400,-0.44226,0.22511
551.42600,-7.59321,-54.64796
552.43200,-16.18412,-191.40335
553.18400,-22.57628,-331.51641
553.76606,-25.02113,-379.56096
554.19400,-20.16431,-237.91008
555.05600,-12.35951,-99.59799
556.15600,-3.00938,-4.71773
557.11200,-4.54209,-18.73609
558.17400,-14.12724,-153.13930
558.97206,-20.91012,-292.85278
559.57406,-25.83098,-412.87091
560.04600,-21.74030,-276.53364
560.74400,-14.87844,-136.46478
561.84000,-5.55881,-23.67920
562.79600,-1.01941,0.14137
563.89000,-11.84896,-115.13214
564.75606,-19.21025,-254.56402
565.46206,-25.21126,-394.73221
565.91006,-23.13190,-315.12190
566.46800,-17.11636,-174.34299
567.52406,-8.10931,-48.27666
568.48006,0.01716,0.14055
569.57800,-9.32668,-77.89743
570.53206,-17.44251,-216.52786
571.26000,-23.63025,-356.24254
571.78406,-24.34862,-354.06571
572.24400,-19.05450,-212.55780
573.20800,-10.65927,-77.62237
574.30806,-1.30891,0.20188
575.26200,-6.68345,-43.12675
576.28800,-15.50390,-178.11462
577.05600,-22.03195,-318.58806
577.66800,-25.33813,-392.51115
578.08200,-20.73984,-251.36894
578.89406,-13.19226,-111.07653
579.99400,-3.84243,-10.05681
580.94800,-3.32280,-7.82898
582.02600,-13.41342,-140.57492
582.84000,-20.33178,-279.46699
583.44000,-25.43248,-400.16964
583.94000,-22.23386,-289.52811
584.58800,-15.66383,-149.10209
585.67600,-6.40926,-31.24800
586.63200,-0.02218,0.15910
587.73006,-11.03242,-102.50351
588.62606,-18.64924,-242.02801
589.34000,-24.71836,-382.24481
589.80806,-23.56244,-327.99903
590.33000,-17.77339,-186.42388
591.36200,-8.94236,-57.39104
592.41400,0.00018,0.17853
593.41400,-8.46739,-65.96519
594.39606,-16.83033,-203.78897
595.13200,-23.08628,-342.95298
595.68606,-24.70472,-366.62094
596.13000,-19.59643,-224.70979
597.04600,-11.49274,-88.02952
598.14606,-2.14196,-0.73691
599.09800,-5.69346,-31.13824
600.14606,-14.84113,-165.61665
600.92806,-21.48799,-305.70092
601.56200,-25.65370,-405.31758
601.97600,-21.24118,-263.47104
602.73006,-14.04354,-123.41086
603.83000,-4.69228,-16.32616
604.78406,-2.14351,-0.59159
605.87006,-12.63107,-127.42140
606.71406,-19.80551,-267.34391
607.37400,-25.41544,-399.41136
607.83600,-22.69753,-302.19594
608.44000,-16.38573,-161.20704
609.51606,-7.22502,-39.10178
610.46800,0.44639,0.09421
611.56606,-10.18024,-89.78200
612.49400,-18.07120,-229.36285
613.21406,-24.19137,-369.13738
613.70800,-23.96172,-340.50170
614.19606,-18.42156,-199.09589
615.19806,-9.79280,-67.02073
616.29806,-0.44226,0.23866
617.25000,-7.59416,-54.40005
618.25606,-16.18412,-190.86083
619.00400,-22.54226,-329.95094
619.59206,-25.00331,-378.18432
620.01800,-20.16909,-237.53559
620.88200,-12.34253,-99.08002
621.98206,-2.99217,-4.49927
622.93606,-4.54030,-18.50526
623.99806,-14.12730,-152.57725
624.79600,-20.91012,-292.16668
625.39800,-25.83122,-412.15431
625.87006,-21.74514,-276.20949
626.57200,-14.84424,-135.65199
627.66800,-5.52575,-23.24800
628.62006,-1.01672,0.17453
629.71406,-11.84908,-114.73279
630.58200,-19.22735,-254.26295
631.28406,-25.19428,-393.54339
631.73600,-23.11432,-314.05710
632.29600,-17.08186,-173.38011
633.35206,-8.07553,-47.68680
634.30400,0.01710,0.15198
635.40406,-9.34337,-77.75799
636.36006,-17.47671,-216.57769
637.08606,-23.64705,-355.81544
637.60806,-24.35161,-353.49626
638.07000,-19.03136,-211.67940
639.03600,-10.62525,-76.91601
640.13606,-1.27465,0.19377
641.08606,-6.68381,-42.89838
642.11400,-15.52112,-177.96263
642.88200,-22.04893,-318.23996
643.49200,-25.34053,-391.82678
643.90800,-20.72310,-250.46965
644.71800,-13.19226,-110.79653
645.81806,-3.84249,-9.95941
646.77206,-3.32179,-7.66986
647.85006,-13.41342,-140.12376
648.66800,-20.36580,-279.51794
649.26406,-25.43242,-399.28745
649.76406,-22.23589,-289.06714
650.41400,-15.64733,-148.52631
651.50200,-6.39233,-30.92177
652.45606,-0.02105,0.13220
653.55400,-11.03236,-102.08107
654.45200,-18.66652,-241.76948
655.16206,-24.70167,-381.05153
655.63406,-23.54570,-326.94936
656.15406,-17.77422,-186.08538
657.18606,-8.94230,-57.17244
658.23806,0.00012,0.18632
659.23806,-8.46661,-65.69196
660.22206,-16.84725,-203.57795
660.96206,-23.13740,-343.44491
661.51000,-24.70622,-366.13952
661.95406,-19.60085,-224.42613
662.87200,-11.47564,-87.56407
663.97206,-2.12498,-0.65050
664.92206,-5.68867,-30.93624
665.97006,-14.84113,-165.10274
666.75400,-21.50503,-305.38889
667.38606,-25.65508,-404.65374
667.80006,-21.24459,-263.12467
668.55400,-14.04360,-123.15352
669.65406,-4.69234,-16.17485
670.60806,-2.14040,-0.58326
671.69806,-12.66527,-127.50793
672.54206,-19.83959,-267.46023
673.19806,-25.41544,-398.65788
673.66206,-22.67738,-301.13149
674.26606,-16.36768,-160.57856
675.34206,-7.20810,-38.74425
676.29206,0.44699,0.08658
677.39000,-10.18042,-89.45335
678.31606,-18.05434,-228.39574
679.03800,-24.19149,-368.38096
679.53206,-23.96417,-340.06037
680.02000,-18.42581,-198.81230
681.02406,-9.77582,-66.59903
682.12400,-0.42522,0.14296
683.07606,-7.60935,-54.31999
684.08406,-16.21808,-190.95514
684.83800,-22.62746,-331.19563
685.41406,-25.02567,-378.49624
685.84406,-20.14715,-236.66680
686.71000,-12.30839,-98.41599
687.81006,-2.95803,-4.30205
688.76000,-4.53772,-18.37621
689.82800,-14.17854,-153.09201
690.62606,-20.96106,-292.64044
691.22206,-25.83122,-411.44177
691.69606,-21.71860,-275.09430
692.39800,-14.82720,-135.10841
693.49400,-5.50889,-22.92139
694.44400,-1.01558,0.15710
695.54206,-11.88286,-114.84035
696.40800,-19.24415,-253.99739
697.11400,-25.24510,-394.07074
697.55806,-23.13650,-314.22492
698.11206,-17.15098,-174.33260
699.17006,-8.12629,-48.10879
700.12806,0.01710,0.14572
701.22800,-9.34384,-77.47627
702.18606,-17.49363,-216.38228
702.91600,-23.69846,-356.37196
703.43200,-24.35424,-353.08968
703.89406,-19.03166,-211.32765
704.86006,-10.62543,-76.70952
705.96000,-1.27471,0.14834
706.91006,-6.68291,-42.65458
707.93806,-15.52112,-177.36821
708.70406,-22.03201,-317.15360
709.31606,-25.34244,-391.37363
709.73400,-20.69446,-249.42383
710.54806,-13.14143,-109.84886
711.64800,-3.79191,-9.45340
712.59800,-3.30439,-7.51152
713.68006,-13.43040,-139.93463
714.49806,-20.38302,-279.27808
715.09206,-25.43248,-398.64492
715.59206,-22.23488,-288.61407
716.24200,-15.64703,-148.18788
717.33000,-6.39239,-30.81552
718.28406,-0.01961,0.12831
719.38406,-11.04916,-101.99766
720.28406,-18.70084,-241.87069
720.99606,-24.75213,-381.70878
721.46000,-23.56621,-327.15298
721.98206,-17.77321,-185.75629
723.01800,-8.90864,-56.58048
724.06606,0.00012,0.18913
725.06806,-8.48335,-65.68309
726.05400,-16.88121,-203.73674
726.79400,-23.17124,-343.62856
727.33800,-24.70807,-365.70068
727.78206,-19.59577,-223.95443
728.70000,-11.47564,-87.27201
729.80006,-2.12498,-0.60441
730.75200,-5.71546,-31.02484
731.80206,-14.87509,-165.25971
732.58406,-21.52213,-305.07892
733.21406,-25.65597,-404.09654
733.62806,-21.24225,-262.64897
734.38806,-13.99248,-122.10536
735.48806,-4.64164,-15.72099
736.43606,-2.13706,-0.49433
737.52606,-12.66533,-127.09721
738.37006,-19.83971,-266.84603
739.02606,-25.41544,-397.99102
739.49006,-22.67696,-300.66147
740.09406,-16.36815,-160.26389
741.17006,-7.20810,-38.59682
742.12006,0.44824,0.15139
743.22006,-10.19710,-89.36809
744.15206,-18.12274,-229.23710
744.87006,-24.22539,-368.59304
745.36206,-23.94253,-338.90881
745.85006,-18.40255,-198.02937
746.85600,-9.74120,-65.98254
747.95606,-0.39138,0.19302
748.90406,-7.61186,-54.11741
749.91206,-16.21820,-190.47055
750.66406,-22.61036,-330.14867
751.24206,-25.02747,-377.99969
751.67206,-20.14338,-236.23826
752.54006,-12.29147,-97.95573
753.64000,-2.94146,-4.06564
754.58800,-4.53958,-18.26182
755.65406,-14.16126,-152.26858
756.45200,-20.94426,-291.67026
757.05006,-25.83128,-410.83001
757.52406,-21.71543,-274.63267
758.22600,-14.82738,-134.79380
759.32406,-5.49173,-22.67432
760.27206,-1.01457,0.16114
761.37006,-11.88292,-114.49463
762.24006,-19.27823,-254.22366
762.94400,-25.26214,-393.90016
763.38806,-23.11253,-313.11195
763.94806,-17.08168,-172.78077
765.00806,-8.04139,-47.01713
765.95606,0.01704,0.21978
767.05600,-9.34331,-77.19713
768.01200,-17.47677,-215.51467
768.74206,-23.68149,-355.32743
769.26200,-24.33241,-351.83046
769.72406,-19.01294,-210.62190
770.69006,-10.60827,-76.26490
771.79006,-1.25785,0.18156
772.74206,-6.68471,-42.47748
773.77406,-15.55496,-177.64829
774.54006,-22.06597,-317.36724
775.14800,-25.34357,-390.85019
775.56606,-20.69428,-249.06144
776.37806,-13.15847,-109.86069
777.47800,-3.80901,-9.48678
778.42806,-3.32436,-7.51831
779.51000,-13.44732,-139.90451
780.33200,-20.43444,-279.89628
780.92006,-25.43248,-398.05632
781.42206,-22.21043,-287.56309
782.07406,-15.61271,-147.40929
783.16206,-6.35837,-30.36127
784.11206,-0.01847,0.14327
785.21206,-11.04928,-101.65049
786.11400,-18.71776,-241.77147
786.82806,-24.78651,-381.83704
787.29006,-23.54409,-325.96868
787.81200,-17.75611,-185.20316
788.84600,-8.90864,-56.41665
789.89406,0.00018,0.17849
790.89406,-8.46697,-65.13976
791.88006,-16.86417,-202.89984
792.62200,-23.17130,-343.02995
793.16800,-24.68816,-364.47830
793.61206,-19.57239,-223.09797
794.53000,-11.45836,-86.93188
795.63006,-2.10812,-0.54108
796.58000,-5.71109,-30.82237
797.63006,-14.87515,-164.88940
798.41006,-21.50509,-304.15969
799.04206,-25.65693,-403.52777
799.45800,-21.21840,-261.77458
800.21406,-14.00952,-122.11857
801.31400,-4.65850,-15.76090
802.26406,-2.13831,-0.45828
803.35406,-12.66533,-126.81709
804.19606,-19.82267,-265.92899
804.85406,-25.41550,-397.34419
805.31606,-22.69974,-300.88680
805.92006,-16.38609,-160.37650
806.99606,-7.22514,-38.60535
807.94806,0.44788,0.11962
809.04600,-10.18030,-88.81945
809.97800,-18.10576,-228.43417
810.69806,-24.22539,-367.99468
811.19006,-23.94492,-338.47310
811.67806,-18.40237,-197.73560
812.68400,-9.74120,-65.82960
813.78406,-0.39138,0.16816
814.73206,-7.60971,-53.85056
815.74006,-16.21820,-190.07865
816.49006,-22.59338,-329.22145
817.07006,-25.02836,-377.51079
817.50006,-20.14099,-235.85403
818.36806,-12.29153,-97.75635
819.46800,-2.94152,-4.04683
820.41600,-4.53964,-18.13607
821.48206,-14.16126,-151.95818
822.28206,-20.96112,-291.54683
822.87806,-25.83140,-410.23925
823.35206,-21.71483,-274.24287
824.05400,-14.82744,-134.61253
825.15000,-5.50894,-22.75896
826.10006,-1.01313,0.12079
827.19806,-11.88298,-114.13573
828.06606,-19.26113,-253.31499
828.77206,-25.26226,-393.30024
829.21606,-23.11337,-312.67773
829.78000,-17.04688,-171.87605
830.83800,-8.02441,-46.69065
831.78406,0.01710,0.19505
832.88406,-9.34331,-76.93751
833.84406,-17.51061,-215.75337
834.57406,-23.71539,-355.56708
835.09000,-24.33391,-351.39795
835.55400,-18.99267,-209.96049
836.52406,-10.55721,-75.54739
837.62400,-1.20727,0.20217
838.56806,-6.70611,-42.55929
839.59800,-15.55502,-177.20576
840.36600,-22.08307,-317.21622
840.97206,-25.34519,-390.31625
841.39000,-20.69309,-248.65633
842.20000,-13.17545,-109.88362
843.30006,-3.82581,-9.55364
844.25200,-3.32466,-7.43554
845.33200,-13.43040,-139.22901
846.15406,-20.41740,-279.00008
846.74400,-25.43248,-397.45554
847.24606,-22.21096,-287.21398
847.90206,-15.57851,-146.57755
848.99006,-6.32441,-29.94613
849.93606,-0.01584,0.18892
851.03600,-11.04934,-101.36181
851.93806,-18.71776,-241.27930
852.65000,-24.76953,-380.91324
853.11400,-23.54529,-325.54533
853.63606,-17.75324,-184.82938
854.67400,-8.87432,-55.88494
855.71800,0.00006,0.17419
856.72006,-8.48455,-65.13312
857.70606,-16.88127,-202.82384
858.44806,-23.18822,-342.88790
858.99206,-24.68942,-364.01998
859.43606,-19.57096,-222.71877
860.35600,-11.44120,-86.48125
861.45606,-2.09132,-0.48614
862.40406,-5.71564,-30.71193
863.45406,-14.87515,-164.50055
864.23806,-21.53917,-304.45527
864.86600,-25.65813,-402.99814
865.28206,-21.22145,-261.48450
866.04006,-13.99248,-121.65557
867.14000,-4.64164,-15.47349
868.08800,-2.13437,-0.44445
869.18006,-12.68255,-126.68068
870.02606,-19.87367,-266.60185
870.67806,-25.41550,-396.87231
871.14200,-22.68252,-300.03281
871.75200,-16.31715,-158.91742
872.83000,-7.13994,-37.64383
873.77406,0.46612,0.14992
874.87400,-10.18030,-88.56546
875.80400,-18.08865,-227.62895
876.52406,-24.20841,-367.02581
877.01806,-23.94468,-338.08947
877.50806,-18.38479,-197.12010
878.51606,-9.70700,-65.31958
879.61600,-0.35754,0.20705
880.56200,-7.59363,-53.47252
881.57200,-16.21820,-189.63207
882.32606,-22.62752,-329.50409
882.90206,-25.02980,-377.06938
883.33200,-20.14207,-235.60025
884.19806,-12.30857,-97.75789
885.29806,-2.95815,-4.06131
886.24806,-4.53862,-17.94978
887.31400,-14.16138,-151.59562
888.11600,-20.97810,-291.41581
888.71000,-25.83187,-409.74420
889.18400,-21.71794,-273.97068
889.88806,-14.81040,-134.05083
890.98406,-5.49179,-22.44831
891.93400,-0.99065,0.16306
893.03206,-11.86606,-113.63292
893.90406,-19.27829,-253.24898
894.61006,-25.27936,-393.21963
895.05206,-23.11660,-312.39530
895.61400,-17.06368,-171.90453
896.67406,-8.02441,-46.52679
897.62006,0.01698,0.19442
898.72006,-9.34342,-76.70231
899.68006,-17.51061,-215.32906
900.41006,-23.71521,-355.02154
900.92600,-24.33552,-351.04282
901.38806,-19.00744,-209.90867
902.35406,-10.60839,-75.94175
903.45406,-1.25785,0.19160
904.40606,-6.68524,-42.11261
905.43806,-15.55502,-176.79023
906.20606,-22.08307,-316.69326
906.81206,-25.34698,-389.94722
907.23006,-20.69117,-248.36978
908.04600,-13.12457,-108.95072
909.14606,-3.77469,-9.10480
910.09206,-3.32352,-7.30739
911.17206,-13.43046,-138.91175
911.99400,-20.41740,-278.42429
912.58406,-25.43254,-396.92707
913.08606,-22.21180,-286.89681
913.74400,-15.56147,-146.09965
914.83200,-6.30737,-29.63526
915.77606,-0.01357,0.14631
916.87606,-11.04928,-101.02447
917.77406,-18.68386,-240.07758
918.48806,-24.75226,-379.94694
918.95406,-23.54750,-325.23714
919.47600,-17.75629,-184.62144
920.51200,-8.89160,-55.89363
921.56006,0.01698,0.16738
922.56206,-8.46673,-64.70712
923.54806,-16.86429,-202.09333
924.28800,-23.15420,-341.53953
924.83606,-24.69079,-363.59515
925.28000,-19.57066,-222.41974
926.20006,-11.44120,-86.27217
927.30006,-2.09138,-0.42674
928.25006,-5.69328,-30.32799
929.30206,-14.87515,-164.10021
930.08606,-21.53917,-303.95873
930.71406,-25.66082,-402.68663
931.13006,-21.22216,-261.20879
931.88806,-13.99254,-121.42504
932.98806,-4.64170,-15.36065
933.93806,-2.11428,-0.38048
935.03000,-12.66539,-126.11107
935.87400,-19.83971,-265.37485
936.53000,-25.41556,-396.31080
936.99400,-22.67828,-299.58863
937.60006,-16.35034,-159.19989
938.67806,-7.17420,-37.89412
939.62606,0.46576,0.16608
940.72606,-10.18042,-88.30658
941.65800,-18.10582,-227.54671
942.37806,-24.22551,-367.00495
942.87006,-23.94725,-337.82389
943.36006,-18.38473,-196.83572
944.37006,-9.69002,-64.84003
945.47006,-0.34056,0.21368
946.41406,-7.59351,-53.31256
947.42406,-16.21820,-189.23843
948.17806,-22.62752,-329.03172
948.75400,-25.02992,-376.73064
949.18400,-20.13663,-235.22312
950.05806,-12.24070,-96.63844
951.15800,-2.89028,-3.66878
952.10006,-4.53826,-17.81868
953.16800,-14.17848,-151.55816
953.97006,-20.99520,-291.31060
954.56206,-25.83193,-409.31515
955.03606,-21.71734,-273.65278
955.74400,-14.77650,-133.35632
956.84000,-5.45729,-22.06006
957.78606,-0.99113,0.18689
958.88406,-11.86612,-113.32844
959.75400,-19.26125,-252.38337
960.46000,-25.26214,-392.30905
960.90406,-23.11749,-312.07249
961.46606,-17.06386,-171.67939
962.52806,-8.00749,-46.25062
963.47406,0.03390,0.17591
964.57406,-9.32668,-76.20975
965.53406,-17.49381,-214.59447
966.26406,-23.69859,-354.15106
966.78206,-24.34055,-350.75873
967.24400,-19.01157,-209.74359
968.21406,-10.57431,-75.30768
969.31400,-1.22413,0.17781
970.26200,-6.68686,-41.98680
971.29406,-15.55502,-176.45830
972.06206,-22.08307,-316.21661
972.66800,-25.34740,-389.57126
973.08606,-20.69231,-248.05715
973.90606,-13.09073,-108.21617
975.00606,-3.74019,-8.82373
975.94806,-3.32184,-7.20097
977.03000,-13.44744,-138.86815
977.85206,-20.43438,-278.41195
978.44006,-25.43254,-396.52478
978.94200,-22.21730,-286.73908
979.59606,-15.59537,-146.40975
980.68400,-6.34157,-29.83801
981.63406,0.00622,0.15719
982.73406,-11.03254,-100.55559
983.63606,-18.70090,-240.06240
984.34800,-24.75226,-379.53179
984.81400,-23.54863,-324.96836
985.33606,-17.75641,-184.41990
986.37206,-8.89166,-55.80118
987.42006,0.01692,0.21150
988.42206,-8.46721,-64.50949
989.40800,-16.86435,-201.68388
990.15000,-23.17130,-341.48239
990.69606,-24.69264,-363.29489
991.14006,-19.57078,-222.19731
992.06606,-11.39068,-85.47815
993.16606,-2.04050,-0.29457
994.11006,-5.69429,-30.17113
995.16206,-14.87515,-163.77350
995.94606,-21.53923,-303.49622
996.57406,-25.65992,-402.22257
996.99006,-21.21900,-260.85129
997.75006,-13.97556,-120.99079
998.85006,-4.62466,-15.15497
999.79806,-2.11308,-0.32174
1000.89006,-12.66545,-125.83395
1001.73600,-19.85687,-265.33967
1002.39006,-25.41556,-395.91782
1002.85406,-22.67810,-299.25060
1003.46206,-16.33324,-158.74078
1004.54006,-7.15698,-37.59703
1005.48600,0.46678,0.16916
1006.58606,-10.18048,-88.03909
1007.52000,-18.12286,-227.56411
1008.24206,-24.25959,-367.38355
1008.73006,-23.94821,-337.45263
1009.22006,-18.38426,-196.61298
1010.23006,-9.69008,-64.74881
1011.33006,-0.34068,0.19534
1012.27406,-7.59380,-53.12284
1013.28406,-16.21826,-188.89617
1014.03800,-22.62758,-328.59825
1014.61406,-25.03261,-376.38284
1015.04406,-20.13872,-234.96918
1015.91006,-12.30857,-97.39644
1017.01006,-2.95821,-3.97213
1017.96206,-4.51907,-17.52648
1019.03000,-14.16138,-150.96137
1019.83406,-20.99520,-290.94603
1020.42600,-25.83265,-408.85359
1020.90000,-21.72452,-273.55604
1021.60406,-14.81052,-133.70631
1022.70006,-5.49185,-22.27066
1023.65000,-0.98850,0.16215
1024.74806,-11.86618,-113.02061
1025.62000,-19.27829,-252.44860
1026.32606,-25.27924,-392.35886
1026.76806,-23.11887,-311.83669
1027.33006,-17.06386,-171.46565
1028.39206,-8.00749,-46.04214
1029.33800,0.03390,0.19103
1030.43800,-9.32674,-76.04842
1031.39806,-17.49381,-214.22898
1032.13000,-23.71544,-354.19360
1032.64600,-24.33887,-350.40569
1033.11012,-18.99214,-209.11103
1034.08006,-10.55733,-75.01674
1035.18006,-1.20733,0.20260
1036.12612,-6.68656,-41.83525
1037.16006,-15.57176,-176.38708
1037.93006,-22.11715,-316.58929
1038.53212,-25.35147,-389.29373
1038.95006,-20.69518,-247.92647
1039.76600,-13.12451,-108.57541
1040.86606,-3.77475,-8.97800
1041.81406,-3.28549,-6.85570
1042.89600,-13.43046,-138.28313
1043.72006,-20.43450,-277.98479
1044.30812,-25.43260,-396.12077
1044.81006,-22.21987,-286.48974
1045.46400,-15.59573,-146.23647
1046.55406,-6.32447,-29.59681
1047.50206,0.00568,0.14049
1048.60200,-11.03260,-100.33361
1049.50613,-18.71788,-240.02066
1050.21800,-24.76959,-379.53794
1050.68200,-23.54917,-324.61207
1051.20412,-17.75664,-184.22445
1052.24400,-8.85752,-55.24293
1053.28812,0.01692,0.19622
1054.29000,-8.46727,-64.25589
1055.27812,-16.88139,-201.70089
1056.02000,-23.18834,-341.48097
1056.56413,-24.69492,-363.02943
1057.00800,-19.57090,-221.91131
1057.93412,-11.39068,-85.30963
1059.03400,-2.04062,-0.27037
1059.97800,-5.69447,-30.06194
1061.03000,-14.87521,-163.47196
1061.81200,-21.52237,-302.69889
1062.44200,-25.66141,-401.86942
1062.85800,-21.21935,-260.59153
1063.61800,-13.97562,-120.82149
1064.71800,-4.62472,-15.10136
1065.66600,-2.11171,-0.27095
1066.75800,-12.66545,-125.57588
1067.60400,-19.85687,-264.95222
1068.25800,-25.41556,-395.50867
1068.72200,-22.68180,-299.06832
1069.33200,-16.31673,-158.23830
1070.41000,-7.14000,-37.27039
1071.35400,0.46725,0.19457
1072.45412,-10.18048,-87.90409
1073.38612,-18.10587,-226.82952
1074.10800,-24.24255,-366.56681
1074.59800,-23.95167,-337.22252
1075.08600,-18.40225,-196.74724
1076.09400,-9.72410,-65.03223
1077.19412,-0.37458,0.23749
1078.14213,-7.59357,-52.95998
1079.15212,-16.21832,-188.56140
1079.90600,-22.62758,-328.19387
1080.48200,-25.03739,-376.13396
1080.91212,-20.14332,-234.82444
1081.78000,-12.29159,-96.99393
1082.88000,-2.94164,-3.76975
1083.83012,-4.51853,-17.47341
1084.90000,-14.17848,-150.94833
1085.70200,-20.99526,-290.54640
1086.29413,-25.83253,-408.47018
1086.76812,-21.72278,-273.22715
1087.47400,-14.79342,-133.28048
1088.57012,-5.47457,-22.06949
1089.51600,-1.00668,0.19571
1090.61400,-11.88304,-113.04708
1091.48800,-19.31267,-252.80744
1092.19412,-25.31368,-392.81625
1092.63213,-23.12048,-311.59703
1093.19412,-17.06392,-171.29418
1094.25400,-8.02453,-46.18878
1095.20012,0.01692,0.20967
1096.30000,-9.34360,-76.04989
1097.26000,-17.51073,-214.23405
1097.99212,-23.73249,-354.11350
1098.50613,-24.34174,-350.18042
1098.97012,-18.99166,-208.85998
1099.94013,-10.55733,-74.84332
1101.04000,-1.20739,0.17107
1101.98613,-6.68566,-41.66425
1103.02000,-15.57182,-176.13560
1103.78812,-22.10017,-315.81976
1104.39213,-25.35182,-388.94959
1104.81000,-20.69279,-247.57871
1105.63000,-13.09073,-107.93913
1106.73012,-3.74025,-8.67063
1107.67412,-3.29895,-6.91821
1108.75613,-13.43052,-138.04406
1109.58012,-20.43456,-277.65814
1110.16812,-25.43260,-395.72153
1110.67000,-22.21353,-286.09820
1111.32600,-15.57869,-145.77760
1112.41600,-6.30743,-29.41828
1113.36200,0.00688,0.16222
1114.46200,-11.03248,-100.15975
1115.36400,-18.70096,-239.31952
1116.07600,-24.75231,-378.71543
1116.54200,-23.55192,-324.39340
1117.06800,-17.72125,-183.32120
1118.10800,-8.82350,-54.73822
1119.14812,0.01692,0.24835
1120.15000,-8.46703,-64.16260
1121.13612,-16.86435,-201.08398
1121.88000,-23.18840,-341.13973
1122.42412,-24.69743,-362.76504
1122.86800,-19.56600,-221.60729
1123.79000,-11.42434,-85.60643
1124.89000,-2.07446,-0.33296
1125.83800,-5.69429,-29.98560
1126.89000,-14.87521,-163.21814
1127.67600,-21.55621,-303.12754
1128.30200,-25.66285,-401.48739
1128.71800,-21.21959,-260.31235
1129.48200,-13.94130,-120.13945
1130.58200,-4.59070,-14.77915
1131.52600,-2.11129,-0.29738
1132.61800,-12.66545,-125.29911
1133.46412,-19.85681,-264.57494
1134.11800,-25.41562,-395.06763
1134.58200,-22.68426,-298.77860
1135.19013,-16.33395,-158.30593
1136.26812,-7.15704,-37.35850
1137.21412,0.46755,0.15174
1138.31413,-10.18036,-87.67543
1139.24613,-18.10587,-226.46246
1139.96612,-24.22557,-365.71559
1140.45800,-23.95335,-336.90225
1140.95012,-18.36530,-195.83134
1141.96012,-9.67316,-64.29553
1143.06000,-0.32382,0.15928
1144.00212,-7.59333,-52.82711
1145.01400,-16.23524,-188.57960
1145.76812,-22.64444,-328.11835
1146.34200,-25.03751,-375.83254
1146.77212,-20.13979,-234.49548
1147.64400,-12.25780,-96.38871
1148.74400,-2.90762,-3.62247
1149.69013,-4.51961,-17.37040
1150.75800,-14.16138,-150.39732
1151.56200,-20.99526,-290.16010
1152.15400,-25.83271,-408.02911
1152.62800,-21.72146,-272.88701
1153.33600,-14.77656,-132.78740
1154.43412,-5.44037,-21.63882
1155.37800,-0.98551,0.19397
1156.47612,-11.86618,-112.56590
1157.35012,-19.29557,-252.04916
1158.05413,-25.27942,-391.50763
1158.49613,-23.12198,-311.26082
1159.06200,-17.02901,-170.44963
1160.12400,-7.97305,-45.48448
1161.06600,0.03384,0.21416
1162.16600,-9.32662,-75.60571
1163.12612,-17.49381,-213.59380
1163.85612,-23.69870,-352.95926
1164.37400,-24.34365,-349.87383
1164.83600,-19.01210,-208.98581
1165.81000,-10.54035,-74.51277
1166.91000,-1.19035,0.21187
1167.85400,-6.68584,-41.57582
1168.88800,-15.57182,-175.86119
1169.65600,-22.10023,-315.41765
1170.26000,-25.35481,-388.62891
1170.67813,-20.69303,-247.37434
1171.49800,-13.09085,-107.76970
1172.59800,-3.74025,-8.64010
1173.54212,-3.30158,-6.85013
1174.62400,-13.43052,-137.74432
1175.44800,-20.43456,-277.24644
1176.03600,-25.43260,-395.21072
1176.53812,-22.21814,-285.84141
1177.19600,-15.56141,-145.23521
1178.28600,-6.29063,-29.11094
1179.23012,0.00837,0.15257
1180.33012,-11.03254,-99.83844
1181.23200,-18.70096,-238.97588
1181.94412,-24.75231,-378.30610
1182.41000,-23.55348,-324.11728
1182.93412,-17.73901,-183.44780
1183.97200,-8.85764,-55.04285
1185.01613,0.01686,0.19699
1186.01812,-8.46703,-63.95641
1187.00400,-16.86441,-200.76517
1187.74613,-23.17148,-340.30490
1188.29212,-24.70000,-362.48319
1188.73613,-19.56940,-221.43578
1189.66000,-11.40754,-85.22112
1190.76000,-2.05754,-0.26555
1191.70600,-5.69459,-29.82259
1192.76000,-14.89231,-163.24976
1193.54600,-21.57325,-303.09850
1194.17000,-25.66440,-401.14090
1194.58600,-21.22019,-260.02737
1195.34800,-13.95846,-120.25676
1196.44800,-4.60762,-14.81446
1197.29600,0.16920,0.18515
1198.39600,0.01650,0.17414
1199.49613,0.01644,0.20491
1200.59612,0.01644,0.15908
1201.69600,0.01656,0.23921
1202.79600,0.01656,0.25660
1203.89612,0.01656,0.23552
1204.99613,0.01656,0.23798
1206.09612,0.01656,0.21280
1207.19600,0.01656,0.24647
1208.29600,0.01656,0.21098
1209.39612,0.01656,0.20630
1210.14213,0.01656,0.26350