File: ball-data/compression/penn world tour.is_comp_RawData/Specimen_RawData_1.csv
Time,Extension,Load
(sec),(mm),(N)
0.00000,0.00000,-0.06230
1.16800,-9.92769,-117.98032
1.97400,-16.77825,-270.50588
2.70400,-22.98380,-423.48102
3.27200,-24.64643,-428.02799
3.66600,-20.10404,-273.55216
4.49600,-12.63149,-121.28199
5.69200,-2.46488,-5.30544
6.76600,-6.54360,-52.23531
7.75000,-15.01117,-204.61919
8.48000,-21.21601,-356.68861
9.14200,-25.66094,-474.08994
9.50400,-21.84278,-318.30985
10.16800,-15.28752,-164.89154
11.31400,-5.54213,-29.81096
12.36800,-2.18913,-3.60773
13.47200,-12.78389,-151.93322
14.24400,-19.34603,-304.42879
14.92400,-25.12558,-457.43875
15.35200,-23.42678,-368.95823
15.85800,-17.83784,-214.10409
16.90000,-8.92472,-66.25941
17.95200,0.01740,0.11161
19.13200,-10.02700,-100.10350
19.98800,-17.30637,-251.49833
20.69800,-23.34158,-404.06443
21.22000,-24.68936,-419.04237
21.62600,-20.01262,-263.99000
22.48200,-12.34175,-112.02671
23.68200,-2.14220,-2.13656
24.72800,-6.63657,-49.43212
25.73000,-15.24871,-200.57039
26.47000,-21.53857,-353.18051
27.08400,-25.71469,-469.50653
27.45200,-21.89749,-314.97311
28.11800,-15.30408,-161.67337
29.26800,-5.52503,-27.96463
30.32000,-2.18895,-2.53278
31.43800,-12.90275,-149.16201
32.22000,-19.54943,-301.81458
32.89600,-25.29604,-455.11097
33.30200,-23.44860,-365.52928
33.80800,-17.85703,-211.57799
34.85200,-8.92478,-64.56491
35.90400,0.01734,0.11926
37.08800,-10.06096,-97.72494
37.96000,-17.47617,-250.19854
38.67200,-23.52824,-403.26446
39.17000,-24.71154,-416.25857
39.57600,-20.03827,-262.05115
40.43800,-12.30791,-109.81228
41.63800,-2.10818,-1.60042
42.68200,-6.65660,-48.02172
43.69400,-15.35101,-199.08283
44.43600,-21.65815,-351.52204
45.03400,-25.72545,-466.47351
45.40800,-21.84511,-310.92940
46.07600,-15.25296,-158.97000
47.23000,-5.44013,-26.34473
48.27200,-2.18734,-2.07769
49.39800,-12.97079,-147.84303
50.18400,-19.65209,-300.40763
50.85400,-25.34698,-452.91018
51.25400,-23.44819,-363.19789
51.76000,-17.85422,-209.81092
52.81200,-8.85662,-62.77121
53.85600,0.01740,0.15645
55.04600,-10.11232,-96.83073
55.92000,-17.54409,-248.81877
56.63000,-23.57895,-401.33376
57.12200,-24.71076,-413.90982
57.53200,-19.98578,-259.06704
58.40000,-12.22325,-107.48993
59.60000,-2.02304,-1.09069
60.63400,-6.65601,-47.02080
61.65000,-15.38509,-197.44651
62.39400,-21.70885,-349.92747
62.98600,-25.72557,-464.24937
63.35800,-21.86909,-310.07307
64.03400,-15.20178,-156.85016
65.19000,-5.37251,-25.16621
66.22401,-2.18561,-1.70036
67.35400,-13.00505,-146.74654
68.14201,-19.70345,-299.19600
68.81400,-25.41401,-452.40127
69.24001,-23.04216,-347.28091
69.79401,-17.12808,-193.74399
70.88200,-7.85413,-50.54392
71.90801,0.44047,0.10468
73.09200,-10.91272,-108.66374
73.93800,-18.10498,-260.20590
74.64001,-24.07203,-412.76991
75.10400,-24.39669,-398.31951
75.53201,-19.43810,-244.14917
76.47000,-11.21962,-92.31823
77.67001,-1.02049,0.16489
78.68800,-7.57772,-58.37282
79.67400,-15.99716,-209.66891
80.40801,-22.23637,-361.74901
80.97601,-25.48743,-450.51377
81.34801,-21.42204,-295.82225
82.06800,-14.50266,-143.46917
83.24400,-4.50532,-16.99625
84.27600,-3.37912,-9.80982
85.38200,-13.65108,-158.31457
86.15801,-20.24736,-310.45983
86.76801,-25.43206,-451.20671
87.22801,-22.64497,-332.84698
87.82201,-16.47039,-179.80264
88.94000,-6.95286,-40.33065
89.96001,-0.04508,0.10280
91.13200,-11.66122,-120.43796
91.95801,-18.68314,-272.51171
92.64800,-24.54843,-424.61552
93.11201,-23.79000,-372.69961
93.59400,-18.34838,-218.16807
94.62200,-9.51998,-69.50578
95.74201,0.00012,0.16462
96.84001,-9.30958,-82.20680
97.75800,-17.11881,-234.51522
98.47401,-23.20484,-386.36565
99.01000,-24.71381,-410.89308
99.41801,-20.01513,-257.54642
100.28800,-12.22325,-105.94466
101.48801,-2.02304,-0.77695
102.52400,-6.67209,-45.73382
103.54801,-15.47023,-195.98676
104.29201,-21.79405,-347.99621
104.91200,-25.48683,-448.90873
105.28600,-21.39992,-294.05221
106.01201,-14.43486,-141.51372
107.18800,-4.43728,-16.11082
108.21201,-3.37141,-9.32811
109.32401,-13.70244,-157.93020
110.10001,-20.29860,-309.87089
110.70400,-25.43200,-449.43433
111.16200,-22.67260,-332.59377
111.75601,-16.48666,-179.25955
112.87401,-6.97008,-40.07086
113.89600,-0.04460,0.11168
115.06801,-11.66128,-119.32052
115.89600,-18.70000,-271.23097
116.58801,-24.58245,-423.77193
117.04801,-23.78761,-371.39561
117.53201,-18.33236,-216.94995
118.56400,-9.46946,-68.35121
119.67801,0.00018,0.16963
120.77801,-9.32633,-81.65463
121.69801,-17.15235,-233.79687
122.41401,-23.23880,-385.55246
122.94601,-24.71566,-409.69752
123.35801,-19.96641,-255.55341
124.24201,-12.07036,-103.16428
125.44201,-1.87034,-0.31395
126.46001,-6.67484,-45.21451
127.48801,-15.50461,-195.34130
128.23201,-21.82789,-347.29656
128.84801,-25.48779,-447.67316
129.22200,-21.39735,-293.15496
129.95002,-14.41800,-140.54194
131.12800,-4.40296,-15.48505
132.14802,-3.37362,-9.08268
133.26400,-13.73634,-157.46454
134.04002,-20.33190,-309.25149
134.64000,-25.43200,-447.98739
135.09800,-22.66638,-331.50893
135.69200,-16.48701,-178.58110
136.81002,-6.97002,-39.73478
137.83200,-0.04389,0.12799
139.00802,-11.69525,-119.06977
139.83602,-18.73408,-270.69135
140.52600,-24.59931,-422.87286
140.98402,-23.78576,-370.41184
141.46600,-18.34820,-216.61455
142.49600,-9.50336,-68.39090
143.61402,0.00018,0.15564
144.71400,-9.32662,-80.98741
145.63600,-17.16945,-232.96205
146.35000,-23.23886,-384.25773
146.88200,-24.71274,-408.64069
147.29400,-19.95696,-254.57701
148.17802,-12.07024,-102.67692
149.37800,-1.87034,-0.32340
150.39802,-6.69349,-44.97729
151.42402,-15.50455,-194.29749
152.16802,-21.82801,-346.05362
152.78402,-25.48737,-446.70478
153.15800,-21.39824,-292.48687
153.88400,-14.43492,-140.25665
155.06402,-4.40302,-15.30877
156.08402,-3.36980,-8.79777
157.20002,-13.73634,-156.54188
157.97602,-20.33190,-308.10241
158.57600,-25.43206,-446.83535
159.03402,-22.66698,-330.80522
159.63200,-16.45234,-177.37657
160.75402,-6.90246,-38.70745
161.76800,-0.04108,0.15022
162.94400,-11.69525,-118.32703
163.77600,-18.76816,-270.32336
164.46600,-24.63345,-422.72955
164.92402,-23.74331,-368.11542
165.41200,-18.25888,-214.12203
166.44602,-9.38432,-66.60368
167.55000,0.00012,0.17328
168.65002,-9.32639,-80.49086
169.57400,-17.18655,-232.34259
170.29200,-23.29046,-384.50137
170.82000,-24.69444,-406.97429
171.23402,-19.91744,-253.00572
172.12402,-11.98528,-100.97735
173.32400,-1.78502,-0.03562
174.33402,-6.68722,-44.54401
175.36202,-15.52159,-193.73225
176.10800,-21.86203,-345.87935
176.72000,-25.48988,-445.92161
177.09800,-21.35203,-290.56020
177.83202,-14.33214,-138.14181
179.01400,-4.28458,-14.09373
180.02000,-3.37452,-8.59041
181.13600,-13.73634,-155.80012
181.91400,-20.34888,-307.47911
182.51202,-25.43200,-445.87985
182.97402,-22.62339,-328.71008
183.57400,-16.40050,-175.89917
184.69802,-6.83436,-37.83856
185.70402,-0.03958,0.12145
186.88000,-11.69525,-117.75062
187.71200,-18.76816,-269.37526
188.40400,-24.65043,-422.32137
188.86002,-23.74373,-367.39159
189.34602,-18.27358,-213.93133
190.38000,-9.40124,-66.48505
191.48600,0.00018,0.15327
192.58602,-9.32674,-80.01066
193.51202,-17.20389,-231.82813
194.23202,-23.32454,-384.51064
194.75602,-24.69552,-406.32855
195.17402,-19.86596,-251.26435
196.07000,-11.90044,-99.45289
197.27000,-1.69999,0.09913
198.37002,-7.59392,-55.79670
199.37002,-16.13324,-206.84494
200.10802,-22.40587,-359.38870
200.68800,-25.21257,-431.31787
201.07600,-20.85386,-276.33425
201.86602,-13.49844,-123.74801
203.06002,-3.34893,-7.05011
204.15400,-5.71665,-32.30291
205.21600,-14.96071,-180.61135
205.97002,-21.36919,-332.10475
206.60000,-25.73735,-457.63098
206.98002,-21.80009,-302.80270
207.67202,-15.01440,-149.65511
208.83802,-5.10016,-20.93808
209.94000,-3.37308,-8.34992
211.06002,-13.77036,-155.77537
211.84002,-20.40018,-307.72770
212.43200,-25.43206,-444.89618
212.89602,-22.60205,-327.32610
213.50202,-16.33144,-174.04810
214.63000,-6.73212,-36.55222
215.72402,-1.04835,0.12570
216.88602,-12.42671,-129.97336
217.69602,-19.31183,-281.38358
218.37402,-25.07583,-433.83516
218.81202,-23.38666,-353.73218
219.33402,-17.65972,-200.47911
220.40202,-8.53388,-55.90769
221.40800,0.01728,0.14260
222.60400,-10.16350,-92.04394
223.49802,-17.76502,-244.22761
224.20602,-23.78319,-396.35811
224.70602,-24.36811,-391.36942
225.14402,-19.30705,-236.74633
226.10802,-10.89717,-85.27710
227.30802,-0.69733,0.16617
228.39402,-8.46757,-67.22687
229.35602,-16.66052,-218.01906
230.08202,-22.83074,-369.93764
230.63802,-24.95925,-418.02108
231.04200,-20.34523,-262.61445
231.88602,-12.68255,-110.58914
233.08602,-2.48198,-2.03256
234.18002,-6.67574,-43.66156
235.21400,-15.55472,-192.83535
235.96000,-21.89569,-344.81656
236.57000,-25.47655,-443.69191
236.94802,-21.32554,-288.76258
237.68400,-14.29848,-136.72204
238.86602,-4.25050,-13.58839
239.96802,-4.59028,-19.41640
241.06202,-14.39910,-167.89393
241.82802,-20.91048,-319.50805
242.41202,-25.77178,-456.90861
242.85802,-22.20528,-314.39211
243.50602,-15.68010,-161.34480
244.65400,-5.91653,-28.25326
245.75202,-2.18285,-0.70881
246.89802,-13.14125,-142.60988
247.69202,-19.89011,-294.39202
248.34202,-25.41514,-443.43013
248.77402,-22.99355,-339.65725
249.33802,-16.98985,-186.46078
250.43802,-7.61551,-45.52960
251.53602,-0.03958,0.12066
252.71602,-11.72932,-117.10689
253.55202,-18.83608,-269.03756
254.23800,-24.66724,-420.86687
254.69402,-23.72603,-365.45530
255.18400,-18.22175,-211.89094
256.22202,-9.31610,-64.87017
257.32000,0.01722,0.16371
258.51800,-10.18096,-91.85395
259.41400,-17.79904,-244.11811
260.12202,-23.81727,-396.36582
260.61802,-24.38437,-391.31951
261.05402,-19.33114,-236.91893
262.01002,-10.98232,-86.09168
263.21003,-0.78223,0.13883
264.30600,-8.46715,-66.73777
265.27003,-16.67756,-217.54090
265.99803,-22.86506,-369.90892
266.55200,-24.94239,-416.41865
266.95400,-20.34135,-262.09315
267.80003,-12.66593,-109.96422
269.00000,-2.46506,-1.82942
270.09200,-6.67538,-43.28840
271.12803,-15.57200,-192.36205
271.87600,-21.92965,-344.75397
272.48203,-25.47625,-442.92215
272.86400,-21.27759,-286.90325
273.61200,-14.16276,-134.01615
274.79800,-4.07998,-12.05338
275.88203,-4.58149,-19.06698
276.97803,-14.39893,-167.18661
277.74803,-20.94462,-319.49598
278.32800,-25.77178,-456.05972
278.77800,-22.15542,-312.31286
279.43403,-15.57768,-158.96788
280.58800,-5.76317,-26.66821
281.67000,-2.16366,-0.57397
282.81600,-13.12457,-141.61864
283.61003,-19.87319,-293.11303
284.26203,-25.41508,-442.57097
284.69600,-22.97477,-338.44147
285.26000,-16.97215,-185.62537
286.36800,-7.53091,-44.33208
287.45603,-0.03821,0.11280
288.63800,-11.74642,-116.76597
289.47600,-18.86987,-269.02704
290.16400,-24.71830,-421.47338
290.61603,-23.70588,-364.08234
291.11200,-18.14695,-209.93786
292.15803,-9.18014,-62.97063
293.24003,0.01728,0.17450
294.43803,-10.18102,-91.37268
295.33400,-17.79898,-243.33891
296.04203,-23.81733,-395.52703
296.54000,-24.36237,-389.72925
296.98203,-19.24750,-234.41717
297.94803,-10.82919,-83.69291
299.14800,-0.62970,0.14050
300.22600,-8.46793,-66.37525
301.19600,-16.72791,-218.02090
301.92400,-22.91612,-370.44927
302.47000,-24.96206,-416.77795
302.87200,-20.36275,-262.16803
303.71200,-12.73349,-110.68532
304.91203,-2.53310,-2.03150
306.01400,-6.69397,-43.27392
307.05200,-15.60649,-192.46761
307.80003,-21.96373,-344.84863
308.40200,-25.47971,-442.40125
308.78403,-21.28064,-286.54998
309.53003,-14.17998,-133.86760
310.71600,-4.09708,-12.12051
311.80200,-4.57695,-18.77461
312.90200,-14.43336,-167.21768
313.67000,-20.96160,-319.07335
314.24600,-25.76288,-454.99343
314.69600,-22.17742,-312.57004
315.34803,-15.62856,-159.62249
316.50200,-5.81483,-26.91368
317.59003,-2.16336,-0.50899
318.74003,-13.15781,-141.72768
319.53600,-19.92419,-293.58743
320.18200,-25.41514,-441.81019
320.61400,-22.99409,-338.61790
321.17400,-17.02351,-186.33902
322.27403,-7.64953,-45.38736
323.37600,-0.03743,0.08549
324.56003,-11.76329,-116.56834
325.39800,-18.88691,-268.67181
326.08400,-24.71823,-420.74833
326.53403,-23.72693,-364.37925
327.02600,-18.20058,-210.57703
328.06600,-9.28226,-63.96754
329.16000,0.01722,0.14893
330.35800,-10.18090,-90.90345
331.25803,-17.83300,-243.38167
331.96403,-23.83449,-395.24563
332.46003,-24.36446,-389.34339
332.89800,-19.28947,-235.10221
333.86003,-10.89724,-84.37919
335.06003,-0.69738,0.14822
336.14603,-8.46787,-66.00777
337.11800,-16.74459,-217.70751
337.84403,-22.91612,-369.77492
338.39000,-24.96588,-416.33777
338.79400,-20.34266,-261.29829
339.64203,-12.64883,-109.13474
340.84200,-2.44802,-1.60629
341.93403,-6.69475,-42.98402
342.97403,-15.62330,-192.16990
343.72200,-21.98107,-344.57281
344.32000,-25.49550,-442.62666
344.70203,-21.30892,-286.91223
345.45000,-14.17998,-133.59555
346.63603,-4.09720,-11.93469
347.72003,-4.60044,-18.80027
348.82000,-14.45005,-167.03293
349.59003,-20.99562,-319.24322
350.16203,-25.76288,-454.32609
350.61003,-22.20373,-312.94908
351.25403,-15.71465,-160.85425
352.40200,-5.94971,-28.06982
353.40600,-1.02952,0.12271
354.57603,-12.47771,-128.65582
355.39400,-19.43111,-281.07153
356.07000,-25.17736,-433.88851
356.49803,-23.36687,-350.96157
357.02403,-17.60651,-197.85959
358.10000,-8.41531,-53.69771
359.19403,0.46014,0.11051
360.38803,-10.98112,-103.16270
361.25403,-18.34276,-255.00361
361.95203,-24.27597,-407.26580
362.42400,-24.05977,-376.60763
362.89000,-18.72846,-221.88216
363.90003,-10.01277,-72.71206
365.08003,0.01722,0.10849
366.18200,-9.32686,-77.84188
367.11800,-17.28927,-229.91959
367.83603,-23.39229,-382.24969
368.35400,-24.68063,-402.64297
368.77200,-19.83768,-248.43646
369.68003,-11.78170,-96.27316
370.88000,-1.58071,0.13926
371.97003,-7.59488,-54.08996
372.97600,-16.18460,-204.20955
373.71403,-22.45694,-356.69945
374.28600,-25.23637,-429.44763
374.67800,-20.82648,-273.55179
375.47403,-13.43058,-121.05597
376.67000,-3.26421,-5.82775
377.75803,-5.72006,-31.10313
378.83003,-15.04519,-179.07120
379.58603,-21.47161,-330.82988
380.20203,-25.75187,-455.02312
380.58800,-21.75578,-299.35671
381.28200,-14.96328,-146.96683
382.45400,-4.99804,-19.28947
383.54603,-3.35700,-7.46567
384.67203,-13.80456,-153.40990
385.46003,-20.50212,-306.42074
386.04000,-25.43212,-441.18945
386.50403,-22.60509,-325.20682
387.11603,-16.28014,-171.26368
388.24803,-6.64782,-34.76839
389.33400,-1.02545,0.10816
390.50403,-12.47777,-128.23677
391.32000,-19.41413,-280.10881
391.99603,-25.16014,-432.74011
392.42603,-23.36681,-350.62250
392.95203,-17.60520,-197.52106
394.03003,-8.39833,-53.29716
395.12200,0.46008,0.09715
396.31600,-10.98124,-102.83045
397.18403,-18.36004,-254.82170
397.88203,-24.29307,-407.19967
398.35203,-24.06270,-376.32592
398.81200,-18.78508,-222.84428
399.81803,-10.09821,-73.63218
401.00600,0.00006,0.12509
402.10803,-9.34384,-77.78401
403.04400,-17.30649,-229.61421
403.76000,-23.39234,-381.62202
404.27800,-24.68236,-402.28944
404.69803,-19.81591,-247.55243
405.60803,-11.74738,-95.56830
406.80800,-1.54687,0.15052
407.89400,-7.59434,-53.82418
408.90200,-16.20152,-204.06313
409.63803,-22.45700,-356.11760
410.21003,-25.23667,-428.92735
410.60203,-20.82510,-273.18059
411.40003,-13.41354,-120.56561
412.59600,-3.24735,-5.70723
413.68200,-5.71474,-30.83437
414.75600,-15.06235,-178.97783
415.51400,-21.50545,-331.11501
416.12600,-25.75200,-454.57594
416.51203,-21.75692,-298.97148
417.20603,-14.96328,-146.73539
418.37803,-4.99810,-19.10906
419.47003,-3.35527,-7.33561
420.59600,-13.80456,-153.00431
421.38203,-20.48514,-305.42750
421.96403,-25.43206,-440.65755
422.42800,-22.60587,-324.82833
423.04400,-16.24678,-170.34758
424.17603,-6.61373,-34.22908
425.25803,-1.02545,0.11578
426.42800,-12.47777,-127.85830
427.24803,-19.44803,-280.33771
427.92203,-25.17730,-432.73889
428.35000,-23.37010,-350.33830
428.87403,-17.62427,-197.69944
429.95203,-8.41531,-53.33445
431.04603,0.46056,0.08996
432.24003,-10.98118,-102.49984
433.11003,-18.37720,-254.67575
433.80800,-24.30987,-407.11280
434.27603,-24.06252,-375.95212
434.73603,-18.78616,-222.56725
435.74203,-10.09815,-73.41440
436.93200,0.01722,0.15556
438.03403,-9.32674,-77.29888
438.97403,-17.32347,-229.63502
439.69003,-23.40914,-381.57072
440.20603,-24.68374,-401.90738
440.62600,-19.81657,-247.38763
441.53200,-11.78170,-95.82726
442.73203,-1.58077,0.15832
443.82203,-7.59536,-53.64101
444.83203,-16.21844,-203.98853
445.56803,-22.47410,-356.02428
446.13803,-25.23816,-428.59316
446.53003,-20.82313,-272.89210
447.32203,-13.46460,-121.09251
448.51803,-3.29799,-5.89825
449.61003,-5.71916,-30.71948
450.68403,-15.06235,-178.49311
451.44203,-21.50551,-330.61165
452.05403,-25.75319,-454.23307
452.44003,-21.75614,-298.74848
453.14000,-14.91162,-145.57906
454.31200,-4.94734,-18.58256
455.39800,-3.35838,-7.21600
456.52603,-13.82148,-152.87117
457.31200,-20.50218,-305.37117
457.89203,-25.43212,-440.21025
458.35603,-22.60623,-324.57255
458.96203,-16.33216,-171.73521
460.09403,-6.69846,-35.02500
461.18603,-1.02425,0.16258
462.35803,-12.49505,-127.78783
463.17603,-19.44791,-279.82291
463.85203,-25.19446,-432.82598
464.27800,-23.36675,-349.95228
464.80403,-17.60592,-197.07149
465.88203,-8.39839,-52.99861
466.97403,0.45966,0.04848
468.17000,-10.99792,-102.43203
469.04403,-18.42826,-255.45154
469.74003,-24.34383,-407.63013
470.20400,-24.06223,-375.65731
470.66403,-18.78359,-222.29886
471.67000,-10.09821,-73.28373
472.86003,0.01716,0.18267
473.96203,-9.32680,-76.98155
474.90403,-17.34045,-229.56461
475.62003,-23.42636,-381.70941
476.13403,-24.68344,-401.66199
476.55203,-19.83176,-247.55087
477.46003,-11.78182,-95.68582
478.66003,-1.58089,0.16615
479.75003,-7.59548,-53.41019
480.76403,-16.25252,-204.27678
481.50003,-22.50800,-356.48391
482.06600,-25.24193,-428.42977
482.45800,-20.82648,-272.73260
483.25003,-13.46466,-120.95570
484.44600,-3.29799,-5.85377
485.53803,-5.72000,-30.53498
486.61400,-15.07939,-178.45415
487.37200,-21.52195,-330.63352
487.98203,-25.75265,-453.80305
488.36800,-21.75268,-298.41043
489.07203,-14.87778,-144.80330
490.24403,-4.91326,-18.20155
491.32603,-3.35969,-7.16714
492.45603,-13.83834,-152.82474
493.24003,-20.50218,-304.90890
493.82003,-25.43206,-439.78754
494.28403,-22.60408,-324.26339
494.89203,-16.31530,-171.19426
496.02403,-6.68178,-34.72061
497.11400,-1.02814,0.12381
498.28600,-12.49499,-127.46964
499.10603,-19.46495,-279.81451
499.78003,-25.19446,-432.40041
500.20603,-23.36944,-349.80915
500.73203,-17.60538,-196.87681
501.81003,-8.39845,-52.86505
502.90203,0.46163,0.14283
504.09803,-10.99798,-102.12421
504.97003,-18.41140,-254.60172
505.66600,-24.32679,-406.75398
506.13203,-24.06581,-375.48218
506.59200,-18.78783,-222.20178
507.59603,-10.11525,-73.32806
508.78803,0.01716,0.16301
509.89000,-9.32668,-76.77756
510.83203,-17.34051,-229.15486
511.55003,-23.44340,-381.72886
512.06200,-24.68768,-401.48567
512.48003,-19.83517,-247.34534
513.38606,-11.79874,-95.72774
514.58600,-1.59781,0.12724
515.67803,-7.59494,-53.23236
516.69000,-16.23548,-203.53749
517.42603,-22.49108,-355.63286
517.99403,-25.24097,-428.12560
518.38606,-20.82570,-272.53721
519.18006,-13.44756,-120.48787
520.37603,-3.28107,-5.74454
521.46600,-5.72066,-30.42030
522.54206,-15.07939,-178.10851
523.30200,-21.53875,-330.61564
523.91003,-25.75271,-453.52325
524.29600,-21.74939,-298.08557
525.00000,-14.87772,-144.58645
526.17200,-4.91332,-18.11035
527.25400,-3.35610,-7.06835
528.38406,-13.83840,-152.55277
529.17006,-20.51910,-304.94113
529.74806,-25.43212,-439.41543
530.21206,-22.60103,-323.92327
530.81806,-16.33222,-171.33338
531.95000,-6.69858,-34.74900
533.04206,-1.02407,0.14941
534.21406,-12.49499,-127.12276
535.03400,-19.46483,-279.41411
535.70800,-25.19434,-431.97706
536.13406,-23.36717,-349.41047
536.66206,-17.58631,-196.25301
537.74200,-8.36377,-52.37044
538.83000,0.46122,0.09951
540.02600,-10.99798,-101.88317
540.89800,-18.41134,-254.19021
541.59406,-24.32679,-406.31503
542.06000,-24.06539,-375.19131
542.52000,-18.78299,-221.84152
543.52800,-10.08123,-72.75596
544.71600,0.01716,0.14334
545.81806,-9.32668,-76.60061
546.76200,-17.35743,-229.14160
547.47800,-23.44340,-381.31259
547.99006,-24.68703,-401.16262
548.40800,-19.82889,-246.95484
549.31806,-11.76460,-95.10516
550.51800,-1.56385,0.16776
551.60600,-7.59542,-53.05684
552.61806,-16.23548,-203.15282
553.35400,-22.49090,-355.17950
553.92200,-25.22633,-427.15270
554.31400,-20.79969,-271.69604
555.11600,-13.37964,-119.23240
556.31200,-3.21333,-5.20513
557.39406,-5.71857,-30.30089
558.47006,-15.07945,-177.75448
559.23006,-21.53869,-330.23771
559.83800,-25.75349,-453.26170
560.22400,-21.75047,-297.90759
560.92200,-14.92884,-145.37582
562.09406,-4.96438,-18.47374
563.18200,-3.35993,-7.03852
564.31200,-13.83840,-152.23595
565.10006,-20.53632,-304.99771
565.67600,-25.43230,-439.10798
566.14000,-22.60450,-323.83393
566.75606,-16.24672,-169.52656
567.89200,-6.57960,-33.40529
568.97006,-1.02348,0.14564
570.14200,-12.49499,-126.86214
570.96406,-19.48211,-279.43524
571.63800,-25.21114,-432.17015
572.06200,-23.37267,-349.40004
572.59000,-17.58738,-196.11843
573.66800,-8.38117,-52.45979
574.75806,0.46104,0.07917
575.95406,-10.99792,-101.65283
576.82606,-18.41128,-253.81396
577.52206,-24.32673,-405.98068
577.98806,-24.06880,-375.06588
578.44800,-18.78712,-221.79499
579.45406,-10.09827,-72.77137
580.64406,0.01716,0.15264
581.74606,-9.32686,-76.39806
582.68806,-17.34051,-228.40543
583.40406,-23.42636,-380.48875
583.91800,-24.68738,-400.96097
584.33600,-19.83104,-246.85673
585.24400,-11.78176,-95.25961
586.44400,-1.58095,0.07258
587.53406,-7.59464,-52.86009
588.54600,-16.23548,-202.83392
589.28206,-22.49114,-354.84727
589.85006,-25.24038,-427.51059
590.24200,-20.81290,-271.80526
591.03600,-13.44761,-120.24138
592.23206,-3.28113,-5.63931
593.32200,-5.71821,-30.15415
594.40000,-15.09637,-177.78492
595.16006,-21.55609,-330.32734
595.76606,-25.75385,-452.94981
596.15206,-21.74903,-297.74798
596.85600,-14.87784,-144.19069
598.03000,-4.89634,-17.82123
599.11006,-3.35748,-6.92422
600.24400,-13.87260,-152.59312
601.03000,-20.55324,-304.94312
601.60400,-25.43218,-438.74171
602.06806,-22.60964,-323.78562
602.68006,-16.28038,-170.04363
603.81200,-6.64782,-34.05380
604.89800,-1.02276,0.08952
606.07000,-12.49505,-126.65275
606.89406,-19.49909,-279.50378
607.56806,-25.22800,-432.36386
607.99006,-23.37112,-349.16792
608.51800,-17.58666,-195.93451
609.59800,-8.36383,-52.16404
610.68606,0.46128,0.08402
611.88200,-10.99804,-101.44709
612.76000,-18.46228,-254.68221
613.45800,-24.39543,-407.54728
613.91600,-24.06820,-374.87805
614.37606,-18.78323,-221.57228
615.38406,-10.08129,-72.49050
616.57200,0.01716,0.08555
617.67400,-9.32698,-76.17873
618.62006,-17.37411,-228.78509
619.33406,-23.44346,-380.57875
619.84600,-24.68768,-400.76129
620.26406,-19.82572,-246.57769
621.17206,-11.78182,-95.08787
622.37200,-1.58089,0.10172
623.46206,-7.59644,-52.77648
624.47800,-16.26950,-203.23269
625.21406,-22.52510,-355.41620
625.77800,-25.24432,-427.41805
626.17006,-20.81494,-271.70388
626.96406,-13.44761,-120.07169
628.16006,-3.28113,-5.51512
629.25000,-5.72401,-30.09639
630.32800,-15.09637,-177.42312
631.08800,-21.55615,-329.92937
631.69400,-25.75570,-452.77122
632.08000,-21.74951,-297.54236
632.78406,-14.87754,-144.08746
633.95800,-4.89622,-17.74463
635.03800,-3.36101,-6.93117
636.17006,-13.85556,-151.97934
636.95606,-20.53638,-304.27294
637.53206,-25.43218,-438.43750
637.99606,-22.60199,-323.39677
638.60006,-16.34878,-171.13527
639.73206,-6.71544,-34.68339
640.82606,-1.02306,0.11783
641.99806,-12.49505,-126.36716
642.82200,-19.49903,-279.14638
643.49400,-25.21120,-431.49371
643.91800,-23.37004,-348.90004
644.45000,-17.54888,-194.98806
645.53000,-8.32987,-51.66393
646.61400,0.46307,0.11954
647.81006,-10.99810,-101.18025
648.68606,-18.44530,-253.90806
649.38200,-24.36117,-406.24317
649.84406,-24.07077,-374.74360
650.30600,-18.76906,-221.02453
651.31400,-10.06425,-72.13847
652.50006,0.01710,0.13726
653.60206,-9.32674,-75.99595
654.54600,-17.35743,-228.06881
655.26200,-23.44346,-380.24899
655.77406,-24.69181,-400.63176
656.19200,-19.82937,-246.50903
657.10006,-11.78176,-94.97114
658.30006,-1.58083,0.14098
659.39000,-7.59620,-52.60377
660.40406,-16.25258,-202.51922
661.14200,-22.52510,-355.08905
661.70606,-25.24337,-427.11660
662.09800,-20.81165,-271.46438
662.89406,-13.43058,-119.61567
664.09000,-3.26433,-5.40252
665.17806,-5.72245,-29.97162
666.25806,-15.11329,-177.49177
667.01606,-21.55609,-329.61205
667.62200,-25.75570,-452.49719
668.00806,-21.75130,-297.40846
668.71206,-14.87754,-143.90644
669.88406,-4.91344,-17.81344
670.96600,-3.36131,-6.77234
672.09800,-13.85550,-151.73401
672.88606,-20.55336,-304.28516
673.46000,-25.43224,-438.08367
673.92400,-22.60288,-323.16837
674.53000,-16.33240,-170.68351
675.66206,-6.69852,-34.41662
676.75400,-1.02109,0.10803
677.92806,-12.51233,-126.44940
678.75006,-19.49909,-278.77908
679.42206,-25.21126,-431.16700
679.84600,-23.37184,-348.75408
680.37806,-17.55151,-194.89005
681.46000,-8.31343,-51.36115
682.54206,0.46211,0.07363
683.73806,-10.99804,-100.98725
684.61400,-18.44524,-253.58915
685.31006,-24.36123,-405.92153
685.77206,-24.06994,-374.46685
686.23206,-18.78801,-221.33486
687.24200,-10.06425,-72.07363
688.42806,0.01704,0.15286
689.53000,-9.32650,-75.83247
690.47406,-17.35749,-227.76814
691.19200,-23.46044,-380.38906
691.70200,-24.69145,-400.38574
692.12006,-19.82805,-246.24353
693.03406,-11.73034,-94.17229
694.23400,-1.53031,0.11326
695.31806,-7.59590,-52.44656
696.33406,-16.26950,-202.62608
697.07000,-22.52504,-354.77620
697.63406,-25.24528,-426.97702
698.02606,-20.81207,-271.28132
698.82800,-13.37969,-118.71597
700.02406,-3.21339,-4.99897
701.10600,-5.72389,-29.87021
702.18606,-15.11329,-177.26794
702.94606,-21.57355,-329.71811
703.55006,-25.75612,-452.29726
703.93606,-21.74885,-297.17997
704.64000,-14.87754,-143.81006
705.81400,-4.89628,-17.57951
706.89406,-3.35868,-6.66912
708.02606,-13.85562,-151.50508
708.81400,-20.55330,-304.03834
709.38806,-25.43218,-437.82983
709.85206,-22.60438,-323.07819
710.45800,-16.33258,-170.56933
711.59000,-6.69852,-34.34933
712.68200,-1.01839,0.13130
713.85600,-12.51233,-126.22451
714.68006,-19.51577,-278.92947
715.35206,-25.22806,-431.47773
715.77406,-23.37345,-348.61941
716.30206,-17.58612,-195.47284
717.38200,-8.36383,-51.84482
718.47006,0.46229,0.10508
719.66600,-10.99810,-100.85671
720.54206,-18.44524,-253.27764
721.23600,-24.34401,-405.19923
721.70000,-24.07054,-374.28379
722.16006,-18.78395,-221.10282
723.16800,-10.08135,-72.13724
724.35600,0.01710,0.10914
725.45800,-9.32704,-75.66690
726.40600,-17.39133,-228.30920
727.12200,-23.47730,-380.57804
727.63000,-24.69175,-400.24512
728.04806,-19.82901,-246.19792
728.95800,-11.76472,-94.52383
730.15800,-1.56391,0.13547
731.24606,-7.59661,-52.37958
732.26200,-16.26950,-202.32607
732.99606,-22.50818,-354.11041
733.56200,-25.24797,-426.85386
733.95406,-20.81888,-271.34251
734.75006,-13.43064,-119.38863
735.94606,-3.26433,-5.31925
737.03406,-5.72598,-29.81787
738.11206,-15.09643,-176.61816
738.87200,-21.55615,-329.03615
739.47800,-25.75767,-452.13234
739.86400,-21.75304,-297.12819
740.56606,-14.89458,-143.98966
741.73806,-4.93036,-17.80724
742.82200,-3.35748,-6.67393
743.95606,-13.87266,-151.56554
744.74606,-20.58708,-304.57180
745.31606,-25.43224,-437.61641
745.78000,-22.60515,-322.87605
746.39606,-16.24642,-168.74557
747.53206,-6.57972,-33.00477
748.61006,-1.01857,0.13510
749.78206,-12.49511,-125.72497
750.60600,-19.49897,-278.24517
751.28000,-25.22794,-431.20380
751.70200,-23.37405,-348.50113
752.22800,-17.60388,-195.65750
753.30806,-8.38123,-51.94380
754.39800,0.46289,0.08447
755.59406,-10.99810,-100.64656
756.47206,-18.46240,-253.40689
757.16800,-24.37839,-405.93091
757.62806,-24.07125,-374.13243
758.09406,-18.72601,-219.69859
759.10406,-10.01295,-71.20494
760.28406,0.01704,0.11474
761.38606,-9.32692,-75.54264
762.33200,-17.37435,-227.57964
763.04806,-23.46044,-379.86018
763.55806,-24.69253,-400.09052
763.97600,-19.82757,-246.00351
764.88806,-11.74756,-94.16733
766.08800,-1.54693,0.08762
767.17400,-7.59673,-52.23012
768.19200,-16.28630,-202.46118
768.92806,-22.54196,-354.66880
769.49006,-25.24642,-426.65746
769.88006,-20.83222,-271.54114
770.67600,-13.44768,-119.54729
771.87200,-3.28113,-5.35843
772.96206,-5.72455,-29.71961
774.04206,-15.11341,-176.77469
774.80006,-21.55615,-328.80202
775.40606,-25.75821,-451.93698
775.79206,-21.74927,-296.90450
776.49400,-14.89458,-143.83322
777.66600,-4.93042,-17.72943
778.75006,-3.35868,-6.56829
779.88406,-13.87260,-151.28350
780.67206,-20.57016,-303.88262
781.24400,-25.43218,-437.28977
781.70800,-22.60647,-322.75856
782.32000,-16.27990,-169.27510
783.45200,-6.64811,-33.62487
784.53800,-1.01845,0.18216
785.71206,-12.51233,-125.83791
786.53406,-19.49915,-277.95305
787.20800,-25.22794,-430.90977
787.63006,-23.37166,-348.25016
788.16406,-17.53237,-193.99874
789.24400,-8.31343,-51.11285
790.32606,0.46241,0.10636
791.52206,-10.99816,-100.44012
792.40000,-18.46234,-253.13927
793.09600,-24.37845,-405.55324
793.55806,-24.04961,-373.09542
794.02606,-18.68458,-218.59214
795.04006,-9.94509,-70.32735
796.21206,0.01704,0.17274
797.31400,-9.32674,-75.37580
798.26200,-17.39133,-227.68350
798.97800,-23.47736,-380.05516
799.48600,-24.69348,-399.90533
799.90406,-19.82231,-245.76042
800.81606,-11.74762,-94.03465
802.01606,-1.54705,0.18883
803.10206,-7.59596,-52.08974
804.11806,-16.26956,-201.81164
804.85806,-22.55912,-354.87175
805.42006,-25.23003,-425.56521
805.81200,-20.78696,-270.25871
806.61400,-13.36277,-118.09700
807.81006,-3.19653,-4.78570
808.89000,-5.72335,-29.60326
809.97006,-15.11323,-176.46652
810.73006,-21.57349,-328.94924
811.33406,-25.75791,-451.63531
811.72006,-21.75076,-296.74778
812.42206,-14.89476,-143.70666
813.59406,-4.93042,-17.71462
814.67806,-3.35736,-6.46683
815.81200,-13.87260,-151.09287
816.59800,-20.55330,-303.22127
817.17206,-25.43224,-437.01064
817.63606,-22.60653,-322.66915
818.25200,-16.24654,-168.52519
819.38606,-6.59664,-33.04244
820.46606,-1.01768,0.12535
821.64000,-12.51233,-125.61355
822.46206,-19.49915,-277.72117
823.13806,-25.24540,-431.21245
823.55806,-23.37381,-348.18053
824.08200,-17.62254,-195.81519
825.15800,-8.43223,-52.35634
826.25400,0.46307,0.13980
827.45000,-10.99810,-100.28713
828.32806,-18.46240,-252.92711
829.02406,-24.37845,-405.38639
829.48406,-24.07251,-373.83340
829.94606,-18.76535,-220.29029
830.95606,-10.04703,-71.49045
832.14000,0.01704,0.15932
833.24206,-9.32710,-75.21123
834.18806,-17.37435,-227.03569
834.90406,-23.46050,-379.33838
835.41406,-24.69635,-399.86107
835.83406,-19.80593,-245.19596
836.74606,-11.73046,-93.73647
837.94606,-1.53037,0.16352
839.03000,-7.59578,-51.98864
840.04806,-16.28636,-201.96371
840.78406,-22.54208,-354.16264
841.34606,-25.24815,-426.25196
841.73806,-20.81123,-270.84762
842.53406,-13.43069,-119.06534
843.73006,-3.26439,-5.18019
844.81806,-5.72455,-29.50760
845.89800,-15.11341,-176.27552
846.65800,-21.57349,-328.70378
847.26200,-25.75815,-451.51740
847.64800,-21.75011,-296.66213
848.34800,-14.91162,-143.91830
849.52000,-4.94746,-17.75465
850.60600,-3.35802,-6.45660
851.74006,-13.87266,-150.93310
852.53000,-20.58720,-303.83781
853.10006,-25.43230,-436.83611
853.56400,-22.60719,-322.56372
854.17600,-16.28068,-169.07141
855.30806,-6.64793,-33.49283
856.39406,-1.01451,0.15708
857.56806,-12.51239,-125.44593
858.39000,-19.49915,-277.48976
859.06606,-25.24522,-430.99053
859.48806,-23.35288,-347.33556
860.02206,-17.51623,-193.54871
861.10600,-8.26201,-50.41291
862.18206,0.46337,0.07936
863.37806,-10.99816,-100.12394
864.25606,-18.46234,-252.64485
864.95200,-24.37851,-405.19986
865.41206,-24.07418,-373.75141
865.87206,-18.77923,-220.50971
866.88200,-10.06431,-71.59316
868.06806,0.01698,0.13932
869.17006,-9.32710,-75.09078
870.11806,-17.39127,-227.15978
870.83606,-23.49428,-380.02715
871.34406,-24.67549,-398.77012
871.76406,-19.78237,-244.47607
872.68206,-11.66242,-92.68726
873.88200,-1.46245,0.14618
874.95806,-7.59667,-51.87415
875.97600,-16.28636,-201.70501
876.71000,-22.52510,-353.51496
877.27606,-25.23063,-425.29803
877.66800,-20.78923,-270.07379
878.47206,-13.34585,-117.61684
879.67006,-3.16239,-4.49979
880.74606,-5.72407,-29.46054
881.82606,-15.11335,-176.07169
882.58606,-21.57355,-328.50571
883.19006,-25.75839,-451.34161
883.57606,-21.75058,-296.55684
884.28000,-14.87784,-143.21988
885.45606,-4.87930,-17.13361
886.53406,-3.35688,-6.35217
887.66800,-13.87266,-150.70224
888.45606,-20.57022,-303.17480
889.02800,-25.43230,-436.56159
889.49400,-22.58297,-321.65747
890.10806,-16.24588,-168.26231
891.24400,-6.57965,-32.73505
892.32200,-1.02120,0.10093
893.49606,-12.51239,-125.35839
894.32006,-19.51595,-277.64702
894.99400,-25.24534,-430.79175
895.41600,-23.35354,-347.15381
895.94806,-17.53411,-193.76127
897.02800,-8.31337,-50.92802
898.11006,0.46343,0.11096
899.30600,-10.99822,-100.01945
900.18400,-18.46234,-252.40643
900.88200,-24.39555,-405.48492
901.34206,-24.05104,-372.74059
901.80600,-18.72368,-219.12370
902.81806,-9.99603,-70.70483
903.99606,0.01698,0.12332
905.09800,-9.32716,-74.98935
906.04600,-17.39145,-226.98222
906.76006,-23.46050,-378.88169
907.27206,-24.67584,-398.64864
907.69200,-19.77693,-244.27006
908.60806,-11.67946,-92.81345
909.80806,-1.47949,0.14364
910.88606,-7.59608,-51.82538
911.90406,-16.28636,-201.49838
912.64200,-22.55912,-354.18086
913.20200,-25.24976,-425.99287
913.59406,-20.80752,-270.46837
914.39406,-13.39679,-118.33904
915.59000,-3.23049,-4.87854
916.67406,-5.72323,-29.33321
917.75400,-15.11341,-175.85833
918.51200,-21.55627,-327.83538
919.11806,-25.76025,-451.25913
919.50200,-21.77211,-297.06810
920.19606,-14.98050,-144.92380
921.36806,-5.01526,-18.26060
922.46206,-3.35760,-6.37456
923.59606,-13.87266,-150.55903
924.38406,-20.57028,-303.00785
924.95606,-25.43236,-436.44801
925.42006,-22.60372,-322.20460
926.03406,-16.26346,-168.53111
927.16800,-6.61379,-33.06202
928.25006,-1.01343,0.13369
929.42600,-12.52955,-125.32947
930.25006,-19.53269,-277.80926
930.92206,-25.24540,-430.61536
931.34406,-23.36054,-347.24079
931.87400,-17.55240,-194.07321
932.95606,-8.31349,-50.84169
934.03800,0.46403,0.09256
935.23406,-10.99822,-99.80712
936.11406,-18.47950,-252.58493
936.81006,-24.39561,-405.28819
937.27000,-24.05314,-372.66318
937.73600,-18.70712,-218.69866
938.75400,-9.92817,-69.75412
939.92406,0.01692,0.13322
941.02606,-9.32704,-74.84585
941.97406,-17.39121,-226.76239
942.68806,-23.46050,-378.71327
943.20006,-24.67662,-398.52351
943.62206,-19.75953,-243.73006
944.54406,-11.61178,-91.82889
945.74400,-1.41133,0.13820
946.81400,-7.59632,-51.69596
947.83200,-16.28636,-201.33147
948.56806,-22.54214,-353.51790
949.13006,-25.25198,-425.90704
949.51806,-20.85446,-271.50879
950.30806,-13.51572,-120.10152
951.50400,-3.34911,-5.58291
952.60206,-5.72831,-29.35778
953.68206,-15.11341,-175.67189
954.44400,-21.59071,-328.51849
955.04600,-25.76019,-451.05655
955.43400,-21.72308,-295.55755
956.13806,-14.86092,-142.70325
957.31206,-4.87936,-17.04372
958.39006,-3.36202,-6.35167
959.52406,-13.87260,-150.34914
960.31400,-20.58714,-303.25934
960.88406,-25.43230,-436.27691
961.35006,-22.59493,-321.77575
961.96406,-16.24678,-168.10691
963.10006,-6.57983,-32.69542
964.17806,-1.01445,0.15760
965.35406,-12.52955,-125.25003
966.17806,-19.53269,-277.63030
966.85006,-25.24546,-430.35831
967.27000,-23.37632,-347.69639
967.80206,-17.55193,-193.97693
968.88606,-8.29669,-50.60206
969.96606,0.46397,0.11977
971.16406,-11.01508,-99.94261
972.04006,-18.46246,-251.96241
972.73600,-24.37851,-404.57625
973.19806,-24.05427,-372.48693
973.66206,-18.72661,-219.01138
974.67600,-9.97905,-70.32912
975.85206,0.01698,0.20456
976.95406,-9.32716,-74.72427
977.90206,-17.39145,-226.52933
978.61806,-23.47742,-378.97497
979.12806,-24.67949,-398.45765
979.54806,-19.78213,-244.19367
980.46406,-11.67952,-92.69250
981.66406,-1.47949,0.15108
982.74206,-7.59691,-51.61085
983.76200,-16.30322,-201.47083
984.50006,-22.57628,-354.24758
985.06006,-25.23517,-424.93083
985.45200,-20.78935,-269.76723
986.25606,-13.34597,-117.37110
987.45200,-3.17961,-4.55237
988.53000,-5.72455,-29.18867
989.61006,-15.11335,-175.49029
990.37006,-21.57355,-327.87234
990.97406,-25.76025,-450.84894
991.36206,-21.72505,-295.46281
992.06400,-14.87778,-142.90461
993.23806,-4.89634,-17.12464
994.31806,-3.36155,-6.28255
995.45406,-13.88964,-150.53952
996.24400,-20.60436,-303.37347
996.81206,-25.43230,-436.05976
997.27806,-22.57969,-321.21573
997.89200,-16.24582,-168.01149
999.02406,-6.61379,-32.91917
1000.10600,-1.01230,0.17364
1001.28000,-12.51239,-124.80119
1002.10406,-19.51595,-276.96116
1002.78000,-25.26250,-430.74522
1003.20006,-23.35013,-346.70219
1003.73206,-17.53225,-193.44393
1004.81606,-8.27953,-50.34369
1005.89406,0.46415,0.09025
1007.09000,-10.99816,-99.62001
1007.97006,-18.47962,-252.20487
1008.66606,-24.39561,-404.80755
1009.12606,-24.05643,-372.48429
1009.59000,-18.72685,-218.90488
1010.60406,-9.97905,-70.35768
1011.78000,0.01692,0.12405
1012.88200,-9.32674,-74.60732
1013.83006,-17.39145,-226.34311
1014.54600,-23.47748,-378.73372
1015.05600,-24.68051,-398.37960
1015.47406,-19.79881,-244.50403
1016.39200,-11.67952,-92.64031
1017.59206,-1.47949,0.13729
1018.67006,-7.59614,-51.55210
1019.68806,-16.28636,-200.94553
1020.42600,-22.55918,-353.56823
1020.98806,-25.23434,-424.78077
1021.38006,-20.78086,-269.45652
1022.18806,-13.31195,-116.71230
1023.38606,-3.12843,-4.22281
1024.45800,-5.72305,-29.12178
1025.53806,-15.11347,-175.32080
1026.30006,-21.59071,-328.07842
1026.90212,-25.76096,-450.75994
1027.28806,-21.74933,-296.05391
1027.99206,-14.87778,-142.82648
1029.16600,-4.89640,-17.15009
1030.24613,-3.36119,-6.26131
1031.38206,-13.88964,-150.38542
1032.17006,-20.58720,-302.82147
1032.74000,-25.43236,-435.86485
1033.20606,-22.58124,-321.15456
1033.82413,-16.21204,-167.31156
1034.96206,-6.52812,-32.09259
1036.03406,-1.01062,0.14391
1037.21006,-12.52961,-124.94721
1038.03406,-19.53281,-277.18913
1038.70800,-25.26196,-430.50103
1039.12612,-23.35432,-346.76008
1039.66212,-17.51378,-193.02551
1040.74613,-8.26213,-50.07956
1041.82200,0.46427,0.08144
1043.01806,-10.99816,-99.48944
1043.89806,-18.47956,-252.04245
1044.59606,-24.41259,-405.17572
1045.05406,-24.05959,-372.47740
1045.52000,-18.70730,-218.46386
1046.53406,-9.96219,-70.04868
1047.70800,0.01692,0.09189
1048.81000,-9.32692,-74.58192
1049.75800,-17.39151,-226.22354
1050.47200,-23.46050,-378.10229
1050.98400,-24.68045,-398.33181
1051.40400,-19.77574,-243.88820
1052.32200,-11.66248,-92.31788
1053.52212,-1.46251,0.10914
1054.59800,-7.59602,-51.50471
1055.62000,-16.32026,-201.52617
1056.35612,-22.57622,-353.86987
1056.91600,-25.23535,-424.69367
1057.30600,-20.80806,-270.14991
1058.10612,-13.39685,-118.02217
1059.30413,-3.21351,-4.65100
1060.38612,-5.72317,-29.12710
1061.46800,-15.13051,-175.53434
1062.23012,-21.60769,-328.35074
1062.83012,-25.76096,-450.60929
1063.21612,-21.74556,-295.86487
1063.91812,-14.89470,-143.14793
1065.09200,-4.91356,-17.26763
1066.17412,-3.36304,-6.28945
1067.30812,-13.87272,-149.92457
1068.09612,-20.57028,-302.24834
1068.66812,-25.43236,-435.67810
1069.13400,-22.58381,-321.16633
1069.74800,-16.24648,-167.83379
1070.88400,-6.57995,-32.48223
1071.96200,-1.01008,0.09190
1073.13612,-12.51245,-124.52919
1073.96012,-19.51583,-276.63214
1074.63400,-25.24546,-429.84333
1075.05600,-23.35426,-346.60809
1075.58800,-17.53339,-193.29306
1076.66812,-8.31355,-50.64272
1077.75000,0.46474,0.03408
1078.94800,-11.01526,-99.63320
1079.82600,-18.47962,-251.84177
1080.52212,-24.39549,-404.50290
1080.98200,-24.05499,-372.26625
1081.44600,-18.72045,-218.63956
1082.46412,-9.94515,-69.73939
1083.63612,0.01686,0.12841
1084.73800,-9.32728,-74.41131
1085.68813,-17.40825,-226.38470
1086.40212,-23.47748,-378.37129
1086.91212,-24.68152,-398.17281
1087.33012,-19.79750,-244.23711
1088.24613,-11.69674,-92.70352
1089.44600,-1.49677,0.14887
1090.52600,-7.59542,-51.35009
1091.54600,-16.30328,-200.99364
1092.28212,-22.55924,-353.24313
1092.84400,-25.23918,-424.76296
1093.23613,-20.78427,-269.40899
1094.03812,-13.36289,-117.42879
1095.23613,-3.17961,-4.46264
1096.31413,-5.72233,-29.04231
1097.39812,-15.14761,-175.64300
1098.15812,-21.60757,-328.20709
1098.75800,-25.76276,-450.58165
1099.14600,-21.72475,-295.22516
1099.84800,-14.87790,-142.67368
1101.02212,-4.89640,-17.06772
1102.10200,-3.36406,-6.21392
1103.23800,-13.88964,-150.08983
1104.02600,-20.58720,-302.46919
1104.59612,-25.43242,-435.60352
1105.06200,-22.58770,-321.18347
1105.67600,-16.24690,-167.76269
1106.81600,-6.54534,-32.14631
1107.89000,-1.00913,0.08709
1109.06413,-12.51245,-124.48212
1109.89000,-19.53275,-276.83446
1110.56413,-25.26238,-430.21314
1110.98400,-23.35533,-346.54163
1111.51613,-17.53285,-193.22962
1112.60012,-8.27953,-50.23041
1113.67813,0.46498,0.08093
1114.87400,-10.99804,-99.24064
1115.75212,-18.46252,-251.21156
1116.44800,-24.37851,-403.83171
1116.91000,-24.05523,-372.19409
1117.37400,-18.72087,-218.57481
1118.38800,-9.97911,-70.07733
1119.56413,0.01686,0.07382
1120.66600,-9.32692,-74.35747
1121.61612,-17.40843,-226.20544
1122.33200,-23.49434,-378.68429
1122.84012,-24.68200,-398.07659
1123.25800,-19.79935,-244.29018
1124.17412,-11.69674,-92.63332
1125.37400,-1.49653,0.14534
1126.45412,-7.59632,-51.25774
1127.47400,-16.30328,-200.76387
1128.21012,-22.55930,-353.03280
1128.77212,-25.24008,-424.60725
1129.16400,-20.79037,-269.43063
1129.97012,-13.32899,-116.76673
1131.16812,-3.14541,-4.28565
1132.24212,-5.72377,-28.96138
1133.32413,-15.13045,-175.13433
1134.08413,-21.59077,-327.58117
1134.68600,-25.76323,-450.41319
1135.07413,-21.72769,-295.20607
1135.77600,-14.87784,-142.54658
1136.95012,-4.89640,-17.00071
1138.03000,-3.35963,-6.16211
1139.16812,-13.90644,-150.20958
1139.95600,-20.60430,-302.69073
1140.52400,-25.43236,-435.38596
1140.99012,-22.58542,-321.01061
1141.60400,-16.24636,-167.70884
1142.73800,-6.59687,-32.59332
1143.81812,-1.00853,0.13995
1144.99400,-12.52961,-124.58449
1145.81812,-19.53281,-276.66783
1146.49012,-25.24552,-429.48876
1146.91212,-23.35617,-346.51186
1147.44412,-17.53339,-193.13943
1148.52812,-8.27953,-50.11112
1149.60612,0.46588,0.05802
1150.80200,-10.99822,-99.12973
1151.68000,-18.46246,-251.04064
1152.37612,-24.37863,-403.66992
1152.83800,-24.05768,-372.13910
1153.30000,-18.74335,-218.97625
1154.31600,-9.97911,-69.99751
1155.49212,0.01686,0.11613
1156.59400,-9.32674,-74.22269
1157.54600,-17.42541,-226.44496
1158.26000,-23.49440,-378.54705
1158.76812,-24.68344,-398.03512
1159.18813,-19.77526,-243.55190
1160.10800,-11.64586,-91.85680
1161.30812,-1.44559,0.15503
1162.38213,-7.59614,-51.20581
1163.40000,-16.28648,-200.23515
1164.13800,-22.55924,-352.86263
1164.70012,-25.24002,-424.51855
1165.09200,-20.78116,-269.15034
1165.89400,-13.36295,-117.24732
1167.09200,-3.17961,-4.40501
1168.17000,-5.72335,-28.90243
1169.25212,-15.13051,-174.96569
1170.01212,-21.59077,-327.36156
1170.61400,-25.76383,-450.32419
1171.00212,-21.72470,-295.07808
1171.70412,-14.87802,-142.50064
1172.88000,-4.87936,-16.80418
1173.95800,-3.36543,-6.14629
1175.09413,-13.88970,-149.75636
1175.88213,-20.58726,-302.12164
1176.45200,-25.43230,-435.25144
1176.91812,-22.58495,-320.95823
1177.53400,-16.22854,-167.23575
1178.67412,-6.52818,-31.84277
1179.74613,-1.00691,0.13065
1180.92200,-12.52961,-124.44486
1181.74613,-19.53269,-276.47862
1182.42000,-25.26262,-429.91180
1182.84012,-23.35593,-346.38755
1183.37213,-17.53345,-193.05930
1184.45600,-8.27947,-50.05761
1185.53400,0.46534,0.11462
1186.73200,-11.01532,-99.29036
1187.60800,-18.46258,-250.84227
1188.30413,-24.37857,-403.46909
1188.76613,-24.05738,-372.01986
1189.23012,-18.72553,-218.49487
1190.24212,-9.99609,-70.12784
1191.42000,0.01686,0.12584
1192.52212,-9.32704,-74.15776
1193.47400,-17.42541,-226.27991
1194.19013,-23.51156,-378.85007
1194.69600,-24.68356,-397.97362
1195.11400,-19.79786,-244.06668
1196.03212,-11.67982,-92.28757
1197.23200,-1.47955,0.16675
1198.21200,0.01877,0.11858
1199.41212,0.01650,0.13401
1200.61200,0.01650,0.17021
1201.81200,0.01650,0.12605
1203.01212,0.01650,0.12916
1204.21200,0.01650,0.16194
1205.41212,0.01650,0.16408
1206.61200,0.01650,0.17718
1207.81200,0.01650,0.13782
1209.01212,0.01650,0.14923
1210.21200,0.01650,0.16214
1211.41212,0.01650,0.14020
1212.61200,0.01650,0.15003
1213.81200,0.01650,0.15004
1215.01212,0.01650,0.12173
1216.21200,0.01650,0.13501
1217.41212,0.01650,0.12811
1218.61200,0.01650,0.11865
1219.81200,0.01650,0.14760
1221.01212,0.01650,0.11519
1222.21200,0.01650,0.13106
1223.41212,0.01650,0.10460
1224.61200,0.01650,0.07823
1225.81200,0.01650,0.15444
1227.01212,0.01650,0.09530
1228.21200,0.01650,0.15536
1229.41212,0.01650,0.12207
1230.61200,0.01650,0.08805
1231.81200,0.01650,0.13133
1233.01212,0.01650,0.11528
1234.21200,0.01650,0.10563
1235.41212,0.01650,0.12227
1236.61200,0.01650,0.09047
1237.81200,0.01650,0.11141
1239.01212,0.01650,0.13078
1240.21200,0.01650,0.13138
1241.41212,0.01650,-10.94986
1242.61200,0.01650,-25.65986
1243.81200,0.01650,-29.67708
1245.01212,0.01644,-66.82920
1245.85200,0.01644,-31.72172