File: ball-data/compression/Penn Extra Duty.is_comp_RawData/Specimen_RawData_1.csv
Time,Extension,Load
(sec),(mm),(N)
0.00000,0.00000,-0.08446
1.19000,-10.11519,-114.93465
2.06800,-17.57775,-266.13858
2.83400,-24.08889,-418.72341
3.35000,-23.77045,-369.14714
3.85200,-18.18354,-215.75749
4.90200,-9.18008,-69.82175
5.98400,0.01728,0.77141
7.17800,-10.14652,-102.70855
8.08400,-17.85022,-254.20314
8.81400,-24.05505,-406.44452
9.34000,-23.70444,-363.53752
9.85200,-18.04202,-209.75038
10.91600,-8.92466,-65.00634
11.96800,0.01740,0.79056
13.16400,-10.16368,-100.28642
14.08000,-17.95180,-252.12046
14.81000,-24.15693,-405.13359
15.31800,-23.77009,-364.12764
15.82000,-18.18599,-211.20856
16.88200,-9.07820,-65.82705
17.95200,0.01740,0.74279
19.15000,-10.18066,-98.98161
20.07400,-18.03664,-251.36031
20.80400,-24.24165,-404.77358
21.30200,-23.76854,-362.71852
21.81200,-18.11359,-208.65699
22.88000,-8.95910,-63.77876
23.93600,0.01740,0.79919
25.13600,-10.19782,-98.19732
26.06200,-18.07096,-250.30198
26.78800,-24.24171,-402.94979
27.28400,-23.79257,-362.54544
27.79000,-18.16770,-209.03500
28.85400,-9.04454,-64.25659
29.92000,0.01740,0.77119
31.12000,-10.19788,-97.36496
32.05000,-18.10498,-249.65985
32.77600,-24.27585,-402.36574
33.26800,-23.79233,-361.70159
33.77000,-18.20381,-209.17550
34.83200,-9.09518,-64.49156
35.90400,0.01740,0.74616
37.10400,-10.19794,-96.63342
38.03400,-18.10498,-248.45289
38.76000,-24.27585,-401.24036
39.25000,-23.81834,-361.90234
39.75400,-18.20632,-208.77844
40.81600,-9.09506,-64.13654
41.88800,0.01746,0.76589
43.08800,-10.19782,-96.12374
44.02000,-18.12202,-247.91036
44.74400,-24.27591,-400.34704
45.23400,-23.81613,-361.27556
45.73600,-18.22270,-208.66513
46.79800,-9.11204,-64.08203
47.87200,0.01734,0.79995
49.07200,-10.19794,-95.63374
50.00800,-18.15622,-247.81805
50.73200,-24.30963,-400.34715
51.21800,-23.81326,-360.64282
51.72600,-18.16531,-207.03573
52.79600,-8.99342,-62.43696
53.85600,0.01734,0.82207
55.05600,-10.19782,-95.18303
55.99400,-18.17308,-247.43073
56.71800,-24.32661,-400.08225
57.20200,-23.81314,-360.22607
57.71200,-18.14611,-206.20916
58.78200,-8.97626,-62.01354
59.84000,0.01734,0.78065
61.04000,-10.19788,-94.76376
61.97800,-18.17308,-246.81650
62.70000,-24.30969,-399.00530
63.18600,-23.81511,-359.86830
63.69600,-18.14827,-206.00991
64.76800,-8.95910,-61.65062
65.82401,0.01740,0.76801
67.02400,-10.19782,-94.44182
67.96401,-18.19006,-246.64085
68.68800,-24.34365,-399.34356
69.17001,-23.81595,-359.50549
69.67800,-18.16740,-206.11770
70.75000,-8.97626,-61.66372
71.80801,0.01734,0.80216
73.00800,-10.19806,-94.12187
73.94801,-18.19000,-246.16003
74.67001,-24.32661,-398.33065
75.15401,-23.81511,-359.15073
75.66400,-18.14552,-205.40513
76.73801,-8.94200,-61.13122
77.79201,0.01734,0.74784
78.99201,-10.19794,-93.88038
79.93401,-18.20704,-246.05189
80.65801,-24.36093,-398.84735
81.13800,-23.81822,-358.95038
81.64600,-18.16782,-205.61583
82.71800,-8.97638,-61.36829
83.77600,0.01734,0.79113
84.97601,-10.19794,-93.58359
85.91801,-18.20710,-245.62445
86.64201,-24.36099,-398.44364
87.12200,-23.81416,-358.58192
87.63200,-18.14773,-204.92038
88.70400,-8.95910,-61.05873
89.76000,0.01734,0.77409
90.96001,-10.19788,-93.36187
91.90201,-18.20704,-245.15707
92.62601,-24.36093,-397.99236
93.10600,-23.81763,-358.38325
93.61800,-18.13093,-204.39561
94.69200,-8.92472,-60.49902
95.74400,0.01734,0.80689
96.94401,-10.19800,-93.06713
97.88600,-18.20704,-244.74319
98.61001,-24.36093,-397.61622
99.09001,-23.81852,-358.19430
99.60001,-18.14785,-204.59553
100.67600,-8.92472,-60.39083
101.72801,0.01734,0.82536
102.92800,-10.19800,-92.81620
103.87000,-18.20704,-244.45217
104.59400,-24.36093,-397.27151
105.07401,-23.81506,-357.81328
105.58401,-18.14611,-204.33776
106.65801,-8.94200,-60.45232
107.71201,0.01734,0.75002
108.91200,-10.19788,-92.66768
109.85800,-18.24082,-244.89824
110.58201,-24.39525,-397.89554
111.05801,-23.81745,-357.67969
111.57001,-18.13039,-203.78383
112.64600,-8.90762,-59.93586
113.69601,0.01734,0.79677
114.89600,-10.19800,-92.44340
115.84200,-18.24082,-244.60824
116.56400,-24.37803,-397.12794
117.04201,-23.81912,-357.48798
117.55200,-18.14815,-204.03441
118.62601,-8.94200,-60.21253
119.68001,0.01722,0.82100
120.88001,-10.19800,-92.33225
121.82601,-18.24082,-244.28235
122.54801,-24.37815,-396.80485
123.02601,-23.81786,-357.22971
123.53801,-18.13027,-203.50214
124.61401,-8.90768,-59.74019
125.66401,0.01728,0.80829
126.86401,-10.19794,-92.10164
127.81001,-18.24082,-244.04762
128.53402,-24.39513,-397.06171
129.01001,-23.81948,-357.16671
129.52200,-18.12973,-203.31025
130.60001,-8.89070,-59.47460
131.64802,0.01734,0.79876
132.84800,-10.19794,-91.98462
133.79600,-18.25774,-244.09613
134.51800,-24.39513,-396.73474
134.99400,-23.81739,-356.93124
135.50602,-18.13075,-203.25119
136.58200,-8.90762,-59.59545
137.63200,0.01728,0.80216
138.83200,-10.19794,-91.78735
139.78202,-18.27472,-244.27833
140.50202,-24.39525,-396.54002
140.97802,-23.82008,-356.79363
141.49000,-18.13260,-203.12777
142.56802,-8.89070,-59.33148
143.61602,0.01734,0.76410
144.81602,-10.19794,-91.65865
145.76600,-18.27472,-244.02082
146.48800,-24.41223,-396.78358
146.96200,-23.81852,-356.61541
147.47402,-18.13015,-202.98572
148.55200,-8.89070,-59.23457
149.60000,0.01734,0.77867
150.80000,-10.19806,-91.53001
151.74800,-18.25774,-243.44629
152.47402,-24.42915,-397.00948
152.94602,-23.81876,-356.50965
153.45800,-18.13033,-202.84222
154.53402,-8.90762,-59.31284
155.58402,0.01734,0.78730
156.78402,-10.19794,-91.41189
157.73202,-18.25774,-243.24007
158.45602,-24.41217,-396.33457
158.93002,-23.82044,-356.38154
159.44200,-18.12961,-202.71542
160.52000,-8.89076,-59.11196
161.56802,0.01728,0.78003
162.76800,-10.19806,-91.26477
163.71800,-18.27472,-243.40672
164.43800,-24.39519,-395.66763
164.91400,-23.81990,-356.27961
165.42802,-18.11544,-202.31221
166.50402,-8.89070,-58.99749
167.55200,0.01734,0.76216
168.75202,-10.19782,-91.15540
169.70002,-18.25768,-242.86101
170.42402,-24.41223,-395.93730
170.90002,-23.79772,-355.39519
171.41200,-18.11496,-202.17858
172.48800,-8.89076,-58.89994
173.53602,0.01734,0.82548
174.73600,-10.19788,-91.02412
175.68800,-18.29170,-243.36765
176.41000,-24.42915,-396.16428
176.88200,-23.82037,-356.02715
177.39402,-18.12961,-202.37818
178.47202,-8.89076,-58.83834
179.52000,0.01734,0.80148
180.72000,-10.19812,-90.91167
181.67202,-18.29170,-243.21236
182.39202,-24.41223,-395.56183
182.86602,-23.82259,-355.95477
183.37800,-18.13356,-202.34548
184.45602,-8.89070,-58.80020
185.50402,0.01722,0.78891
186.70402,-10.19794,-90.73243
187.65600,-18.29176,-242.98653
188.38000,-24.44643,-396.29299
188.85000,-23.82349,-355.86189
189.36202,-18.13290,-202.24888
190.44000,-8.89070,-58.73139
191.48800,0.01734,0.77844
192.68800,-10.19800,-90.71805
193.64402,-18.32572,-243.58952
194.36402,-24.44631,-396.15180
194.83602,-23.79766,-354.90658
195.35000,-18.09679,-201.38288
196.42802,-8.85662,-58.27520
197.47202,0.01728,0.79976
198.67202,-10.19788,-90.59737
199.62402,-18.29176,-242.66750
200.34402,-24.41223,-395.07758
200.81802,-23.82139,-355.60887
201.33002,-18.13302,-202.09342
202.40800,-8.89070,-58.58313
203.45602,0.01728,0.80021
204.65600,-10.19788,-90.46162
205.60802,-18.29176,-242.48781
206.33002,-24.42921,-395.41554
206.80402,-23.80214,-354.83837
207.31602,-18.11317,-201.56840
208.39402,-8.87378,-58.35932
209.44000,0.01728,0.75624
210.64002,-10.19818,-90.39225
211.59402,-18.30868,-242.73524
212.31602,-24.44637,-395.70514
212.78802,-23.79993,-354.67286
213.30000,-18.11467,-201.51718
214.37600,-8.89076,-58.53032
215.42402,0.01734,0.74658
216.62402,-10.19806,-90.26401
217.57800,-18.30874,-242.56488
218.30000,-24.44637,-395.60318
218.77000,-23.82127,-355.32564
219.28202,-18.13314,-201.84696
220.36002,-8.89076,-58.43625
221.40800,0.01734,0.76490
222.60802,-10.19806,-90.21756
223.56202,-18.30874,-242.49824
224.28202,-24.42921,-395.02461
224.75602,-23.80196,-354.55007
225.27000,-18.09565,-200.98237
226.34800,-8.85668,-58.01416
227.39202,0.01728,0.75987
228.59202,-10.19806,-90.12653
229.54800,-18.32572,-242.68406
230.26800,-24.44643,-395.35832
230.73800,-23.82109,-355.10283
231.24602,-18.16686,-202.39048
232.32200,-8.94206,-58.91064
233.37600,0.01728,0.74290
234.57600,-10.19794,-90.01815
235.52802,-18.29170,-241.86557
236.24802,-24.41223,-394.25876
236.72202,-23.82193,-355.03127
237.23402,-18.13027,-201.56231
238.31202,-8.89070,-58.28997
239.36002,0.01728,0.79537
240.56002,-10.19806,-90.00719
241.51600,-18.32566,-242.39708
242.23402,-24.42927,-394.63248
242.70602,-23.82522,-355.04922
243.21802,-18.13140,-201.50980
244.29800,-8.87378,-58.06131
245.34402,0.01728,0.73322
246.54400,-10.19788,-89.90232
247.49802,-18.30874,-241.90603
248.21802,-24.42921,-394.42327
248.69002,-23.82336,-354.92573
249.20402,-18.11520,-201.11153
250.28202,-8.87378,-58.04026
251.32802,0.01734,0.74498
252.52802,-10.19812,-89.77013
253.48402,-18.32572,-242.15160
254.20002,-24.41223,-393.83460
254.67402,-23.82259,-354.81989
255.18600,-18.12889,-201.32147
256.26400,-8.89076,-58.17528
257.31202,0.01728,0.77203
258.51203,-10.19806,-89.71061
259.46802,-18.32572,-242.06920
260.18600,-24.42921,-394.20173
260.66000,-23.80065,-354.00115
261.17402,-18.09721,-200.58429
262.25200,-8.85668,-57.74752
263.29603,0.01728,0.77986
264.49600,-10.19806,-89.64076
265.45203,-18.32578,-241.95665
266.17203,-24.44637,-394.53767
266.64400,-23.80214,-353.95969
267.15803,-18.09601,-200.51261
268.23603,-8.85668,-57.75247
269.28000,0.01734,0.73743
270.48000,-10.19818,-89.57623
271.43803,-18.34276,-242.14622
272.15803,-24.46347,-394.91948
272.62803,-23.80405,-353.88157
273.14200,-18.09924,-200.50056
274.22200,-8.83964,-57.49132
275.26400,0.01728,0.78249
276.46403,-10.19794,-89.53075
277.42203,-18.34270,-242.04677
278.14200,-24.46353,-394.76264
278.61200,-23.80304,-353.74664
279.12803,-18.08005,-200.03403
280.20603,-8.83958,-57.50677
281.24803,0.01728,0.75318
282.44803,-10.19800,-89.46172
283.40403,-18.32572,-241.53050
284.12403,-24.44649,-394.21622
284.59600,-23.80399,-353.74958
285.11003,-18.09840,-200.34740
286.18803,-8.85668,-57.60958
287.23203,0.01728,0.73886
288.43200,-10.19794,-89.34536
289.39000,-18.34288,-241.81304
290.10800,-24.44637,-394.08613
290.57800,-23.82647,-354.41354
291.09403,-18.09440,-200.21474
292.17203,-8.85668,-57.56170
293.21600,0.01728,0.75295
294.41600,-10.19794,-89.29879
295.37600,-18.35998,-242.05992
296.09403,-24.46353,-394.46887
296.56200,-23.82773,-354.41063
297.07400,-18.13433,-200.94542
298.15200,-8.89082,-57.90698
299.20203,0.03420,0.74030
300.40200,-10.18090,-89.00855
301.36003,-18.32578,-241.23969
302.07800,-24.42927,-393.45946
302.55200,-23.80202,-353.51459
303.06600,-18.09266,-200.03468
304.14400,-8.85668,-57.53453
305.19000,0.03420,0.72555
306.39000,-10.18084,-88.91128
307.34803,-18.32572,-241.09690
308.06600,-24.42927,-393.39885
308.54000,-23.80345,-353.46471
309.05800,-18.05930,-199.29450
310.13800,-8.80592,-56.90690
311.17603,0.01728,0.74157
312.37600,-10.19812,-89.09323
313.33603,-18.35998,-241.76812
314.05403,-24.46359,-394.19696
314.52200,-23.82845,-354.22657
315.03403,-18.13445,-200.84742
316.11203,-8.89076,-57.80364
317.16000,0.01722,0.73990
318.36003,-10.19812,-89.00736
319.31600,-18.32578,-240.89435
320.03403,-24.42927,-393.18297
320.51000,-23.78074,-352.54270
321.03200,-18.00405,-198.03395
322.12003,-8.68694,-55.52151
323.14400,0.01728,0.73580
324.34403,-10.19782,-88.94872
325.30403,-18.36004,-241.60212
326.02200,-24.46359,-394.00328
326.49200,-23.80417,-353.28619
327.00600,-18.09541,-199.87170
328.08603,-8.83964,-57.18904
329.13000,0.03420,0.73063
330.33003,-10.18108,-88.64167
331.29000,-18.34276,-241.14253
332.00600,-24.42933,-392.96512
332.48000,-23.80250,-353.18960
332.99403,-18.09733,-199.86920
334.07203,-8.85674,-57.32703
335.11800,0.03420,0.76536
336.31803,-10.18096,-88.64088
337.27800,-18.34282,-241.01833
337.99803,-24.46353,-393.87405
338.46803,-23.80423,-353.22588
338.98400,-18.07873,-199.45363
340.06403,-8.82284,-56.91723
341.10400,0.01722,0.72217
342.30403,-10.19812,-88.79422
343.26203,-18.34282,-240.90882
343.98400,-24.48051,-394.16987
344.45000,-23.82582,-353.82006
344.96200,-18.13392,-200.59073
346.04000,-8.89070,-57.59148
347.08800,0.01722,0.77128
348.28803,-10.19818,-88.76123
349.24803,-18.35986,-241.24756
349.96600,-24.46353,-393.61440
350.43403,-23.82671,-353.83016
350.94600,-18.13356,-200.50634
352.02200,-8.90768,-57.81247
353.07400,0.03420,0.76205
354.27403,-10.18114,-88.44051
355.23203,-18.32578,-240.39071
355.95000,-24.42927,-392.68188
356.42400,-23.80399,-352.98940
356.93600,-18.11502,-200.07463
358.01400,-8.87384,-57.37549
359.06200,0.03420,0.72048
360.26203,-10.18102,-88.36708
361.22003,-18.32584,-240.30916
361.93803,-24.42927,-392.58994
362.41203,-23.80364,-352.94533
362.92400,-18.11138,-199.91536
364.00200,-8.87384,-57.35427
365.04800,0.01722,0.74048
366.24803,-10.19806,-88.61384
367.20800,-18.35998,-240.99994
367.92400,-24.44643,-392.99730
368.39400,-23.82791,-353.69132
368.90403,-18.15012,-200.70141
369.98203,-8.90768,-57.66917
371.03200,0.01722,0.72367
372.23203,-10.19812,-88.52955
373.19203,-18.35998,-240.88670
373.90803,-24.44625,-392.88700
374.37803,-23.82875,-353.66304
374.89000,-18.13159,-200.25859
375.96803,-8.89082,-57.44459
377.01800,0.03414,0.71555
378.21803,-10.18102,-88.26094
379.17800,-18.34282,-240.44449
379.89800,-24.46359,-393.30281
380.36800,-23.80663,-352.85220
380.88203,-18.09457,-199.44102
381.96003,-8.85674,-57.06919
383.00600,0.03420,0.74763
384.20603,-10.18114,-88.23612
385.16203,-18.30886,-239.59218
385.88203,-24.42927,-392.26022
386.35603,-23.81021,-352.92692
386.86800,-18.11305,-199.83087
387.94600,-8.87384,-57.24978
388.99403,0.03420,0.77442
390.19403,-10.18090,-88.17207
391.15200,-18.32590,-239.84244
391.87003,-24.42927,-392.15565
392.34403,-23.81069,-352.92059
392.86003,-18.07777,-198.98616
393.93803,-8.83970,-56.82215
394.98203,0.03420,0.76642
396.18200,-10.18090,-88.08203
397.14400,-18.36004,-240.55788
397.86003,-24.44631,-392.58309
398.33203,-23.80656,-352.74476
398.84403,-18.11335,-199.67331
399.92203,-8.87390,-57.18732
400.97003,0.03414,0.74208
402.17000,-10.18108,-88.05915
403.12803,-18.32596,-239.67333
403.84803,-24.44643,-392.44816
404.31803,-23.82803,-353.37083
404.83003,-18.13248,-200.06653
405.90803,-8.89082,-57.32618
406.95800,0.03420,0.75343
408.15803,-10.18084,-87.97500
409.11603,-18.32578,-239.63844
409.83603,-24.44643,-392.39798
410.30800,-23.80746,-352.65125
410.82400,-18.07610,-198.87257
411.90200,-8.83970,-56.79348
412.94600,0.03420,0.77013
414.14603,-10.18108,-87.93934
415.10603,-18.34288,-239.92300
415.82203,-24.42927,-391.86869
416.29400,-23.82917,-353.33045
416.80603,-18.13146,-199.96999
417.88403,-8.89088,-57.23154
418.93403,0.03414,0.77057
420.13403,-10.18102,-87.88359
421.09403,-18.34288,-239.88143
421.81403,-24.46359,-392.75497
422.28200,-23.83030,-353.28250
422.79400,-18.13146,-199.87917
423.87200,-8.89082,-57.25147
424.92203,0.03420,0.71285
426.12200,-10.18096,-87.85937
427.08203,-18.34288,-239.78654
427.79803,-24.42927,-391.75324
428.27203,-23.80938,-352.57686
428.78403,-18.11616,-199.56488
429.86400,-8.85674,-56.83796
430.91003,0.03420,0.76424
432.11003,-10.18102,-87.82057
433.07000,-18.34282,-239.75220
433.78600,-24.42915,-391.69185
434.25803,-23.82911,-353.16724
434.77003,-18.13266,-199.87773
435.84803,-8.89082,-57.20867
436.89800,0.03414,0.76861
438.09803,-10.18102,-87.76079
439.05800,-18.34288,-239.62669
439.77403,-24.42927,-391.59667
440.24803,-23.80573,-352.35081
440.76400,-18.07514,-198.63611
441.84403,-8.82284,-56.41616
442.88603,0.03414,0.75094
444.08603,-10.18102,-87.71984
445.04603,-18.34288,-239.55766
445.76400,-24.44643,-392.00462
446.23400,-23.82869,-353.07016
446.74603,-18.12997,-199.72323
447.82403,-8.89082,-57.12618
448.87403,0.03414,0.75340
450.07403,-10.18096,-87.67031
451.03403,-18.34288,-239.53311
451.75403,-24.46365,-392.42536
452.22200,-23.83186,-353.15346
452.73400,-18.13260,-199.78862
453.81200,-8.89082,-57.13067
454.86203,0.03414,0.76242
456.06200,-10.18102,-87.64018
457.02203,-18.34294,-239.40943
457.73800,-24.42921,-391.38883
458.21203,-23.80656,-352.26259
458.72403,-18.11162,-199.27584
459.80203,-8.87390,-56.96192
460.85003,0.03408,0.79194
462.05003,-10.18108,-87.58671
463.01203,-18.36004,-239.80068
463.72803,-24.44643,-391.84753
464.20000,-23.80621,-352.23279
464.71603,-18.07592,-198.51189
465.79803,-8.80598,-56.17608
466.83800,0.03414,0.79944
468.03803,-10.18096,-87.55045
468.99803,-18.34288,-239.32723
469.71203,-24.41241,-390.79603
470.18803,-23.80555,-352.16358
470.70400,-18.07664,-198.48110
471.78600,-8.80598,-56.13131
472.82603,0.03420,0.77422
474.02603,-10.18102,-87.50196
474.98603,-18.34288,-239.26824
475.70203,-24.42939,-391.26176
476.17400,-23.82845,-352.85562
476.68603,-18.13248,-199.59958
477.76400,-8.89082,-57.05070
478.81403,0.03414,0.75605
480.01400,-10.18108,-87.48018
480.97403,-18.34300,-239.18105
481.69403,-24.46347,-392.11053
482.16203,-23.83024,-352.89213
482.67603,-18.11377,-199.21260
483.75403,-8.87390,-56.84765
484.80203,0.03414,0.78079
486.00200,-10.18132,-87.40015
486.96003,-18.32590,-238.78023
487.67800,-24.42915,-391.12236
488.15200,-23.80627,-352.04273
488.66803,-18.07407,-198.28714
489.75003,-8.80598,-56.05448
490.79000,0.03408,0.77664
491.99003,-10.18102,-87.37687
492.95203,-18.36010,-239.43044
493.66803,-24.44655,-391.51892
494.14000,-23.80405,-351.95880
494.65603,-18.07156,-198.19064
495.73803,-8.80592,-56.02138
496.77800,0.03414,0.77222
497.97803,-10.18102,-87.38634
498.94003,-18.36004,-239.39772
499.65603,-24.44643,-391.47899
500.12603,-23.82875,-352.76029
500.63603,-18.14773,-199.74241
501.71403,-8.90774,-57.08778
502.76603,0.03414,0.80190
503.96603,-10.18102,-87.35473
504.92800,-18.36010,-239.34385
505.64800,-24.48051,-392.31811
506.11400,-23.82833,-352.72725
506.62603,-18.12949,-199.38352
507.70400,-8.89100,-56.95185
508.75403,0.03414,0.75675
509.95400,-10.18090,-87.26207
510.91600,-18.36016,-239.32984
511.63403,-24.46365,-391.83907
512.10206,-23.82940,-352.68471
512.61803,-18.09613,-198.62482
513.69800,-8.83970,-56.36807
514.74200,0.03414,0.76619
515.94203,-10.18108,-87.20925
516.90406,-18.36004,-239.20363
517.62000,-24.44637,-391.27551
518.09203,-23.80914,-351.94967
518.61003,-18.05900,-197.86848
519.69403,-8.77202,-55.61071
520.73003,0.03420,0.76250
521.93006,-10.18108,-87.17442
522.89203,-18.36016,-239.15175
523.61003,-24.46353,-391.69997
524.07800,-23.82952,-352.58118
524.59000,-18.12931,-199.30921
525.66800,-8.89094,-56.87042
526.71800,0.03414,0.78086
527.91800,-10.18102,-87.12564
528.88000,-18.36010,-239.05620
529.59600,-24.44643,-391.11998
530.06606,-23.83096,-352.57544
530.58000,-18.11084,-198.84812
531.65800,-8.87396,-56.63241
532.70606,0.03414,0.81450
533.90600,-10.18102,-87.10746
534.86806,-18.36010,-239.03236
535.58406,-24.44655,-391.14110
536.05400,-23.83359,-352.61970
536.56806,-18.11221,-198.83914
537.64800,-8.85680,-56.44185
538.69400,0.03414,0.78234
539.89406,-10.18102,-87.06008
540.85400,-18.34288,-238.53790
541.57406,-24.46347,-391.50354
542.04206,-23.83162,-352.51044
542.55806,-18.09565,-198.49937
543.63606,-8.85680,-56.46984
544.68200,0.03414,0.75274
545.88200,-10.18108,-87.03071
546.84406,-18.36010,-238.88221
547.56000,-24.44649,-391.05009
548.03000,-23.82857,-352.41380
548.53800,-18.16704,-199.93162
549.61600,-8.92484,-57.18093
550.67006,0.03414,0.80616
551.87006,-10.18108,-87.04338
552.83000,-18.34300,-238.51560
553.54806,-24.44649,-390.95651
554.01800,-23.82940,-352.41786
554.53400,-18.09386,-198.30437
555.61806,-8.80598,-55.85134
556.65800,0.03414,0.76882
557.85806,-10.18102,-87.01399
558.81806,-18.34300,-238.46108
559.53600,-24.44655,-390.90369
560.00606,-23.83000,-352.40859
560.52206,-18.09368,-198.31490
561.60806,-8.78900,-55.58828
562.64606,0.03420,0.72820
563.84600,-10.18120,-86.90830
564.80806,-18.36010,-238.74559
565.52600,-24.46359,-391.29626
565.99400,-23.83251,-352.43362
566.51000,-18.09350,-198.27358
567.59406,-8.80604,-55.80818
568.63406,0.03414,0.76895
569.83406,-10.18120,-86.91789
570.79600,-18.36010,-238.74279
571.51200,-24.44649,-390.75535
571.98206,-23.82654,-352.20474
572.49400,-18.12758,-198.98985
573.57200,-8.89094,-56.69764
574.62200,0.03414,0.77567
575.82200,-10.18102,-86.88435
576.78406,-18.36004,-238.67270
577.50000,-24.44643,-390.79212
577.97006,-23.83096,-352.41056
578.48600,-18.09398,-198.21862
579.57200,-8.78906,-55.64095
580.61006,0.03408,0.80511
581.81000,-10.18108,-86.85543
582.77206,-18.36016,-238.64239
583.48806,-24.44655,-390.71765
583.95800,-23.83072,-352.34362
584.46800,-18.14468,-199.28753
585.54600,-8.90780,-56.88026
586.59800,0.03408,0.77814
587.79806,-10.18126,-86.80662
588.76200,-18.37732,-238.96394
589.47800,-24.46353,-391.11100
589.94606,-23.83024,-352.27280
590.45406,-18.16393,-199.67671
591.53206,-8.92490,-57.08699
592.58600,0.03408,0.76974
593.78600,-10.18120,-86.75907
594.75000,-18.37726,-238.90637
595.46406,-24.44637,-390.58961
595.93606,-23.81177,-351.61115
596.45406,-18.05780,-197.42267
597.54400,-8.72090,-54.81388
598.57406,0.03414,0.76401
599.77406,-10.18108,-86.75479
600.73400,-18.34294,-238.09101
601.45000,-24.42933,-390.14228
601.92206,-23.83090,-352.23436
602.43806,-18.09069,-198.09177
603.52206,-8.80604,-55.72930
604.56200,0.03414,0.75524
605.76200,-10.18102,-86.69168
606.72600,-18.37726,-238.82706
607.44200,-24.46365,-391.01113
607.91006,-23.83317,-352.22083
608.42600,-18.09404,-198.13402
609.50606,-8.83982,-56.02502
610.55006,0.03408,0.77594
611.75000,-10.18120,-86.71447
612.71206,-18.36016,-238.39764
613.42806,-24.44649,-390.45013
613.89800,-23.83449,-352.23007
614.41006,-18.12872,-198.87529
615.48806,-8.89088,-56.56719
616.53800,0.03408,0.73468
617.73806,-10.18114,-86.66634
618.70200,-18.37738,-238.67572
619.42006,-24.48069,-391.39155
619.88606,-23.83210,-352.14886
620.40206,-18.09003,-197.96936
621.49006,-8.77202,-55.25225
622.52600,0.03414,0.75784
623.72600,-10.18108,-86.66266
624.69000,-18.37726,-238.67328
625.40600,-24.46365,-390.89266
625.87400,-23.83712,-352.29929
626.38406,-18.14928,-199.24043
627.46406,-8.89088,-56.51460
628.51406,0.03408,0.74052
629.71406,-10.18102,-86.58340
630.67806,-18.37732,-238.65156
631.39406,-24.46365,-390.90648
631.86400,-23.81464,-351.57740
632.38200,-18.05655,-197.30827
633.47006,-8.73782,-54.95294
634.50200,0.03408,0.70867
635.70200,-10.18120,-86.59706
636.66400,-18.36016,-238.26798
637.38000,-24.44655,-390.34821
637.85006,-23.83251,-352.15426
638.36806,-18.07192,-197.61695
639.45200,-8.78912,-55.46113
640.49006,0.03414,0.72769
641.69000,-10.18108,-86.60273
642.65206,-18.36016,-238.15505
643.36600,-24.42939,-389.83651
643.83800,-23.83269,-352.10919
644.34800,-18.14504,-199.10375
645.42600,-8.90774,-56.70553
646.47800,0.03408,0.75718
647.67806,-10.18102,-86.54182
648.64200,-18.37726,-238.47679
649.36006,-24.48069,-391.26713
649.82606,-23.83317,-352.09458
650.34406,-18.07293,-197.60108
651.43400,-8.73782,-54.83275
652.46600,0.03414,0.74248
653.66600,-10.18120,-86.47312
654.62806,-18.36010,-238.06937
655.34600,-24.46353,-390.69794
655.81606,-23.81219,-351.38562
656.33200,-18.07622,-197.57448
657.41800,-8.77208,-55.18274
658.45200,0.01722,0.76625
659.65206,-10.19812,-86.69882
660.61600,-18.39442,-238.79284
661.33000,-24.46353,-390.60265
661.79806,-23.83443,-352.04090
662.31400,-18.09451,-197.95913
663.39606,-8.82296,-55.73296
664.43806,0.03408,0.77013
665.63806,-10.18114,-86.43962
666.60206,-18.37732,-238.35046
667.31606,-24.44655,-390.06494
667.78600,-23.83718,-352.10319
668.30200,-18.09284,-197.87837
669.38406,-8.82290,-55.71678
670.42600,0.03414,0.77243
671.62606,-10.18120,-86.40610
672.58800,-18.36010,-237.94940
673.30806,-24.48057,-391.00684
673.77406,-23.83634,-352.08784
674.28600,-18.12662,-198.57841
675.36600,-8.87396,-56.22909
676.41406,0.03408,0.74599
677.61400,-10.18114,-86.35307
678.57800,-18.37732,-238.33059
679.29600,-24.48069,-390.99377
679.76200,-23.83550,-352.01248
680.27406,-18.13021,-198.66223
681.35400,-8.87396,-56.21151
682.40206,0.03408,0.76928
683.60206,-10.18120,-86.39757
684.56606,-18.37732,-238.25878
685.28206,-24.46371,-390.47483
685.75006,-23.83610,-351.98878
686.26606,-18.09075,-197.72997
687.35400,-8.77208,-55.12272
688.39000,0.03402,0.81039
689.59000,-10.18120,-86.37006
690.55400,-18.37732,-238.20996
691.27206,-24.48069,-390.89926
691.73806,-23.83497,-351.95559
692.25400,-18.09105,-197.76419
693.34000,-8.78906,-55.27839
694.37806,0.03408,0.75208
695.57800,-10.18126,-86.30116
696.54006,-18.36016,-237.77513
697.25606,-24.44661,-389.90360
697.72600,-23.83777,-351.98256
698.24200,-18.09601,-197.89513
699.32000,-8.85686,-56.01971
700.36600,0.03408,0.71575
701.56606,-10.18120,-86.29997
702.53000,-18.37732,-238.08520
703.24606,-24.46377,-390.32321
703.71406,-23.83759,-351.93700
704.23006,-18.09601,-197.81122
705.31200,-8.82296,-55.64054
706.35400,0.03408,0.74641
707.55400,-10.18120,-86.25926
708.51800,-18.37732,-238.09323
709.23400,-24.46371,-390.26473
709.70406,-23.81452,-351.17906
710.22006,-18.07472,-197.36368
711.30806,-8.75504,-54.90713
712.34206,0.03408,0.74694
713.54206,-10.18114,-86.23066
714.50606,-18.37738,-238.02456
715.22206,-24.46371,-390.27676
715.69006,-23.83885,-351.94751
716.20606,-18.09529,-197.72854
717.29006,-8.80610,-55.42728
718.33000,0.03408,0.73768
719.53000,-10.18120,-86.19763
720.49606,-18.39436,-238.39964
721.21206,-24.48069,-390.72338
721.67806,-23.83796,-351.87628
722.19400,-18.09248,-197.69771
723.28000,-8.78912,-55.19847
724.31806,0.03408,0.78461
725.51800,-10.18114,-86.14507
726.48400,-18.39442,-238.32338
727.19806,-24.46371,-390.18866
727.66600,-23.83724,-351.86626
728.17600,-18.14862,-198.87287
729.25400,-8.90792,-56.48582
730.30600,0.03408,0.79430
731.50606,-10.18132,-86.16047
732.47006,-18.37732,-237.93591
733.18606,-24.46371,-390.14429
733.65406,-23.83766,-351.80815
734.16600,-18.12955,-198.41485
735.24606,-8.87396,-56.08555
736.29400,0.03414,0.77356
737.49400,-10.18114,-86.13313
738.45800,-18.37732,-237.87959
739.17206,-24.44655,-389.63296
739.64200,-23.83909,-351.84059
740.15000,-18.16608,-199.16672
741.22800,-8.92502,-56.67075
742.28206,0.03408,0.78435
743.48206,-10.18108,-86.06018
744.44606,-18.37738,-237.82307
745.16206,-24.46371,-390.07992
745.63200,-23.81523,-351.04740
746.14800,-18.07574,-197.22903
747.23206,-8.78912,-55.19399
748.27000,0.03408,0.74397
749.47006,-10.18114,-86.08813
750.43400,-18.37732,-237.87230
751.15000,-24.46371,-390.11549
751.61806,-23.83801,-351.74709
752.13200,-18.11185,-198.00026
753.21000,-8.87396,-56.08920
754.25806,0.03414,0.77423
755.45800,-10.18132,-86.04078
756.42206,-18.37732,-237.79027
757.13806,-24.46341,-390.02247
757.60600,-23.83855,-351.77518
758.12400,-18.07604,-197.23253
759.20406,-8.82296,-55.52590
760.24606,0.03414,0.76533
761.44606,-10.18108,-86.04046
762.41006,-18.37732,-237.71495
763.12806,-24.48057,-390.43233
763.59406,-23.83879,-351.75212
764.10806,-18.11168,-197.94665
765.18606,-8.87402,-56.06899
766.23400,0.03414,0.76259
767.43400,-10.18126,-86.00418
768.39800,-18.37744,-237.68354
769.11400,-24.46365,-389.91615
769.58406,-23.81577,-350.92771
770.10006,-18.07233,-197.11545
771.19006,-8.73788,-54.51764
772.22206,0.03408,0.79778
773.42206,-10.18114,-85.94695
774.38606,-18.37738,-237.64785
775.10206,-24.46377,-389.91999
775.57000,-23.83861,-351.70726
776.08200,-18.12692,-198.21484
777.16006,-8.89100,-56.22394
778.21000,0.03408,0.79786
779.41006,-10.18108,-85.92349
780.37606,-18.39442,-237.96117
781.09206,-24.48075,-390.35402
781.56006,-23.81763,-350.96053
782.07406,-18.09637,-197.59569
783.15206,-8.85686,-55.83706
784.19806,0.03402,0.78374
785.39800,-10.18114,-85.93250
786.36206,-18.37738,-237.53390
787.07806,-24.46377,-389.81967
787.54806,-23.81715,-350.94623
788.06606,-18.05649,-196.71755
789.15206,-8.75504,-54.68044
790.18606,0.03402,0.75263
791.38606,-10.18120,-85.90056
792.34800,-18.36016,-237.12303
793.06400,-24.44643,-389.32662
793.53406,-23.83861,-351.57263
794.05006,-18.09087,-197.40205
795.13606,-8.78912,-55.04013
796.17400,0.03408,0.79455
797.37400,-10.18114,-85.86293
798.33800,-18.37744,-237.48364
799.05400,-24.46377,-389.74326
799.52206,-23.83945,-351.63239
800.04006,-18.07586,-197.11941
801.12006,-8.82296,-55.42739
802.16206,0.03408,0.75995
803.36206,-10.18102,-85.86812
804.32606,-18.37738,-237.45162
805.04206,-24.46371,-389.74106
805.51200,-23.82420,-351.08402
806.02800,-18.07532,-197.03999
807.11806,-8.73788,-54.49626
808.15000,0.03402,0.77530
809.35006,-10.18126,-85.78706
810.31400,-18.37738,-237.40754
811.03206,-24.48075,-390.15997
811.49806,-23.84118,-351.62747
812.00806,-18.15048,-198.66891
813.08606,-8.90786,-56.29812
814.13806,0.03402,0.77062
815.33800,-10.18120,-85.85177
816.30206,-18.37738,-237.36492
817.02000,-24.48069,-390.12000
817.48806,-23.82660,-351.05981
818.00006,-18.11879,-197.94479
819.08000,-8.85692,-55.74794
820.12606,0.03408,0.81110
821.32606,-10.18114,-85.75357
822.29006,-18.37738,-237.35007
823.00606,-24.46371,-389.57786
823.47406,-23.84453,-351.65325
823.98600,-18.12991,-198.14361
825.06606,-8.87402,-55.89884
826.11400,0.03402,0.77927
827.31400,-10.18114,-85.75521
828.27800,-18.37732,-237.30639
828.99400,-24.46377,-389.55700
829.46206,-23.84250,-351.58779
829.97206,-18.15036,-198.60955
831.05206,-8.89100,-56.10161
832.10206,0.03402,0.75393
833.30206,-10.18114,-85.73029
834.26606,-18.37738,-237.30038
834.98206,-24.46377,-389.57935
835.45000,-23.84190,-351.56287
835.96800,-18.07431,-196.96994
837.05400,-8.77214,-54.85093
838.09000,0.03408,0.74321
839.29006,-10.18132,-85.71896
840.25400,-18.37738,-237.22535
840.97006,-24.46377,-389.53822
841.43806,-23.84346,-351.53903
841.94806,-18.14952,-198.50256
843.02800,-8.89106,-56.00938
844.07806,0.03408,0.80862
845.27800,-10.18108,-85.66084
846.24206,-18.37738,-237.19925
846.96000,-24.48075,-389.99502
847.42600,-23.84674,-351.72641
847.93606,-18.14821,-198.50221
849.01406,-8.90792,-56.24794
850.06606,0.03408,0.76367
851.26606,-10.18114,-85.67531
852.23006,-18.37738,-237.17700
852.94400,-24.44667,-389.01236
853.41406,-23.84298,-351.53557
853.92806,-18.11448,-197.72243
855.01006,-8.83982,-55.50908
856.05400,0.03396,0.78721
857.25400,-10.18114,-85.65275
858.21800,-18.37738,-237.17180
858.93606,-24.48081,-389.91705
859.40206,-23.84238,-351.49451
859.91406,-18.12925,-197.99314
861.00006,-8.82302,-55.30126
862.04206,0.03402,0.76504
863.24206,-10.18108,-85.62505
864.20606,-18.37738,-237.09849
864.92206,-24.46377,-389.37204
865.39000,-23.84190,-351.45640
865.90406,-18.11108,-197.64405
866.98406,-8.85692,-55.68991
868.03000,0.03402,0.77288
869.23006,-10.18108,-85.61184
870.19400,-18.37732,-237.04603
870.91206,-24.48075,-389.79709
871.37806,-23.83891,-351.34342
871.89000,-18.12919,-198.03407
872.96800,-8.89100,-55.95493
874.01806,0.03402,0.78076
875.21800,-10.18114,-85.57520
876.18206,-18.37732,-237.06680
876.89806,-24.46377,-389.29231
877.36600,-23.84250,-351.42228
877.87400,-18.16453,-198.74068
878.95200,-8.92502,-56.37879
880.00606,0.03396,0.79123
881.20606,-10.18120,-85.53810
882.17006,-18.37738,-237.01318
882.88606,-24.46377,-389.29041
883.35406,-23.84369,-351.47838
883.87006,-18.09308,-197.21471
884.95806,-8.77214,-54.68627
885.99400,0.03402,0.76927
887.19400,-10.18126,-85.51612
888.16006,-18.39448,-237.35845
888.87606,-24.48075,-389.70072
889.34206,-23.84357,-351.41174
889.85406,-18.12860,-197.96148
890.93606,-8.85692,-55.60517
891.98206,0.03402,0.75824
893.18206,-10.18126,-85.51160
894.14806,-18.39448,-237.32267
894.86400,-24.48081,-389.68634
895.33000,-23.84531,-351.46758
895.84206,-18.12883,-197.95878
896.92206,-8.87408,-55.73960
897.97006,0.03402,0.75314
899.17006,-10.18132,-85.48367
900.13406,-18.37738,-236.91935
900.85006,-24.46383,-389.19356
901.31806,-23.84423,-351.44202
901.83000,-18.12961,-197.90886
902.91006,-8.87408,-55.79768
903.95806,0.03396,0.77135
905.15800,-10.18120,-85.51881
906.12206,-18.37744,-236.91414
906.84000,-24.48051,-389.65907
907.30600,-23.84597,-351.45622
907.82406,-18.07443,-196.77574
908.91006,-8.77220,-54.68764
909.94606,0.03402,0.73323
911.14606,-10.18120,-85.45450
912.11206,-18.39448,-237.29507
912.82806,-24.48081,-389.67945
913.29406,-23.84465,-351.41319
913.80206,-18.16800,-198.72453
914.88006,-8.92502,-56.35010
915.93400,0.03402,0.76401
917.13406,-10.18126,-85.47843
918.09800,-18.37738,-236.85221
918.81606,-24.48069,-389.64041
919.28206,-23.84561,-351.40965
919.79006,-18.16596,-198.71820
920.86806,-8.92508,-56.31362
921.92206,0.03396,0.77972
923.12206,-10.18126,-85.43294
924.08606,-18.37744,-236.83207
924.80400,-24.48081,-389.57071
925.27000,-23.84710,-351.50316
925.77800,-18.16572,-198.67323
926.85806,-8.90792,-56.14666
927.91006,0.03396,0.75137
929.11006,-10.18126,-85.43209
930.07406,-18.37738,-236.76310
930.79006,-24.46377,-389.08157
931.25806,-23.84656,-351.43487
931.76806,-18.14647,-198.24913
932.84606,-8.90798,-56.14025
933.89806,0.03396,0.77640
935.09800,-10.18126,-85.41821
936.06206,-18.37738,-236.78834
936.77800,-24.46383,-389.08266
937.24806,-23.82528,-350.74234
937.76200,-18.09218,-197.06080
938.84606,-8.80616,-54.97383
939.88606,0.03402,0.79092
941.08606,-10.18120,-85.33699
942.05006,-18.37744,-236.75768
942.76606,-24.46371,-389.00752
943.23406,-23.84680,-351.35169
943.74806,-18.11150,-197.47388
944.83000,-8.83988,-55.35909
945.87400,0.03396,0.77150
947.07406,-10.18114,-85.36347
948.04006,-18.39442,-237.08737
948.75606,-24.48081,-389.46133
949.22206,-23.84782,-351.41833
949.73206,-18.15120,-198.28795
950.81206,-8.89106,-55.82451
951.86206,0.03396,0.73488
953.06206,-10.18132,-85.34252
954.02606,-18.37744,-236.66192
954.74400,-24.48075,-389.41290
955.21000,-23.84794,-351.36309
955.72800,-18.07413,-196.68607
956.81400,-8.77220,-54.59145
957.85006,0.03402,0.82030
959.05006,-10.18132,-85.34832
960.01406,-18.37744,-236.61081
960.73006,-24.46377,-388.92787
961.19806,-23.84818,-351.36141
961.71206,-18.11442,-197.50344
962.79206,-8.85698,-55.50606
963.83806,0.03402,0.78928
965.03800,-10.18126,-85.28873
966.00400,-18.39454,-237.00943
966.72006,-24.48081,-389.43306
967.18606,-23.84728,-351.32352
967.69400,-18.16686,-198.56932
968.77406,-8.90798,-56.07473
969.82606,0.03396,0.78417
971.02606,-10.18132,-85.29153
971.99006,-18.37744,-236.59699
972.70606,-24.46383,-388.91237
973.17406,-23.84782,-351.33790
973.68400,-18.14773,-198.14884
974.76406,-8.89106,-55.90682
975.81400,0.03396,0.72509
977.01406,-10.18126,-85.31018
977.98006,-18.39448,-236.91837
978.69806,-24.49773,-389.81058
979.16206,-23.84734,-351.29368
979.67806,-18.09350,-197.00518
980.76406,-8.78912,-54.74550
981.80206,0.03402,0.79555
983.00206,-10.18120,-85.22338
983.96606,-18.37738,-236.51907
984.68206,-24.46383,-388.79439
985.15000,-23.84890,-351.31916
985.65800,-18.16513,-198.50727
986.73600,-8.92508,-56.19519
987.79006,0.03402,0.77050
988.99006,-10.18120,-85.17703
989.95406,-18.37744,-236.45805
990.67206,-24.48081,-389.27842
991.13806,-23.84848,-351.27781
991.65406,-18.09320,-196.93285
992.74006,-8.78918,-54.74492
993.77806,0.03402,0.81432
994.97800,-10.18137,-85.20442
995.94206,-18.37744,-236.47008
996.66006,-24.48093,-389.25577
997.12606,-23.84776,-351.25021
997.63406,-18.16662,-198.51191
998.71206,-8.92508,-56.15369
999.76606,0.03396,0.78004
1000.96606,-10.18126,-85.16909
1001.93006,-18.37744,-236.42676
1002.65000,-24.49779,-389.72300
1003.11406,-23.84997,-351.29104
1003.62606,-18.12824,-197.73072
1004.70806,-8.85698,-55.42660
1005.75400,0.03396,0.75127
1006.95406,-10.18120,-85.19135
1007.92206,-18.41146,-237.18448
1008.64006,-24.51477,-390.17316
1009.13606,-23.46935,-338.40559
1009.67806,-17.55288,-185.85829
1010.78800,-8.07517,-47.15514
1011.84206,0.45506,0.77765
1013.04206,-11.03236,-97.59663
1013.97206,-18.93814,-248.98143
1014.67600,-24.92212,-401.56778
1015.12606,-23.44723,-337.64318
1015.67806,-17.44682,-183.69112
1016.79806,-7.88851,-45.23289
1017.83006,0.45536,0.76993
1019.03000,-11.03224,-97.52093
1019.96206,-18.95519,-249.40649
1020.66606,-24.93916,-402.00509
1021.11206,-23.46822,-338.35597
1021.66606,-17.44747,-183.70844
1022.78606,-7.88857,-45.23906
1023.81806,0.45326,0.79145
1025.01806,-11.03230,-97.52939
1025.94800,-18.93821,-248.97702
1026.65406,-24.93916,-401.95912
1027.10012,-23.46833,-338.31414
1027.64806,-17.50021,-184.72349
1028.76206,-7.99045,-46.26035
1029.80600,0.45404,0.72879
1031.00613,-11.03236,-97.50061
1031.93800,-18.95525,-249.29028
1032.64206,-24.93922,-401.97495
1033.09006,-23.44759,-337.56491
1033.64000,-17.46457,-184.00565
1034.75400,-7.95661,-45.85454
1035.79406,0.45584,0.76781
1036.99400,-11.03236,-97.46746
1037.92406,-18.93821,-248.92159
1038.63000,-24.93922,-401.95916
1039.07606,-23.46971,-338.31410
1039.61806,-17.55324,-185.74305
1040.72800,-8.07523,-47.10784
1041.78212,0.45560,0.78146
1042.98206,-11.03242,-97.46657
1043.91212,-18.93821,-248.88776
1044.61606,-24.92206,-401.45628
1045.06406,-23.46828,-338.23628
1045.60606,-17.55133,-185.71837
1046.71606,-8.07517,-47.04995
1047.77000,0.45470,0.77678
1048.97012,-11.03236,-97.44528
1049.90212,-18.95525,-249.22758
1050.60612,-24.93922,-401.92790
1051.05413,-23.44669,-337.51074
1051.60612,-17.44478,-183.58223
1052.72612,-7.88857,-45.16115
1053.75800,0.45595,0.77310
1054.95800,-11.03182,-97.36838
1055.89213,-18.97228,-249.54047
1056.59612,-24.95626,-402.35244
1057.04200,-23.44735,-337.57191
1057.58800,-17.50021,-184.68158
1058.70012,-8.00731,-46.37783
1059.74613,0.45661,0.72654
1060.94600,-11.03236,-97.39454
1061.87612,-18.93814,-248.80987
1062.58012,-24.92212,-401.36315
1063.02812,-23.47067,-338.28773
1063.58200,-17.44699,-183.61870
1064.70012,-7.90543,-45.32900
1065.73400,0.45578,0.74520
1066.93412,-11.03230,-97.36923
1067.86800,-18.97228,-249.50122
1068.57200,-24.95626,-402.30416
1069.01812,-23.44831,-337.48176
1069.57200,-17.42959,-183.24906
1070.69200,-7.87159,-44.99500
1071.72200,0.45607,0.76370
1072.92200,-11.03236,-97.35365
1073.85200,-18.93821,-248.71781
1074.55812,-24.93832,-401.76719
1075.00613,-23.43222,-337.00980
1075.55812,-17.44454,-183.52607
1076.67812,-7.88857,-45.14179
1077.71012,0.45584,0.76781
1078.91000,-11.03242,-97.35684
1079.84012,-18.93827,-248.69293
1080.54413,-24.92212,-401.31245
1080.99212,-23.46959,-338.19959
1081.54200,-17.48078,-184.23628
1082.65812,-7.95655,-45.76798
1083.69800,0.45584,0.77165
1084.89812,-11.03236,-97.31728
1085.83200,-18.97222,-249.41120
1086.53600,-24.95626,-402.26623
1086.98012,-23.47013,-338.21657
1087.52212,-17.55145,-185.60529
1088.63400,-8.05837,-46.88089
1089.68600,0.45691,0.77462
1090.88612,-11.03224,-97.26917
1091.81800,-18.95525,-249.02709
1092.52000,-24.92206,-401.25191
1092.96800,-23.47055,-338.20368
1093.51000,-17.55169,-185.66122
1094.62000,-8.07529,-47.02684
1095.67412,0.45601,0.71180
1096.87400,-11.03236,-97.30753
1097.80600,-18.95525,-248.98393
1098.51000,-24.93910,-401.65421
1098.95600,-23.47115,-338.20845
1099.50212,-17.51599,-184.88176
1100.61200,-8.04121,-46.64150
1101.66212,0.45584,0.72344
1102.86200,-11.03230,-97.25908
1103.79600,-18.97228,-249.38397
1104.50212,-24.97336,-402.65471
1104.97800,-23.08467,-325.67352
1105.56200,-16.88611,-172.56748
1106.69800,-7.20840,-38.42038
1107.75000,-0.03211,0.76179
1108.94600,-11.84896,-109.88208
1109.84612,-19.49915,-261.50312
1110.53812,-25.38124,-414.36549
1110.97200,-23.01740,-323.59738
1111.56200,-16.78226,-170.64461
1112.70412,-7.05534,-36.94279
1113.73800,-0.03151,0.74197
1114.93412,-11.84890,-109.79932
1115.83413,-19.49915,-261.46349
1116.52600,-25.38124,-414.32273
1116.95800,-23.03899,-324.21071
1117.54600,-16.81693,-171.27929
1118.68813,-7.08996,-37.25142
1119.72612,-0.02989,0.75904
1120.92200,-11.84884,-109.80473
1121.82012,-19.48235,-261.05959
1122.51400,-25.38124,-414.32127
1122.94600,-23.03851,-324.23709
1123.53600,-16.79852,-170.89963
1124.68200,-7.03818,-36.74336
1125.71412,-0.03360,0.72121
1126.91000,-11.84896,-109.79195
1127.81000,-19.49915,-261.40571
1128.50212,-25.38136,-414.29110
1128.93000,-23.08467,-325.59860
1129.51212,-16.90219,-172.85777
1130.64812,-7.22544,-38.49579
1131.70200,-0.02918,0.73398
1132.89812,-11.84890,-109.78416
1133.79812,-19.49915,-261.40267
1134.49012,-25.38124,-414.26700
1134.91812,-23.08443,-325.63463
1135.50000,-16.90207,-172.87118
1136.63612,-7.22544,-38.52605
1137.69013,-0.03079,0.77168
1138.88612,-11.84896,-109.77146
1139.78600,-19.49921,-261.41362
1140.47800,-25.38130,-414.24952
1140.90600,-23.08401,-325.60471
1141.49012,-16.88467,-172.50402
1142.63000,-7.17390,-37.97864
1143.67813,-0.03396,0.76268
1144.87400,-11.84890,-109.78714
1145.77400,-19.49921,-261.38714
1146.46612,-25.38142,-414.25891
1146.89812,-23.04090,-324.22654
1147.48613,-16.81663,-171.21360
1148.63000,-7.07268,-37.02189
1149.66600,-0.02942,0.77690
1150.86200,-11.84879,-109.73070
1151.76400,-19.51601,-261.74294
1152.45600,-25.39852,-414.70747
1152.88400,-23.06374,-324.91911
1153.47012,-16.85113,-171.85597
1154.61200,-7.12350,-37.56026
1155.65400,-0.02846,0.79088
1156.85012,-11.84890,-109.76886
1157.75212,-19.51601,-261.67506
1158.44412,-25.39852,-414.67492
1158.87000,-23.08168,-325.48998
1159.45600,-16.86871,-172.21311
1160.59400,-7.17396,-38.04255
1161.64213,-0.02995,0.74144
1162.83800,-11.84902,-109.72715
1163.74212,-19.53281,-262.04271
1164.43200,-25.39852,-414.65182
1164.85800,-23.08437,-325.52697
1165.44412,-16.86787,-172.16967
1166.58200,-7.17396,-38.02620
1167.63000,-0.02983,0.70265
1168.82600,-11.84890,-109.71148
1169.72800,-19.51601,-261.65780
1170.42000,-25.39846,-414.62008
1170.84612,-23.08359,-325.53557
1171.43200,-16.86787,-172.17984
1172.56812,-7.19118,-38.20879
1173.61800,-0.02966,0.74374
1174.81413,-11.84890,-109.69940
1175.71612,-19.51601,-261.64858
1176.40812,-25.39840,-414.65264
1176.83600,-23.06446,-324.88387
1177.42200,-16.85083,-171.83401
1178.56413,-7.12356,-37.53048
1179.60612,-0.02798,0.72443
1180.80200,-11.84884,-109.63493
1181.70200,-19.49921,-261.20748
1182.39213,-25.36426,-413.56541
1182.82413,-23.06440,-324.90954
1183.41212,-16.83260,-171.49203
1184.55413,-7.10700,-37.38669
1185.59413,-0.02942,0.72561
1186.79000,-11.84896,-109.62447
1187.69200,-19.51607,-261.57957
1188.38400,-25.39846,-414.57653
1188.81000,-23.08479,-325.50152
1189.39213,-16.90261,-172.81054
1190.52812,-7.22544,-38.45997
1191.58200,-0.03001,0.70545
1192.77812,-11.84896,-109.65170
1193.68000,-19.51601,-261.58605
1194.37213,-25.39858,-414.55448
1194.79812,-23.08383,-325.43752
1195.38400,-16.86811,-172.13713
1196.52212,-7.17396,-37.99757
1197.47200,0.45865,0.69500
1198.67200,0.01656,0.81450
1199.87213,0.01650,0.81437
1201.07200,0.01650,0.81796
1202.27212,0.01650,0.78925
1203.47200,0.01650,0.81618
1204.67200,0.01650,0.80355
1205.87213,0.01650,0.76241
1207.07200,0.01650,0.76080
1208.27212,0.01650,0.79915
1209.47200,0.01650,0.79044
1210.67200,0.01650,0.79343
1211.87213,0.01650,0.75615
1213.07200,0.01650,0.76873
1214.27212,0.01650,0.77299
1215.47200,0.01650,0.75281
1216.16000,0.01650,0.82048