File: ball-data/compression/dunlop all surface.is_comp_RawData/Specimen_RawData_1.csv
Time,Extension,Load
(sec),(mm),(N)
0.00000,0.00000,-0.07896
1.19000,-10.11495,-110.48312
2.09000,-17.76490,-261.82521
2.89800,-24.63274,-414.73661
3.37600,-23.57243,-338.65556
3.91800,-17.59049,-185.49692
5.05800,-7.85383,-48.50176
6.08600,0.46977,0.01760
7.27800,-10.96414,-108.55273
8.19800,-18.78538,-260.61155
8.95200,-25.19392,-413.20279
9.40800,-23.07044,-315.98922
10.02800,-16.52283,-162.47891
11.20000,-6.54480,-33.78184
12.27400,-0.98330,-0.01740
13.45000,-12.52889,-131.06244
14.33200,-20.02637,-283.15274
14.96800,-25.43218,-414.94198
15.46600,-22.25832,-289.11510
16.18600,-15.06480,-136.58942
17.38200,-4.89640,-18.67881
18.46200,-3.30020,-10.08980
19.61000,-13.99134,-154.82231
20.45800,-21.19921,-306.86308
21.12200,-25.68228,-416.93643
21.53000,-21.35298,-262.96822
22.36400,-13.44785,-111.32342
23.56400,-3.24693,-6.66658
24.65000,-5.69441,-32.61182
25.75800,-15.35101,-178.88444
26.57800,-22.32092,-331.09616
27.17800,-25.15201,-390.30384
27.60600,-20.30428,-236.02191
28.56200,-11.66218,-86.93924
29.76200,-1.46185,-0.02707
30.83800,-7.59070,-54.51926
31.89800,-16.64271,-203.25158
32.69000,-23.37477,-355.18620
33.22400,-24.57253,-363.44036
33.69000,-19.18860,-209.61933
34.75200,-9.94491,-66.08876
35.92400,0.01704,0.05185
37.02600,-9.32633,-76.52360
38.03000,-17.86690,-227.42635
38.79600,-24.37797,-379.47915
39.27400,-23.90528,-337.09470
39.80600,-17.95419,-183.59881
40.94000,-8.24503,-47.62580
42.01400,0.46929,-0.01283
43.21400,-11.03146,-100.51245
44.15800,-19.05671,-252.12537
44.90000,-25.36420,-404.62017
45.33400,-23.09429,-309.22331
45.96000,-16.48970,-156.45139
47.13800,-6.45966,-30.34119
48.20200,-0.98186,0.04014
49.38800,-12.61355,-125.27896
50.28200,-20.21310,-276.90837
50.89600,-25.43218,-405.49610
51.39400,-22.25760,-283.75512
52.12400,-14.97990,-131.41127
53.32200,-4.79410,-16.22901
54.39000,-3.29883,-8.30207
55.54800,-14.07606,-150.18545
56.40800,-21.38593,-302.86446
57.08600,-25.43846,-399.20408
57.51000,-20.73602,-243.43735
58.42400,-12.32507,-93.38797
59.62400,-2.12504,-0.92757
60.67800,-6.68453,-41.63330
61.77400,-16.09886,-187.86144
62.58400,-22.98392,-340.31257
63.16600,-24.55148,-359.02597
63.64000,-19.09025,-205.07762
64.71001,-9.79191,-62.94384
65.86401,0.01704,0.05234
66.96600,-9.32585,-74.21227
67.98200,-17.96860,-225.47267
68.74800,-24.47997,-377.56786
69.25201,-23.48244,-319.63810
69.83601,-17.15026,-166.68648
71.00000,-7.22502,-36.70553
72.05400,0.01309,0.01493
73.25000,-11.84860,-110.88304
74.17800,-19.73663,-263.22220
74.84801,-25.43218,-402.56627
75.35001,-22.21252,-280.71241
76.09001,-14.86086,-128.41993
77.29000,-4.65814,-14.75453
78.34200,-3.29954,-7.78074
79.50201,-14.09310,-148.53289
80.36201,-21.40285,-300.58485
81.03800,-25.43685,-396.97528
81.46401,-20.70989,-241.35245
82.38600,-12.24005,-91.36200
83.58601,-2.04008,-0.60525
84.63001,-6.68447,-40.73543
85.72801,-16.11608,-186.17161
86.53800,-23.00066,-338.14065
87.12000,-24.52978,-356.30535
87.60001,-19.00248,-201.94786
88.68201,-9.62216,-60.35544
89.81600,0.01704,0.01632
90.91801,-9.32603,-73.12494
91.93401,-17.96860,-223.45068
92.70200,-24.49702,-375.76996
93.20400,-23.48621,-318.21806
93.79601,-17.08108,-164.46730
94.96401,-7.12284,-35.24913
96.00601,0.01471,-0.00377
97.20200,-11.84855,-109.52370
98.13400,-19.77077,-261.97974
98.80000,-25.43218,-400.44088
99.30200,-22.21413,-279.51991
100.05000,-14.79288,-126.56158
101.25001,-4.59022,-13.93429
102.29401,-3.29524,-7.44614
103.45400,-14.09310,-147.08539
104.31600,-21.42001,-299.04559
104.99201,-25.42058,-394.54576
105.41801,-20.68890,-239.78857
106.35001,-12.13858,-89.43431
107.55000,-1.93748,-0.37625
108.58201,-6.68160,-40.09186
109.68201,-16.13294,-184.98141
110.49400,-23.03504,-337.15684
111.07001,-24.55340,-355.83328
111.55000,-19.02705,-201.63234
112.62801,-9.67316,-60.41721
113.76801,0.01704,0.01871
114.87000,-9.32597,-72.35405
115.89401,-18.03682,-223.31623
116.66000,-24.54784,-375.30057
117.15601,-23.48568,-317.10099
117.75001,-17.06183,-163.34245
118.91801,-7.10580,-34.71362
119.95801,0.01489,0.03234
121.15401,-11.84855,-108.59955
122.08801,-19.78787,-260.87193
122.75201,-25.43212,-398.84821
123.25401,-22.21353,-278.51397
124.00601,-14.75868,-125.36505
125.20601,-4.55632,-13.42650
126.24600,-3.29775,-7.17654
127.40801,-14.11008,-146.29919
128.27400,-21.47071,-298.65218
128.94200,-25.43828,-394.06911
129.36801,-20.71192,-239.54742
130.29801,-12.17219,-89.39247
131.49800,-1.97174,-0.32409
132.53402,-6.68064,-39.54447
133.63800,-16.16684,-184.43499
134.45202,-23.08580,-336.95392
135.02200,-24.55399,-354.79795
135.50802,-18.96619,-199.66289
136.59402,-9.55436,-58.76605
137.72000,0.01698,0.01201
138.82200,-9.32591,-71.71429
139.84602,-18.03682,-222.12708
140.61402,-24.56493,-374.42856
141.11000,-23.46295,-315.47852
141.71200,-16.97400,-161.31889
142.88200,-7.00410,-33.42908
143.91000,0.01333,0.01022
145.10800,-11.86553,-108.11010
146.04600,-19.83894,-260.74000
146.70402,-25.43218,-397.48706
147.20800,-22.18986,-277.10082
147.96600,-14.69046,-123.87731
149.16600,-4.48840,-12.82073
150.19802,-3.29871,-6.90164
151.36202,-14.12712,-145.66173
152.23002,-21.50485,-298.14256
152.89402,-25.43882,-392.93684
153.32200,-20.68998,-238.37904
154.25402,-12.13852,-88.55545
155.45402,-1.93748,-0.23530
156.48600,-6.68094,-39.21006
157.59002,-16.16684,-183.53615
158.40202,-23.06912,-335.40435
158.97402,-24.55483,-353.93272
159.45800,-18.98651,-199.49978
160.54600,-9.55430,-58.46240
161.67202,0.01698,-0.01324
162.77400,-9.32597,-71.16403
163.80000,-18.05398,-221.48732
164.57000,-24.59872,-374.11958
165.06002,-23.48484,-315.36765
165.66200,-16.99236,-161.08422
166.83200,-7.02114,-33.35457
167.86202,0.01501,-0.01275
169.06002,-11.86559,-107.45828
169.99600,-19.82183,-259.29961
170.65600,-25.43224,-396.43336
171.16000,-22.18651,-276.37431
171.92202,-14.65620,-122.92530
173.12202,-4.45474,-12.38215
174.15002,-3.29703,-6.73130
175.31602,-14.14422,-145.22073
176.18400,-21.52183,-297.57041
176.84602,-25.44061,-392.09217
177.27200,-20.71437,-238.38323
178.20202,-12.17225,-88.59087
179.40202,-1.97174,-0.27304
180.43800,-6.68052,-38.86176
181.54400,-16.18388,-183.09450
182.36002,-23.11988,-335.51276
182.92602,-24.55429,-353.09296
183.41200,-18.96702,-198.55449
184.49802,-9.55430,-58.21586
185.62402,0.01698,-0.00394
186.72602,-9.32597,-70.68431
187.75602,-18.08830,-221.33915
188.52602,-24.63274,-373.99646
189.01400,-23.46439,-314.05076
189.61602,-16.97430,-160.33722
190.78802,-6.98712,-32.89735
191.81402,0.01543,-0.04785
193.01202,-11.86559,-106.86709
193.95402,-19.87313,-259.58844
194.60800,-25.43224,-395.41721
195.11402,-22.16283,-275.14406
195.87402,-14.65620,-122.52632
197.07400,-4.45474,-12.27351
198.10200,-3.29590,-6.57806
199.27000,-14.16108,-144.90553
200.13602,-21.52189,-296.67534
200.79800,-25.43948,-391.27238
201.22802,-20.66744,-236.80428
202.16200,-12.10403,-87.44857
203.36202,-1.90358,-0.13082
204.39002,-6.68142,-38.57986
205.49802,-16.20080,-182.74488
206.31602,-23.15408,-335.51864
206.87800,-24.55764,-352.49576
207.36602,-18.95076,-197.82195
208.45402,-9.52016,-57.60483
209.57600,0.01698,0.02439
210.67802,-9.32597,-70.35021
211.71000,-18.10540,-220.95287
212.48002,-24.64989,-373.58295
212.96600,-23.46104,-313.31401
213.56802,-16.97508,-159.95508
214.73800,-7.00422,-32.82462
215.76600,0.01566,-0.01446
216.96400,-11.86559,-106.39040
217.90400,-19.85603,-258.35097
218.56002,-25.43224,-394.59359
219.06602,-22.16702,-274.73785
219.82800,-14.63928,-121.94902
221.02802,-4.43752,-12.04382
222.05402,-3.29398,-6.47142
223.22202,-14.16114,-144.31380
224.09002,-21.53893,-296.24840
224.75002,-25.44169,-390.53530
225.18002,-20.66307,-236.21170
226.11402,-12.10409,-87.19007
227.31402,-1.90358,-0.10566
228.34202,-6.68435,-38.33093
229.45202,-16.21760,-182.42029
230.26800,-23.15408,-334.66622
230.83002,-24.55489,-351.74973
231.31602,-18.96260,-197.72252
232.40202,-9.55436,-57.73253
233.52802,0.01698,0.04405
234.63000,-9.32591,-70.00602
235.66202,-18.10540,-220.29715
236.43200,-24.64995,-372.72997
236.91802,-23.46068,-312.77195
237.52000,-16.97406,-159.61556
238.69202,-6.98712,-32.53073
239.71802,0.01537,-0.02110
240.91602,-11.86559,-105.97389
241.85602,-19.85609,-257.72084
242.51202,-25.43218,-393.79939
243.01800,-22.16451,-274.19060
243.78002,-14.63946,-121.65117
244.98002,-4.43752,-11.93158
246.00602,-3.29739,-6.33770
247.17402,-14.16114,-143.82620
248.04400,-21.55591,-295.95761
248.70202,-25.44007,-389.81490
249.13402,-20.63754,-235.24452
250.07000,-12.07007,-86.60047
251.27002,-1.86992,-0.12235
252.29400,-6.68435,-38.09121
253.40202,-16.20080,-181.58743
254.22002,-23.15408,-333.96371
254.78202,-24.55800,-351.33928
255.26800,-18.96619,-197.40028
256.35602,-9.53714,-57.41309
257.48002,0.01698,0.07345
258.58200,-9.32633,-69.72326
259.61200,-18.08830,-219.31993
260.38400,-24.64989,-372.06218
260.87003,-23.46236,-312.36134
261.47202,-16.97352,-159.29157
262.64603,-6.97002,-32.18572
263.67000,0.01584,-0.00844
264.87003,-11.88250,-105.83188
265.81200,-19.89011,-257.85239
266.46403,-25.43224,-393.17291
266.97000,-22.16630,-273.86349
267.73203,-14.63940,-121.44569
268.93200,-4.43752,-11.83903
269.95800,-3.29512,-6.22520
271.12600,-14.16114,-143.36212
271.99803,-21.57295,-295.66113
272.65403,-25.43983,-389.31895
273.08600,-20.63629,-234.86935
274.02200,-12.07012,-86.32233
275.22200,-1.86986,-0.06506
276.24600,-6.68190,-37.88351
277.35800,-16.23446,-181.76697
278.17203,-23.15414,-333.36483
278.73400,-24.55650,-350.77132
279.22000,-18.96696,-197.19396
280.30800,-9.53714,-57.23073
281.43200,0.01698,0.05705
282.53403,-9.32633,-69.43748
283.56600,-18.10540,-219.17826
284.33800,-24.66711,-371.88768
284.82203,-23.46427,-311.93599
285.42400,-16.97496,-159.08347
286.59600,-6.98712,-32.21828
287.62200,0.01632,-0.00264
288.82000,-11.86553,-105.22811
289.76203,-19.87319,-256.88872
290.41600,-25.43212,-392.54453
290.92203,-22.16594,-273.50128
291.68600,-14.62206,-120.96541
292.88603,-4.42024,-11.62439
293.91000,-3.29452,-6.12620
295.07800,-14.16120,-142.95424
295.95203,-21.58999,-295.55107
296.60603,-25.44229,-388.84927
297.03803,-20.63922,-234.56981
297.97803,-12.03646,-85.69906
299.17800,-1.83590,-0.06692
300.19803,-6.68500,-37.67598
301.30800,-16.21766,-180.98257
302.12403,-23.15414,-332.79937
302.68600,-24.55669,-350.29631
303.17400,-18.94149,-196.32164
304.26603,-9.48608,-56.51442
305.38400,0.01686,0.02660
306.48603,-9.32609,-69.13657
307.52003,-18.12256,-219.08533
308.29203,-24.68416,-371.74825
308.77403,-23.46391,-311.54370
309.37803,-16.95618,-158.46593
310.55200,-6.95310,-31.79010
311.57400,0.01716,-0.01517
312.77403,-11.88250,-105.18848
313.71600,-19.89011,-256.82176
314.36800,-25.43224,-391.90978
314.87600,-22.14400,-272.53333
315.64203,-14.58804,-120.21989
316.84200,-4.38586,-11.28764
317.86203,-3.29703,-6.04833
319.03200,-14.17806,-142.88893
319.90403,-21.58999,-295.03748
320.55800,-25.44085,-388.23180
320.99003,-20.63730,-234.33784
321.93403,-12.00214,-85.10029
323.13400,-1.80182,-0.00963
324.15003,-6.68004,-37.50256
325.26400,-16.25150,-181.22684
326.08003,-23.18798,-333.08551
326.63800,-24.55943,-349.95884
327.12403,-18.96613,-196.53697
328.21403,-9.52010,-56.66489
329.33603,0.01692,0.00466
330.43803,-9.32603,-68.94393
331.47200,-18.12256,-218.60337
332.24003,-24.64995,-370.32228
332.72803,-23.44071,-310.48942
333.33800,-16.88736,-156.97438
334.51400,-6.86820,-30.89187
335.52600,0.01925,-0.01820
336.72600,-11.88250,-104.88479
337.66803,-19.89011,-256.35518
338.32000,-25.43224,-391.38999
338.82800,-22.14352,-272.19051
339.59403,-14.58786,-120.06791
340.79400,-4.38586,-11.23327
341.81403,-3.29733,-5.99711
342.98400,-14.17812,-142.57276
343.85400,-21.57295,-294.19668
344.51000,-25.44157,-387.89105
344.94203,-20.63611,-233.97496
345.88400,-12.01924,-85.15410
347.08400,-1.81880,-0.08577
348.10203,-6.68477,-37.38270
349.21403,-16.23441,-180.50017
350.03200,-23.18798,-332.62752
350.59003,-24.55788,-349.57867
351.07800,-18.94120,-195.81836
352.17203,-9.46928,-56.09183
353.28803,0.01692,0.01305
354.39000,-9.32597,-68.70513
355.42603,-18.13954,-218.54009
356.19803,-24.70119,-371.19966
356.67800,-23.46672,-310.95454
357.28403,-16.94106,-157.79898
358.46003,-6.91914,-31.27195
359.47803,0.01818,0.03204
360.67800,-11.88250,-104.59990
361.62200,-19.90698,-256.29530
362.27200,-25.43224,-390.92798
362.78003,-22.14244,-271.89318
363.55003,-14.55456,-119.35714
364.75003,-4.35214,-10.92998
365.76603,-3.29524,-5.91979
366.93600,-14.17812,-142.21742
367.80800,-21.59005,-294.06698
368.46200,-25.44223,-387.36042
368.89603,-20.61213,-233.14670
369.84200,-11.96830,-84.34613
371.04203,-1.76804,-0.02146
372.05403,-6.68477,-37.25453
373.16600,-16.23441,-180.16670
373.98400,-23.18804,-332.13820
374.54203,-24.56213,-349.28765
375.03200,-18.92541,-195.32543
376.12600,-9.45224,-55.79956
377.24003,0.01692,0.03940
378.34200,-9.32633,-68.52448
379.37600,-18.12244,-217.77552
380.14800,-24.68416,-370.26614
380.63000,-23.46361,-310.54007
381.23800,-16.92270,-157.21103
382.41403,-6.90204,-31.02615
383.43003,0.01752,-0.02189
384.63000,-11.88250,-104.26195
385.57603,-19.92396,-256.21148
386.22403,-25.43230,-390.45274
386.73203,-22.13999,-271.58929
387.50200,-14.55462,-119.19692
388.70203,-4.35208,-10.88300
389.71803,-3.29871,-5.85051
390.88803,-14.17818,-141.95683
391.76203,-21.60685,-294.04806
392.41403,-25.44211,-387.01974
392.84600,-20.63748,-233.52498
393.78803,-12.01918,-84.86617
394.98800,-1.81880,-0.02988
396.00600,-6.68130,-37.03442
397.11800,-16.23441,-179.79275
397.93600,-23.18810,-331.64136
398.49603,-24.53743,-348.00872
398.98603,-18.90221,-194.58158
400.08203,-9.41840,-55.31441
401.19203,0.01692,0.01181
402.29400,-9.32603,-68.36507
403.33003,-18.13954,-217.76401
404.10203,-24.70114,-370.29762
404.58203,-23.46576,-310.28880
405.18803,-16.93932,-157.33408
406.36400,-6.91920,-31.09923
407.38203,0.01931,-0.02650
408.58203,-11.88262,-104.11561
409.52800,-19.92396,-255.79631
410.17603,-25.43230,-389.99237
410.68403,-22.14280,-271.39202
411.45203,-14.57118,-119.28011
412.65200,-4.36900,-10.89289
413.67000,-3.29637,-5.73871
414.84403,-14.21220,-142.21012
415.71803,-21.64087,-294.36687
416.36800,-25.42764,-385.95293
416.80403,-20.56340,-231.51595
417.75003,-11.93434,-83.62485
418.95000,-1.73396,0.03119
419.95800,-6.68142,-36.91988
421.07203,-16.25156,-179.84124
421.89000,-23.20526,-331.67411
422.45000,-24.51967,-346.93684
422.94003,-18.88673,-194.05195
424.03600,-9.40142,-54.98440
425.14400,0.01674,0.05111
426.24603,-9.32609,-68.15929
427.28200,-18.13948,-217.40772
428.05403,-24.70119,-369.83937
428.53403,-23.46469,-309.94471
429.14203,-16.92276,-156.79648
430.31803,-6.90210,-30.79111
431.33400,0.01859,-0.05703
432.53403,-11.88250,-103.81617
433.48000,-19.92401,-255.47799
434.12803,-25.43230,-389.68798
434.63603,-22.14274,-271.12860
435.40600,-14.55462,-118.87599
436.60603,-4.35208,-10.74109
437.62200,-3.29745,-5.69724
438.79400,-14.19510,-141.70785
439.66803,-21.62383,-293.60170
440.31803,-25.44258,-386.21247
440.75200,-20.61195,-232.44480
441.69803,-11.96830,-83.94070
442.89800,-1.76804,-0.02416
443.91003,-6.68441,-36.83894
445.02403,-16.25156,-179.53428
445.84600,-23.23916,-332.14979
446.40003,-24.54084,-347.48103
446.89203,-18.88146,-193.74704
447.98800,-9.40142,-54.88730
449.09600,0.01686,-0.02827
450.19803,-9.32626,-67.97658
451.23603,-18.15640,-217.42562
452.01000,-24.73533,-370.39690
452.48800,-23.44334,-309.01024
453.10003,-16.86991,-155.75579
454.27603,-6.85134,-30.33597
455.28600,0.02057,0.00188
456.48603,-11.88262,-103.64105
457.43200,-19.92407,-255.09141
458.08003,-25.43224,-389.26791
458.59003,-22.11937,-270.26327
459.36203,-14.52066,-118.25490
460.56200,-4.31776,-10.49207
461.57403,-3.29620,-5.64666
462.74603,-14.19516,-141.43770
463.62003,-21.62389,-293.23330
464.27003,-25.44420,-385.93672
464.70400,-20.61046,-232.22547
465.65003,-11.96836,-83.79227
466.85003,-1.76810,0.00202
467.86203,-6.68345,-36.69004
468.97600,-16.25156,-179.25464
469.79603,-23.22230,-331.37958
470.35403,-24.51914,-346.33182
470.84803,-18.84224,-192.77588
471.94803,-9.33356,-54.06629
473.05003,0.03390,-0.01061
474.25003,-10.17988,-79.06717
475.26000,-18.76858,-230.00816
476.01803,-25.21102,-382.78967
476.47803,-23.00969,-295.37495
477.13803,-16.12666,-143.05574
478.32803,-6.00101,-23.03686
479.33800,-0.97403,0.01430
480.53200,-12.68189,-115.98508
481.45400,-20.51952,-267.93722
482.09200,-25.80228,-401.60559
482.58203,-21.64045,-257.42423
483.41403,-13.66907,-105.91682
484.61400,-3.46797,-5.21455
485.62603,-4.52433,-14.94949
486.78403,-14.92597,-154.18150
487.64000,-22.20193,-306.46412
488.25600,-25.13874,-372.09745
488.70803,-19.97884,-217.62719
489.72003,-10.96539,-71.76335
490.92000,-0.76525,0.02190
492.01403,-8.46583,-57.02569
493.08003,-17.54415,-204.40388
493.86603,-24.22497,-356.33557
494.37200,-23.80274,-320.39974
494.94003,-17.53847,-167.42382
496.09803,-7.65013,-37.52129
497.10203,0.47174,-0.02465
498.30203,-11.03182,-90.73544
499.28003,-19.34675,-242.05232
499.99403,-25.41514,-388.16318
500.46803,-22.56725,-282.26355
501.18203,-15.33900,-130.33793
502.38003,-5.15122,-16.25152
503.39000,-2.10453,-0.20271
504.57403,-13.44666,-128.30074
505.47003,-21.06312,-279.86208
506.14400,-25.72228,-397.96490
506.58203,-21.06952,-242.94673
507.47803,-12.71603,-93.00207
508.67800,-2.51624,-1.09838
509.77800,-6.68471,-36.54144
510.89400,-16.26890,-179.13705
511.71403,-23.23916,-331.16914
512.26800,-24.54287,-346.83015
512.75800,-18.90060,-193.73892
513.85400,-9.41846,-54.85136
514.96406,0.01686,0.04379
516.06603,-9.32633,-67.61047
517.10206,-18.13954,-216.28462
517.87403,-24.70119,-368.53269
518.36003,-23.39922,-306.97411
518.97203,-16.83469,-154.74695
520.14800,-6.81720,-29.83315
521.15406,0.02009,-0.01932
522.35400,-11.88262,-103.11038
523.30200,-19.94123,-254.66496
523.94800,-25.43236,-388.31569
524.46000,-22.09856,-269.14725
525.23600,-14.46888,-117.06715
526.43606,-4.26694,-9.97535
527.44200,-3.29608,-5.50018
528.61600,-14.21226,-141.13436
529.48806,-21.62383,-292.39386
530.14000,-25.42614,-384.40082
530.57606,-20.55946,-230.55905
531.52600,-11.90020,-82.64825
532.72600,-1.70011,0.00756
533.73006,-6.68435,-36.44043
534.84800,-16.28618,-179.17844
535.67006,-23.27330,-331.71177
536.22206,-24.52213,-345.71674
536.71600,-18.84111,-192.32618
537.81400,-9.35054,-53.98306
538.91600,0.01680,0.04334
540.01800,-9.32639,-67.48703
541.05806,-18.17332,-216.71908
541.83200,-24.75250,-369.51218
542.31200,-23.39952,-306.81720
542.92400,-16.83505,-154.60717
544.10006,-6.81720,-29.74686
545.10600,0.02176,-0.00579
546.30600,-11.88262,-102.92673
547.25400,-19.94117,-254.37564
547.90000,-25.43236,-387.99156
548.41400,-22.07458,-268.26985
549.19200,-14.43528,-116.49027
550.39200,-4.23322,-9.71384
551.49400,-4.52481,-14.84349
552.65206,-14.92603,-153.56907
553.50806,-22.20188,-305.59378
554.12400,-25.14310,-371.53631
554.57406,-20.00999,-217.89776
555.57406,-11.08444,-72.83678
556.77406,-0.88435,0.08988
557.78206,-7.59076,-46.31422
558.87606,-16.93239,-191.52960
559.68200,-23.78325,-344.16012
560.20406,-24.20177,-333.61286
560.72800,-18.26760,-180.72465
561.85806,-8.56849,-46.06003
562.87006,0.03390,0.03931
564.07000,-10.17994,-78.50600
565.08200,-18.78568,-229.32278
565.84000,-25.22818,-382.08459
566.30006,-22.98912,-293.97426
566.97006,-16.02413,-140.85600
568.16206,-5.88257,-21.83140
569.25806,-2.10220,-0.14641
570.44400,-13.46388,-128.01562
571.34206,-21.09732,-279.79786
572.01200,-25.72192,-397.15204
572.45000,-21.07149,-242.49265
573.35006,-12.68189,-92.26918
574.55006,-2.48258,-0.97311
575.64606,-6.68082,-36.18784
576.76406,-16.28618,-178.77320
577.58600,-23.27330,-331.17827
578.13800,-24.52081,-345.28412
578.63000,-18.86185,-192.47724
579.72800,-9.36758,-54.08116
580.83200,0.01680,0.06001
581.93400,-9.32591,-67.22084
582.97600,-18.19012,-216.61269
583.74806,-24.75243,-369.04819
584.22800,-23.40227,-306.48533
584.85006,-16.74770,-152.88767
586.03206,-6.68058,-28.50899
587.12200,-0.97242,0.03357
588.31806,-12.69911,-115.41363
589.24200,-20.55342,-267.40430
589.87606,-25.80234,-400.19855
590.37200,-21.57134,-254.86581
591.22006,-13.48199,-102.84183
592.42006,-3.28125,-4.05068
593.51000,-5.69005,-25.77171
594.65000,-15.62276,-166.01535
595.48806,-22.74590,-318.09039
596.07000,-24.85228,-358.37729
596.54006,-19.42429,-204.45602
597.60006,-10.14921,-62.22504
598.79600,0.01680,0.03607
599.89800,-9.32650,-67.10070
600.93806,-18.17338,-216.14129
601.71000,-24.73539,-368.37816
602.19200,-23.39695,-306.23186
602.81006,-16.78190,-153.39985
603.99200,-6.71460,-28.70454
605.08600,-0.96967,-0.02686
606.28206,-12.69911,-115.27308
607.20406,-20.53650,-266.85139
607.84000,-25.80264,-399.98416
608.33600,-21.57211,-254.75198
609.18200,-13.49909,-103.02985
610.38200,-3.29805,-4.12300
611.47400,-5.68981,-25.72562
612.61400,-15.62294,-165.92087
613.45406,-22.76294,-318.35239
614.03406,-24.85234,-358.22324
614.50400,-19.42405,-204.37319
615.56400,-10.14921,-62.16449
616.76000,0.01680,0.01552
617.86200,-9.32656,-67.02481
618.90406,-18.19012,-216.33197
619.67806,-24.76977,-369.10143
620.15600,-23.40251,-306.25951
620.77600,-16.76647,-153.04395
621.95800,-6.69756,-28.56598
623.05006,-0.97092,-0.03456
624.24606,-12.69911,-115.16170
625.17206,-20.57040,-267.42311
625.80400,-25.80300,-399.84241
626.30006,-21.58024,-254.82425
627.13406,-13.60091,-104.36203
628.33406,-3.40011,-4.61043
629.33800,-4.52062,-14.59837
630.49606,-14.92597,-152.92889
631.35400,-22.21897,-305.15753
631.96800,-25.14388,-370.70587
632.41800,-20.00778,-217.32390
633.41800,-11.08438,-72.54135
634.61806,-0.88435,0.02338
635.62606,-7.59225,-46.11499
636.72006,-16.93239,-190.80823
637.52800,-23.80029,-343.73522
638.05006,-24.18043,-332.10695
638.58406,-18.15449,-178.13968
639.72406,-8.38123,-44.03480
640.81400,0.47299,0.04467
642.01406,-11.03182,-89.82607
642.99806,-19.39721,-241.58064
643.70606,-25.41508,-386.37940
644.18200,-22.54303,-280.45230
644.91006,-15.20280,-127.52513
646.11006,-4.99828,-14.83842
647.20200,-3.29703,-5.29621
648.37806,-14.22930,-140.50241
649.25606,-21.69235,-292.59490
649.90000,-25.42961,-383.18865
650.33800,-20.54445,-229.42424
651.29600,-11.81530,-81.21190
652.49606,-1.61533,0.02700
653.59000,-7.59237,-46.05836
654.68200,-16.91517,-190.30564
655.49006,-23.78337,-343.06016
656.01406,-24.18270,-332.01888
656.54806,-18.15245,-178.01564
657.68806,-8.38123,-43.96925
658.77800,0.47222,-0.01930
659.97800,-11.03188,-89.75101
660.96406,-19.41407,-241.77432
661.67006,-25.41526,-386.20420
662.14606,-22.54519,-280.38613
662.87606,-15.18540,-127.18238
664.07606,-4.98160,-14.71478
665.16600,-3.29608,-5.23473
666.34206,-14.22924,-140.37790
667.21800,-21.67519,-292.03545
667.86400,-25.43003,-383.06046
668.30200,-20.53452,-229.13501
669.26406,-11.78146,-80.72084
670.46406,-1.58107,0.02138
671.55400,-7.59386,-46.03202
672.65206,-16.96665,-191.15072
673.45606,-23.80035,-343.24020
673.97800,-24.18163,-331.87617
674.51200,-18.15496,-177.98105
675.65206,-8.38123,-43.96763
676.74200,0.47156,-0.04143
677.94200,-11.03188,-89.66671
678.92600,-19.39727,-241.23902
679.63406,-25.41520,-385.94909
680.10806,-22.56761,-280.88836
680.82606,-15.30474,-128.95875
682.02406,-5.11756,-15.64643
683.03000,-2.10322,-0.15076
684.21800,-13.48122,-127.54813
685.12006,-21.14838,-279.77901
685.78406,-25.72168,-395.93160
686.22006,-21.08782,-242.18360
687.11806,-12.71615,-92.30752
688.31806,-2.51630,-0.91781
689.41800,-6.68722,-35.92927
690.53600,-16.28624,-177.86723
691.36006,-23.29028,-330.35085
691.91006,-24.52428,-344.36714
692.40800,-18.80320,-190.65622
693.51606,-9.23150,-52.33627
694.60600,0.03384,0.03650
695.80600,-10.18012,-77.80614
696.82406,-18.83644,-229.13586
697.57800,-25.24534,-381.13594
698.03600,-22.98368,-292.87117
698.70406,-16.04105,-140.52455
699.89800,-5.88251,-21.54278
700.99400,-2.10214,-0.15920
702.18200,-13.48122,-127.39732
703.08406,-21.14844,-279.65924
703.74806,-25.72073,-395.76661
704.18400,-21.08513,-242.04465
705.08800,-12.66509,-91.53903
706.28800,-2.46560,-0.82353
707.38200,-6.68459,-35.84201
708.50400,-16.32032,-178.30133
709.32806,-23.32388,-331.05891
709.87400,-24.51932,-344.06804
710.37200,-18.80027,-190.54148
711.47800,-9.24854,-52.45944
712.57000,0.03390,0.00608
713.77000,-10.18000,-77.65500
714.78800,-18.83638,-228.94086
715.54400,-25.26226,-381.39414
716.00006,-22.98835,-292.87862
716.67400,-15.98963,-139.64789
717.86806,-5.83127,-21.09439
718.95800,-2.10298,-0.15929
720.14606,-13.48122,-127.25571
721.05006,-21.16548,-279.87786
721.71206,-25.72037,-395.57390
722.15000,-21.06127,-241.36588
723.05600,-12.63137,-91.11524
724.25606,-2.43098,-0.75443
725.34600,-6.68321,-35.74379
726.46406,-16.28624,-177.56352
727.29006,-23.30714,-330.50403
727.83800,-24.52428,-344.20189
728.33606,-18.79794,-190.42885
729.44400,-9.23150,-52.21329
730.53406,0.03384,-0.00045
731.73400,-10.18012,-77.62322
732.75200,-18.83638,-228.83171
733.50806,-25.26232,-381.26867
733.96406,-22.98392,-292.69021
734.63806,-15.98945,-139.63535
735.83200,-5.83133,-21.05813
736.92206,-2.10232,-0.13875
738.11006,-13.48122,-127.16201
739.01000,-21.13146,-278.97768
739.67600,-25.72312,-395.54052
740.11400,-21.06498,-241.38451
741.02000,-12.63143,-91.03588
742.22006,-2.43104,-0.72741
743.31006,-6.68722,-35.75614
744.43006,-16.30334,-177.79399
745.25400,-23.30714,-330.35543
745.80206,-24.52440,-343.94529
746.30006,-18.79872,-190.36865
747.40600,-9.24854,-52.35456
748.49806,0.03384,0.05993
749.69806,-10.18000,-77.53265
750.71406,-18.81952,-228.32407
751.47006,-25.24534,-380.62345
751.92600,-23.00670,-293.20816
752.60006,-16.00673,-139.77366
753.79400,-5.84819,-21.16343
754.88606,-2.10172,-0.11675
756.07406,-13.48122,-127.07991
756.97600,-21.14850,-279.16187
757.63806,-25.73203,-395.79570
758.07406,-21.11155,-242.38218
758.96800,-12.76709,-92.77182
760.16800,-2.56724,-1.06357
761.17400,-5.69985,-25.46026
762.31606,-15.64004,-165.10788
763.15406,-22.76294,-316.85751
763.73400,-24.85324,-356.99923
764.20406,-19.41849,-203.47379
765.27000,-10.09827,-61.11921
766.46000,0.01662,0.02549
767.56200,-9.32668,-66.43097
768.60806,-18.22372,-215.71189
769.38006,-24.78693,-367.99934
769.85406,-23.42505,-305.84570
770.46800,-16.83421,-153.58519
771.64800,-6.78288,-28.98770
772.75006,-0.96955,0.01543
773.94606,-12.69923,-114.26518
774.87400,-20.58720,-266.41877
775.50200,-25.79612,-398.07703
776.00006,-21.57139,-253.77370
776.84800,-13.48211,-102.13795
778.04806,-3.28131,-3.87020
779.13806,-5.70069,-25.37835
780.28000,-15.64004,-165.02308
781.12200,-22.79702,-317.51331
781.69806,-24.85455,-356.89976
782.17006,-19.40157,-203.03264
783.23600,-10.08147,-60.89071
784.42400,0.01674,0.04188
785.52606,-9.32633,-66.32189
786.57200,-18.22378,-215.60870
787.34600,-24.80380,-368.31375
787.82000,-23.40358,-305.09807
788.44200,-16.74859,-152.07856
789.62400,-6.68064,-28.04690
790.71406,-0.97020,-0.00528
791.91006,-12.69923,-114.19982
792.83800,-20.58720,-266.33048
793.46606,-25.79564,-397.96688
793.96206,-21.59507,-254.28688
794.80600,-13.53287,-102.75287
796.00606,-3.33273,-4.10037
797.10206,-5.70069,-25.36268
798.24400,-15.63998,-164.86751
799.08406,-22.77998,-316.98022
799.66006,-24.87429,-357.63185
800.13006,-19.44056,-203.85269
801.18806,-10.18305,-61.97642
802.38806,0.01674,-0.02402
803.49006,-9.32674,-66.26963
804.53600,-18.22372,-215.51326
805.30806,-24.78693,-367.76874
805.78406,-23.40502,-305.03431
806.40606,-16.74871,-151.96913
807.58800,-6.68064,-28.10249
808.67806,-0.96787,0.00693
809.87400,-12.69923,-114.08392
810.80206,-20.58720,-266.14482
811.43006,-25.79618,-397.77361
811.92600,-21.61325,-254.65647
812.76200,-13.60098,-103.65574
813.96206,-3.40017,-4.48093
814.96606,-4.52595,-14.25940
816.12606,-14.94289,-151.96671
816.98600,-22.25323,-304.24854
817.59606,-25.14633,-369.30669
818.04806,-19.97807,-215.83596
819.06200,-10.94865,-70.47478
820.26200,-0.74821,0.03126
821.35406,-8.46691,-55.66378
822.42600,-17.59557,-202.58190
823.21606,-24.31017,-355.01834
823.71406,-23.78809,-317.29437
824.29006,-17.44939,-164.28296
825.45406,-7.51416,-35.42627
826.54206,0.02487,-0.04177
827.74206,-11.88280,-101.42555
828.70000,-20.02679,-253.68826
829.33606,-25.43242,-385.11403
829.85006,-22.07512,-266.58934
830.64000,-14.33340,-113.92796
831.84000,-4.13128,-8.67276
832.93006,-4.52941,-14.28487
834.09000,-14.94289,-151.91627
834.95200,-22.27027,-304.44594
835.56006,-25.14818,-369.24928
836.01200,-19.97962,-215.78195
837.02800,-10.93161,-70.19770
838.22800,-0.73093,0.02232
839.31806,-8.46691,-55.62987
840.39200,-17.61279,-202.79933
841.18206,-24.32745,-355.40294
841.67600,-23.80902,-317.89869
842.25400,-17.44682,-164.15700
843.41800,-7.51410,-35.40941
844.50606,0.02583,-0.00079
845.70606,-11.88274,-101.32685
846.66406,-20.02673,-253.56460
847.30006,-25.43248,-385.05059
847.81400,-22.07452,-266.46331
848.60406,-14.33340,-113.84002
849.80400,-4.13128,-8.64814
850.89406,-4.53019,-14.25505
852.05400,-14.94289,-151.83142
852.91600,-22.27021,-304.41916
853.52406,-25.14633,-369.07665
853.97600,-19.97693,-215.65994
854.99206,-10.93155,-70.20555
856.19200,-0.73087,0.01695
857.28206,-8.46589,-55.57967
858.35600,-17.61285,-202.70282
859.14606,-24.32745,-355.28470
859.64000,-23.81045,-317.89221
860.21606,-17.46720,-164.48177
861.38006,-7.53103,-35.56243
862.47006,0.02463,-0.04664
863.67006,-11.88274,-101.24926
864.62806,-20.02679,-253.44102
865.26406,-25.43242,-384.92471
865.77800,-22.07548,-266.46217
866.56806,-14.33340,-113.80174
867.76806,-4.13122,-8.64524
868.85806,-4.53192,-14.21456
870.01806,-14.94295,-151.72343
870.88006,-22.27027,-304.26014
871.48600,-25.16749,-369.91891
871.93806,-20.00144,-216.10379
872.94806,-10.99894,-70.88316
874.14806,-0.79921,0.02172
875.24606,-8.46661,-55.47953
876.32006,-17.61279,-202.59181
877.11006,-24.32745,-355.09910
877.60406,-23.81410,-317.93471
878.18006,-17.46696,-164.37320
879.34406,-7.53109,-35.50627
880.43400,0.02481,-0.01401
881.63406,-11.88280,-101.13061
882.59206,-20.02673,-253.32190
883.22800,-25.43248,-384.74325
883.74206,-22.07279,-266.32756
884.53000,-14.35032,-114.00543
885.73006,-4.14838,-8.70063
886.82200,-4.52798,-14.16552
887.98206,-14.94295,-151.63016
888.84206,-22.25323,-303.74851
889.45200,-25.14746,-368.98643
889.90406,-19.97842,-215.57173
890.92006,-10.93161,-70.12975
892.12006,-0.73093,-0.01538
893.21000,-8.46697,-55.49897
894.28406,-17.61279,-202.46055
895.07406,-24.32745,-354.96637
895.56806,-23.81141,-317.72364
896.14406,-17.46673,-164.34934
897.30806,-7.53103,-35.51901
898.39806,0.02732,-0.05840
899.59800,-11.88280,-101.07426
900.55806,-20.04383,-253.55317
901.19200,-25.43248,-384.60650
901.70406,-22.09987,-266.91152
902.49606,-14.33340,-113.65247
903.69606,-4.13128,-8.64148
904.78606,-4.52852,-14.13960
905.94606,-14.94289,-151.52323
906.81006,-22.28725,-304.36145
907.41600,-25.14818,-368.84662
907.86806,-19.97950,-215.51376
908.88406,-10.93161,-70.01890
910.08406,-0.73099,-0.00719
911.17406,-8.46583,-55.39023
912.25006,-17.62977,-202.68520
913.03800,-24.32745,-354.86333
913.53206,-23.81159,-317.62414
914.10806,-17.46678,-164.29119
915.27206,-7.53103,-35.43284
916.36206,0.02708,-0.01914
917.56206,-11.88280,-101.02690
918.52000,-20.02679,-253.11910
919.15606,-25.43254,-384.50308
919.67006,-22.07512,-266.26050
920.46000,-14.33346,-113.65063
921.66006,-4.13128,-8.51464
922.75006,-4.52959,-14.14839
923.91006,-14.94295,-151.44047
924.77406,-22.28732,-304.31075
925.38006,-25.14968,-368.82989
925.83406,-19.95445,-214.90909
926.85006,-10.91457,-69.81924
928.05006,-0.71383,-0.03108
929.13806,-8.46661,-55.30939
930.21206,-17.61279,-202.26672
931.00200,-24.32751,-354.76055
931.49606,-23.81189,-317.63963
932.07200,-17.46702,-164.27545
933.23600,-7.53097,-35.44118
934.32606,0.02750,-0.04530
935.52606,-11.88280,-100.94536
936.48406,-20.02679,-252.98366
937.12006,-25.43248,-384.37311
937.63406,-22.07590,-266.13213
938.42600,-14.31612,-113.32541
939.62606,-4.11424,-8.44556
940.71406,-4.53013,-14.12335
941.87400,-14.94283,-151.36261
942.73806,-22.28732,-304.18692
943.34206,-25.16731,-369.44356
943.79406,-20.00186,-215.86047
944.81006,-10.94865,-70.13085
946.01006,-0.74827,0.04659
947.10206,-8.46613,-55.26991
948.17406,-17.59563,-201.85618
948.96606,-24.32751,-354.62201
949.46000,-23.81165,-317.50217
950.03606,-17.46738,-164.19558
951.20006,-7.53103,-35.34998
952.29006,0.02673,-0.06301
953.49006,-11.88280,-100.84730
954.44806,-20.02685,-252.89454
955.08406,-25.43254,-384.29052
955.59800,-22.07542,-266.05720
956.38806,-14.33340,-113.53143
957.58806,-4.13128,-8.54487
958.67806,-4.52941,-14.05310
959.83806,-14.94307,-151.20986
960.70406,-22.30417,-304.33638
961.30806,-25.14890,-368.53582
961.76006,-19.97693,-215.27469
962.77606,-10.93161,-69.88819
963.97606,-0.73099,0.01337
965.06606,-8.46595,-55.25355
966.14006,-17.61279,-202.01242
966.93006,-24.32739,-354.42024
967.42406,-23.81308,-317.40092
968.00006,-17.46720,-164.09200
969.16406,-7.53109,-35.37031
970.25400,0.02619,0.03553
971.45406,-11.88286,-100.71777
972.41206,-20.02685,-252.70594
973.04806,-25.43260,-384.15156
973.56206,-22.07315,-265.95164
974.35006,-14.35032,-113.72386
975.55006,-4.14843,-8.66924
976.64200,-4.52834,-14.05331
977.80206,-14.94295,-151.14530
978.66606,-22.28725,-303.91095
979.27206,-25.14920,-368.40927
979.72406,-19.97502,-215.15368
980.73806,-10.94871,-70.01997
981.93806,-0.74827,0.03259
983.03000,-8.46661,-55.20818
984.10206,-17.59569,-201.63981
984.89200,-24.31023,-353.90984
985.38806,-23.81308,-317.36352
985.96606,-17.44969,-163.71313
987.13006,-7.51410,-35.15746
988.21800,0.02607,-0.00073
989.41800,-11.88280,-100.74033
990.37400,-20.00993,-252.32615
991.01200,-25.43248,-383.99305
991.52606,-22.07602,-265.89394
992.31606,-14.33346,-113.47011
993.51606,-4.13134,-8.53337
994.60600,-4.53246,-14.03791
995.76606,-14.94295,-151.07321
996.63006,-22.28725,-303.74628
997.23600,-25.15063,-368.30101
997.68806,-19.97543,-215.08919
998.70406,-10.93161,-69.85226
999.90406,-0.73105,0.00454
1000.99400,-8.46631,-55.10400
1002.06806,-17.61285,-201.85241
1002.86006,-24.34449,-354.66228
1003.35206,-23.81200,-317.20705
1003.92806,-17.46565,-163.99989
1005.09206,-7.53109,-35.29250
1006.18206,0.02643,0.02269
1007.38200,-11.88280,-100.64381
1008.34206,-20.04383,-252.88846
1008.97606,-25.43254,-383.89612
1009.49006,-22.07422,-265.79821
1010.28000,-14.33334,-113.39771
1011.48006,-4.13134,-8.48802
1012.57006,-4.53025,-14.00365
1013.73006,-14.94301,-150.97080
1014.59406,-22.28732,-303.61217
1015.20006,-25.15093,-368.23466
1015.65406,-19.95044,-214.50063
1016.67006,-10.91457,-69.62560
1017.87006,-0.71383,0.02535
1018.95806,-8.46589,-55.06485
1020.03206,-17.61285,-201.72054
1020.82406,-24.34449,-354.55730
1021.31606,-23.81248,-317.12484
1021.89200,-17.46517,-163.91823
1023.05600,-7.53109,-35.25594
1024.14600,0.02625,0.00264
1025.34606,-11.88280,-100.55876
1026.30600,-20.04371,-252.78762
1026.94006,-25.43260,-383.76007
1027.45800,-22.04152,-264.79762
1028.25613,-14.23080,-111.91328
1029.45606,-4.02951,-7.84096
1030.53406,-4.52911,-13.97305
1031.69406,-14.94289,-150.89010
1032.55812,-22.28725,-303.63545
1033.16406,-25.15015,-368.13766
1033.61806,-19.95403,-214.52056
1034.63406,-10.91457,-69.61905
1035.83413,-0.71383,0.06574
1036.92200,-8.46703,-55.04305
1037.99806,-17.62977,-201.98308
1038.78806,-24.34455,-354.46841
1039.28000,-23.81356,-317.10956
1039.85606,-17.46726,-163.86239
1041.02000,-7.53109,-35.21265
1042.11012,0.02708,-0.02622
1043.31006,-11.88286,-100.48293
1044.27212,-20.06087,-253.08270
1044.90406,-25.43254,-383.63412
1045.41806,-22.08194,-265.82774
1046.21006,-14.31618,-113.08282
1047.41006,-4.11424,-8.34724
1048.49806,-4.52774,-13.93908
1049.65812,-14.94307,-150.82331
1050.52000,-22.27033,-303.01539
1051.12800,-25.15039,-368.06256
1051.58012,-19.98028,-214.99202
1052.59612,-10.93161,-69.73929
1053.79600,-0.73105,0.02314
1054.88612,-8.46697,-54.98820
1055.96200,-17.62983,-201.81455
1056.75000,-24.32751,-353.89941
1057.24400,-23.81374,-317.00689
1057.82012,-17.46720,-163.81260
1058.98400,-7.53109,-35.17967
1060.07413,0.02708,-0.03925
1061.27400,-11.88280,-100.45013
1062.23400,-20.04389,-252.62900
1062.86800,-25.43254,-383.57314
1063.38213,-22.07620,-265.64501
1064.17200,-14.33346,-113.26077
1065.37213,-4.13139,-8.42246
1066.46200,-4.53085,-13.96669
1067.62400,-14.95987,-151.06115
1068.48800,-22.30424,-303.75469
1069.09200,-25.15081,-367.97658
1069.54413,-19.97615,-214.84343
1070.55812,-10.94871,-69.85961
1071.75800,-0.74833,-0.00402
1072.85012,-8.46673,-54.94030
1073.92412,-17.61279,-201.49304
1074.71412,-24.32745,-353.82591
1075.20800,-23.81601,-317.04150
1075.78600,-17.44969,-163.42932
1076.95012,-7.51416,-35.00453
1078.03812,0.02744,0.03246
1079.23800,-11.88286,-100.39597
1080.20200,-20.07773,-253.22579
1080.83200,-25.43254,-383.46786
1081.34612,-22.07745,-265.59010
1082.13612,-14.33352,-113.19478
1083.33600,-4.13134,-8.43587
1084.42600,-4.52947,-13.91042
1085.58800,-14.95999,-151.01940
1086.45200,-22.30424,-303.61300
1087.05600,-25.15087,-367.93906
1087.50800,-19.97430,-214.80327
1088.52212,-10.94871,-69.83491
1089.72200,-0.74833,0.01545
1090.81413,-8.46667,-54.89663
1091.88800,-17.61285,-201.36775
1092.67812,-24.32757,-353.71546
1093.17200,-23.81488,-316.93924
1093.74800,-17.46744,-163.72975
1094.91212,-7.53115,-35.11099
1096.00212,0.02720,-0.00495
1097.20200,-11.88286,-100.34810
1098.16000,-20.02691,-252.04824
1098.79600,-25.43260,-383.34344
1099.31000,-22.07638,-265.45497
1100.10012,-14.33352,-113.13873
1101.30000,-4.13139,-8.39267
1102.39000,-4.53228,-13.92836
1103.55000,-14.94301,-150.60737
1104.41400,-22.28732,-303.08452
1105.02000,-25.15117,-367.73600
1105.47200,-19.97531,-214.72529
1106.48800,-10.93161,-69.62812
1107.68813,-0.73105,0.03743
1108.77812,-8.46691,-54.85593
1109.85400,-17.62977,-201.59019
1110.64400,-24.34461,-354.03006
1111.13612,-23.81296,-316.78081
1111.71012,-17.48299,-163.92764
1112.87400,-7.54807,-35.23314
1113.96612,0.02816,-0.01256
1115.16600,-11.88292,-100.27622
1116.12612,-20.04341,-252.27176
1116.76000,-25.43272,-383.25846
1117.27600,-22.03775,-264.42075
1118.06800,-14.29896,-112.66621
1119.26812,-4.09731,-8.15395
1120.35400,-4.53145,-13.87009
1121.51400,-14.94301,-150.52197
1122.38000,-22.30430,-303.43024
1122.98400,-25.15153,-367.72985
1123.44013,-19.92820,-213.57689
1124.45600,-10.89765,-69.18696
1125.65600,-0.69691,0.03750
1126.74212,-8.46673,-54.81001
1127.82200,-17.66373,-202.20619
1128.61200,-24.37839,-354.74081
1129.10012,-23.81356,-316.60561
1129.67813,-17.44723,-163.24580
1130.84200,-7.51416,-34.87252
1131.93000,0.02810,0.01501
1133.13000,-11.88292,-100.22881
1134.09012,-20.04389,-252.18554
1134.72400,-25.43260,-383.06247
1135.24012,-22.05037,-264.61929
1136.03212,-14.29884,-112.59564
1137.23200,-4.09737,-8.19144
1138.31800,-4.53091,-13.83886
1139.47800,-14.94295,-150.41455
1140.34400,-22.30424,-303.27378
1140.94800,-25.15428,-367.74073
1141.40000,-19.97986,-214.64534
1142.41600,-10.93167,-69.54140
1143.61612,-0.73111,0.01582
1144.70600,-8.46619,-54.73303
1145.78212,-17.62983,-201.42348
1146.57200,-24.34449,-353.78214
1147.06600,-23.79323,-315.83052
1147.64812,-17.39623,-162.26595
1148.81200,-7.46364,-34.40771
1149.89400,0.02816,0.00064
1151.09400,-11.88292,-100.11970
1152.05600,-20.06087,-252.41677
1152.68813,-25.43260,-383.00935
1153.20200,-22.07751,-265.28517
1153.99400,-14.31618,-112.79729
1155.19412,-4.11424,-8.23034
1156.28212,-4.53234,-13.85772
1157.44412,-14.96005,-150.65885
1158.30812,-22.30435,-303.21555
1158.91212,-25.15177,-367.51769
1159.36400,-19.97400,-214.52460
1160.38000,-10.93167,-69.49695
1161.58012,-0.73111,-0.00155
1162.67000,-8.46679,-54.71474
1163.75000,-17.66379,-202.00966
1164.53812,-24.36147,-354.13392
1165.02812,-23.81763,-316.61350
1165.60612,-17.44861,-163.21426
1166.77000,-7.51422,-34.82075
1167.85800,0.02828,0.00310
1169.05812,-11.88292,-100.09988
1170.02000,-20.06093,-252.39177
1170.65212,-25.43260,-382.88027
1171.16600,-22.07990,-265.31706
1171.95600,-14.33352,-112.93030
1173.15600,-4.13139,-8.34224
1174.24613,-4.52858,-13.80720
1175.40812,-14.95999,-150.57876
1176.27000,-22.28725,-302.70783
1176.87612,-25.15225,-367.47053
1177.33012,-19.95212,-213.98490
1178.34612,-10.91463,-69.31883
1179.54600,-0.71401,0.04523
1180.63400,-8.46697,-54.65903
1181.71012,-17.62989,-201.29930
1182.50000,-24.34461,-353.59029
1182.99400,-23.79329,-315.75166
1183.57800,-17.37895,-161.87670
1184.74400,-7.42908,-34.05379
1185.82200,0.02930,0.00073
1187.02212,-11.88292,-100.05328
1187.98400,-20.06093,-252.29553
1188.61612,-25.43260,-382.84212
1189.13000,-22.07488,-265.12023
1189.92000,-14.33346,-112.94924
1191.12012,-4.13139,-8.30979
1192.21012,-4.53216,-13.80384
1193.37213,-14.96005,-150.53689
1194.23800,-22.32133,-303.42041
1194.84012,-25.15320,-367.44617
1195.29413,-19.95056,-213.90362
1196.31000,-10.91463,-69.22372
1197.51000,-0.71395,-0.01579
1198.50000,0.01746,0.02139
1199.70012,0.01656,0.06626
1200.90000,0.01656,0.04889
1202.10012,0.01656,0.06775
1203.30000,0.01656,0.02572
1204.50000,0.01656,0.06360
1205.70012,0.01656,0.07991
1206.90000,0.01656,0.05797
1208.10012,0.01656,0.02181
1209.30000,0.01656,0.02726
1210.50000,0.01656,0.03654
1211.70012,0.01656,0.05433
1212.90000,0.01656,0.04530
1214.10012,0.01656,0.03090
1215.30000,0.01656,0.04429
1216.50000,0.01656,0.09521
1217.70012,0.01656,0.06267
1218.90000,0.01656,0.03845
1220.10012,0.01656,0.07892
1221.30000,0.01656,0.04109
1222.50000,0.01656,0.06658
1223.70012,0.01656,0.06130
1224.90000,0.01656,0.07323
1226.10012,0.01656,0.13113
1227.30000,0.01656,0.08483
1228.50000,0.01656,0.08760
1229.70012,0.01656,0.09630
1230.90000,0.01656,0.05875
1232.10012,0.01656,0.04388
1233.30000,0.01656,0.09699
1234.50000,0.01656,0.06980
1235.70012,0.01656,0.10423
1236.90000,0.01656,0.11092
1238.10012,0.01656,0.07172
1239.30000,0.01656,0.08271
1240.50000,0.01656,0.06811
1241.46800,0.01656,0.11239